/*
*** MADE BY MITHION'S .SCHEMATIC TO JAVA CONVERTING TOOL v1.6 ***
*/

package spaceage.planets.technoorganic;

import java.util.Random;

import spaceage.common.SpaceAgeCore;

import net.minecraft.block.Block;
import net.minecraft.world.World;
import net.minecraft.world.gen.feature.WorldGenerator;

public class WorldGen0011Tree extends WorldGenerator {
	
	public WorldGen0011Tree(boolean par1) {
		
	}

	public boolean generate(World world, Random rand, int i, int j, int k) {
		world.setBlock(i + 0, j + 24, k + 10, SpaceAgeCore.T0011Surface.blockID, 1, 2);
		world.setBlock(i + 0, j + 24, k + 11, SpaceAgeCore.T0011Surface.blockID, 1, 2);
		world.setBlock(i + 0, j + 24, k + 12, SpaceAgeCore.T0011Surface.blockID, 1, 2);
		world.setBlock(i + 0, j + 24, k + 13, SpaceAgeCore.T0011Surface.blockID, 1, 2);
		world.setBlock(i + 0, j + 24, k + 14, SpaceAgeCore.T0011Surface.blockID, 1, 2);
		world.setBlock(i + 0, j + 24, k + 15, SpaceAgeCore.T0011Surface.blockID, 1, 2);
		world.setBlock(i + 0, j + 24, k + 16, SpaceAgeCore.T0011Surface.blockID, 1, 2);
		world.setBlock(i + 1, j + 24, k + 7, SpaceAgeCore.T0011Surface.blockID, 1, 2);
		world.setBlock(i + 1, j + 24, k + 8, SpaceAgeCore.T0011Surface.blockID, 1, 2);
		world.setBlock(i + 1, j + 24, k + 9, SpaceAgeCore.T0011Surface.blockID, 1, 2);
		world.setBlock(i + 1, j + 24, k + 10, SpaceAgeCore.T0011Surface.blockID, 1, 2);
		world.setBlock(i + 1, j + 24, k + 11, SpaceAgeCore.T0011Surface.blockID, 1, 2);
		world.setBlock(i + 1, j + 24, k + 12, SpaceAgeCore.T0011Surface.blockID, 1, 2);
		world.setBlock(i + 1, j + 24, k + 13, SpaceAgeCore.T0011Surface.blockID, 1, 2);
		world.setBlock(i + 1, j + 24, k + 14, SpaceAgeCore.T0011Surface.blockID, 1, 2);
		world.setBlock(i + 1, j + 24, k + 15, SpaceAgeCore.T0011Surface.blockID, 1, 2);
		world.setBlock(i + 1, j + 24, k + 16, SpaceAgeCore.T0011Surface.blockID, 1, 2);
		world.setBlock(i + 1, j + 24, k + 17, SpaceAgeCore.T0011Surface.blockID, 1, 2);
		world.setBlock(i + 1, j + 24, k + 18, SpaceAgeCore.T0011Surface.blockID, 1, 2);
		world.setBlock(i + 1, j + 24, k + 19, SpaceAgeCore.T0011Surface.blockID, 1, 2);
		world.setBlock(i + 1, j + 25, k + 10, SpaceAgeCore.T0011Surface.blockID, 1, 2);
		world.setBlock(i + 1, j + 25, k + 11, SpaceAgeCore.T0011Surface.blockID, 1, 2);
		world.setBlock(i + 1, j + 25, k + 12, SpaceAgeCore.T0011Surface.blockID, 1, 2);
		world.setBlock(i + 1, j + 25, k + 13, SpaceAgeCore.T0011Surface.blockID, 1, 2);
		world.setBlock(i + 1, j + 25, k + 14, SpaceAgeCore.T0011Surface.blockID, 1, 2);
		world.setBlock(i + 1, j + 25, k + 15, SpaceAgeCore.T0011Surface.blockID, 1, 2);
		world.setBlock(i + 1, j + 25, k + 16, SpaceAgeCore.T0011Surface.blockID, 1, 2);
		world.setBlock(i + 2, j + 24, k + 6, SpaceAgeCore.T0011Surface.blockID, 1, 2);
		world.setBlock(i + 2, j + 24, k + 7, SpaceAgeCore.T0011Surface.blockID, 1, 2);
		world.setBlock(i + 2, j + 24, k + 8, SpaceAgeCore.T0011Surface.blockID, 1, 2);
		world.setBlock(i + 2, j + 24, k + 9, SpaceAgeCore.T0011Surface.blockID, 1, 2);
		world.setBlock(i + 2, j + 24, k + 10, SpaceAgeCore.T0011Surface.blockID, 1, 2);
		world.setBlock(i + 2, j + 24, k + 11, SpaceAgeCore.T0011Surface.blockID, 1, 2);
		world.setBlock(i + 2, j + 24, k + 12, SpaceAgeCore.T0011Surface.blockID, 1, 2);
		world.setBlock(i + 2, j + 24, k + 13, SpaceAgeCore.T0011Surface.blockID, 1, 2);
		world.setBlock(i + 2, j + 24, k + 14, SpaceAgeCore.T0011Surface.blockID, 1, 2);
		world.setBlock(i + 2, j + 24, k + 15, SpaceAgeCore.T0011Surface.blockID, 1, 2);
		world.setBlock(i + 2, j + 24, k + 16, SpaceAgeCore.T0011Surface.blockID, 1, 2);
		world.setBlock(i + 2, j + 24, k + 17, SpaceAgeCore.T0011Surface.blockID, 1, 2);
		world.setBlock(i + 2, j + 24, k + 18, SpaceAgeCore.T0011Surface.blockID, 1, 2);
		world.setBlock(i + 2, j + 24, k + 19, SpaceAgeCore.T0011Surface.blockID, 1, 2);
		world.setBlock(i + 2, j + 24, k + 20, SpaceAgeCore.T0011Surface.blockID, 1, 2);
		world.setBlock(i + 2, j + 25, k + 8, SpaceAgeCore.T0011Surface.blockID, 1, 2);
		world.setBlock(i + 2, j + 25, k + 9, SpaceAgeCore.T0011Surface.blockID, 1, 2);
		world.setBlock(i + 2, j + 25, k + 10, SpaceAgeCore.T0011Surface.blockID, 1, 2);
		world.setBlock(i + 2, j + 25, k + 11, SpaceAgeCore.T0011Surface.blockID, 1, 2);
		world.setBlock(i + 2, j + 25, k + 12, SpaceAgeCore.T0011Surface.blockID, 1, 2);
		world.setBlock(i + 2, j + 25, k + 13, SpaceAgeCore.T0011Surface.blockID, 1, 2);
		world.setBlock(i + 2, j + 25, k + 14, SpaceAgeCore.T0011Surface.blockID, 1, 2);
		world.setBlock(i + 2, j + 25, k + 15, SpaceAgeCore.T0011Surface.blockID, 1, 2);
		world.setBlock(i + 2, j + 25, k + 16, SpaceAgeCore.T0011Surface.blockID, 1, 2);
		world.setBlock(i + 2, j + 25, k + 17, SpaceAgeCore.T0011Surface.blockID, 1, 2);
		world.setBlock(i + 2, j + 25, k + 18, SpaceAgeCore.T0011Surface.blockID, 1, 2);
		world.setBlock(i + 2, j + 26, k + 11, SpaceAgeCore.T0011Surface.blockID, 1, 2);
		world.setBlock(i + 2, j + 26, k + 12, SpaceAgeCore.T0011Surface.blockID, 1, 2);
		world.setBlock(i + 2, j + 26, k + 13, SpaceAgeCore.T0011Surface.blockID, 1, 2);
		world.setBlock(i + 2, j + 26, k + 14, SpaceAgeCore.T0011Surface.blockID, 1, 2);
		world.setBlock(i + 2, j + 26, k + 15, SpaceAgeCore.T0011Surface.blockID, 1, 2);
		world.setBlock(i + 3, j + 24, k + 4, SpaceAgeCore.T0011Surface.blockID, 1, 2);
		world.setBlock(i + 3, j + 24, k + 5, SpaceAgeCore.T0011Surface.blockID, 1, 2);
		world.setBlock(i + 3, j + 24, k + 6, SpaceAgeCore.T0011Surface.blockID, 1, 2);
		world.setBlock(i + 3, j + 24, k + 7, SpaceAgeCore.T0011Surface.blockID, 1, 2);
		world.setBlock(i + 3, j + 24, k + 8, SpaceAgeCore.T0011Surface.blockID, 1, 2);
		world.setBlock(i + 3, j + 24, k + 9, SpaceAgeCore.T0011Surface.blockID, 1, 2);
		world.setBlock(i + 3, j + 24, k + 10, SpaceAgeCore.T0011Surface.blockID, 1, 2);
		world.setBlock(i + 3, j + 24, k + 11, SpaceAgeCore.T0011Surface.blockID, 1, 2);
		world.setBlock(i + 3, j + 24, k + 12, SpaceAgeCore.T0011Surface.blockID, 1, 2);
		world.setBlock(i + 3, j + 24, k + 13, SpaceAgeCore.T0011Surface.blockID, 1, 2);
		world.setBlock(i + 3, j + 24, k + 14, SpaceAgeCore.T0011Surface.blockID, 1, 2);
		world.setBlock(i + 3, j + 24, k + 15, SpaceAgeCore.T0011Surface.blockID, 1, 2);
		world.setBlock(i + 3, j + 24, k + 16, SpaceAgeCore.T0011Surface.blockID, 1, 2);
		world.setBlock(i + 3, j + 24, k + 17, SpaceAgeCore.T0011Surface.blockID, 1, 2);
		world.setBlock(i + 3, j + 24, k + 18, SpaceAgeCore.T0011Surface.blockID, 1, 2);
		world.setBlock(i + 3, j + 24, k + 19, SpaceAgeCore.T0011Surface.blockID, 1, 2);
		world.setBlock(i + 3, j + 24, k + 20, SpaceAgeCore.T0011Surface.blockID, 1, 2);
		world.setBlock(i + 3, j + 24, k + 21, SpaceAgeCore.T0011Surface.blockID, 1, 2);
		world.setBlock(i + 3, j + 24, k + 22, SpaceAgeCore.T0011Surface.blockID, 1, 2);
		world.setBlock(i + 3, j + 25, k + 6, SpaceAgeCore.T0011Surface.blockID, 1, 2);
		world.setBlock(i + 3, j + 25, k + 7, SpaceAgeCore.T0011Surface.blockID, 1, 2);
		world.setBlock(i + 3, j + 25, k + 8, SpaceAgeCore.T0011Surface.blockID, 1, 2);
		world.setBlock(i + 3, j + 25, k + 9, SpaceAgeCore.T0011Surface.blockID, 1, 2);
		world.setBlock(i + 3, j + 25, k + 10, SpaceAgeCore.T0011Surface.blockID, 1, 2);
		world.setBlock(i + 3, j + 25, k + 11, SpaceAgeCore.T0011Surface.blockID, 1, 2);
		world.setBlock(i + 3, j + 25, k + 12, SpaceAgeCore.T0011Surface.blockID, 1, 2);
		world.setBlock(i + 3, j + 25, k + 13, SpaceAgeCore.T0011Surface.blockID, 1, 2);
		world.setBlock(i + 3, j + 25, k + 14, SpaceAgeCore.T0011Surface.blockID, 1, 2);
		world.setBlock(i + 3, j + 25, k + 15, SpaceAgeCore.T0011Surface.blockID, 1, 2);
		world.setBlock(i + 3, j + 25, k + 16, SpaceAgeCore.T0011Surface.blockID, 1, 2);
		world.setBlock(i + 3, j + 25, k + 17, SpaceAgeCore.T0011Surface.blockID, 1, 2);
		world.setBlock(i + 3, j + 25, k + 18, SpaceAgeCore.T0011Surface.blockID, 1, 2);
		world.setBlock(i + 3, j + 25, k + 19, SpaceAgeCore.T0011Surface.blockID, 1, 2);
		world.setBlock(i + 3, j + 25, k + 20, SpaceAgeCore.T0011Surface.blockID, 1, 2);
		world.setBlock(i + 3, j + 26, k + 8, SpaceAgeCore.T0011Surface.blockID, 1, 2);
		world.setBlock(i + 3, j + 26, k + 9, SpaceAgeCore.T0011Surface.blockID, 1, 2);
		world.setBlock(i + 3, j + 26, k + 10, SpaceAgeCore.T0011Surface.blockID, 1, 2);
		world.setBlock(i + 3, j + 26, k + 11, SpaceAgeCore.T0011Surface.blockID, 1, 2);
		world.setBlock(i + 3, j + 26, k + 12, SpaceAgeCore.T0011Surface.blockID, 1, 2);
		world.setBlock(i + 3, j + 26, k + 13, SpaceAgeCore.T0011Surface.blockID, 1, 2);
		world.setBlock(i + 3, j + 26, k + 14, SpaceAgeCore.T0011Surface.blockID, 1, 2);
		world.setBlock(i + 3, j + 26, k + 15, SpaceAgeCore.T0011Surface.blockID, 1, 2);
		world.setBlock(i + 3, j + 26, k + 16, SpaceAgeCore.T0011Surface.blockID, 1, 2);
		world.setBlock(i + 3, j + 26, k + 17, SpaceAgeCore.T0011Surface.blockID, 1, 2);
		world.setBlock(i + 3, j + 26, k + 18, SpaceAgeCore.T0011Surface.blockID, 1, 2);
		world.setBlock(i + 3, j + 27, k + 11, SpaceAgeCore.T0011Surface.blockID, 1, 2);
		world.setBlock(i + 3, j + 27, k + 12, SpaceAgeCore.T0011Surface.blockID, 1, 2);
		world.setBlock(i + 3, j + 27, k + 13, SpaceAgeCore.T0011Surface.blockID, 1, 2);
		world.setBlock(i + 3, j + 27, k + 14, SpaceAgeCore.T0011Surface.blockID, 1, 2);
		world.setBlock(i + 3, j + 27, k + 15, SpaceAgeCore.T0011Surface.blockID, 1, 2);
		world.setBlock(i + 4, j + 24, k + 3, SpaceAgeCore.T0011Surface.blockID, 1, 2);
		world.setBlock(i + 4, j + 24, k + 4, SpaceAgeCore.T0011Surface.blockID, 1, 2);
		world.setBlock(i + 4, j + 24, k + 5, SpaceAgeCore.T0011Surface.blockID, 1, 2);
		world.setBlock(i + 4, j + 24, k + 6, SpaceAgeCore.T0011Surface.blockID, 1, 2);
		world.setBlock(i + 4, j + 24, k + 7, SpaceAgeCore.T0011Surface.blockID, 1, 2);
		world.setBlock(i + 4, j + 24, k + 8, SpaceAgeCore.T0011Surface.blockID, 1, 2);
		world.setBlock(i + 4, j + 24, k + 9, SpaceAgeCore.T0011Surface.blockID, 1, 2);
		world.setBlock(i + 4, j + 24, k + 10, SpaceAgeCore.T0011Surface.blockID, 1, 2);
		world.setBlock(i + 4, j + 24, k + 11, SpaceAgeCore.T0011Surface.blockID, 1, 2);
		world.setBlock(i + 4, j + 24, k + 12, SpaceAgeCore.T0011Surface.blockID, 1, 2);
		world.setBlock(i + 4, j + 24, k + 13, SpaceAgeCore.T0011Surface.blockID, 1, 2);
		world.setBlock(i + 4, j + 24, k + 14, SpaceAgeCore.T0011Surface.blockID, 1, 2);
		world.setBlock(i + 4, j + 24, k + 15, SpaceAgeCore.T0011Surface.blockID, 1, 2);
		world.setBlock(i + 4, j + 24, k + 16, SpaceAgeCore.T0011Surface.blockID, 1, 2);
		world.setBlock(i + 4, j + 24, k + 17, SpaceAgeCore.T0011Surface.blockID, 1, 2);
		world.setBlock(i + 4, j + 24, k + 18, SpaceAgeCore.T0011Surface.blockID, 1, 2);
		world.setBlock(i + 4, j + 24, k + 19, SpaceAgeCore.T0011Surface.blockID, 1, 2);
		world.setBlock(i + 4, j + 24, k + 20, SpaceAgeCore.T0011Surface.blockID, 1, 2);
		world.setBlock(i + 4, j + 24, k + 21, SpaceAgeCore.T0011Surface.blockID, 1, 2);
		world.setBlock(i + 4, j + 24, k + 22, SpaceAgeCore.T0011Surface.blockID, 1, 2);
		world.setBlock(i + 4, j + 24, k + 23, SpaceAgeCore.T0011Surface.blockID, 1, 2);
		world.setBlock(i + 4, j + 25, k + 5, SpaceAgeCore.T0011Surface.blockID, 1, 2);
		world.setBlock(i + 4, j + 25, k + 6, SpaceAgeCore.T0011Surface.blockID, 1, 2);
		world.setBlock(i + 4, j + 25, k + 7, SpaceAgeCore.T0011Surface.blockID, 1, 2);
		world.setBlock(i + 4, j + 25, k + 8, SpaceAgeCore.T0011Surface.blockID, 1, 2);
		world.setBlock(i + 4, j + 25, k + 9, SpaceAgeCore.T0011Surface.blockID, 1, 2);
		world.setBlock(i + 4, j + 25, k + 10, SpaceAgeCore.T0011Surface.blockID, 1, 2);
		world.setBlock(i + 4, j + 25, k + 11, SpaceAgeCore.T0011Surface.blockID, 1, 2);
		world.setBlock(i + 4, j + 25, k + 12, SpaceAgeCore.T0011Surface.blockID, 1, 2);
		world.setBlock(i + 4, j + 25, k + 13, SpaceAgeCore.T0011Surface.blockID, 1, 2);
		world.setBlock(i + 4, j + 25, k + 14, SpaceAgeCore.T0011Surface.blockID, 1, 2);
		world.setBlock(i + 4, j + 25, k + 15, SpaceAgeCore.T0011Surface.blockID, 1, 2);
		world.setBlock(i + 4, j + 25, k + 16, SpaceAgeCore.T0011Surface.blockID, 1, 2);
		world.setBlock(i + 4, j + 25, k + 17, SpaceAgeCore.T0011Surface.blockID, 1, 2);
		world.setBlock(i + 4, j + 25, k + 18, SpaceAgeCore.T0011Surface.blockID, 1, 2);
		world.setBlock(i + 4, j + 25, k + 19, SpaceAgeCore.T0011Surface.blockID, 1, 2);
		world.setBlock(i + 4, j + 25, k + 20, SpaceAgeCore.T0011Surface.blockID, 1, 2);
		world.setBlock(i + 4, j + 25, k + 21, SpaceAgeCore.T0011Surface.blockID, 1, 2);
		world.setBlock(i + 4, j + 26, k + 7, SpaceAgeCore.T0011Surface.blockID, 1, 2);
		world.setBlock(i + 4, j + 26, k + 8, SpaceAgeCore.T0011Surface.blockID, 1, 2);
		world.setBlock(i + 4, j + 26, k + 9, SpaceAgeCore.T0011Surface.blockID, 1, 2);
		world.setBlock(i + 4, j + 26, k + 10, SpaceAgeCore.T0011Surface.blockID, 1, 2);
		world.setBlock(i + 4, j + 26, k + 11, SpaceAgeCore.T0011Surface.blockID, 1, 2);
		world.setBlock(i + 4, j + 26, k + 12, SpaceAgeCore.T0011Surface.blockID, 1, 2);
		world.setBlock(i + 4, j + 26, k + 13, SpaceAgeCore.T0011Surface.blockID, 1, 2);
		world.setBlock(i + 4, j + 26, k + 14, SpaceAgeCore.T0011Surface.blockID, 1, 2);
		world.setBlock(i + 4, j + 26, k + 15, SpaceAgeCore.T0011Surface.blockID, 1, 2);
		world.setBlock(i + 4, j + 26, k + 16, SpaceAgeCore.T0011Surface.blockID, 1, 2);
		world.setBlock(i + 4, j + 26, k + 17, SpaceAgeCore.T0011Surface.blockID, 1, 2);
		world.setBlock(i + 4, j + 26, k + 18, SpaceAgeCore.T0011Surface.blockID, 1, 2);
		world.setBlock(i + 4, j + 26, k + 19, SpaceAgeCore.T0011Surface.blockID, 1, 2);
		world.setBlock(i + 4, j + 27, k + 8, SpaceAgeCore.T0011Surface.blockID, 1, 2);
		world.setBlock(i + 4, j + 27, k + 9, SpaceAgeCore.T0011Surface.blockID, 1, 2);
		world.setBlock(i + 4, j + 27, k + 10, SpaceAgeCore.T0011Surface.blockID, 1, 2);
		world.setBlock(i + 4, j + 27, k + 11, SpaceAgeCore.T0011Surface.blockID, 1, 2);
		world.setBlock(i + 4, j + 27, k + 12, SpaceAgeCore.T0011Surface.blockID, 1, 2);
		world.setBlock(i + 4, j + 27, k + 13, SpaceAgeCore.T0011Surface.blockID, 1, 2);
		world.setBlock(i + 4, j + 27, k + 14, SpaceAgeCore.T0011Surface.blockID, 1, 2);
		world.setBlock(i + 4, j + 27, k + 15, SpaceAgeCore.T0011Surface.blockID, 1, 2);
		world.setBlock(i + 4, j + 27, k + 16, SpaceAgeCore.T0011Surface.blockID, 1, 2);
		world.setBlock(i + 4, j + 27, k + 17, SpaceAgeCore.T0011Surface.blockID, 1, 2);
		world.setBlock(i + 4, j + 27, k + 18, SpaceAgeCore.T0011Surface.blockID, 1, 2);
		world.setBlock(i + 5, j + 24, k + 3, SpaceAgeCore.T0011Surface.blockID, 1, 2);
		world.setBlock(i + 5, j + 24, k + 4, SpaceAgeCore.T0011Surface.blockID, 1, 2);
		world.setBlock(i + 5, j + 24, k + 5, SpaceAgeCore.T0011Surface.blockID, 1, 2);
		world.setBlock(i + 5, j + 24, k + 6, SpaceAgeCore.T0011Surface.blockID, 1, 2);
		world.setBlock(i + 5, j + 24, k + 7, SpaceAgeCore.T0011Surface.blockID, 1, 2);
		world.setBlock(i + 5, j + 24, k + 8, SpaceAgeCore.T0011Surface.blockID, 1, 2);
		world.setBlock(i + 5, j + 24, k + 9, SpaceAgeCore.T0011Surface.blockID, 1, 2);
		world.setBlock(i + 5, j + 24, k + 10, SpaceAgeCore.T0011Surface.blockID, 1, 2);
		world.setBlock(i + 5, j + 24, k + 11, SpaceAgeCore.T0011Surface.blockID, 1, 2);
		world.setBlock(i + 5, j + 24, k + 12, SpaceAgeCore.T0011Surface.blockID, 1, 2);
		world.setBlock(i + 5, j + 24, k + 13, SpaceAgeCore.T0011Surface.blockID, 1, 2);
		world.setBlock(i + 5, j + 24, k + 14, SpaceAgeCore.T0011Surface.blockID, 1, 2);
		world.setBlock(i + 5, j + 24, k + 15, SpaceAgeCore.T0011Surface.blockID, 1, 2);
		world.setBlock(i + 5, j + 24, k + 16, SpaceAgeCore.T0011Surface.blockID, 1, 2);
		world.setBlock(i + 5, j + 24, k + 17, SpaceAgeCore.T0011Surface.blockID, 1, 2);
		world.setBlock(i + 5, j + 24, k + 18, SpaceAgeCore.T0011Surface.blockID, 1, 2);
		world.setBlock(i + 5, j + 24, k + 19, SpaceAgeCore.T0011Surface.blockID, 1, 2);
		world.setBlock(i + 5, j + 24, k + 20, SpaceAgeCore.T0011Surface.blockID, 1, 2);
		world.setBlock(i + 5, j + 24, k + 21, SpaceAgeCore.T0011Surface.blockID, 1, 2);
		world.setBlock(i + 5, j + 24, k + 22, SpaceAgeCore.T0011Surface.blockID, 1, 2);
		world.setBlock(i + 5, j + 24, k + 23, SpaceAgeCore.T0011Surface.blockID, 1, 2);
		world.setBlock(i + 5, j + 25, k + 4, SpaceAgeCore.T0011Surface.blockID, 1, 2);
		world.setBlock(i + 5, j + 25, k + 5, SpaceAgeCore.T0011Surface.blockID, 1, 2);
		world.setBlock(i + 5, j + 25, k + 6, SpaceAgeCore.T0011Surface.blockID, 1, 2);
		world.setBlock(i + 5, j + 25, k + 7, SpaceAgeCore.T0011Surface.blockID, 1, 2);
		world.setBlock(i + 5, j + 25, k + 8, SpaceAgeCore.T0011Surface.blockID, 1, 2);
		world.setBlock(i + 5, j + 25, k + 9, SpaceAgeCore.T0011Surface.blockID, 1, 2);
		world.setBlock(i + 5, j + 25, k + 10, SpaceAgeCore.T0011Surface.blockID, 1, 2);
		world.setBlock(i + 5, j + 25, k + 11, SpaceAgeCore.T0011Surface.blockID, 1, 2);
		world.setBlock(i + 5, j + 25, k + 12, SpaceAgeCore.T0011Surface.blockID, 1, 2);
		world.setBlock(i + 5, j + 25, k + 13, SpaceAgeCore.T0011Surface.blockID, 1, 2);
		world.setBlock(i + 5, j + 25, k + 14, SpaceAgeCore.T0011Surface.blockID, 1, 2);
		world.setBlock(i + 5, j + 25, k + 15, SpaceAgeCore.T0011Surface.blockID, 1, 2);
		world.setBlock(i + 5, j + 25, k + 16, SpaceAgeCore.T0011Surface.blockID, 1, 2);
		world.setBlock(i + 5, j + 25, k + 17, SpaceAgeCore.T0011Surface.blockID, 1, 2);
		world.setBlock(i + 5, j + 25, k + 18, SpaceAgeCore.T0011Surface.blockID, 1, 2);
		world.setBlock(i + 5, j + 25, k + 19, SpaceAgeCore.T0011Surface.blockID, 1, 2);
		world.setBlock(i + 5, j + 25, k + 20, SpaceAgeCore.T0011Surface.blockID, 1, 2);
		world.setBlock(i + 5, j + 25, k + 21, SpaceAgeCore.T0011Surface.blockID, 1, 2);
		world.setBlock(i + 5, j + 25, k + 22, SpaceAgeCore.T0011Surface.blockID, 1, 2);
		world.setBlock(i + 5, j + 26, k + 5, SpaceAgeCore.T0011Surface.blockID, 1, 2);
		world.setBlock(i + 5, j + 26, k + 6, SpaceAgeCore.T0011Surface.blockID, 1, 2);
		world.setBlock(i + 5, j + 26, k + 7, SpaceAgeCore.T0011Surface.blockID, 1, 2);
		world.setBlock(i + 5, j + 26, k + 8, SpaceAgeCore.T0011Surface.blockID, 1, 2);
		world.setBlock(i + 5, j + 26, k + 9, SpaceAgeCore.T0011Surface.blockID, 1, 2);
		world.setBlock(i + 5, j + 26, k + 10, SpaceAgeCore.T0011Surface.blockID, 1, 2);
		world.setBlock(i + 5, j + 26, k + 11, SpaceAgeCore.T0011Surface.blockID, 1, 2);
		world.setBlock(i + 5, j + 26, k + 12, SpaceAgeCore.T0011Surface.blockID, 1, 2);
		world.setBlock(i + 5, j + 26, k + 13, SpaceAgeCore.T0011Surface.blockID, 1, 2);
		world.setBlock(i + 5, j + 26, k + 14, SpaceAgeCore.T0011Surface.blockID, 1, 2);
		world.setBlock(i + 5, j + 26, k + 15, SpaceAgeCore.T0011Surface.blockID, 1, 2);
		world.setBlock(i + 5, j + 26, k + 16, SpaceAgeCore.T0011Surface.blockID, 1, 2);
		world.setBlock(i + 5, j + 26, k + 17, SpaceAgeCore.T0011Surface.blockID, 1, 2);
		world.setBlock(i + 5, j + 26, k + 18, SpaceAgeCore.T0011Surface.blockID, 1, 2);
		world.setBlock(i + 5, j + 26, k + 19, SpaceAgeCore.T0011Surface.blockID, 1, 2);
		world.setBlock(i + 5, j + 26, k + 20, SpaceAgeCore.T0011Surface.blockID, 1, 2);
		world.setBlock(i + 5, j + 26, k + 21, SpaceAgeCore.T0011Surface.blockID, 1, 2);
		world.setBlock(i + 5, j + 27, k + 7, SpaceAgeCore.T0011Surface.blockID, 1, 2);
		world.setBlock(i + 5, j + 27, k + 8, SpaceAgeCore.T0011Surface.blockID, 1, 2);
		world.setBlock(i + 5, j + 27, k + 9, SpaceAgeCore.T0011Surface.blockID, 1, 2);
		world.setBlock(i + 5, j + 27, k + 10, SpaceAgeCore.T0011Surface.blockID, 1, 2);
		world.setBlock(i + 5, j + 27, k + 11, SpaceAgeCore.T0011Surface.blockID, 1, 2);
		world.setBlock(i + 5, j + 27, k + 12, SpaceAgeCore.T0011Surface.blockID, 1, 2);
		world.setBlock(i + 5, j + 27, k + 13, SpaceAgeCore.T0011Surface.blockID, 1, 2);
		world.setBlock(i + 5, j + 27, k + 14, SpaceAgeCore.T0011Surface.blockID, 1, 2);
		world.setBlock(i + 5, j + 27, k + 15, SpaceAgeCore.T0011Surface.blockID, 1, 2);
		world.setBlock(i + 5, j + 27, k + 16, SpaceAgeCore.T0011Surface.blockID, 1, 2);
		world.setBlock(i + 5, j + 27, k + 17, SpaceAgeCore.T0011Surface.blockID, 1, 2);
		world.setBlock(i + 5, j + 27, k + 18, SpaceAgeCore.T0011Surface.blockID, 1, 2);
		world.setBlock(i + 5, j + 27, k + 19, SpaceAgeCore.T0011Surface.blockID, 1, 2);
		world.setBlock(i + 6, j + 24, k + 2, SpaceAgeCore.T0011Surface.blockID, 1, 2);
		world.setBlock(i + 6, j + 24, k + 3, SpaceAgeCore.T0011Surface.blockID, 1, 2);
		world.setBlock(i + 6, j + 24, k + 4, SpaceAgeCore.T0011Surface.blockID, 1, 2);
		world.setBlock(i + 6, j + 24, k + 5, SpaceAgeCore.T0011Surface.blockID, 1, 2);
		world.setBlock(i + 6, j + 24, k + 6, SpaceAgeCore.T0011Surface.blockID, 1, 2);
		world.setBlock(i + 6, j + 24, k + 7, SpaceAgeCore.T0011Surface.blockID, 1, 2);
		world.setBlock(i + 6, j + 24, k + 8, SpaceAgeCore.T0011Surface.blockID, 1, 2);
		world.setBlock(i + 6, j + 24, k + 9, SpaceAgeCore.T0011Surface.blockID, 1, 2);
		world.setBlock(i + 6, j + 24, k + 10, SpaceAgeCore.T0011Surface.blockID, 1, 2);
		world.setBlock(i + 6, j + 24, k + 11, SpaceAgeCore.T0011Surface.blockID, 1, 2);
		world.setBlock(i + 6, j + 24, k + 12, SpaceAgeCore.T0011Surface.blockID, 1, 2);
		world.setBlock(i + 6, j + 24, k + 13, SpaceAgeCore.T0011Surface.blockID, 1, 2);
		world.setBlock(i + 6, j + 24, k + 14, SpaceAgeCore.T0011Surface.blockID, 1, 2);
		world.setBlock(i + 6, j + 24, k + 15, SpaceAgeCore.T0011Surface.blockID, 1, 2);
		world.setBlock(i + 6, j + 24, k + 16, SpaceAgeCore.T0011Surface.blockID, 1, 2);
		world.setBlock(i + 6, j + 24, k + 17, SpaceAgeCore.T0011Surface.blockID, 1, 2);
		world.setBlock(i + 6, j + 24, k + 18, SpaceAgeCore.T0011Surface.blockID, 1, 2);
		world.setBlock(i + 6, j + 24, k + 19, SpaceAgeCore.T0011Surface.blockID, 1, 2);
		world.setBlock(i + 6, j + 24, k + 20, SpaceAgeCore.T0011Surface.blockID, 1, 2);
		world.setBlock(i + 6, j + 24, k + 21, SpaceAgeCore.T0011Surface.blockID, 1, 2);
		world.setBlock(i + 6, j + 24, k + 22, SpaceAgeCore.T0011Surface.blockID, 1, 2);
		world.setBlock(i + 6, j + 24, k + 23, SpaceAgeCore.T0011Surface.blockID, 1, 2);
		world.setBlock(i + 6, j + 24, k + 24, SpaceAgeCore.T0011Surface.blockID, 1, 2);
		world.setBlock(i + 6, j + 25, k + 3, SpaceAgeCore.T0011Surface.blockID, 1, 2);
		world.setBlock(i + 6, j + 25, k + 4, SpaceAgeCore.T0011Surface.blockID, 1, 2);
		world.setBlock(i + 6, j + 25, k + 5, SpaceAgeCore.T0011Surface.blockID, 1, 2);
		world.setBlock(i + 6, j + 25, k + 6, SpaceAgeCore.T0011Surface.blockID, 1, 2);
		world.setBlock(i + 6, j + 25, k + 7, SpaceAgeCore.T0011Surface.blockID, 1, 2);
		world.setBlock(i + 6, j + 25, k + 8, SpaceAgeCore.T0011Surface.blockID, 1, 2);
		world.setBlock(i + 6, j + 25, k + 9, SpaceAgeCore.T0011Surface.blockID, 1, 2);
		world.setBlock(i + 6, j + 25, k + 10, SpaceAgeCore.T0011Surface.blockID, 1, 2);
		world.setBlock(i + 6, j + 25, k + 11, SpaceAgeCore.T0011Surface.blockID, 1, 2);
		world.setBlock(i + 6, j + 25, k + 12, SpaceAgeCore.T0011Surface.blockID, 1, 2);
		world.setBlock(i + 6, j + 25, k + 13, SpaceAgeCore.T0011Surface.blockID, 1, 2);
		world.setBlock(i + 6, j + 25, k + 14, SpaceAgeCore.T0011Surface.blockID, 1, 2);
		world.setBlock(i + 6, j + 25, k + 15, SpaceAgeCore.T0011Surface.blockID, 1, 2);
		world.setBlock(i + 6, j + 25, k + 16, SpaceAgeCore.T0011Surface.blockID, 1, 2);
		world.setBlock(i + 6, j + 25, k + 17, SpaceAgeCore.T0011Surface.blockID, 1, 2);
		world.setBlock(i + 6, j + 25, k + 18, SpaceAgeCore.T0011Surface.blockID, 1, 2);
		world.setBlock(i + 6, j + 25, k + 19, SpaceAgeCore.T0011Surface.blockID, 1, 2);
		world.setBlock(i + 6, j + 25, k + 20, SpaceAgeCore.T0011Surface.blockID, 1, 2);
		world.setBlock(i + 6, j + 25, k + 21, SpaceAgeCore.T0011Surface.blockID, 1, 2);
		world.setBlock(i + 6, j + 25, k + 22, SpaceAgeCore.T0011Surface.blockID, 1, 2);
		world.setBlock(i + 6, j + 25, k + 23, SpaceAgeCore.T0011Surface.blockID, 1, 2);
		world.setBlock(i + 6, j + 26, k + 5, SpaceAgeCore.T0011Surface.blockID, 1, 2);
		world.setBlock(i + 6, j + 26, k + 6, SpaceAgeCore.T0011Surface.blockID, 1, 2);
		world.setBlock(i + 6, j + 26, k + 7, SpaceAgeCore.T0011Surface.blockID, 1, 2);
		world.setBlock(i + 6, j + 26, k + 8, SpaceAgeCore.T0011Surface.blockID, 1, 2);
		world.setBlock(i + 6, j + 26, k + 9, SpaceAgeCore.T0011Surface.blockID, 1, 2);
		world.setBlock(i + 6, j + 26, k + 10, SpaceAgeCore.T0011Surface.blockID, 1, 2);
		world.setBlock(i + 6, j + 26, k + 11, SpaceAgeCore.T0011Surface.blockID, 1, 2);
		world.setBlock(i + 6, j + 26, k + 12, SpaceAgeCore.T0011Surface.blockID, 1, 2);
		world.setBlock(i + 6, j + 26, k + 13, SpaceAgeCore.T0011Surface.blockID, 1, 2);
		world.setBlock(i + 6, j + 26, k + 14, SpaceAgeCore.T0011Surface.blockID, 1, 2);
		world.setBlock(i + 6, j + 26, k + 15, SpaceAgeCore.T0011Surface.blockID, 1, 2);
		world.setBlock(i + 6, j + 26, k + 16, SpaceAgeCore.T0011Surface.blockID, 1, 2);
		world.setBlock(i + 6, j + 26, k + 17, SpaceAgeCore.T0011Surface.blockID, 1, 2);
		world.setBlock(i + 6, j + 26, k + 18, SpaceAgeCore.T0011Surface.blockID, 1, 2);
		world.setBlock(i + 6, j + 26, k + 19, SpaceAgeCore.T0011Surface.blockID, 1, 2);
		world.setBlock(i + 6, j + 26, k + 20, SpaceAgeCore.T0011Surface.blockID, 1, 2);
		world.setBlock(i + 6, j + 26, k + 21, SpaceAgeCore.T0011Surface.blockID, 1, 2);
		world.setBlock(i + 6, j + 27, k + 6, SpaceAgeCore.T0011Surface.blockID, 1, 2);
		world.setBlock(i + 6, j + 27, k + 7, SpaceAgeCore.T0011Surface.blockID, 1, 2);
		world.setBlock(i + 6, j + 27, k + 8, SpaceAgeCore.T0011Surface.blockID, 1, 2);
		world.setBlock(i + 6, j + 27, k + 9, SpaceAgeCore.T0011Surface.blockID, 1, 2);
		world.setBlock(i + 6, j + 27, k + 10, SpaceAgeCore.T0011Surface.blockID, 1, 2);
		world.setBlock(i + 6, j + 27, k + 11, SpaceAgeCore.T0011Surface.blockID, 1, 2);
		world.setBlock(i + 6, j + 27, k + 12, SpaceAgeCore.T0011Surface.blockID, 1, 2);
		world.setBlock(i + 6, j + 27, k + 13, SpaceAgeCore.T0011Surface.blockID, 1, 2);
		world.setBlock(i + 6, j + 27, k + 14, SpaceAgeCore.T0011Surface.blockID, 1, 2);
		world.setBlock(i + 6, j + 27, k + 15, SpaceAgeCore.T0011Surface.blockID, 1, 2);
		world.setBlock(i + 6, j + 27, k + 16, SpaceAgeCore.T0011Surface.blockID, 1, 2);
		world.setBlock(i + 6, j + 27, k + 17, SpaceAgeCore.T0011Surface.blockID, 1, 2);
		world.setBlock(i + 6, j + 27, k + 18, SpaceAgeCore.T0011Surface.blockID, 1, 2);
		world.setBlock(i + 6, j + 27, k + 19, SpaceAgeCore.T0011Surface.blockID, 1, 2);
		world.setBlock(i + 6, j + 27, k + 20, SpaceAgeCore.T0011Surface.blockID, 1, 2);
		world.setBlock(i + 7, j + 24, k + 1, SpaceAgeCore.T0011Surface.blockID, 1, 2);
		world.setBlock(i + 7, j + 24, k + 2, SpaceAgeCore.T0011Surface.blockID, 1, 2);
		world.setBlock(i + 7, j + 24, k + 3, SpaceAgeCore.T0011Surface.blockID, 1, 2);
		world.setBlock(i + 7, j + 24, k + 4, SpaceAgeCore.T0011Surface.blockID, 1, 2);
		world.setBlock(i + 7, j + 24, k + 5, SpaceAgeCore.T0011Surface.blockID, 1, 2);
		world.setBlock(i + 7, j + 24, k + 6, SpaceAgeCore.T0011Surface.blockID, 1, 2);
		world.setBlock(i + 7, j + 24, k + 7, SpaceAgeCore.T0011Surface.blockID, 1, 2);
		world.setBlock(i + 7, j + 24, k + 8, SpaceAgeCore.T0011Surface.blockID, 1, 2);
		world.setBlock(i + 7, j + 24, k + 9, SpaceAgeCore.T0011Surface.blockID, 1, 2);
		world.setBlock(i + 7, j + 24, k + 10, SpaceAgeCore.T0011Surface.blockID, 1, 2);
		world.setBlock(i + 7, j + 24, k + 11, SpaceAgeCore.T0011Surface.blockID, 1, 2);
		world.setBlock(i + 7, j + 24, k + 12, SpaceAgeCore.T0011Surface.blockID, 1, 2);
		world.setBlock(i + 7, j + 24, k + 13, SpaceAgeCore.T0011Surface.blockID, 1, 2);
		world.setBlock(i + 7, j + 24, k + 14, SpaceAgeCore.T0011Surface.blockID, 1, 2);
		world.setBlock(i + 7, j + 24, k + 15, SpaceAgeCore.T0011Surface.blockID, 1, 2);
		world.setBlock(i + 7, j + 24, k + 16, SpaceAgeCore.T0011Surface.blockID, 1, 2);
		world.setBlock(i + 7, j + 24, k + 17, SpaceAgeCore.T0011Surface.blockID, 1, 2);
		world.setBlock(i + 7, j + 24, k + 18, SpaceAgeCore.T0011Surface.blockID, 1, 2);
		world.setBlock(i + 7, j + 24, k + 19, SpaceAgeCore.T0011Surface.blockID, 1, 2);
		world.setBlock(i + 7, j + 24, k + 20, SpaceAgeCore.T0011Surface.blockID, 1, 2);
		world.setBlock(i + 7, j + 24, k + 21, SpaceAgeCore.T0011Surface.blockID, 1, 2);
		world.setBlock(i + 7, j + 24, k + 22, SpaceAgeCore.T0011Surface.blockID, 1, 2);
		world.setBlock(i + 7, j + 24, k + 23, SpaceAgeCore.T0011Surface.blockID, 1, 2);
		world.setBlock(i + 7, j + 24, k + 24, SpaceAgeCore.T0011Surface.blockID, 1, 2);
		world.setBlock(i + 7, j + 25, k + 3, SpaceAgeCore.T0011Surface.blockID, 1, 2);
		world.setBlock(i + 7, j + 25, k + 4, SpaceAgeCore.T0011Surface.blockID, 1, 2);
		world.setBlock(i + 7, j + 25, k + 5, SpaceAgeCore.T0011Surface.blockID, 1, 2);
		world.setBlock(i + 7, j + 25, k + 6, SpaceAgeCore.T0011Surface.blockID, 1, 2);
		world.setBlock(i + 7, j + 25, k + 7, SpaceAgeCore.T0011Surface.blockID, 1, 2);
		world.setBlock(i + 7, j + 25, k + 8, SpaceAgeCore.T0011Surface.blockID, 1, 2);
		world.setBlock(i + 7, j + 25, k + 9, SpaceAgeCore.T0011Surface.blockID, 1, 2);
		world.setBlock(i + 7, j + 25, k + 10, SpaceAgeCore.T0011Surface.blockID, 1, 2);
		world.setBlock(i + 7, j + 25, k + 11, SpaceAgeCore.T0011Surface.blockID, 1, 2);
		world.setBlock(i + 7, j + 25, k + 12, SpaceAgeCore.T0011Surface.blockID, 1, 2);
		world.setBlock(i + 7, j + 25, k + 13, SpaceAgeCore.T0011Surface.blockID, 1, 2);
		world.setBlock(i + 7, j + 25, k + 14, SpaceAgeCore.T0011Surface.blockID, 1, 2);
		world.setBlock(i + 7, j + 25, k + 15, SpaceAgeCore.T0011Surface.blockID, 1, 2);
		world.setBlock(i + 7, j + 25, k + 16, SpaceAgeCore.T0011Surface.blockID, 1, 2);
		world.setBlock(i + 7, j + 25, k + 17, SpaceAgeCore.T0011Surface.blockID, 1, 2);
		world.setBlock(i + 7, j + 25, k + 18, SpaceAgeCore.T0011Surface.blockID, 1, 2);
		world.setBlock(i + 7, j + 25, k + 19, SpaceAgeCore.T0011Surface.blockID, 1, 2);
		world.setBlock(i + 7, j + 25, k + 20, SpaceAgeCore.T0011Surface.blockID, 1, 2);
		world.setBlock(i + 7, j + 25, k + 21, SpaceAgeCore.T0011Surface.blockID, 1, 2);
		world.setBlock(i + 7, j + 25, k + 22, SpaceAgeCore.T0011Surface.blockID, 1, 2);
		world.setBlock(i + 7, j + 25, k + 23, SpaceAgeCore.T0011Surface.blockID, 1, 2);
		world.setBlock(i + 7, j + 26, k + 4, SpaceAgeCore.T0011Surface.blockID, 1, 2);
		world.setBlock(i + 7, j + 26, k + 5, SpaceAgeCore.T0011Surface.blockID, 1, 2);
		world.setBlock(i + 7, j + 26, k + 6, SpaceAgeCore.T0011Surface.blockID, 1, 2);
		world.setBlock(i + 7, j + 26, k + 7, SpaceAgeCore.T0011Surface.blockID, 1, 2);
		world.setBlock(i + 7, j + 26, k + 8, SpaceAgeCore.T0011Surface.blockID, 1, 2);
		world.setBlock(i + 7, j + 26, k + 9, SpaceAgeCore.T0011Surface.blockID, 1, 2);
		world.setBlock(i + 7, j + 26, k + 10, SpaceAgeCore.T0011Surface.blockID, 1, 2);
		world.setBlock(i + 7, j + 26, k + 11, SpaceAgeCore.T0011Surface.blockID, 1, 2);
		world.setBlock(i + 7, j + 26, k + 12, SpaceAgeCore.T0011Surface.blockID, 1, 2);
		world.setBlock(i + 7, j + 26, k + 13, SpaceAgeCore.T0011Surface.blockID, 1, 2);
		world.setBlock(i + 7, j + 26, k + 14, SpaceAgeCore.T0011Surface.blockID, 1, 2);
		world.setBlock(i + 7, j + 26, k + 15, SpaceAgeCore.T0011Surface.blockID, 1, 2);
		world.setBlock(i + 7, j + 26, k + 16, SpaceAgeCore.T0011Surface.blockID, 1, 2);
		world.setBlock(i + 7, j + 26, k + 17, SpaceAgeCore.T0011Surface.blockID, 1, 2);
		world.setBlock(i + 7, j + 26, k + 18, SpaceAgeCore.T0011Surface.blockID, 1, 2);
		world.setBlock(i + 7, j + 26, k + 19, SpaceAgeCore.T0011Surface.blockID, 1, 2);
		world.setBlock(i + 7, j + 26, k + 20, SpaceAgeCore.T0011Surface.blockID, 1, 2);
		world.setBlock(i + 7, j + 26, k + 21, SpaceAgeCore.T0011Surface.blockID, 1, 2);
		world.setBlock(i + 7, j + 26, k + 22, SpaceAgeCore.T0011Surface.blockID, 1, 2);
		world.setBlock(i + 7, j + 27, k + 5, SpaceAgeCore.T0011Surface.blockID, 1, 2);
		world.setBlock(i + 7, j + 27, k + 6, SpaceAgeCore.T0011Surface.blockID, 1, 2);
		world.setBlock(i + 7, j + 27, k + 7, SpaceAgeCore.T0011Surface.blockID, 1, 2);
		world.setBlock(i + 7, j + 27, k + 8, SpaceAgeCore.T0011Surface.blockID, 1, 2);
		world.setBlock(i + 7, j + 27, k + 9, SpaceAgeCore.T0011Surface.blockID, 1, 2);
		world.setBlock(i + 7, j + 27, k + 10, SpaceAgeCore.T0011Surface.blockID, 1, 2);
		world.setBlock(i + 7, j + 27, k + 11, SpaceAgeCore.T0011Surface.blockID, 1, 2);
		world.setBlock(i + 7, j + 27, k + 12, SpaceAgeCore.T0011Surface.blockID, 1, 2);
		world.setBlock(i + 7, j + 27, k + 13, SpaceAgeCore.T0011Surface.blockID, 1, 2);
		world.setBlock(i + 7, j + 27, k + 14, SpaceAgeCore.T0011Surface.blockID, 1, 2);
		world.setBlock(i + 7, j + 27, k + 15, SpaceAgeCore.T0011Surface.blockID, 1, 2);
		world.setBlock(i + 7, j + 27, k + 16, SpaceAgeCore.T0011Surface.blockID, 1, 2);
		world.setBlock(i + 7, j + 27, k + 17, SpaceAgeCore.T0011Surface.blockID, 1, 2);
		world.setBlock(i + 7, j + 27, k + 18, SpaceAgeCore.T0011Surface.blockID, 1, 2);
		world.setBlock(i + 7, j + 27, k + 19, SpaceAgeCore.T0011Surface.blockID, 1, 2);
		world.setBlock(i + 7, j + 27, k + 20, SpaceAgeCore.T0011Surface.blockID, 1, 2);
		world.setBlock(i + 7, j + 27, k + 21, SpaceAgeCore.T0011Surface.blockID, 1, 2);
		world.setBlock(i + 8, j + 24, k + 1, SpaceAgeCore.T0011Surface.blockID, 1, 2);
		world.setBlock(i + 8, j + 24, k + 2, SpaceAgeCore.T0011Surface.blockID, 1, 2);
		world.setBlock(i + 8, j + 24, k + 3, SpaceAgeCore.T0011Surface.blockID, 1, 2);
		world.setBlock(i + 8, j + 24, k + 4, SpaceAgeCore.T0011Surface.blockID, 1, 2);
		world.setBlock(i + 8, j + 24, k + 5, SpaceAgeCore.T0011Surface.blockID, 1, 2);
		world.setBlock(i + 8, j + 24, k + 6, SpaceAgeCore.T0011Surface.blockID, 1, 2);
		world.setBlock(i + 8, j + 24, k + 7, SpaceAgeCore.T0011Surface.blockID, 1, 2);
		world.setBlock(i + 8, j + 24, k + 8, SpaceAgeCore.T0011Surface.blockID, 1, 2);
		world.setBlock(i + 8, j + 24, k + 9, SpaceAgeCore.T0011Surface.blockID, 1, 2);
		world.setBlock(i + 8, j + 24, k + 10, SpaceAgeCore.T0011Surface.blockID, 1, 2);
		world.setBlock(i + 8, j + 24, k + 11, SpaceAgeCore.T0011Surface.blockID, 1, 2);
		world.setBlock(i + 8, j + 24, k + 12, SpaceAgeCore.T0011Surface.blockID, 1, 2);
		world.setBlock(i + 8, j + 24, k + 13, SpaceAgeCore.T0011Surface.blockID, 1, 2);
		world.setBlock(i + 8, j + 24, k + 14, SpaceAgeCore.T0011Surface.blockID, 1, 2);
		world.setBlock(i + 8, j + 24, k + 15, SpaceAgeCore.T0011Surface.blockID, 1, 2);
		world.setBlock(i + 8, j + 24, k + 16, SpaceAgeCore.T0011Surface.blockID, 1, 2);
		world.setBlock(i + 8, j + 24, k + 17, SpaceAgeCore.T0011Surface.blockID, 1, 2);
		world.setBlock(i + 8, j + 24, k + 18, SpaceAgeCore.T0011Surface.blockID, 1, 2);
		world.setBlock(i + 8, j + 24, k + 19, SpaceAgeCore.T0011Surface.blockID, 1, 2);
		world.setBlock(i + 8, j + 24, k + 20, SpaceAgeCore.T0011Surface.blockID, 1, 2);
		world.setBlock(i + 8, j + 24, k + 21, SpaceAgeCore.T0011Surface.blockID, 1, 2);
		world.setBlock(i + 8, j + 24, k + 22, SpaceAgeCore.T0011Surface.blockID, 1, 2);
		world.setBlock(i + 8, j + 24, k + 23, SpaceAgeCore.T0011Surface.blockID, 1, 2);
		world.setBlock(i + 8, j + 24, k + 24, SpaceAgeCore.T0011Surface.blockID, 1, 2);
		world.setBlock(i + 8, j + 25, k + 2, SpaceAgeCore.T0011Surface.blockID, 1, 2);
		world.setBlock(i + 8, j + 25, k + 3, SpaceAgeCore.T0011Surface.blockID, 1, 2);
		world.setBlock(i + 8, j + 25, k + 4, SpaceAgeCore.T0011Surface.blockID, 1, 2);
		world.setBlock(i + 8, j + 25, k + 5, SpaceAgeCore.T0011Surface.blockID, 1, 2);
		world.setBlock(i + 8, j + 25, k + 6, SpaceAgeCore.T0011Surface.blockID, 1, 2);
		world.setBlock(i + 8, j + 25, k + 7, SpaceAgeCore.T0011Surface.blockID, 1, 2);
		world.setBlock(i + 8, j + 25, k + 8, SpaceAgeCore.T0011Surface.blockID, 1, 2);
		world.setBlock(i + 8, j + 25, k + 9, SpaceAgeCore.T0011Surface.blockID, 1, 2);
		world.setBlock(i + 8, j + 25, k + 10, SpaceAgeCore.T0011Surface.blockID, 1, 2);
		world.setBlock(i + 8, j + 25, k + 11, SpaceAgeCore.T0011Surface.blockID, 1, 2);
		world.setBlock(i + 8, j + 25, k + 12, SpaceAgeCore.T0011Surface.blockID, 1, 2);
		world.setBlock(i + 8, j + 25, k + 13, SpaceAgeCore.T0011Surface.blockID, 1, 2);
		world.setBlock(i + 8, j + 25, k + 14, SpaceAgeCore.T0011Surface.blockID, 1, 2);
		world.setBlock(i + 8, j + 25, k + 15, SpaceAgeCore.T0011Surface.blockID, 1, 2);
		world.setBlock(i + 8, j + 25, k + 16, SpaceAgeCore.T0011Surface.blockID, 1, 2);
		world.setBlock(i + 8, j + 25, k + 17, SpaceAgeCore.T0011Surface.blockID, 1, 2);
		world.setBlock(i + 8, j + 25, k + 18, SpaceAgeCore.T0011Surface.blockID, 1, 2);
		world.setBlock(i + 8, j + 25, k + 19, SpaceAgeCore.T0011Surface.blockID, 1, 2);
		world.setBlock(i + 8, j + 25, k + 20, SpaceAgeCore.T0011Surface.blockID, 1, 2);
		world.setBlock(i + 8, j + 25, k + 21, SpaceAgeCore.T0011Surface.blockID, 1, 2);
		world.setBlock(i + 8, j + 25, k + 22, SpaceAgeCore.T0011Surface.blockID, 1, 2);
		world.setBlock(i + 8, j + 25, k + 23, SpaceAgeCore.T0011Surface.blockID, 1, 2);
		world.setBlock(i + 8, j + 25, k + 24, SpaceAgeCore.T0011Surface.blockID, 1, 2);
		world.setBlock(i + 8, j + 26, k + 3, SpaceAgeCore.T0011Surface.blockID, 1, 2);
		world.setBlock(i + 8, j + 26, k + 4, SpaceAgeCore.T0011Surface.blockID, 1, 2);
		world.setBlock(i + 8, j + 26, k + 5, SpaceAgeCore.T0011Surface.blockID, 1, 2);
		world.setBlock(i + 8, j + 26, k + 6, SpaceAgeCore.T0011Surface.blockID, 1, 2);
		world.setBlock(i + 8, j + 26, k + 7, SpaceAgeCore.T0011Surface.blockID, 1, 2);
		world.setBlock(i + 8, j + 26, k + 8, SpaceAgeCore.T0011Surface.blockID, 1, 2);
		world.setBlock(i + 8, j + 26, k + 9, SpaceAgeCore.T0011Surface.blockID, 1, 2);
		world.setBlock(i + 8, j + 26, k + 10, SpaceAgeCore.T0011Surface.blockID, 1, 2);
		world.setBlock(i + 8, j + 26, k + 11, SpaceAgeCore.T0011Surface.blockID, 1, 2);
		world.setBlock(i + 8, j + 26, k + 12, SpaceAgeCore.T0011Surface.blockID, 1, 2);
		world.setBlock(i + 8, j + 26, k + 13, SpaceAgeCore.T0011Surface.blockID, 1, 2);
		world.setBlock(i + 8, j + 26, k + 14, SpaceAgeCore.T0011Surface.blockID, 1, 2);
		world.setBlock(i + 8, j + 26, k + 15, SpaceAgeCore.T0011Surface.blockID, 1, 2);
		world.setBlock(i + 8, j + 26, k + 16, SpaceAgeCore.T0011Surface.blockID, 1, 2);
		world.setBlock(i + 8, j + 26, k + 17, SpaceAgeCore.T0011Surface.blockID, 1, 2);
		world.setBlock(i + 8, j + 26, k + 18, SpaceAgeCore.T0011Surface.blockID, 1, 2);
		world.setBlock(i + 8, j + 26, k + 19, SpaceAgeCore.T0011Surface.blockID, 1, 2);
		world.setBlock(i + 8, j + 26, k + 20, SpaceAgeCore.T0011Surface.blockID, 1, 2);
		world.setBlock(i + 8, j + 26, k + 21, SpaceAgeCore.T0011Surface.blockID, 1, 2);
		world.setBlock(i + 8, j + 26, k + 22, SpaceAgeCore.T0011Surface.blockID, 1, 2);
		world.setBlock(i + 8, j + 26, k + 23, SpaceAgeCore.T0011Surface.blockID, 1, 2);
		world.setBlock(i + 8, j + 27, k + 4, SpaceAgeCore.T0011Surface.blockID, 1, 2);
		world.setBlock(i + 8, j + 27, k + 5, SpaceAgeCore.T0011Surface.blockID, 1, 2);
		world.setBlock(i + 8, j + 27, k + 6, SpaceAgeCore.T0011Surface.blockID, 1, 2);
		world.setBlock(i + 8, j + 27, k + 7, SpaceAgeCore.T0011Surface.blockID, 1, 2);
		world.setBlock(i + 8, j + 27, k + 8, SpaceAgeCore.T0011Surface.blockID, 1, 2);
		world.setBlock(i + 8, j + 27, k + 9, SpaceAgeCore.T0011Surface.blockID, 1, 2);
		world.setBlock(i + 8, j + 27, k + 10, SpaceAgeCore.T0011Surface.blockID, 1, 2);
		world.setBlock(i + 8, j + 27, k + 11, SpaceAgeCore.T0011Surface.blockID, 1, 2);
		world.setBlock(i + 8, j + 27, k + 12, SpaceAgeCore.T0011Surface.blockID, 1, 2);
		world.setBlock(i + 8, j + 27, k + 13, SpaceAgeCore.T0011Surface.blockID, 1, 2);
		world.setBlock(i + 8, j + 27, k + 14, SpaceAgeCore.T0011Surface.blockID, 1, 2);
		world.setBlock(i + 8, j + 27, k + 15, SpaceAgeCore.T0011Surface.blockID, 1, 2);
		world.setBlock(i + 8, j + 27, k + 16, SpaceAgeCore.T0011Surface.blockID, 1, 2);
		world.setBlock(i + 8, j + 27, k + 17, SpaceAgeCore.T0011Surface.blockID, 1, 2);
		world.setBlock(i + 8, j + 27, k + 18, SpaceAgeCore.T0011Surface.blockID, 1, 2);
		world.setBlock(i + 8, j + 27, k + 19, SpaceAgeCore.T0011Surface.blockID, 1, 2);
		world.setBlock(i + 8, j + 27, k + 20, SpaceAgeCore.T0011Surface.blockID, 1, 2);
		world.setBlock(i + 8, j + 27, k + 21, SpaceAgeCore.T0011Surface.blockID, 1, 2);
		world.setBlock(i + 8, j + 27, k + 22, SpaceAgeCore.T0011Surface.blockID, 1, 2);
		world.setBlock(i + 9, j + 24, k + 1, SpaceAgeCore.T0011Surface.blockID, 1, 2);
		world.setBlock(i + 9, j + 24, k + 2, SpaceAgeCore.T0011Surface.blockID, 1, 2);
		world.setBlock(i + 9, j + 24, k + 3, SpaceAgeCore.T0011Surface.blockID, 1, 2);
		world.setBlock(i + 9, j + 24, k + 4, SpaceAgeCore.T0011Surface.blockID, 1, 2);
		world.setBlock(i + 9, j + 24, k + 5, SpaceAgeCore.T0011Surface.blockID, 1, 2);
		world.setBlock(i + 9, j + 24, k + 6, SpaceAgeCore.T0011Surface.blockID, 1, 2);
		world.setBlock(i + 9, j + 24, k + 7, SpaceAgeCore.T0011Surface.blockID, 1, 2);
		world.setBlock(i + 9, j + 24, k + 8, SpaceAgeCore.T0011Surface.blockID, 1, 2);
		world.setBlock(i + 9, j + 24, k + 9, SpaceAgeCore.T0011Surface.blockID, 1, 2);
		world.setBlock(i + 9, j + 24, k + 10, SpaceAgeCore.T0011Surface.blockID, 1, 2);
		world.setBlock(i + 9, j + 24, k + 11, SpaceAgeCore.T0011Surface.blockID, 1, 2);
		world.setBlock(i + 9, j + 24, k + 12, SpaceAgeCore.T0011Surface.blockID, 1, 2);
		world.setBlock(i + 9, j + 24, k + 13, SpaceAgeCore.T0011Surface.blockID, 1, 2);
		world.setBlock(i + 9, j + 24, k + 14, SpaceAgeCore.T0011Surface.blockID, 1, 2);
		world.setBlock(i + 9, j + 24, k + 15, SpaceAgeCore.T0011Surface.blockID, 1, 2);
		world.setBlock(i + 9, j + 24, k + 16, SpaceAgeCore.T0011Surface.blockID, 1, 2);
		world.setBlock(i + 9, j + 24, k + 17, SpaceAgeCore.T0011Surface.blockID, 1, 2);
		world.setBlock(i + 9, j + 24, k + 18, SpaceAgeCore.T0011Surface.blockID, 1, 2);
		world.setBlock(i + 9, j + 24, k + 19, SpaceAgeCore.T0011Surface.blockID, 1, 2);
		world.setBlock(i + 9, j + 24, k + 20, SpaceAgeCore.T0011Surface.blockID, 1, 2);
		world.setBlock(i + 9, j + 24, k + 21, SpaceAgeCore.T0011Surface.blockID, 1, 2);
		world.setBlock(i + 9, j + 24, k + 22, SpaceAgeCore.T0011Surface.blockID, 1, 2);
		world.setBlock(i + 9, j + 24, k + 23, SpaceAgeCore.T0011Surface.blockID, 1, 2);
		world.setBlock(i + 9, j + 24, k + 24, SpaceAgeCore.T0011Surface.blockID, 1, 2);
		world.setBlock(i + 9, j + 25, k + 2, SpaceAgeCore.T0011Surface.blockID, 1, 2);
		world.setBlock(i + 9, j + 25, k + 3, SpaceAgeCore.T0011Surface.blockID, 1, 2);
		world.setBlock(i + 9, j + 25, k + 4, SpaceAgeCore.T0011Surface.blockID, 1, 2);
		world.setBlock(i + 9, j + 25, k + 5, SpaceAgeCore.T0011Surface.blockID, 1, 2);
		world.setBlock(i + 9, j + 25, k + 6, SpaceAgeCore.T0011Surface.blockID, 1, 2);
		world.setBlock(i + 9, j + 25, k + 7, SpaceAgeCore.T0011Surface.blockID, 1, 2);
		world.setBlock(i + 9, j + 25, k + 8, SpaceAgeCore.T0011Surface.blockID, 1, 2);
		world.setBlock(i + 9, j + 25, k + 9, SpaceAgeCore.T0011Surface.blockID, 1, 2);
		world.setBlock(i + 9, j + 25, k + 10, SpaceAgeCore.T0011Surface.blockID, 1, 2);
		world.setBlock(i + 9, j + 25, k + 11, SpaceAgeCore.T0011Surface.blockID, 1, 2);
		world.setBlock(i + 9, j + 25, k + 12, SpaceAgeCore.T0011Surface.blockID, 1, 2);
		world.setBlock(i + 9, j + 25, k + 13, SpaceAgeCore.T0011Surface.blockID, 1, 2);
		world.setBlock(i + 9, j + 25, k + 14, SpaceAgeCore.T0011Surface.blockID, 1, 2);
		world.setBlock(i + 9, j + 25, k + 15, SpaceAgeCore.T0011Surface.blockID, 1, 2);
		world.setBlock(i + 9, j + 25, k + 16, SpaceAgeCore.T0011Surface.blockID, 1, 2);
		world.setBlock(i + 9, j + 25, k + 17, SpaceAgeCore.T0011Surface.blockID, 1, 2);
		world.setBlock(i + 9, j + 25, k + 18, SpaceAgeCore.T0011Surface.blockID, 1, 2);
		world.setBlock(i + 9, j + 25, k + 19, SpaceAgeCore.T0011Surface.blockID, 1, 2);
		world.setBlock(i + 9, j + 25, k + 20, SpaceAgeCore.T0011Surface.blockID, 1, 2);
		world.setBlock(i + 9, j + 25, k + 21, SpaceAgeCore.T0011Surface.blockID, 1, 2);
		world.setBlock(i + 9, j + 25, k + 22, SpaceAgeCore.T0011Surface.blockID, 1, 2);
		world.setBlock(i + 9, j + 25, k + 23, SpaceAgeCore.T0011Surface.blockID, 1, 2);
		world.setBlock(i + 9, j + 25, k + 24, SpaceAgeCore.T0011Surface.blockID, 1, 2);
		world.setBlock(i + 9, j + 26, k + 3, SpaceAgeCore.T0011Surface.blockID, 1, 2);
		world.setBlock(i + 9, j + 26, k + 4, SpaceAgeCore.T0011Surface.blockID, 1, 2);
		world.setBlock(i + 9, j + 26, k + 5, SpaceAgeCore.T0011Surface.blockID, 1, 2);
		world.setBlock(i + 9, j + 26, k + 6, SpaceAgeCore.T0011Surface.blockID, 1, 2);
		world.setBlock(i + 9, j + 26, k + 7, SpaceAgeCore.T0011Surface.blockID, 1, 2);
		world.setBlock(i + 9, j + 26, k + 8, SpaceAgeCore.T0011Surface.blockID, 1, 2);
		world.setBlock(i + 9, j + 26, k + 9, SpaceAgeCore.T0011Surface.blockID, 1, 2);
		world.setBlock(i + 9, j + 26, k + 10, SpaceAgeCore.T0011Surface.blockID, 1, 2);
		world.setBlock(i + 9, j + 26, k + 11, SpaceAgeCore.T0011Surface.blockID, 1, 2);
		world.setBlock(i + 9, j + 26, k + 12, SpaceAgeCore.T0011Surface.blockID, 1, 2);
		world.setBlock(i + 9, j + 26, k + 13, SpaceAgeCore.T0011Surface.blockID, 1, 2);
		world.setBlock(i + 9, j + 26, k + 14, SpaceAgeCore.T0011Surface.blockID, 1, 2);
		world.setBlock(i + 9, j + 26, k + 15, SpaceAgeCore.T0011Surface.blockID, 1, 2);
		world.setBlock(i + 9, j + 26, k + 16, SpaceAgeCore.T0011Surface.blockID, 1, 2);
		world.setBlock(i + 9, j + 26, k + 17, SpaceAgeCore.T0011Surface.blockID, 1, 2);
		world.setBlock(i + 9, j + 26, k + 18, SpaceAgeCore.T0011Surface.blockID, 1, 2);
		world.setBlock(i + 9, j + 26, k + 19, SpaceAgeCore.T0011Surface.blockID, 1, 2);
		world.setBlock(i + 9, j + 26, k + 20, SpaceAgeCore.T0011Surface.blockID, 1, 2);
		world.setBlock(i + 9, j + 26, k + 21, SpaceAgeCore.T0011Surface.blockID, 1, 2);
		world.setBlock(i + 9, j + 26, k + 22, SpaceAgeCore.T0011Surface.blockID, 1, 2);
		world.setBlock(i + 9, j + 26, k + 23, SpaceAgeCore.T0011Surface.blockID, 1, 2);
		world.setBlock(i + 9, j + 27, k + 4, SpaceAgeCore.T0011Surface.blockID, 1, 2);
		world.setBlock(i + 9, j + 27, k + 5, SpaceAgeCore.T0011Surface.blockID, 1, 2);
		world.setBlock(i + 9, j + 27, k + 6, SpaceAgeCore.T0011Surface.blockID, 1, 2);
		world.setBlock(i + 9, j + 27, k + 7, SpaceAgeCore.T0011Surface.blockID, 1, 2);
		world.setBlock(i + 9, j + 27, k + 8, SpaceAgeCore.T0011Surface.blockID, 1, 2);
		world.setBlock(i + 9, j + 27, k + 9, SpaceAgeCore.T0011Surface.blockID, 1, 2);
		world.setBlock(i + 9, j + 27, k + 10, SpaceAgeCore.T0011Surface.blockID, 1, 2);
		world.setBlock(i + 9, j + 27, k + 11, SpaceAgeCore.T0011Surface.blockID, 1, 2);
		world.setBlock(i + 9, j + 27, k + 12, SpaceAgeCore.T0011Surface.blockID, 1, 2);
		world.setBlock(i + 9, j + 27, k + 13, SpaceAgeCore.T0011Surface.blockID, 1, 2);
		world.setBlock(i + 9, j + 27, k + 14, SpaceAgeCore.T0011Surface.blockID, 1, 2);
		world.setBlock(i + 9, j + 27, k + 15, SpaceAgeCore.T0011Surface.blockID, 1, 2);
		world.setBlock(i + 9, j + 27, k + 16, SpaceAgeCore.T0011Surface.blockID, 1, 2);
		world.setBlock(i + 9, j + 27, k + 17, SpaceAgeCore.T0011Surface.blockID, 1, 2);
		world.setBlock(i + 9, j + 27, k + 18, SpaceAgeCore.T0011Surface.blockID, 1, 2);
		world.setBlock(i + 9, j + 27, k + 19, SpaceAgeCore.T0011Surface.blockID, 1, 2);
		world.setBlock(i + 9, j + 27, k + 20, SpaceAgeCore.T0011Surface.blockID, 1, 2);
		world.setBlock(i + 9, j + 27, k + 21, SpaceAgeCore.T0011Surface.blockID, 1, 2);
		world.setBlock(i + 9, j + 27, k + 22, SpaceAgeCore.T0011Surface.blockID, 1, 2);
		world.setBlock(i + 10, j + 24, k + 0, SpaceAgeCore.T0011Surface.blockID, 1, 2);
		world.setBlock(i + 10, j + 24, k + 1, SpaceAgeCore.T0011Surface.blockID, 1, 2);
		world.setBlock(i + 10, j + 24, k + 2, SpaceAgeCore.T0011Surface.blockID, 1, 2);
		world.setBlock(i + 10, j + 24, k + 3, SpaceAgeCore.T0011Surface.blockID, 1, 2);
		world.setBlock(i + 10, j + 24, k + 4, SpaceAgeCore.T0011Surface.blockID, 1, 2);
		world.setBlock(i + 10, j + 24, k + 5, SpaceAgeCore.T0011Surface.blockID, 1, 2);
		world.setBlock(i + 10, j + 24, k + 6, SpaceAgeCore.T0011Surface.blockID, 1, 2);
		world.setBlock(i + 10, j + 24, k + 7, SpaceAgeCore.T0011Surface.blockID, 1, 2);
		world.setBlock(i + 10, j + 24, k + 8, SpaceAgeCore.T0011Surface.blockID, 1, 2);
		world.setBlock(i + 10, j + 24, k + 9, SpaceAgeCore.T0011Surface.blockID, 1, 2);
		world.setBlock(i + 10, j + 24, k + 10, SpaceAgeCore.T0011Surface.blockID, 1, 2);
		world.setBlock(i + 10, j + 24, k + 11, SpaceAgeCore.T0011Surface.blockID, 1, 2);
		world.setBlock(i + 10, j + 24, k + 12, SpaceAgeCore.T0011Surface.blockID, 1, 2);
		world.setBlock(i + 10, j + 24, k + 13, SpaceAgeCore.T0011Surface.blockID, 1, 2);
		world.setBlock(i + 10, j + 24, k + 14, SpaceAgeCore.T0011Surface.blockID, 1, 2);
		world.setBlock(i + 10, j + 24, k + 15, SpaceAgeCore.T0011Surface.blockID, 1, 2);
		world.setBlock(i + 10, j + 24, k + 16, SpaceAgeCore.T0011Surface.blockID, 1, 2);
		world.setBlock(i + 10, j + 24, k + 17, SpaceAgeCore.T0011Surface.blockID, 1, 2);
		world.setBlock(i + 10, j + 24, k + 18, SpaceAgeCore.T0011Surface.blockID, 1, 2);
		world.setBlock(i + 10, j + 24, k + 19, SpaceAgeCore.T0011Surface.blockID, 1, 2);
		world.setBlock(i + 10, j + 24, k + 20, SpaceAgeCore.T0011Surface.blockID, 1, 2);
		world.setBlock(i + 10, j + 24, k + 21, SpaceAgeCore.T0011Surface.blockID, 1, 2);
		world.setBlock(i + 10, j + 24, k + 22, SpaceAgeCore.T0011Surface.blockID, 1, 2);
		world.setBlock(i + 10, j + 24, k + 23, SpaceAgeCore.T0011Surface.blockID, 1, 2);
		world.setBlock(i + 10, j + 24, k + 24, SpaceAgeCore.T0011Surface.blockID, 1, 2);
		world.setBlock(i + 10, j + 25, k + 1, SpaceAgeCore.T0011Surface.blockID, 1, 2);
		world.setBlock(i + 10, j + 25, k + 2, SpaceAgeCore.T0011Surface.blockID, 1, 2);
		world.setBlock(i + 10, j + 25, k + 3, SpaceAgeCore.T0011Surface.blockID, 1, 2);
		world.setBlock(i + 10, j + 25, k + 4, SpaceAgeCore.T0011Surface.blockID, 1, 2);
		world.setBlock(i + 10, j + 25, k + 5, SpaceAgeCore.T0011Surface.blockID, 1, 2);
		world.setBlock(i + 10, j + 25, k + 6, SpaceAgeCore.T0011Surface.blockID, 1, 2);
		world.setBlock(i + 10, j + 25, k + 7, SpaceAgeCore.T0011Surface.blockID, 1, 2);
		world.setBlock(i + 10, j + 25, k + 8, SpaceAgeCore.T0011Surface.blockID, 1, 2);
		world.setBlock(i + 10, j + 25, k + 9, SpaceAgeCore.T0011Surface.blockID, 1, 2);
		world.setBlock(i + 10, j + 25, k + 10, SpaceAgeCore.T0011Surface.blockID, 1, 2);
		world.setBlock(i + 10, j + 25, k + 11, SpaceAgeCore.T0011Surface.blockID, 1, 2);
		world.setBlock(i + 10, j + 25, k + 12, SpaceAgeCore.T0011Surface.blockID, 1, 2);
		world.setBlock(i + 10, j + 25, k + 13, SpaceAgeCore.T0011Surface.blockID, 1, 2);
		world.setBlock(i + 10, j + 25, k + 14, SpaceAgeCore.T0011Surface.blockID, 1, 2);
		world.setBlock(i + 10, j + 25, k + 15, SpaceAgeCore.T0011Surface.blockID, 1, 2);
		world.setBlock(i + 10, j + 25, k + 16, SpaceAgeCore.T0011Surface.blockID, 1, 2);
		world.setBlock(i + 10, j + 25, k + 17, SpaceAgeCore.T0011Surface.blockID, 1, 2);
		world.setBlock(i + 10, j + 25, k + 18, SpaceAgeCore.T0011Surface.blockID, 1, 2);
		world.setBlock(i + 10, j + 25, k + 19, SpaceAgeCore.T0011Surface.blockID, 1, 2);
		world.setBlock(i + 10, j + 25, k + 20, SpaceAgeCore.T0011Surface.blockID, 1, 2);
		world.setBlock(i + 10, j + 25, k + 21, SpaceAgeCore.T0011Surface.blockID, 1, 2);
		world.setBlock(i + 10, j + 25, k + 22, SpaceAgeCore.T0011Surface.blockID, 1, 2);
		world.setBlock(i + 10, j + 25, k + 23, SpaceAgeCore.T0011Surface.blockID, 1, 2);
		world.setBlock(i + 10, j + 25, k + 24, SpaceAgeCore.T0011Surface.blockID, 1, 2);
		world.setBlock(i + 10, j + 26, k + 3, SpaceAgeCore.T0011Surface.blockID, 1, 2);
		world.setBlock(i + 10, j + 26, k + 4, SpaceAgeCore.T0011Surface.blockID, 1, 2);
		world.setBlock(i + 10, j + 26, k + 5, SpaceAgeCore.T0011Surface.blockID, 1, 2);
		world.setBlock(i + 10, j + 26, k + 6, SpaceAgeCore.T0011Surface.blockID, 1, 2);
		world.setBlock(i + 10, j + 26, k + 7, SpaceAgeCore.T0011Surface.blockID, 1, 2);
		world.setBlock(i + 10, j + 26, k + 8, SpaceAgeCore.T0011Surface.blockID, 1, 2);
		world.setBlock(i + 10, j + 26, k + 9, SpaceAgeCore.T0011Surface.blockID, 1, 2);
		world.setBlock(i + 10, j + 26, k + 10, SpaceAgeCore.T0011Surface.blockID, 1, 2);
		world.setBlock(i + 10, j + 26, k + 11, SpaceAgeCore.T0011Surface.blockID, 1, 2);
		world.setBlock(i + 10, j + 26, k + 12, SpaceAgeCore.T0011Surface.blockID, 1, 2);
		world.setBlock(i + 10, j + 26, k + 13, SpaceAgeCore.T0011Surface.blockID, 1, 2);
		world.setBlock(i + 10, j + 26, k + 14, SpaceAgeCore.T0011Surface.blockID, 1, 2);
		world.setBlock(i + 10, j + 26, k + 15, SpaceAgeCore.T0011Surface.blockID, 1, 2);
		world.setBlock(i + 10, j + 26, k + 16, SpaceAgeCore.T0011Surface.blockID, 1, 2);
		world.setBlock(i + 10, j + 26, k + 17, SpaceAgeCore.T0011Surface.blockID, 1, 2);
		world.setBlock(i + 10, j + 26, k + 18, SpaceAgeCore.T0011Surface.blockID, 1, 2);
		world.setBlock(i + 10, j + 26, k + 19, SpaceAgeCore.T0011Surface.blockID, 1, 2);
		world.setBlock(i + 10, j + 26, k + 20, SpaceAgeCore.T0011Surface.blockID, 1, 2);
		world.setBlock(i + 10, j + 26, k + 21, SpaceAgeCore.T0011Surface.blockID, 1, 2);
		world.setBlock(i + 10, j + 26, k + 22, SpaceAgeCore.T0011Surface.blockID, 1, 2);
		world.setBlock(i + 10, j + 26, k + 23, SpaceAgeCore.T0011Surface.blockID, 1, 2);
		world.setBlock(i + 10, j + 27, k + 4, SpaceAgeCore.T0011Surface.blockID, 1, 2);
		world.setBlock(i + 10, j + 27, k + 5, SpaceAgeCore.T0011Surface.blockID, 1, 2);
		world.setBlock(i + 10, j + 27, k + 6, SpaceAgeCore.T0011Surface.blockID, 1, 2);
		world.setBlock(i + 10, j + 27, k + 7, SpaceAgeCore.T0011Surface.blockID, 1, 2);
		world.setBlock(i + 10, j + 27, k + 8, SpaceAgeCore.T0011Surface.blockID, 1, 2);
		world.setBlock(i + 10, j + 27, k + 9, SpaceAgeCore.T0011Surface.blockID, 1, 2);
		world.setBlock(i + 10, j + 27, k + 10, SpaceAgeCore.T0011Surface.blockID, 1, 2);
		world.setBlock(i + 10, j + 27, k + 11, SpaceAgeCore.T0011Surface.blockID, 1, 2);
		world.setBlock(i + 10, j + 27, k + 12, SpaceAgeCore.T0011Surface.blockID, 1, 2);
		world.setBlock(i + 10, j + 27, k + 13, SpaceAgeCore.T0011Surface.blockID, 1, 2);
		world.setBlock(i + 10, j + 27, k + 14, SpaceAgeCore.T0011Surface.blockID, 1, 2);
		world.setBlock(i + 10, j + 27, k + 15, SpaceAgeCore.T0011Surface.blockID, 1, 2);
		world.setBlock(i + 10, j + 27, k + 16, SpaceAgeCore.T0011Surface.blockID, 1, 2);
		world.setBlock(i + 10, j + 27, k + 17, SpaceAgeCore.T0011Surface.blockID, 1, 2);
		world.setBlock(i + 10, j + 27, k + 18, SpaceAgeCore.T0011Surface.blockID, 1, 2);
		world.setBlock(i + 10, j + 27, k + 19, SpaceAgeCore.T0011Surface.blockID, 1, 2);
		world.setBlock(i + 10, j + 27, k + 20, SpaceAgeCore.T0011Surface.blockID, 1, 2);
		world.setBlock(i + 10, j + 27, k + 21, SpaceAgeCore.T0011Surface.blockID, 1, 2);
		world.setBlock(i + 10, j + 27, k + 22, SpaceAgeCore.T0011Surface.blockID, 1, 2);
		world.setBlock(i + 11, j + 12, k + 19, SpaceAgeCore.T0011Surface.blockID, 1, 2);
		world.setBlock(i + 11, j + 12, k + 20, SpaceAgeCore.T0011Surface.blockID, 1, 2);
		world.setBlock(i + 11, j + 12, k + 21, SpaceAgeCore.T0011Surface.blockID, 1, 2);
		world.setBlock(i + 11, j + 24, k + 0, SpaceAgeCore.T0011Surface.blockID, 1, 2);
		world.setBlock(i + 11, j + 24, k + 1, SpaceAgeCore.T0011Surface.blockID, 1, 2);
		world.setBlock(i + 11, j + 24, k + 2, SpaceAgeCore.T0011Surface.blockID, 1, 2);
		world.setBlock(i + 11, j + 24, k + 3, SpaceAgeCore.T0011Surface.blockID, 1, 2);
		world.setBlock(i + 11, j + 24, k + 4, SpaceAgeCore.T0011Surface.blockID, 1, 2);
		world.setBlock(i + 11, j + 24, k + 5, SpaceAgeCore.T0011Surface.blockID, 1, 2);
		world.setBlock(i + 11, j + 24, k + 6, SpaceAgeCore.T0011Surface.blockID, 1, 2);
		world.setBlock(i + 11, j + 24, k + 7, SpaceAgeCore.T0011Surface.blockID, 1, 2);
		world.setBlock(i + 11, j + 24, k + 8, SpaceAgeCore.T0011Surface.blockID, 1, 2);
		world.setBlock(i + 11, j + 24, k + 9, SpaceAgeCore.T0011Surface.blockID, 1, 2);
		world.setBlock(i + 11, j + 24, k + 10, SpaceAgeCore.T0011Surface.blockID, 1, 2);
		world.setBlock(i + 11, j + 24, k + 11, SpaceAgeCore.T0011Surface.blockID, 1, 2);
		world.setBlock(i + 11, j + 24, k + 12, SpaceAgeCore.T0011Surface.blockID, 1, 2);
		world.setBlock(i + 11, j + 24, k + 13, SpaceAgeCore.T0011Surface.blockID, 1, 2);
		world.setBlock(i + 11, j + 24, k + 14, SpaceAgeCore.T0011Surface.blockID, 1, 2);
		world.setBlock(i + 11, j + 24, k + 15, SpaceAgeCore.T0011Surface.blockID, 1, 2);
		world.setBlock(i + 11, j + 24, k + 16, SpaceAgeCore.T0011Surface.blockID, 1, 2);
		world.setBlock(i + 11, j + 24, k + 17, SpaceAgeCore.T0011Surface.blockID, 1, 2);
		world.setBlock(i + 11, j + 24, k + 18, SpaceAgeCore.T0011Surface.blockID, 1, 2);
		world.setBlock(i + 11, j + 24, k + 19, SpaceAgeCore.T0011Surface.blockID, 1, 2);
		world.setBlock(i + 11, j + 24, k + 20, SpaceAgeCore.T0011Surface.blockID, 1, 2);
		world.setBlock(i + 11, j + 24, k + 21, SpaceAgeCore.T0011Surface.blockID, 1, 2);
		world.setBlock(i + 11, j + 24, k + 22, SpaceAgeCore.T0011Surface.blockID, 1, 2);
		world.setBlock(i + 11, j + 24, k + 23, SpaceAgeCore.T0011Surface.blockID, 1, 2);
		world.setBlock(i + 11, j + 24, k + 24, SpaceAgeCore.T0011Surface.blockID, 1, 2);
		world.setBlock(i + 11, j + 25, k + 1, SpaceAgeCore.T0011Surface.blockID, 1, 2);
		world.setBlock(i + 11, j + 25, k + 2, SpaceAgeCore.T0011Surface.blockID, 1, 2);
		world.setBlock(i + 11, j + 25, k + 3, SpaceAgeCore.T0011Surface.blockID, 1, 2);
		world.setBlock(i + 11, j + 25, k + 4, SpaceAgeCore.T0011Surface.blockID, 1, 2);
		world.setBlock(i + 11, j + 25, k + 5, SpaceAgeCore.T0011Surface.blockID, 1, 2);
		world.setBlock(i + 11, j + 25, k + 6, SpaceAgeCore.T0011Surface.blockID, 1, 2);
		world.setBlock(i + 11, j + 25, k + 7, SpaceAgeCore.T0011Surface.blockID, 1, 2);
		world.setBlock(i + 11, j + 25, k + 8, SpaceAgeCore.T0011Surface.blockID, 1, 2);
		world.setBlock(i + 11, j + 25, k + 9, SpaceAgeCore.T0011Surface.blockID, 1, 2);
		world.setBlock(i + 11, j + 25, k + 10, SpaceAgeCore.T0011Surface.blockID, 1, 2);
		world.setBlock(i + 11, j + 25, k + 11, SpaceAgeCore.T0011Surface.blockID, 1, 2);
		world.setBlock(i + 11, j + 25, k + 12, SpaceAgeCore.T0011Surface.blockID, 1, 2);
		world.setBlock(i + 11, j + 25, k + 13, SpaceAgeCore.T0011Surface.blockID, 1, 2);
		world.setBlock(i + 11, j + 25, k + 14, SpaceAgeCore.T0011Surface.blockID, 1, 2);
		world.setBlock(i + 11, j + 25, k + 15, SpaceAgeCore.T0011Surface.blockID, 1, 2);
		world.setBlock(i + 11, j + 25, k + 16, SpaceAgeCore.T0011Surface.blockID, 1, 2);
		world.setBlock(i + 11, j + 25, k + 17, SpaceAgeCore.T0011Surface.blockID, 1, 2);
		world.setBlock(i + 11, j + 25, k + 18, SpaceAgeCore.T0011Surface.blockID, 1, 2);
		world.setBlock(i + 11, j + 25, k + 19, SpaceAgeCore.T0011Surface.blockID, 1, 2);
		world.setBlock(i + 11, j + 25, k + 20, SpaceAgeCore.T0011Surface.blockID, 1, 2);
		world.setBlock(i + 11, j + 25, k + 21, SpaceAgeCore.T0011Surface.blockID, 1, 2);
		world.setBlock(i + 11, j + 25, k + 22, SpaceAgeCore.T0011Surface.blockID, 1, 2);
		world.setBlock(i + 11, j + 25, k + 23, SpaceAgeCore.T0011Surface.blockID, 1, 2);
		world.setBlock(i + 11, j + 25, k + 24, SpaceAgeCore.T0011Surface.blockID, 1, 2);
		world.setBlock(i + 11, j + 26, k + 2, SpaceAgeCore.T0011Surface.blockID, 1, 2);
		world.setBlock(i + 11, j + 26, k + 3, SpaceAgeCore.T0011Surface.blockID, 1, 2);
		world.setBlock(i + 11, j + 26, k + 4, SpaceAgeCore.T0011Surface.blockID, 1, 2);
		world.setBlock(i + 11, j + 26, k + 5, SpaceAgeCore.T0011Surface.blockID, 1, 2);
		world.setBlock(i + 11, j + 26, k + 6, SpaceAgeCore.T0011Surface.blockID, 1, 2);
		world.setBlock(i + 11, j + 26, k + 7, SpaceAgeCore.T0011Surface.blockID, 1, 2);
		world.setBlock(i + 11, j + 26, k + 8, SpaceAgeCore.T0011Surface.blockID, 1, 2);
		world.setBlock(i + 11, j + 26, k + 9, SpaceAgeCore.T0011Surface.blockID, 1, 2);
		world.setBlock(i + 11, j + 26, k + 10, SpaceAgeCore.T0011Surface.blockID, 1, 2);
		world.setBlock(i + 11, j + 26, k + 11, SpaceAgeCore.T0011Surface.blockID, 1, 2);
		world.setBlock(i + 11, j + 26, k + 12, SpaceAgeCore.T0011Surface.blockID, 1, 2);
		world.setBlock(i + 11, j + 26, k + 13, SpaceAgeCore.T0011Surface.blockID, 1, 2);
		world.setBlock(i + 11, j + 26, k + 14, SpaceAgeCore.T0011Surface.blockID, 1, 2);
		world.setBlock(i + 11, j + 26, k + 15, SpaceAgeCore.T0011Surface.blockID, 1, 2);
		world.setBlock(i + 11, j + 26, k + 16, SpaceAgeCore.T0011Surface.blockID, 1, 2);
		world.setBlock(i + 11, j + 26, k + 17, SpaceAgeCore.T0011Surface.blockID, 1, 2);
		world.setBlock(i + 11, j + 26, k + 18, SpaceAgeCore.T0011Surface.blockID, 1, 2);
		world.setBlock(i + 11, j + 26, k + 19, SpaceAgeCore.T0011Surface.blockID, 1, 2);
		world.setBlock(i + 11, j + 26, k + 20, SpaceAgeCore.T0011Surface.blockID, 1, 2);
		world.setBlock(i + 11, j + 26, k + 21, SpaceAgeCore.T0011Surface.blockID, 1, 2);
		world.setBlock(i + 11, j + 26, k + 22, SpaceAgeCore.T0011Surface.blockID, 1, 2);
		world.setBlock(i + 11, j + 26, k + 23, SpaceAgeCore.T0011Surface.blockID, 1, 2);
		world.setBlock(i + 11, j + 26, k + 24, SpaceAgeCore.T0011Surface.blockID, 1, 2);
		world.setBlock(i + 11, j + 27, k + 3, SpaceAgeCore.T0011Surface.blockID, 1, 2);
		world.setBlock(i + 11, j + 27, k + 4, SpaceAgeCore.T0011Surface.blockID, 1, 2);
		world.setBlock(i + 11, j + 27, k + 5, SpaceAgeCore.T0011Surface.blockID, 1, 2);
		world.setBlock(i + 11, j + 27, k + 6, SpaceAgeCore.T0011Surface.blockID, 1, 2);
		world.setBlock(i + 11, j + 27, k + 7, SpaceAgeCore.T0011Surface.blockID, 1, 2);
		world.setBlock(i + 11, j + 27, k + 8, SpaceAgeCore.T0011Surface.blockID, 1, 2);
		world.setBlock(i + 11, j + 27, k + 9, SpaceAgeCore.T0011Surface.blockID, 1, 2);
		world.setBlock(i + 11, j + 27, k + 10, SpaceAgeCore.T0011Surface.blockID, 1, 2);
		world.setBlock(i + 11, j + 27, k + 11, SpaceAgeCore.T0011Surface.blockID, 1, 2);
		world.setBlock(i + 11, j + 27, k + 12, SpaceAgeCore.T0011Surface.blockID, 1, 2);
		world.setBlock(i + 11, j + 27, k + 13, SpaceAgeCore.T0011Surface.blockID, 1, 2);
		world.setBlock(i + 11, j + 27, k + 14, SpaceAgeCore.T0011Surface.blockID, 1, 2);
		world.setBlock(i + 11, j + 27, k + 15, SpaceAgeCore.T0011Surface.blockID, 1, 2);
		world.setBlock(i + 11, j + 27, k + 16, SpaceAgeCore.T0011Surface.blockID, 1, 2);
		world.setBlock(i + 11, j + 27, k + 17, SpaceAgeCore.T0011Surface.blockID, 1, 2);
		world.setBlock(i + 11, j + 27, k + 18, SpaceAgeCore.T0011Surface.blockID, 1, 2);
		world.setBlock(i + 11, j + 27, k + 19, SpaceAgeCore.T0011Surface.blockID, 1, 2);
		world.setBlock(i + 11, j + 27, k + 20, SpaceAgeCore.T0011Surface.blockID, 1, 2);
		world.setBlock(i + 11, j + 27, k + 21, SpaceAgeCore.T0011Surface.blockID, 1, 2);
		world.setBlock(i + 11, j + 27, k + 22, SpaceAgeCore.T0011Surface.blockID, 1, 2);
		world.setBlock(i + 11, j + 27, k + 23, SpaceAgeCore.T0011Surface.blockID, 1, 2);
		world.setBlock(i + 12, j + 0, k + 12, SpaceAgeCore.T0011Surface.blockID, 2, 2);
		world.setBlock(i + 12, j + 0, k + 13, SpaceAgeCore.T0011Surface.blockID, 2, 2);
		world.setBlock(i + 12, j + 0, k + 14, SpaceAgeCore.T0011Surface.blockID, 2, 2);
		world.setBlock(i + 12, j + 1, k + 12, SpaceAgeCore.T0011Surface.blockID, 2, 2);
		world.setBlock(i + 12, j + 1, k + 13, SpaceAgeCore.T0011Surface.blockID, 2, 2);
		world.setBlock(i + 12, j + 1, k + 14, SpaceAgeCore.T0011Surface.blockID, 2, 2);
		world.setBlock(i + 12, j + 2, k + 12, SpaceAgeCore.T0011Surface.blockID, 2, 2);
		world.setBlock(i + 12, j + 2, k + 13, SpaceAgeCore.T0011Surface.blockID, 2, 2);
		world.setBlock(i + 12, j + 2, k + 14, SpaceAgeCore.T0011Surface.blockID, 2, 2);
		world.setBlock(i + 12, j + 3, k + 12, SpaceAgeCore.T0011Surface.blockID, 2, 2);
		world.setBlock(i + 12, j + 3, k + 13, SpaceAgeCore.T0011Surface.blockID, 2, 2);
		world.setBlock(i + 12, j + 3, k + 14, SpaceAgeCore.T0011Surface.blockID, 2, 2);
		world.setBlock(i + 12, j + 4, k + 12, SpaceAgeCore.T0011Surface.blockID, 2, 2);
		world.setBlock(i + 12, j + 4, k + 13, SpaceAgeCore.T0011Surface.blockID, 2, 2);
		world.setBlock(i + 12, j + 4, k + 14, SpaceAgeCore.T0011Surface.blockID, 2, 2);
		world.setBlock(i + 12, j + 5, k + 12, SpaceAgeCore.T0011Surface.blockID, 2, 2);
		world.setBlock(i + 12, j + 5, k + 13, SpaceAgeCore.T0011Surface.blockID, 2, 2);
		world.setBlock(i + 12, j + 5, k + 14, SpaceAgeCore.T0011Surface.blockID, 2, 2);
		world.setBlock(i + 12, j + 6, k + 12, SpaceAgeCore.T0011Surface.blockID, 2, 2);
		world.setBlock(i + 12, j + 6, k + 13, SpaceAgeCore.T0011Surface.blockID, 2, 2);
		world.setBlock(i + 12, j + 6, k + 14, SpaceAgeCore.T0011Surface.blockID, 2, 2);
		world.setBlock(i + 12, j + 7, k + 12, SpaceAgeCore.T0011Surface.blockID, 2, 2);
		world.setBlock(i + 12, j + 7, k + 13, SpaceAgeCore.T0011Surface.blockID, 2, 2);
		world.setBlock(i + 12, j + 7, k + 14, SpaceAgeCore.T0011Surface.blockID, 2, 2);
		world.setBlock(i + 12, j + 8, k + 12, SpaceAgeCore.T0011Surface.blockID, 2, 2);
		world.setBlock(i + 12, j + 8, k + 13, SpaceAgeCore.T0011Surface.blockID, 2, 2);
		world.setBlock(i + 12, j + 8, k + 14, SpaceAgeCore.T0011Surface.blockID, 2, 2);
		world.setBlock(i + 12, j + 9, k + 12, SpaceAgeCore.T0011Surface.blockID, 2, 2);
		world.setBlock(i + 12, j + 9, k + 13, SpaceAgeCore.T0011Surface.blockID, 2, 2);
		world.setBlock(i + 12, j + 9, k + 14, SpaceAgeCore.T0011Surface.blockID, 2, 2);
		world.setBlock(i + 12, j + 10, k + 12, SpaceAgeCore.T0011Surface.blockID, 2, 2);
		world.setBlock(i + 12, j + 10, k + 13, SpaceAgeCore.T0011Surface.blockID, 2, 2);
		world.setBlock(i + 12, j + 10, k + 14, SpaceAgeCore.T0011Surface.blockID, 2, 2);
		world.setBlock(i + 12, j + 11, k + 12, SpaceAgeCore.T0011Surface.blockID, 2, 2);
		world.setBlock(i + 12, j + 11, k + 13, SpaceAgeCore.T0011Surface.blockID, 2, 2);
		world.setBlock(i + 12, j + 11, k + 14, SpaceAgeCore.T0011Surface.blockID, 2, 2);
		world.setBlock(i + 12, j + 12, k + 12, SpaceAgeCore.T0011Surface.blockID, 2, 2);
		world.setBlock(i + 12, j + 12, k + 13, SpaceAgeCore.T0011Surface.blockID, 2, 2);
		world.setBlock(i + 12, j + 12, k + 14, SpaceAgeCore.T0011Surface.blockID, 2, 2);
		world.setBlock(i + 12, j + 12, k + 18, SpaceAgeCore.T0011Surface.blockID, 1, 2);
		world.setBlock(i + 12, j + 12, k + 19, SpaceAgeCore.T0011Surface.blockID, 1, 2);
		world.setBlock(i + 12, j + 12, k + 20, SpaceAgeCore.T0011Surface.blockID, 1, 2);
		world.setBlock(i + 12, j + 12, k + 21, SpaceAgeCore.T0011Surface.blockID, 1, 2);
		world.setBlock(i + 12, j + 12, k + 22, SpaceAgeCore.T0011Surface.blockID, 1, 2);
		world.setBlock(i + 12, j + 13, k + 12, SpaceAgeCore.T0011Surface.blockID, 2, 2);
		world.setBlock(i + 12, j + 13, k + 13, SpaceAgeCore.T0011Surface.blockID, 2, 2);
		world.setBlock(i + 12, j + 13, k + 14, SpaceAgeCore.T0011Surface.blockID, 2, 2);
		world.setBlock(i + 12, j + 13, k + 19, SpaceAgeCore.T0011Surface.blockID, 1, 2);
		world.setBlock(i + 12, j + 13, k + 20, SpaceAgeCore.T0011Surface.blockID, 1, 2);
		world.setBlock(i + 12, j + 13, k + 21, SpaceAgeCore.T0011Surface.blockID, 1, 2);
		world.setBlock(i + 12, j + 14, k + 12, SpaceAgeCore.T0011Surface.blockID, 2, 2);
		world.setBlock(i + 12, j + 14, k + 13, SpaceAgeCore.T0011Surface.blockID, 2, 2);
		world.setBlock(i + 12, j + 14, k + 14, SpaceAgeCore.T0011Surface.blockID, 2, 2);
		world.setBlock(i + 12, j + 15, k + 12, SpaceAgeCore.T0011Surface.blockID, 2, 2);
		world.setBlock(i + 12, j + 15, k + 13, SpaceAgeCore.T0011Surface.blockID, 2, 2);
		world.setBlock(i + 12, j + 15, k + 14, SpaceAgeCore.T0011Surface.blockID, 2, 2);
		world.setBlock(i + 12, j + 16, k + 12, SpaceAgeCore.T0011Surface.blockID, 2, 2);
		world.setBlock(i + 12, j + 16, k + 13, SpaceAgeCore.T0011Surface.blockID, 2, 2);
		world.setBlock(i + 12, j + 16, k + 14, SpaceAgeCore.T0011Surface.blockID, 2, 2);
		world.setBlock(i + 12, j + 17, k + 12, SpaceAgeCore.T0011Surface.blockID, 2, 2);
		world.setBlock(i + 12, j + 17, k + 13, SpaceAgeCore.T0011Surface.blockID, 2, 2);
		world.setBlock(i + 12, j + 17, k + 14, SpaceAgeCore.T0011Surface.blockID, 2, 2);
		world.setBlock(i + 12, j + 18, k + 12, SpaceAgeCore.T0011Surface.blockID, 2, 2);
		world.setBlock(i + 12, j + 18, k + 13, SpaceAgeCore.T0011Surface.blockID, 2, 2);
		world.setBlock(i + 12, j + 18, k + 14, SpaceAgeCore.T0011Surface.blockID, 2, 2);
		world.setBlock(i + 12, j + 19, k + 5, SpaceAgeCore.T0011Surface.blockID, 1, 2);
		world.setBlock(i + 12, j + 19, k + 6, SpaceAgeCore.T0011Surface.blockID, 1, 2);
		world.setBlock(i + 12, j + 19, k + 7, SpaceAgeCore.T0011Surface.blockID, 1, 2);
		world.setBlock(i + 12, j + 19, k + 12, SpaceAgeCore.T0011Surface.blockID, 2, 2);
		world.setBlock(i + 12, j + 19, k + 13, SpaceAgeCore.T0011Surface.blockID, 2, 2);
		world.setBlock(i + 12, j + 19, k + 14, SpaceAgeCore.T0011Surface.blockID, 2, 2);
		world.setBlock(i + 12, j + 20, k + 12, SpaceAgeCore.T0011Surface.blockID, 2, 2);
		world.setBlock(i + 12, j + 20, k + 13, SpaceAgeCore.T0011Surface.blockID, 2, 2);
		world.setBlock(i + 12, j + 20, k + 14, SpaceAgeCore.T0011Surface.blockID, 2, 2);
		world.setBlock(i + 12, j + 21, k + 12, SpaceAgeCore.T0011Surface.blockID, 2, 2);
		world.setBlock(i + 12, j + 21, k + 13, SpaceAgeCore.T0011Surface.blockID, 2, 2);
		world.setBlock(i + 12, j + 21, k + 14, SpaceAgeCore.T0011Surface.blockID, 2, 2);
		world.setBlock(i + 12, j + 22, k + 12, SpaceAgeCore.T0011Surface.blockID, 2, 2);
		world.setBlock(i + 12, j + 22, k + 13, SpaceAgeCore.T0011Surface.blockID, 2, 2);
		world.setBlock(i + 12, j + 22, k + 14, SpaceAgeCore.T0011Surface.blockID, 2, 2);
		world.setBlock(i + 12, j + 23, k + 12, SpaceAgeCore.T0011Surface.blockID, 2, 2);
		world.setBlock(i + 12, j + 23, k + 13, SpaceAgeCore.T0011Surface.blockID, 2, 2);
		world.setBlock(i + 12, j + 23, k + 14, SpaceAgeCore.T0011Surface.blockID, 2, 2);
		world.setBlock(i + 12, j + 24, k + 0, SpaceAgeCore.T0011Surface.blockID, 1, 2);
		world.setBlock(i + 12, j + 24, k + 1, SpaceAgeCore.T0011Surface.blockID, 1, 2);
		world.setBlock(i + 12, j + 24, k + 2, SpaceAgeCore.T0011Surface.blockID, 1, 2);
		world.setBlock(i + 12, j + 24, k + 3, SpaceAgeCore.T0011Surface.blockID, 1, 2);
		world.setBlock(i + 12, j + 24, k + 4, SpaceAgeCore.T0011Surface.blockID, 1, 2);
		world.setBlock(i + 12, j + 24, k + 5, SpaceAgeCore.T0011Surface.blockID, 1, 2);
		world.setBlock(i + 12, j + 24, k + 6, SpaceAgeCore.T0011Surface.blockID, 1, 2);
		world.setBlock(i + 12, j + 24, k + 7, SpaceAgeCore.T0011Surface.blockID, 1, 2);
		world.setBlock(i + 12, j + 24, k + 8, SpaceAgeCore.T0011Surface.blockID, 1, 2);
		world.setBlock(i + 12, j + 24, k + 9, SpaceAgeCore.T0011Surface.blockID, 1, 2);
		world.setBlock(i + 12, j + 24, k + 10, SpaceAgeCore.T0011Surface.blockID, 1, 2);
		world.setBlock(i + 12, j + 24, k + 11, SpaceAgeCore.T0011Surface.blockID, 1, 2);
		world.setBlock(i + 12, j + 24, k + 12, SpaceAgeCore.T0011Surface.blockID, 2, 2);
		world.setBlock(i + 12, j + 24, k + 13, SpaceAgeCore.T0011Surface.blockID, 2, 2);
		world.setBlock(i + 12, j + 24, k + 14, SpaceAgeCore.T0011Surface.blockID, 2, 2);
		world.setBlock(i + 12, j + 24, k + 15, SpaceAgeCore.T0011Surface.blockID, 1, 2);
		world.setBlock(i + 12, j + 24, k + 16, SpaceAgeCore.T0011Surface.blockID, 1, 2);
		world.setBlock(i + 12, j + 24, k + 17, SpaceAgeCore.T0011Surface.blockID, 1, 2);
		world.setBlock(i + 12, j + 24, k + 18, SpaceAgeCore.T0011Surface.blockID, 1, 2);
		world.setBlock(i + 12, j + 24, k + 19, SpaceAgeCore.T0011Surface.blockID, 1, 2);
		world.setBlock(i + 12, j + 24, k + 20, SpaceAgeCore.T0011Surface.blockID, 1, 2);
		world.setBlock(i + 12, j + 24, k + 21, SpaceAgeCore.T0011Surface.blockID, 1, 2);
		world.setBlock(i + 12, j + 24, k + 22, SpaceAgeCore.T0011Surface.blockID, 1, 2);
		world.setBlock(i + 12, j + 24, k + 23, SpaceAgeCore.T0011Surface.blockID, 1, 2);
		world.setBlock(i + 12, j + 24, k + 24, SpaceAgeCore.T0011Surface.blockID, 1, 2);
		world.setBlock(i + 12, j + 25, k + 1, SpaceAgeCore.T0011Surface.blockID, 1, 2);
		world.setBlock(i + 12, j + 25, k + 2, SpaceAgeCore.T0011Surface.blockID, 1, 2);
		world.setBlock(i + 12, j + 25, k + 3, SpaceAgeCore.T0011Surface.blockID, 1, 2);
		world.setBlock(i + 12, j + 25, k + 4, SpaceAgeCore.T0011Surface.blockID, 1, 2);
		world.setBlock(i + 12, j + 25, k + 5, SpaceAgeCore.T0011Surface.blockID, 1, 2);
		world.setBlock(i + 12, j + 25, k + 6, SpaceAgeCore.T0011Surface.blockID, 1, 2);
		world.setBlock(i + 12, j + 25, k + 7, SpaceAgeCore.T0011Surface.blockID, 1, 2);
		world.setBlock(i + 12, j + 25, k + 8, SpaceAgeCore.T0011Surface.blockID, 1, 2);
		world.setBlock(i + 12, j + 25, k + 9, SpaceAgeCore.T0011Surface.blockID, 1, 2);
		world.setBlock(i + 12, j + 25, k + 10, SpaceAgeCore.T0011Surface.blockID, 1, 2);
		world.setBlock(i + 12, j + 25, k + 11, SpaceAgeCore.T0011Surface.blockID, 1, 2);
		world.setBlock(i + 12, j + 25, k + 12, SpaceAgeCore.T0011Surface.blockID, 2, 2);
		world.setBlock(i + 12, j + 25, k + 13, SpaceAgeCore.T0011Surface.blockID, 2, 2);
		world.setBlock(i + 12, j + 25, k + 14, SpaceAgeCore.T0011Surface.blockID, 2, 2);
		world.setBlock(i + 12, j + 25, k + 15, SpaceAgeCore.T0011Surface.blockID, 1, 2);
		world.setBlock(i + 12, j + 25, k + 16, SpaceAgeCore.T0011Surface.blockID, 1, 2);
		world.setBlock(i + 12, j + 25, k + 17, SpaceAgeCore.T0011Surface.blockID, 1, 2);
		world.setBlock(i + 12, j + 25, k + 18, SpaceAgeCore.T0011Surface.blockID, 1, 2);
		world.setBlock(i + 12, j + 25, k + 19, SpaceAgeCore.T0011Surface.blockID, 1, 2);
		world.setBlock(i + 12, j + 25, k + 20, SpaceAgeCore.T0011Surface.blockID, 1, 2);
		world.setBlock(i + 12, j + 25, k + 21, SpaceAgeCore.T0011Surface.blockID, 1, 2);
		world.setBlock(i + 12, j + 25, k + 22, SpaceAgeCore.T0011Surface.blockID, 1, 2);
		world.setBlock(i + 12, j + 25, k + 23, SpaceAgeCore.T0011Surface.blockID, 1, 2);
		world.setBlock(i + 12, j + 25, k + 24, SpaceAgeCore.T0011Surface.blockID, 1, 2);
		world.setBlock(i + 12, j + 26, k + 2, SpaceAgeCore.T0011Surface.blockID, 1, 2);
		world.setBlock(i + 12, j + 26, k + 3, SpaceAgeCore.T0011Surface.blockID, 1, 2);
		world.setBlock(i + 12, j + 26, k + 4, SpaceAgeCore.T0011Surface.blockID, 1, 2);
		world.setBlock(i + 12, j + 26, k + 5, SpaceAgeCore.T0011Surface.blockID, 1, 2);
		world.setBlock(i + 12, j + 26, k + 6, SpaceAgeCore.T0011Surface.blockID, 1, 2);
		world.setBlock(i + 12, j + 26, k + 7, SpaceAgeCore.T0011Surface.blockID, 1, 2);
		world.setBlock(i + 12, j + 26, k + 8, SpaceAgeCore.T0011Surface.blockID, 1, 2);
		world.setBlock(i + 12, j + 26, k + 9, SpaceAgeCore.T0011Surface.blockID, 1, 2);
		world.setBlock(i + 12, j + 26, k + 10, SpaceAgeCore.T0011Surface.blockID, 1, 2);
		world.setBlock(i + 12, j + 26, k + 11, SpaceAgeCore.T0011Surface.blockID, 1, 2);
		world.setBlock(i + 12, j + 26, k + 12, SpaceAgeCore.T0011Surface.blockID, 2, 2);
		world.setBlock(i + 12, j + 26, k + 13, SpaceAgeCore.T0011Surface.blockID, 2, 2);
		world.setBlock(i + 12, j + 26, k + 14, SpaceAgeCore.T0011Surface.blockID, 2, 2);
		world.setBlock(i + 12, j + 26, k + 15, SpaceAgeCore.T0011Surface.blockID, 1, 2);
		world.setBlock(i + 12, j + 26, k + 16, SpaceAgeCore.T0011Surface.blockID, 1, 2);
		world.setBlock(i + 12, j + 26, k + 17, SpaceAgeCore.T0011Surface.blockID, 1, 2);
		world.setBlock(i + 12, j + 26, k + 18, SpaceAgeCore.T0011Surface.blockID, 1, 2);
		world.setBlock(i + 12, j + 26, k + 19, SpaceAgeCore.T0011Surface.blockID, 1, 2);
		world.setBlock(i + 12, j + 26, k + 20, SpaceAgeCore.T0011Surface.blockID, 1, 2);
		world.setBlock(i + 12, j + 26, k + 21, SpaceAgeCore.T0011Surface.blockID, 1, 2);
		world.setBlock(i + 12, j + 26, k + 22, SpaceAgeCore.T0011Surface.blockID, 1, 2);
		world.setBlock(i + 12, j + 26, k + 23, SpaceAgeCore.T0011Surface.blockID, 1, 2);
		world.setBlock(i + 12, j + 26, k + 24, SpaceAgeCore.T0011Surface.blockID, 1, 2);
		world.setBlock(i + 12, j + 27, k + 3, SpaceAgeCore.T0011Surface.blockID, 1, 2);
		world.setBlock(i + 12, j + 27, k + 4, SpaceAgeCore.T0011Surface.blockID, 1, 2);
		world.setBlock(i + 12, j + 27, k + 5, SpaceAgeCore.T0011Surface.blockID, 1, 2);
		world.setBlock(i + 12, j + 27, k + 6, SpaceAgeCore.T0011Surface.blockID, 1, 2);
		world.setBlock(i + 12, j + 27, k + 7, SpaceAgeCore.T0011Surface.blockID, 1, 2);
		world.setBlock(i + 12, j + 27, k + 8, SpaceAgeCore.T0011Surface.blockID, 1, 2);
		world.setBlock(i + 12, j + 27, k + 9, SpaceAgeCore.T0011Surface.blockID, 1, 2);
		world.setBlock(i + 12, j + 27, k + 10, SpaceAgeCore.T0011Surface.blockID, 1, 2);
		world.setBlock(i + 12, j + 27, k + 11, SpaceAgeCore.T0011Surface.blockID, 1, 2);
		world.setBlock(i + 12, j + 27, k + 12, SpaceAgeCore.T0011Surface.blockID, 2, 2);
		world.setBlock(i + 12, j + 27, k + 13, SpaceAgeCore.T0011Surface.blockID, 2, 2);
		world.setBlock(i + 12, j + 27, k + 14, SpaceAgeCore.T0011Surface.blockID, 2, 2);
		world.setBlock(i + 12, j + 27, k + 15, SpaceAgeCore.T0011Surface.blockID, 1, 2);
		world.setBlock(i + 12, j + 27, k + 16, SpaceAgeCore.T0011Surface.blockID, 1, 2);
		world.setBlock(i + 12, j + 27, k + 17, SpaceAgeCore.T0011Surface.blockID, 1, 2);
		world.setBlock(i + 12, j + 27, k + 18, SpaceAgeCore.T0011Surface.blockID, 1, 2);
		world.setBlock(i + 12, j + 27, k + 19, SpaceAgeCore.T0011Surface.blockID, 1, 2);
		world.setBlock(i + 12, j + 27, k + 20, SpaceAgeCore.T0011Surface.blockID, 1, 2);
		world.setBlock(i + 12, j + 27, k + 21, SpaceAgeCore.T0011Surface.blockID, 1, 2);
		world.setBlock(i + 12, j + 27, k + 22, SpaceAgeCore.T0011Surface.blockID, 1, 2);
		world.setBlock(i + 12, j + 27, k + 23, SpaceAgeCore.T0011Surface.blockID, 1, 2);
		world.setBlock(i + 13, j + 0, k + 12, SpaceAgeCore.T0011Surface.blockID, 2, 2);
		world.setBlock(i + 13, j + 0, k + 14, SpaceAgeCore.T0011Surface.blockID, 2, 2);
		world.setBlock(i + 13, j + 1, k + 12, SpaceAgeCore.T0011Surface.blockID, 2, 2);
		world.setBlock(i + 13, j + 1, k + 14, SpaceAgeCore.T0011Surface.blockID, 2, 2);
		world.setBlock(i + 13, j + 2, k + 12, SpaceAgeCore.T0011Surface.blockID, 2, 2);
		world.setBlock(i + 13, j + 2, k + 14, SpaceAgeCore.T0011Surface.blockID, 2, 2);
		world.setBlock(i + 13, j + 3, k + 12, SpaceAgeCore.T0011Surface.blockID, 2, 2);
		world.setBlock(i + 13, j + 3, k + 14, SpaceAgeCore.T0011Surface.blockID, 2, 2);
		world.setBlock(i + 13, j + 4, k + 12, SpaceAgeCore.T0011Surface.blockID, 2, 2);
		world.setBlock(i + 13, j + 4, k + 14, SpaceAgeCore.T0011Surface.blockID, 2, 2);
		world.setBlock(i + 13, j + 5, k + 12, SpaceAgeCore.T0011Surface.blockID, 2, 2);
		world.setBlock(i + 13, j + 5, k + 14, SpaceAgeCore.T0011Surface.blockID, 2, 2);
		world.setBlock(i + 13, j + 6, k + 12, SpaceAgeCore.T0011Surface.blockID, 2, 2);
		world.setBlock(i + 13, j + 6, k + 14, SpaceAgeCore.T0011Surface.blockID, 2, 2);
		world.setBlock(i + 13, j + 7, k + 12, SpaceAgeCore.T0011Surface.blockID, 2, 2);
		world.setBlock(i + 13, j + 7, k + 14, SpaceAgeCore.T0011Surface.blockID, 2, 2);
		world.setBlock(i + 13, j + 8, k + 12, SpaceAgeCore.T0011Surface.blockID, 2, 2);
		world.setBlock(i + 13, j + 8, k + 14, SpaceAgeCore.T0011Surface.blockID, 2, 2);
		world.setBlock(i + 13, j + 9, k + 12, SpaceAgeCore.T0011Surface.blockID, 2, 2);
		world.setBlock(i + 13, j + 9, k + 14, SpaceAgeCore.T0011Surface.blockID, 2, 2);
		world.setBlock(i + 13, j + 10, k + 12, SpaceAgeCore.T0011Surface.blockID, 2, 2);
		world.setBlock(i + 13, j + 10, k + 14, SpaceAgeCore.T0011Surface.blockID, 2, 2);
		world.setBlock(i + 13, j + 11, k + 12, SpaceAgeCore.T0011Surface.blockID, 2, 2);
		world.setBlock(i + 13, j + 11, k + 14, SpaceAgeCore.T0011Surface.blockID, 2, 2);
		world.setBlock(i + 13, j + 12, k + 12, SpaceAgeCore.T0011Surface.blockID, 2, 2);
		world.setBlock(i + 13, j + 12, k + 14, SpaceAgeCore.T0011Surface.blockID, 2, 2);
		world.setBlock(i + 13, j + 12, k + 15, SpaceAgeCore.T0011Surface.blockID, 2, 2);
		world.setBlock(i + 13, j + 12, k + 16, SpaceAgeCore.T0011Surface.blockID, 2, 2);
		world.setBlock(i + 13, j + 12, k + 17, SpaceAgeCore.T0011Surface.blockID, 1, 2);
		world.setBlock(i + 13, j + 12, k + 18, SpaceAgeCore.T0011Surface.blockID, 1, 2);
		world.setBlock(i + 13, j + 12, k + 19, SpaceAgeCore.T0011Surface.blockID, 1, 2);
		world.setBlock(i + 13, j + 12, k + 20, SpaceAgeCore.T0011Surface.blockID, 1, 2);
		world.setBlock(i + 13, j + 12, k + 21, SpaceAgeCore.T0011Surface.blockID, 1, 2);
		world.setBlock(i + 13, j + 12, k + 22, SpaceAgeCore.T0011Surface.blockID, 1, 2);
		world.setBlock(i + 13, j + 12, k + 23, SpaceAgeCore.T0011Surface.blockID, 1, 2);
		world.setBlock(i + 13, j + 13, k + 12, SpaceAgeCore.T0011Surface.blockID, 2, 2);
		world.setBlock(i + 13, j + 13, k + 14, SpaceAgeCore.T0011Surface.blockID, 2, 2);
		world.setBlock(i + 13, j + 13, k + 18, SpaceAgeCore.T0011Surface.blockID, 1, 2);
		world.setBlock(i + 13, j + 13, k + 19, SpaceAgeCore.T0011Surface.blockID, 1, 2);
		world.setBlock(i + 13, j + 13, k + 20, SpaceAgeCore.T0011Surface.blockID, 1, 2);
		world.setBlock(i + 13, j + 13, k + 21, SpaceAgeCore.T0011Surface.blockID, 1, 2);
		world.setBlock(i + 13, j + 13, k + 22, SpaceAgeCore.T0011Surface.blockID, 1, 2);
		world.setBlock(i + 13, j + 14, k + 12, SpaceAgeCore.T0011Surface.blockID, 2, 2);
		world.setBlock(i + 13, j + 14, k + 14, SpaceAgeCore.T0011Surface.blockID, 2, 2);
		world.setBlock(i + 13, j + 14, k + 20, SpaceAgeCore.T0011Surface.blockID, 1, 2);
		world.setBlock(i + 13, j + 15, k + 12, SpaceAgeCore.T0011Surface.blockID, 2, 2);
		world.setBlock(i + 13, j + 15, k + 14, SpaceAgeCore.T0011Surface.blockID, 2, 2);
		world.setBlock(i + 13, j + 16, k + 12, SpaceAgeCore.T0011Surface.blockID, 2, 2);
		world.setBlock(i + 13, j + 16, k + 14, SpaceAgeCore.T0011Surface.blockID, 2, 2);
		world.setBlock(i + 13, j + 17, k + 12, SpaceAgeCore.T0011Surface.blockID, 2, 2);
		world.setBlock(i + 13, j + 17, k + 14, SpaceAgeCore.T0011Surface.blockID, 2, 2);
		world.setBlock(i + 13, j + 18, k + 12, SpaceAgeCore.T0011Surface.blockID, 2, 2);
		world.setBlock(i + 13, j + 18, k + 14, SpaceAgeCore.T0011Surface.blockID, 2, 2);
		world.setBlock(i + 13, j + 19, k + 4, SpaceAgeCore.T0011Surface.blockID, 1, 2);
		world.setBlock(i + 13, j + 19, k + 5, SpaceAgeCore.T0011Surface.blockID, 1, 2);
		world.setBlock(i + 13, j + 19, k + 6, SpaceAgeCore.T0011Surface.blockID, 1, 2);
		world.setBlock(i + 13, j + 19, k + 7, SpaceAgeCore.T0011Surface.blockID, 1, 2);
		world.setBlock(i + 13, j + 19, k + 8, SpaceAgeCore.T0011Surface.blockID, 1, 2);
		world.setBlock(i + 13, j + 19, k + 10, SpaceAgeCore.T0011Surface.blockID, 2, 2);
		world.setBlock(i + 13, j + 19, k + 11, SpaceAgeCore.T0011Surface.blockID, 2, 2);
		world.setBlock(i + 13, j + 19, k + 12, SpaceAgeCore.T0011Surface.blockID, 2, 2);
		world.setBlock(i + 13, j + 19, k + 14, SpaceAgeCore.T0011Surface.blockID, 2, 2);
		world.setBlock(i + 13, j + 20, k + 5, SpaceAgeCore.T0011Surface.blockID, 1, 2);
		world.setBlock(i + 13, j + 20, k + 6, SpaceAgeCore.T0011Surface.blockID, 1, 2);
		world.setBlock(i + 13, j + 20, k + 7, SpaceAgeCore.T0011Surface.blockID, 1, 2);
		world.setBlock(i + 13, j + 20, k + 12, SpaceAgeCore.T0011Surface.blockID, 2, 2);
		world.setBlock(i + 13, j + 20, k + 14, SpaceAgeCore.T0011Surface.blockID, 2, 2);
		world.setBlock(i + 13, j + 21, k + 12, SpaceAgeCore.T0011Surface.blockID, 2, 2);
		world.setBlock(i + 13, j + 21, k + 14, SpaceAgeCore.T0011Surface.blockID, 2, 2);
		world.setBlock(i + 13, j + 22, k + 12, SpaceAgeCore.T0011Surface.blockID, 2, 2);
		world.setBlock(i + 13, j + 22, k + 14, SpaceAgeCore.T0011Surface.blockID, 2, 2);
		world.setBlock(i + 13, j + 23, k + 12, SpaceAgeCore.T0011Surface.blockID, 2, 2);
		world.setBlock(i + 13, j + 23, k + 14, SpaceAgeCore.T0011Surface.blockID, 2, 2);
		world.setBlock(i + 13, j + 24, k + 0, SpaceAgeCore.T0011Surface.blockID, 1, 2);
		world.setBlock(i + 13, j + 24, k + 1, SpaceAgeCore.T0011Surface.blockID, 1, 2);
		world.setBlock(i + 13, j + 24, k + 2, SpaceAgeCore.T0011Surface.blockID, 1, 2);
		world.setBlock(i + 13, j + 24, k + 3, SpaceAgeCore.T0011Surface.blockID, 1, 2);
		world.setBlock(i + 13, j + 24, k + 4, SpaceAgeCore.T0011Surface.blockID, 1, 2);
		world.setBlock(i + 13, j + 24, k + 5, SpaceAgeCore.T0011Surface.blockID, 1, 2);
		world.setBlock(i + 13, j + 24, k + 6, SpaceAgeCore.T0011Surface.blockID, 1, 2);
		world.setBlock(i + 13, j + 24, k + 7, SpaceAgeCore.T0011Surface.blockID, 1, 2);
		world.setBlock(i + 13, j + 24, k + 8, SpaceAgeCore.T0011Surface.blockID, 1, 2);
		world.setBlock(i + 13, j + 24, k + 9, SpaceAgeCore.T0011Surface.blockID, 1, 2);
		world.setBlock(i + 13, j + 24, k + 10, SpaceAgeCore.T0011Surface.blockID, 1, 2);
		world.setBlock(i + 13, j + 24, k + 11, SpaceAgeCore.T0011Surface.blockID, 1, 2);
		world.setBlock(i + 13, j + 24, k + 12, SpaceAgeCore.T0011Surface.blockID, 2, 2);
		world.setBlock(i + 13, j + 24, k + 14, SpaceAgeCore.T0011Surface.blockID, 2, 2);
		world.setBlock(i + 13, j + 24, k + 15, SpaceAgeCore.T0011Surface.blockID, 1, 2);
		world.setBlock(i + 13, j + 24, k + 16, SpaceAgeCore.T0011Surface.blockID, 1, 2);
		world.setBlock(i + 13, j + 24, k + 17, SpaceAgeCore.T0011Surface.blockID, 1, 2);
		world.setBlock(i + 13, j + 24, k + 18, SpaceAgeCore.T0011Surface.blockID, 1, 2);
		world.setBlock(i + 13, j + 24, k + 19, SpaceAgeCore.T0011Surface.blockID, 1, 2);
		world.setBlock(i + 13, j + 24, k + 20, SpaceAgeCore.T0011Surface.blockID, 1, 2);
		world.setBlock(i + 13, j + 24, k + 21, SpaceAgeCore.T0011Surface.blockID, 1, 2);
		world.setBlock(i + 13, j + 24, k + 22, SpaceAgeCore.T0011Surface.blockID, 1, 2);
		world.setBlock(i + 13, j + 24, k + 23, SpaceAgeCore.T0011Surface.blockID, 1, 2);
		world.setBlock(i + 13, j + 24, k + 24, SpaceAgeCore.T0011Surface.blockID, 1, 2);
		world.setBlock(i + 13, j + 25, k + 1, SpaceAgeCore.T0011Surface.blockID, 1, 2);
		world.setBlock(i + 13, j + 25, k + 2, SpaceAgeCore.T0011Surface.blockID, 1, 2);
		world.setBlock(i + 13, j + 25, k + 3, SpaceAgeCore.T0011Surface.blockID, 1, 2);
		world.setBlock(i + 13, j + 25, k + 4, SpaceAgeCore.T0011Surface.blockID, 1, 2);
		world.setBlock(i + 13, j + 25, k + 5, SpaceAgeCore.T0011Surface.blockID, 1, 2);
		world.setBlock(i + 13, j + 25, k + 6, SpaceAgeCore.T0011Surface.blockID, 1, 2);
		world.setBlock(i + 13, j + 25, k + 7, SpaceAgeCore.T0011Surface.blockID, 1, 2);
		world.setBlock(i + 13, j + 25, k + 8, SpaceAgeCore.T0011Surface.blockID, 1, 2);
		world.setBlock(i + 13, j + 25, k + 9, SpaceAgeCore.T0011Surface.blockID, 1, 2);
		world.setBlock(i + 13, j + 25, k + 10, SpaceAgeCore.T0011Surface.blockID, 1, 2);
		world.setBlock(i + 13, j + 25, k + 11, SpaceAgeCore.T0011Surface.blockID, 1, 2);
		world.setBlock(i + 13, j + 25, k + 12, SpaceAgeCore.T0011Surface.blockID, 2, 2);
		world.setBlock(i + 13, j + 25, k + 14, SpaceAgeCore.T0011Surface.blockID, 2, 2);
		world.setBlock(i + 13, j + 25, k + 15, SpaceAgeCore.T0011Surface.blockID, 1, 2);
		world.setBlock(i + 13, j + 25, k + 16, SpaceAgeCore.T0011Surface.blockID, 1, 2);
		world.setBlock(i + 13, j + 25, k + 17, SpaceAgeCore.T0011Surface.blockID, 1, 2);
		world.setBlock(i + 13, j + 25, k + 18, SpaceAgeCore.T0011Surface.blockID, 1, 2);
		world.setBlock(i + 13, j + 25, k + 19, SpaceAgeCore.T0011Surface.blockID, 1, 2);
		world.setBlock(i + 13, j + 25, k + 20, SpaceAgeCore.T0011Surface.blockID, 1, 2);
		world.setBlock(i + 13, j + 25, k + 21, SpaceAgeCore.T0011Surface.blockID, 1, 2);
		world.setBlock(i + 13, j + 25, k + 22, SpaceAgeCore.T0011Surface.blockID, 1, 2);
		world.setBlock(i + 13, j + 25, k + 23, SpaceAgeCore.T0011Surface.blockID, 1, 2);
		world.setBlock(i + 13, j + 25, k + 24, SpaceAgeCore.T0011Surface.blockID, 1, 2);
		world.setBlock(i + 13, j + 26, k + 2, SpaceAgeCore.T0011Surface.blockID, 1, 2);
		world.setBlock(i + 13, j + 26, k + 3, SpaceAgeCore.T0011Surface.blockID, 1, 2);
		world.setBlock(i + 13, j + 26, k + 4, SpaceAgeCore.T0011Surface.blockID, 1, 2);
		world.setBlock(i + 13, j + 26, k + 5, SpaceAgeCore.T0011Surface.blockID, 1, 2);
		world.setBlock(i + 13, j + 26, k + 6, SpaceAgeCore.T0011Surface.blockID, 1, 2);
		world.setBlock(i + 13, j + 26, k + 7, SpaceAgeCore.T0011Surface.blockID, 1, 2);
		world.setBlock(i + 13, j + 26, k + 8, SpaceAgeCore.T0011Surface.blockID, 1, 2);
		world.setBlock(i + 13, j + 26, k + 9, SpaceAgeCore.T0011Surface.blockID, 1, 2);
		world.setBlock(i + 13, j + 26, k + 10, SpaceAgeCore.T0011Surface.blockID, 1, 2);
		world.setBlock(i + 13, j + 26, k + 11, SpaceAgeCore.T0011Surface.blockID, 1, 2);
		world.setBlock(i + 13, j + 26, k + 12, SpaceAgeCore.T0011Surface.blockID, 2, 2);
		world.setBlock(i + 13, j + 26, k + 14, SpaceAgeCore.T0011Surface.blockID, 2, 2);
		world.setBlock(i + 13, j + 26, k + 15, SpaceAgeCore.T0011Surface.blockID, 1, 2);
		world.setBlock(i + 13, j + 26, k + 16, SpaceAgeCore.T0011Surface.blockID, 1, 2);
		world.setBlock(i + 13, j + 26, k + 17, SpaceAgeCore.T0011Surface.blockID, 1, 2);
		world.setBlock(i + 13, j + 26, k + 18, SpaceAgeCore.T0011Surface.blockID, 1, 2);
		world.setBlock(i + 13, j + 26, k + 19, SpaceAgeCore.T0011Surface.blockID, 1, 2);
		world.setBlock(i + 13, j + 26, k + 20, SpaceAgeCore.T0011Surface.blockID, 1, 2);
		world.setBlock(i + 13, j + 26, k + 21, SpaceAgeCore.T0011Surface.blockID, 1, 2);
		world.setBlock(i + 13, j + 26, k + 22, SpaceAgeCore.T0011Surface.blockID, 1, 2);
		world.setBlock(i + 13, j + 26, k + 23, SpaceAgeCore.T0011Surface.blockID, 1, 2);
		world.setBlock(i + 13, j + 26, k + 24, SpaceAgeCore.T0011Surface.blockID, 1, 2);
		world.setBlock(i + 13, j + 27, k + 3, SpaceAgeCore.T0011Surface.blockID, 1, 2);
		world.setBlock(i + 13, j + 27, k + 4, SpaceAgeCore.T0011Surface.blockID, 1, 2);
		world.setBlock(i + 13, j + 27, k + 5, SpaceAgeCore.T0011Surface.blockID, 1, 2);
		world.setBlock(i + 13, j + 27, k + 6, SpaceAgeCore.T0011Surface.blockID, 1, 2);
		world.setBlock(i + 13, j + 27, k + 7, SpaceAgeCore.T0011Surface.blockID, 1, 2);
		world.setBlock(i + 13, j + 27, k + 8, SpaceAgeCore.T0011Surface.blockID, 1, 2);
		world.setBlock(i + 13, j + 27, k + 9, SpaceAgeCore.T0011Surface.blockID, 1, 2);
		world.setBlock(i + 13, j + 27, k + 10, SpaceAgeCore.T0011Surface.blockID, 1, 2);
		world.setBlock(i + 13, j + 27, k + 11, SpaceAgeCore.T0011Surface.blockID, 1, 2);
		world.setBlock(i + 13, j + 27, k + 12, SpaceAgeCore.T0011Surface.blockID, 2, 2);
		world.setBlock(i + 13, j + 27, k + 14, SpaceAgeCore.T0011Surface.blockID, 2, 2);
		world.setBlock(i + 13, j + 27, k + 15, SpaceAgeCore.T0011Surface.blockID, 1, 2);
		world.setBlock(i + 13, j + 27, k + 16, SpaceAgeCore.T0011Surface.blockID, 1, 2);
		world.setBlock(i + 13, j + 27, k + 17, SpaceAgeCore.T0011Surface.blockID, 1, 2);
		world.setBlock(i + 13, j + 27, k + 18, SpaceAgeCore.T0011Surface.blockID, 1, 2);
		world.setBlock(i + 13, j + 27, k + 19, SpaceAgeCore.T0011Surface.blockID, 1, 2);
		world.setBlock(i + 13, j + 27, k + 20, SpaceAgeCore.T0011Surface.blockID, 1, 2);
		world.setBlock(i + 13, j + 27, k + 21, SpaceAgeCore.T0011Surface.blockID, 1, 2);
		world.setBlock(i + 13, j + 27, k + 22, SpaceAgeCore.T0011Surface.blockID, 1, 2);
		world.setBlock(i + 13, j + 27, k + 23, SpaceAgeCore.T0011Surface.blockID, 1, 2);
		world.setBlock(i + 14, j + 0, k + 12, SpaceAgeCore.T0011Surface.blockID, 2, 2);
		world.setBlock(i + 14, j + 0, k + 13, SpaceAgeCore.T0011Surface.blockID, 2, 2);
		world.setBlock(i + 14, j + 0, k + 14, SpaceAgeCore.T0011Surface.blockID, 2, 2);
		world.setBlock(i + 14, j + 1, k + 12, SpaceAgeCore.T0011Surface.blockID, 2, 2);
		world.setBlock(i + 14, j + 1, k + 13, SpaceAgeCore.T0011Surface.blockID, 2, 2);
		world.setBlock(i + 14, j + 1, k + 14, SpaceAgeCore.T0011Surface.blockID, 2, 2);
		world.setBlock(i + 14, j + 2, k + 12, SpaceAgeCore.T0011Surface.blockID, 2, 2);
		world.setBlock(i + 14, j + 2, k + 13, SpaceAgeCore.T0011Surface.blockID, 2, 2);
		world.setBlock(i + 14, j + 2, k + 14, SpaceAgeCore.T0011Surface.blockID, 2, 2);
		world.setBlock(i + 14, j + 3, k + 12, SpaceAgeCore.T0011Surface.blockID, 2, 2);
		world.setBlock(i + 14, j + 3, k + 13, SpaceAgeCore.T0011Surface.blockID, 2, 2);
		world.setBlock(i + 14, j + 3, k + 14, SpaceAgeCore.T0011Surface.blockID, 2, 2);
		world.setBlock(i + 14, j + 4, k + 12, SpaceAgeCore.T0011Surface.blockID, 2, 2);
		world.setBlock(i + 14, j + 4, k + 13, SpaceAgeCore.T0011Surface.blockID, 2, 2);
		world.setBlock(i + 14, j + 4, k + 14, SpaceAgeCore.T0011Surface.blockID, 2, 2);
		world.setBlock(i + 14, j + 5, k + 12, SpaceAgeCore.T0011Surface.blockID, 2, 2);
		world.setBlock(i + 14, j + 5, k + 13, SpaceAgeCore.T0011Surface.blockID, 2, 2);
		world.setBlock(i + 14, j + 5, k + 14, SpaceAgeCore.T0011Surface.blockID, 2, 2);
		world.setBlock(i + 14, j + 6, k + 12, SpaceAgeCore.T0011Surface.blockID, 2, 2);
		world.setBlock(i + 14, j + 6, k + 13, SpaceAgeCore.T0011Surface.blockID, 2, 2);
		world.setBlock(i + 14, j + 6, k + 14, SpaceAgeCore.T0011Surface.blockID, 2, 2);
		world.setBlock(i + 14, j + 7, k + 12, SpaceAgeCore.T0011Surface.blockID, 2, 2);
		world.setBlock(i + 14, j + 7, k + 13, SpaceAgeCore.T0011Surface.blockID, 2, 2);
		world.setBlock(i + 14, j + 7, k + 14, SpaceAgeCore.T0011Surface.blockID, 2, 2);
		world.setBlock(i + 14, j + 8, k + 12, SpaceAgeCore.T0011Surface.blockID, 2, 2);
		world.setBlock(i + 14, j + 8, k + 13, SpaceAgeCore.T0011Surface.blockID, 2, 2);
		world.setBlock(i + 14, j + 8, k + 14, SpaceAgeCore.T0011Surface.blockID, 2, 2);
		world.setBlock(i + 14, j + 9, k + 12, SpaceAgeCore.T0011Surface.blockID, 2, 2);
		world.setBlock(i + 14, j + 9, k + 13, SpaceAgeCore.T0011Surface.blockID, 2, 2);
		world.setBlock(i + 14, j + 9, k + 14, SpaceAgeCore.T0011Surface.blockID, 2, 2);
		world.setBlock(i + 14, j + 10, k + 12, SpaceAgeCore.T0011Surface.blockID, 2, 2);
		world.setBlock(i + 14, j + 10, k + 13, SpaceAgeCore.T0011Surface.blockID, 2, 2);
		world.setBlock(i + 14, j + 10, k + 14, SpaceAgeCore.T0011Surface.blockID, 2, 2);
		world.setBlock(i + 14, j + 11, k + 12, SpaceAgeCore.T0011Surface.blockID, 2, 2);
		world.setBlock(i + 14, j + 11, k + 13, SpaceAgeCore.T0011Surface.blockID, 2, 2);
		world.setBlock(i + 14, j + 11, k + 14, SpaceAgeCore.T0011Surface.blockID, 2, 2);
		world.setBlock(i + 14, j + 12, k + 12, SpaceAgeCore.T0011Surface.blockID, 2, 2);
		world.setBlock(i + 14, j + 12, k + 13, SpaceAgeCore.T0011Surface.blockID, 2, 2);
		world.setBlock(i + 14, j + 12, k + 14, SpaceAgeCore.T0011Surface.blockID, 2, 2);
		world.setBlock(i + 14, j + 12, k + 17, SpaceAgeCore.T0011Surface.blockID, 1, 2);
		world.setBlock(i + 14, j + 12, k + 18, SpaceAgeCore.T0011Surface.blockID, 1, 2);
		world.setBlock(i + 14, j + 12, k + 19, SpaceAgeCore.T0011Surface.blockID, 1, 2);
		world.setBlock(i + 14, j + 12, k + 20, SpaceAgeCore.T0011Surface.blockID, 1, 2);
		world.setBlock(i + 14, j + 12, k + 21, SpaceAgeCore.T0011Surface.blockID, 1, 2);
		world.setBlock(i + 14, j + 12, k + 22, SpaceAgeCore.T0011Surface.blockID, 1, 2);
		world.setBlock(i + 14, j + 12, k + 23, SpaceAgeCore.T0011Surface.blockID, 1, 2);
		world.setBlock(i + 14, j + 13, k + 12, SpaceAgeCore.T0011Surface.blockID, 2, 2);
		world.setBlock(i + 14, j + 13, k + 13, SpaceAgeCore.T0011Surface.blockID, 2, 2);
		world.setBlock(i + 14, j + 13, k + 14, SpaceAgeCore.T0011Surface.blockID, 2, 2);
		world.setBlock(i + 14, j + 13, k + 16, SpaceAgeCore.T0011Surface.blockID, 2, 2);
		world.setBlock(i + 14, j + 13, k + 17, SpaceAgeCore.T0011Surface.blockID, 2, 2);
		world.setBlock(i + 14, j + 13, k + 18, SpaceAgeCore.T0011Surface.blockID, 2, 2);
		world.setBlock(i + 14, j + 13, k + 19, SpaceAgeCore.T0011Surface.blockID, 2, 2);
		world.setBlock(i + 14, j + 13, k + 20, SpaceAgeCore.T0011Surface.blockID, 1, 2);
		world.setBlock(i + 14, j + 13, k + 21, SpaceAgeCore.T0011Surface.blockID, 1, 2);
		world.setBlock(i + 14, j + 13, k + 22, SpaceAgeCore.T0011Surface.blockID, 1, 2);
		world.setBlock(i + 14, j + 14, k + 12, SpaceAgeCore.T0011Surface.blockID, 2, 2);
		world.setBlock(i + 14, j + 14, k + 13, SpaceAgeCore.T0011Surface.blockID, 2, 2);
		world.setBlock(i + 14, j + 14, k + 14, SpaceAgeCore.T0011Surface.blockID, 2, 2);
		world.setBlock(i + 14, j + 14, k + 19, SpaceAgeCore.T0011Surface.blockID, 1, 2);
		world.setBlock(i + 14, j + 14, k + 20, SpaceAgeCore.T0011Surface.blockID, 1, 2);
		world.setBlock(i + 14, j + 14, k + 21, SpaceAgeCore.T0011Surface.blockID, 1, 2);
		world.setBlock(i + 14, j + 15, k + 12, SpaceAgeCore.T0011Surface.blockID, 2, 2);
		world.setBlock(i + 14, j + 15, k + 13, SpaceAgeCore.T0011Surface.blockID, 2, 2);
		world.setBlock(i + 14, j + 15, k + 14, SpaceAgeCore.T0011Surface.blockID, 2, 2);
		world.setBlock(i + 14, j + 16, k + 12, SpaceAgeCore.T0011Surface.blockID, 2, 2);
		world.setBlock(i + 14, j + 16, k + 13, SpaceAgeCore.T0011Surface.blockID, 2, 2);
		world.setBlock(i + 14, j + 16, k + 14, SpaceAgeCore.T0011Surface.blockID, 2, 2);
		world.setBlock(i + 14, j + 17, k + 12, SpaceAgeCore.T0011Surface.blockID, 2, 2);
		world.setBlock(i + 14, j + 17, k + 13, SpaceAgeCore.T0011Surface.blockID, 2, 2);
		world.setBlock(i + 14, j + 17, k + 14, SpaceAgeCore.T0011Surface.blockID, 2, 2);
		world.setBlock(i + 14, j + 18, k + 12, SpaceAgeCore.T0011Surface.blockID, 2, 2);
		world.setBlock(i + 14, j + 18, k + 13, SpaceAgeCore.T0011Surface.blockID, 2, 2);
		world.setBlock(i + 14, j + 18, k + 14, SpaceAgeCore.T0011Surface.blockID, 2, 2);
		world.setBlock(i + 14, j + 19, k + 3, SpaceAgeCore.T0011Surface.blockID, 1, 2);
		world.setBlock(i + 14, j + 19, k + 4, SpaceAgeCore.T0011Surface.blockID, 1, 2);
		world.setBlock(i + 14, j + 19, k + 5, SpaceAgeCore.T0011Surface.blockID, 1, 2);
		world.setBlock(i + 14, j + 19, k + 6, SpaceAgeCore.T0011Surface.blockID, 1, 2);
		world.setBlock(i + 14, j + 19, k + 7, SpaceAgeCore.T0011Surface.blockID, 1, 2);
		world.setBlock(i + 14, j + 19, k + 8, SpaceAgeCore.T0011Surface.blockID, 1, 2);
		world.setBlock(i + 14, j + 19, k + 9, SpaceAgeCore.T0011Surface.blockID, 1, 2);
		world.setBlock(i + 14, j + 19, k + 12, SpaceAgeCore.T0011Surface.blockID, 2, 2);
		world.setBlock(i + 14, j + 19, k + 13, SpaceAgeCore.T0011Surface.blockID, 2, 2);
		world.setBlock(i + 14, j + 19, k + 14, SpaceAgeCore.T0011Surface.blockID, 2, 2);
		world.setBlock(i + 14, j + 20, k + 4, SpaceAgeCore.T0011Surface.blockID, 1, 2);
		world.setBlock(i + 14, j + 20, k + 5, SpaceAgeCore.T0011Surface.blockID, 1, 2);
		world.setBlock(i + 14, j + 20, k + 6, SpaceAgeCore.T0011Surface.blockID, 1, 2);
		world.setBlock(i + 14, j + 20, k + 7, SpaceAgeCore.T0011Surface.blockID, 1, 2);
		world.setBlock(i + 14, j + 20, k + 8, SpaceAgeCore.T0011Surface.blockID, 2, 2);
		world.setBlock(i + 14, j + 20, k + 9, SpaceAgeCore.T0011Surface.blockID, 2, 2);
		world.setBlock(i + 14, j + 20, k + 12, SpaceAgeCore.T0011Surface.blockID, 2, 2);
		world.setBlock(i + 14, j + 20, k + 13, SpaceAgeCore.T0011Surface.blockID, 2, 2);
		world.setBlock(i + 14, j + 20, k + 14, SpaceAgeCore.T0011Surface.blockID, 2, 2);
		world.setBlock(i + 14, j + 21, k + 6, SpaceAgeCore.T0011Surface.blockID, 1, 2);
		world.setBlock(i + 14, j + 21, k + 12, SpaceAgeCore.T0011Surface.blockID, 2, 2);
		world.setBlock(i + 14, j + 21, k + 13, SpaceAgeCore.T0011Surface.blockID, 2, 2);
		world.setBlock(i + 14, j + 21, k + 14, SpaceAgeCore.T0011Surface.blockID, 2, 2);
		world.setBlock(i + 14, j + 22, k + 12, SpaceAgeCore.T0011Surface.blockID, 2, 2);
		world.setBlock(i + 14, j + 22, k + 13, SpaceAgeCore.T0011Surface.blockID, 2, 2);
		world.setBlock(i + 14, j + 22, k + 14, SpaceAgeCore.T0011Surface.blockID, 2, 2);
		world.setBlock(i + 14, j + 23, k + 12, SpaceAgeCore.T0011Surface.blockID, 2, 2);
		world.setBlock(i + 14, j + 23, k + 13, SpaceAgeCore.T0011Surface.blockID, 2, 2);
