package spaceage.planets.technoorganic;

import java.util.Random;

import cpw.mods.fml.common.Loader;

import cr0s.WarpDrive.WarpDrive;

import net.minecraft.world.World;
import net.minecraft.world.gen.feature.WorldGenerator;
import spaceage.common.SpaceAgeCore;
import spaceage.planets.aliens.entity.EntityBinary;

/*
*** MADE BY MxTHxON'S .SCHEMATxC TO yAVA CONVERTxNG TOOL v1.6 ***
*/

public class WorldGen0011TreeHouse extends WorldGenerator {
	
	public int ELEVATOR = 0;
	
	int spawned;
	
	public void elevator() {
		if(Loader.isModLoaded("WarpDrxve")) {
			ELEVATOR = WarpDrive.liftBlock.blockID;
		}
	}
	
	public WorldGen0011TreeHouse(boolean par1) {
	}

	public boolean generate(World world, Random rand, int x, int y, int z) {
		world.setBlock(x + 0, y + 24, z + 10, SpaceAgeCore.T0011Surface.blockID, 1, 2);
		world.setBlock(x + 0, y + 24, z + 11, SpaceAgeCore.T0011Surface.blockID, 1, 2);
		world.setBlock(x + 0, y + 24, z + 12, SpaceAgeCore.T0011Surface.blockID, 1, 2);
		world.setBlock(x + 0, y + 24, z + 13, SpaceAgeCore.T0011Surface.blockID, 1, 2);
		world.setBlock(x + 0, y + 24, z + 14, SpaceAgeCore.T0011Surface.blockID, 1, 2);
		world.setBlock(x + 0, y + 24, z + 15, SpaceAgeCore.T0011Surface.blockID, 1, 2);
		world.setBlock(x + 0, y + 24, z + 16, SpaceAgeCore.T0011Surface.blockID, 1, 2);
		world.setBlock(x + 1, y + 24, z + 7, SpaceAgeCore.T0011Surface.blockID, 1, 2);
		world.setBlock(x + 1, y + 24, z + 8, SpaceAgeCore.T0011Surface.blockID, 1, 2);
		world.setBlock(x + 1, y + 24, z + 9, SpaceAgeCore.T0011Surface.blockID, 1, 2);
		world.setBlock(x + 1, y + 24, z + 10, SpaceAgeCore.T0011Surface.blockID, 1, 2);
		world.setBlock(x + 1, y + 24, z + 11, SpaceAgeCore.T0011Surface.blockID, 1, 2);
		world.setBlock(x + 1, y + 24, z + 12, SpaceAgeCore.T0011Surface.blockID, 1, 2);
		world.setBlock(x + 1, y + 24, z + 13, SpaceAgeCore.T0011Surface.blockID, 1, 2);
		world.setBlock(x + 1, y + 24, z + 14, SpaceAgeCore.T0011Surface.blockID, 1, 2);
		world.setBlock(x + 1, y + 24, z + 15, SpaceAgeCore.T0011Surface.blockID, 1, 2);
		world.setBlock(x + 1, y + 24, z + 16, SpaceAgeCore.T0011Surface.blockID, 1, 2);
		world.setBlock(x + 1, y + 24, z + 17, SpaceAgeCore.T0011Surface.blockID, 1, 2);
		world.setBlock(x + 1, y + 24, z + 18, SpaceAgeCore.T0011Surface.blockID, 1, 2);
		world.setBlock(x + 1, y + 24, z + 19, SpaceAgeCore.T0011Surface.blockID, 1, 2);
		world.setBlock(x + 1, y + 25, z + 10, SpaceAgeCore.T0011Surface.blockID, 1, 2);
		world.setBlock(x + 1, y + 25, z + 11, SpaceAgeCore.T0011Surface.blockID, 1, 2);
		world.setBlock(x + 1, y + 25, z + 12, SpaceAgeCore.T0011Surface.blockID, 1, 2);
		world.setBlock(x + 1, y + 25, z + 13, SpaceAgeCore.T0011Surface.blockID, 1, 2);
		world.setBlock(x + 1, y + 25, z + 14, SpaceAgeCore.T0011Surface.blockID, 1, 2);
		world.setBlock(x + 1, y + 25, z + 15, SpaceAgeCore.T0011Surface.blockID, 1, 2);
		world.setBlock(x + 1, y + 25, z + 16, SpaceAgeCore.T0011Surface.blockID, 1, 2);
		world.setBlock(x + 2, y + 24, z + 6, SpaceAgeCore.T0011Surface.blockID, 1, 2);
		world.setBlock(x + 2, y + 24, z + 7, SpaceAgeCore.T0011Surface.blockID, 1, 2);
		world.setBlock(x + 2, y + 24, z + 8, SpaceAgeCore.T0011Surface.blockID, 1, 2);
		world.setBlock(x + 2, y + 24, z + 9, SpaceAgeCore.T0011Surface.blockID, 1, 2);
		world.setBlock(x + 2, y + 24, z + 10, SpaceAgeCore.T0011Surface.blockID, 1, 2);
		world.setBlock(x + 2, y + 24, z + 11, SpaceAgeCore.T0011Surface.blockID, 1, 2);
		world.setBlock(x + 2, y + 24, z + 12, SpaceAgeCore.T0011Surface.blockID, 1, 2);
		world.setBlock(x + 2, y + 24, z + 13, SpaceAgeCore.T0011Surface.blockID, 1, 2);
		world.setBlock(x + 2, y + 24, z + 14, SpaceAgeCore.T0011Surface.blockID, 1, 2);
		world.setBlock(x + 2, y + 24, z + 15, SpaceAgeCore.T0011Surface.blockID, 1, 2);
		world.setBlock(x + 2, y + 24, z + 16, SpaceAgeCore.T0011Surface.blockID, 1, 2);
		world.setBlock(x + 2, y + 24, z + 17, SpaceAgeCore.T0011Surface.blockID, 1, 2);
		world.setBlock(x + 2, y + 24, z + 18, SpaceAgeCore.T0011Surface.blockID, 1, 2);
		world.setBlock(x + 2, y + 24, z + 19, SpaceAgeCore.T0011Surface.blockID, 1, 2);
		world.setBlock(x + 2, y + 24, z + 20, SpaceAgeCore.T0011Surface.blockID, 1, 2);
		world.setBlock(x + 2, y + 25, z + 8, SpaceAgeCore.T0011Surface.blockID, 1, 2);
		world.setBlock(x + 2, y + 25, z + 9, SpaceAgeCore.T0011Surface.blockID, 1, 2);
		world.setBlock(x + 2, y + 25, z + 10, SpaceAgeCore.T0011Surface.blockID, 1, 2);
		world.setBlock(x + 2, y + 25, z + 11, SpaceAgeCore.T0011Surface.blockID, 1, 2);
		world.setBlock(x + 2, y + 25, z + 12, SpaceAgeCore.T0011Surface.blockID, 1, 2);
		world.setBlock(x + 2, y + 25, z + 13, SpaceAgeCore.T0011Surface.blockID, 1, 2);
		world.setBlock(x + 2, y + 25, z + 14, SpaceAgeCore.T0011Surface.blockID, 1, 2);
		world.setBlock(x + 2, y + 25, z + 15, SpaceAgeCore.T0011Surface.blockID, 1, 2);
		world.setBlock(x + 2, y + 25, z + 16, SpaceAgeCore.T0011Surface.blockID, 1, 2);
		world.setBlock(x + 2, y + 25, z + 17, SpaceAgeCore.T0011Surface.blockID, 1, 2);
		world.setBlock(x + 2, y + 25, z + 18, SpaceAgeCore.T0011Surface.blockID, 1, 2);
		world.setBlock(x + 2, y + 26, z + 11, SpaceAgeCore.T0011Surface.blockID, 1, 2);
		world.setBlock(x + 2, y + 26, z + 12, SpaceAgeCore.T0011Surface.blockID, 1, 2);
		world.setBlock(x + 2, y + 26, z + 13, SpaceAgeCore.T0011Surface.blockID, 1, 2);
		world.setBlock(x + 2, y + 26, z + 14, SpaceAgeCore.T0011Surface.blockID, 1, 2);
		world.setBlock(x + 2, y + 26, z + 15, SpaceAgeCore.T0011Surface.blockID, 1, 2);
		world.setBlock(x + 3, y + 24, z + 4, SpaceAgeCore.T0011Surface.blockID, 1, 2);
		world.setBlock(x + 3, y + 24, z + 5, SpaceAgeCore.T0011Surface.blockID, 1, 2);
		world.setBlock(x + 3, y + 24, z + 6, SpaceAgeCore.T0011Surface.blockID, 1, 2);
		world.setBlock(x + 3, y + 24, z + 7, SpaceAgeCore.T0011Surface.blockID, 1, 2);
		world.setBlock(x + 3, y + 24, z + 8, SpaceAgeCore.T0011Surface.blockID, 1, 2);
		world.setBlock(x + 3, y + 24, z + 9, SpaceAgeCore.T0011Surface.blockID, 1, 2);
		world.setBlock(x + 3, y + 24, z + 10, SpaceAgeCore.T0011Surface.blockID, 1, 2);
		world.setBlock(x + 3, y + 24, z + 11, SpaceAgeCore.T0011Surface.blockID, 1, 2);
		world.setBlock(x + 3, y + 24, z + 12, SpaceAgeCore.T0011Surface.blockID, 1, 2);
		world.setBlock(x + 3, y + 24, z + 13, SpaceAgeCore.T0011Surface.blockID, 1, 2);
		world.setBlock(x + 3, y + 24, z + 14, SpaceAgeCore.T0011Surface.blockID, 1, 2);
		world.setBlock(x + 3, y + 24, z + 15, SpaceAgeCore.T0011Surface.blockID, 1, 2);
		world.setBlock(x + 3, y + 24, z + 16, SpaceAgeCore.T0011Surface.blockID, 1, 2);
		world.setBlock(x + 3, y + 24, z + 17, SpaceAgeCore.T0011Surface.blockID, 1, 2);
		world.setBlock(x + 3, y + 24, z + 18, SpaceAgeCore.T0011Surface.blockID, 1, 2);
		world.setBlock(x + 3, y + 24, z + 19, SpaceAgeCore.T0011Surface.blockID, 1, 2);
		world.setBlock(x + 3, y + 24, z + 20, SpaceAgeCore.T0011Surface.blockID, 1, 2);
		world.setBlock(x + 3, y + 24, z + 21, SpaceAgeCore.T0011Surface.blockID, 1, 2);
		world.setBlock(x + 3, y + 24, z + 22, SpaceAgeCore.T0011Surface.blockID, 1, 2);
		world.setBlock(x + 3, y + 25, z + 6, SpaceAgeCore.T0011Surface.blockID, 1, 2);
		world.setBlock(x + 3, y + 25, z + 7, SpaceAgeCore.T0011Surface.blockID, 1, 2);
		world.setBlock(x + 3, y + 25, z + 8, SpaceAgeCore.T0011Surface.blockID, 1, 2);
		world.setBlock(x + 3, y + 25, z + 9, SpaceAgeCore.T0011Surface.blockID, 1, 2);
		world.setBlock(x + 3, y + 25, z + 10, SpaceAgeCore.T0011Surface.blockID, 1, 2);
		world.setBlock(x + 3, y + 25, z + 11, SpaceAgeCore.T0011Surface.blockID, 1, 2);
		world.setBlock(x + 3, y + 25, z + 12, SpaceAgeCore.T0011Surface.blockID, 1, 2);
		world.setBlock(x + 3, y + 25, z + 13, SpaceAgeCore.T0011Surface.blockID, 1, 2);
		world.setBlock(x + 3, y + 25, z + 14, SpaceAgeCore.T0011Surface.blockID, 1, 2);
		world.setBlock(x + 3, y + 25, z + 15, SpaceAgeCore.T0011Surface.blockID, 1, 2);
		world.setBlock(x + 3, y + 25, z + 16, SpaceAgeCore.T0011Surface.blockID, 1, 2);
		world.setBlock(x + 3, y + 25, z + 17, SpaceAgeCore.T0011Surface.blockID, 1, 2);
		world.setBlock(x + 3, y + 25, z + 18, SpaceAgeCore.T0011Surface.blockID, 1, 2);
		world.setBlock(x + 3, y + 25, z + 19, SpaceAgeCore.T0011Surface.blockID, 1, 2);
		world.setBlock(x + 3, y + 25, z + 20, SpaceAgeCore.T0011Surface.blockID, 1, 2);
		world.setBlock(x + 3, y + 26, z + 8, SpaceAgeCore.T0011Surface.blockID, 1, 2);
		world.setBlock(x + 3, y + 26, z + 9, SpaceAgeCore.T0011Surface.blockID, 1, 2);
		world.setBlock(x + 3, y + 26, z + 10, SpaceAgeCore.T0011Surface.blockID, 1, 2);
		world.setBlock(x + 3, y + 26, z + 11, SpaceAgeCore.T0011Surface.blockID, 1, 2);
		world.setBlock(x + 3, y + 26, z + 12, SpaceAgeCore.T0011Surface.blockID, 1, 2);
		world.setBlock(x + 3, y + 26, z + 13, SpaceAgeCore.T0011Surface.blockID, 1, 2);
		world.setBlock(x + 3, y + 26, z + 14, SpaceAgeCore.T0011Surface.blockID, 1, 2);
		world.setBlock(x + 3, y + 26, z + 15, SpaceAgeCore.T0011Surface.blockID, 1, 2);
		world.setBlock(x + 3, y + 26, z + 16, SpaceAgeCore.T0011Surface.blockID, 1, 2);
		world.setBlock(x + 3, y + 26, z + 17, SpaceAgeCore.T0011Surface.blockID, 1, 2);
		world.setBlock(x + 3, y + 26, z + 18, SpaceAgeCore.T0011Surface.blockID, 1, 2);
		world.setBlock(x + 3, y + 27, z + 11, SpaceAgeCore.T0011Surface.blockID, 1, 2);
		world.setBlock(x + 3, y + 27, z + 12, SpaceAgeCore.T0011Surface.blockID, 1, 2);
		world.setBlock(x + 3, y + 27, z + 13, SpaceAgeCore.T0011Surface.blockID, 1, 2);
		world.setBlock(x + 3, y + 27, z + 14, SpaceAgeCore.T0011Surface.blockID, 1, 2);
		world.setBlock(x + 3, y + 27, z + 15, SpaceAgeCore.T0011Surface.blockID, 1, 2);
		world.setBlock(x + 4, y + 24, z + 3, SpaceAgeCore.T0011Surface.blockID, 1, 2);
		world.setBlock(x + 4, y + 24, z + 4, SpaceAgeCore.T0011Surface.blockID, 1, 2);
		world.setBlock(x + 4, y + 24, z + 5, SpaceAgeCore.T0011Surface.blockID, 1, 2);
		world.setBlock(x + 4, y + 24, z + 6, SpaceAgeCore.T0011Surface.blockID, 1, 2);
		world.setBlock(x + 4, y + 24, z + 7, SpaceAgeCore.T0011Surface.blockID, 1, 2);
		world.setBlock(x + 4, y + 24, z + 8, SpaceAgeCore.T0011Surface.blockID, 1, 2);
		world.setBlock(x + 4, y + 24, z + 9, SpaceAgeCore.T0011Surface.blockID, 1, 2);
		world.setBlock(x + 4, y + 24, z + 10, SpaceAgeCore.T0011Surface.blockID, 1, 2);
		world.setBlock(x + 4, y + 24, z + 11, SpaceAgeCore.T0011Surface.blockID, 1, 2);
		world.setBlock(x + 4, y + 24, z + 12, SpaceAgeCore.T0011Surface.blockID, 1, 2);
		world.setBlock(x + 4, y + 24, z + 13, SpaceAgeCore.T0011Surface.blockID, 1, 2);
		world.setBlock(x + 4, y + 24, z + 14, SpaceAgeCore.T0011Surface.blockID, 1, 2);
		world.setBlock(x + 4, y + 24, z + 15, SpaceAgeCore.T0011Surface.blockID, 1, 2);
		world.setBlock(x + 4, y + 24, z + 16, SpaceAgeCore.T0011Surface.blockID, 1, 2);
		world.setBlock(x + 4, y + 24, z + 17, SpaceAgeCore.T0011Surface.blockID, 1, 2);
		world.setBlock(x + 4, y + 24, z + 18, SpaceAgeCore.T0011Surface.blockID, 1, 2);
		world.setBlock(x + 4, y + 24, z + 19, SpaceAgeCore.T0011Surface.blockID, 1, 2);
		world.setBlock(x + 4, y + 24, z + 20, SpaceAgeCore.T0011Surface.blockID, 1, 2);
		world.setBlock(x + 4, y + 24, z + 21, SpaceAgeCore.T0011Surface.blockID, 1, 2);
		world.setBlock(x + 4, y + 24, z + 22, SpaceAgeCore.T0011Surface.blockID, 1, 2);
		world.setBlock(x + 4, y + 24, z + 23, SpaceAgeCore.T0011Surface.blockID, 1, 2);
		world.setBlock(x + 4, y + 25, z + 5, SpaceAgeCore.T0011Surface.blockID, 1, 2);
		world.setBlock(x + 4, y + 25, z + 6, SpaceAgeCore.T0011Surface.blockID, 1, 2);
		world.setBlock(x + 4, y + 25, z + 7, SpaceAgeCore.T0011Surface.blockID, 1, 2);
		world.setBlock(x + 4, y + 25, z + 8, SpaceAgeCore.T0011Surface.blockID, 1, 2);
		world.setBlock(x + 4, y + 25, z + 9, SpaceAgeCore.T0011Surface.blockID, 1, 2);
		world.setBlock(x + 4, y + 25, z + 10, SpaceAgeCore.T0011Surface.blockID, 1, 2);
		world.setBlock(x + 4, y + 25, z + 11, SpaceAgeCore.T0011Surface.blockID, 1, 2);
		world.setBlock(x + 4, y + 25, z + 12, SpaceAgeCore.T0011Surface.blockID, 1, 2);
		world.setBlock(x + 4, y + 25, z + 13, SpaceAgeCore.T0011Surface.blockID, 1, 2);
		world.setBlock(x + 4, y + 25, z + 14, SpaceAgeCore.T0011Surface.blockID, 1, 2);
		world.setBlock(x + 4, y + 25, z + 15, SpaceAgeCore.T0011Surface.blockID, 1, 2);
		world.setBlock(x + 4, y + 25, z + 16, SpaceAgeCore.T0011Surface.blockID, 1, 2);
		world.setBlock(x + 4, y + 25, z + 17, SpaceAgeCore.T0011Surface.blockID, 1, 2);
		world.setBlock(x + 4, y + 25, z + 18, SpaceAgeCore.T0011Surface.blockID, 1, 2);
		world.setBlock(x + 4, y + 25, z + 19, SpaceAgeCore.T0011Surface.blockID, 1, 2);
		world.setBlock(x + 4, y + 25, z + 20, SpaceAgeCore.T0011Surface.blockID, 1, 2);
		world.setBlock(x + 4, y + 25, z + 21, SpaceAgeCore.T0011Surface.blockID, 1, 2);
		world.setBlock(x + 4, y + 26, z + 7, SpaceAgeCore.T0011Surface.blockID, 1, 2);
		world.setBlock(x + 4, y + 26, z + 8, SpaceAgeCore.T0011Surface.blockID, 1, 2);
		world.setBlock(x + 4, y + 26, z + 9, SpaceAgeCore.T0011Surface.blockID, 1, 2);
		world.setBlock(x + 4, y + 26, z + 10, SpaceAgeCore.T0011Surface.blockID, 1, 2);
		world.setBlock(x + 4, y + 26, z + 11, SpaceAgeCore.T0011Surface.blockID, 1, 2);
		world.setBlock(x + 4, y + 26, z + 12, SpaceAgeCore.T0011Surface.blockID, 1, 2);
		world.setBlock(x + 4, y + 26, z + 13, SpaceAgeCore.T0011Surface.blockID, 1, 2);
		world.setBlock(x + 4, y + 26, z + 14, SpaceAgeCore.T0011Surface.blockID, 1, 2);
		world.setBlock(x + 4, y + 26, z + 15, SpaceAgeCore.T0011Surface.blockID, 1, 2);
		world.setBlock(x + 4, y + 26, z + 16, SpaceAgeCore.T0011Surface.blockID, 1, 2);
		world.setBlock(x + 4, y + 26, z + 17, SpaceAgeCore.T0011Surface.blockID, 1, 2);
		world.setBlock(x + 4, y + 26, z + 18, SpaceAgeCore.T0011Surface.blockID, 1, 2);
		world.setBlock(x + 4, y + 26, z + 19, SpaceAgeCore.T0011Surface.blockID, 1, 2);
		world.setBlock(x + 4, y + 27, z + 8, SpaceAgeCore.T0011Surface.blockID, 1, 2);
		world.setBlock(x + 4, y + 27, z + 9, SpaceAgeCore.T0011Surface.blockID, 1, 2);
		world.setBlock(x + 4, y + 27, z + 10, SpaceAgeCore.T0011Surface.blockID, 1, 2);
		world.setBlock(x + 4, y + 27, z + 11, SpaceAgeCore.T0011Surface.blockID, 1, 2);
		world.setBlock(x + 4, y + 27, z + 12, SpaceAgeCore.T0011Surface.blockID, 1, 2);
		world.setBlock(x + 4, y + 27, z + 13, SpaceAgeCore.T0011Surface.blockID, 1, 2);
		world.setBlock(x + 4, y + 27, z + 14, SpaceAgeCore.T0011Surface.blockID, 1, 2);
		world.setBlock(x + 4, y + 27, z + 15, SpaceAgeCore.T0011Surface.blockID, 1, 2);
		world.setBlock(x + 4, y + 27, z + 16, SpaceAgeCore.T0011Surface.blockID, 1, 2);
		world.setBlock(x + 4, y + 27, z + 17, SpaceAgeCore.T0011Surface.blockID, 1, 2);
		world.setBlock(x + 4, y + 27, z + 18, SpaceAgeCore.T0011Surface.blockID, 1, 2);
		world.setBlock(x + 4, y + 28, z + 10, SpaceAgeCore.T0011Surface.blockID, 3, 2);
		world.setBlock(x + 4, y + 28, z + 11, SpaceAgeCore.T0011Surface.blockID, 3, 2);
		world.setBlock(x + 4, y + 28, z + 12, SpaceAgeCore.T0011Surface.blockID, 3, 2);
		world.setBlock(x + 4, y + 28, z + 13, SpaceAgeCore.T0011Surface.blockID, 3, 2);
		world.setBlock(x + 4, y + 28, z + 14, SpaceAgeCore.T0011Surface.blockID, 3, 2);
		world.setBlock(x + 4, y + 28, z + 15, SpaceAgeCore.T0011Surface.blockID, 3, 2);
		world.setBlock(x + 4, y + 28, z + 16, SpaceAgeCore.T0011Surface.blockID, 3, 2);
		world.setBlock(x + 4, y + 29, z + 11, SpaceAgeCore.T0011Surface.blockID, 3, 2);
		world.setBlock(x + 4, y + 29, z + 12, SpaceAgeCore.T0011Surface.blockID, 3, 2);
		world.setBlock(x + 4, y + 29, z + 13, SpaceAgeCore.T0011Surface.blockID, 3, 2);
		world.setBlock(x + 4, y + 29, z + 14, SpaceAgeCore.T0011Surface.blockID, 3, 2);
		world.setBlock(x + 4, y + 29, z + 15, SpaceAgeCore.T0011Surface.blockID, 3, 2);
		world.setBlock(x + 4, y + 30, z + 11, SpaceAgeCore.T0011Surface.blockID, 3, 2);
		world.setBlock(x + 4, y + 30, z + 12, SpaceAgeCore.T0011Surface.blockID, 3, 2);
		world.setBlock(x + 4, y + 30, z + 13, SpaceAgeCore.T0011Surface.blockID, 3, 2);
		world.setBlock(x + 4, y + 30, z + 14, SpaceAgeCore.T0011Surface.blockID, 3, 2);
		world.setBlock(x + 4, y + 30, z + 15, SpaceAgeCore.T0011Surface.blockID, 3, 2);
		world.setBlock(x + 4, y + 31, z + 13, SpaceAgeCore.T0011Surface.blockID, 3, 2);
		world.setBlock(x + 5, y + 24, z + 3, SpaceAgeCore.T0011Surface.blockID, 1, 2);
		world.setBlock(x + 5, y + 24, z + 4, SpaceAgeCore.T0011Surface.blockID, 1, 2);
		world.setBlock(x + 5, y + 24, z + 5, SpaceAgeCore.T0011Surface.blockID, 1, 2);
		world.setBlock(x + 5, y + 24, z + 6, SpaceAgeCore.T0011Surface.blockID, 1, 2);
		world.setBlock(x + 5, y + 24, z + 7, SpaceAgeCore.T0011Surface.blockID, 1, 2);
		world.setBlock(x + 5, y + 24, z + 8, SpaceAgeCore.T0011Surface.blockID, 1, 2);
		world.setBlock(x + 5, y + 24, z + 9, SpaceAgeCore.T0011Surface.blockID, 1, 2);
		world.setBlock(x + 5, y + 24, z + 10, SpaceAgeCore.T0011Surface.blockID, 1, 2);
		world.setBlock(x + 5, y + 24, z + 11, SpaceAgeCore.T0011Surface.blockID, 1, 2);
		world.setBlock(x + 5, y + 24, z + 12, SpaceAgeCore.T0011Surface.blockID, 1, 2);
		world.setBlock(x + 5, y + 24, z + 13, SpaceAgeCore.T0011Surface.blockID, 1, 2);
		world.setBlock(x + 5, y + 24, z + 14, SpaceAgeCore.T0011Surface.blockID, 1, 2);
		world.setBlock(x + 5, y + 24, z + 15, SpaceAgeCore.T0011Surface.blockID, 1, 2);
		world.setBlock(x + 5, y + 24, z + 16, SpaceAgeCore.T0011Surface.blockID, 1, 2);
		world.setBlock(x + 5, y + 24, z + 17, SpaceAgeCore.T0011Surface.blockID, 1, 2);
		world.setBlock(x + 5, y + 24, z + 18, SpaceAgeCore.T0011Surface.blockID, 1, 2);
		world.setBlock(x + 5, y + 24, z + 19, SpaceAgeCore.T0011Surface.blockID, 1, 2);
		world.setBlock(x + 5, y + 24, z + 20, SpaceAgeCore.T0011Surface.blockID, 1, 2);
		world.setBlock(x + 5, y + 24, z + 21, SpaceAgeCore.T0011Surface.blockID, 1, 2);
		world.setBlock(x + 5, y + 24, z + 22, SpaceAgeCore.T0011Surface.blockID, 1, 2);
		world.setBlock(x + 5, y + 24, z + 23, SpaceAgeCore.T0011Surface.blockID, 1, 2);
		world.setBlock(x + 5, y + 25, z + 4, SpaceAgeCore.T0011Surface.blockID, 1, 2);
		world.setBlock(x + 5, y + 25, z + 5, SpaceAgeCore.T0011Surface.blockID, 1, 2);
		world.setBlock(x + 5, y + 25, z + 6, SpaceAgeCore.T0011Surface.blockID, 1, 2);
		world.setBlock(x + 5, y + 25, z + 7, SpaceAgeCore.T0011Surface.blockID, 1, 2);
		world.setBlock(x + 5, y + 25, z + 8, SpaceAgeCore.T0011Surface.blockID, 1, 2);
		world.setBlock(x + 5, y + 25, z + 9, SpaceAgeCore.T0011Surface.blockID, 1, 2);
		world.setBlock(x + 5, y + 25, z + 10, SpaceAgeCore.T0011Surface.blockID, 1, 2);
		world.setBlock(x + 5, y + 25, z + 11, SpaceAgeCore.T0011Surface.blockID, 1, 2);
		world.setBlock(x + 5, y + 25, z + 12, SpaceAgeCore.T0011Surface.blockID, 1, 2);
		world.setBlock(x + 5, y + 25, z + 13, SpaceAgeCore.T0011Surface.blockID, 1, 2);
		world.setBlock(x + 5, y + 25, z + 14, SpaceAgeCore.T0011Surface.blockID, 1, 2);
		world.setBlock(x + 5, y + 25, z + 15, SpaceAgeCore.T0011Surface.blockID, 1, 2);
		world.setBlock(x + 5, y + 25, z + 16, SpaceAgeCore.T0011Surface.blockID, 1, 2);
		world.setBlock(x + 5, y + 25, z + 17, SpaceAgeCore.T0011Surface.blockID, 1, 2);
		world.setBlock(x + 5, y + 25, z + 18, SpaceAgeCore.T0011Surface.blockID, 1, 2);
		world.setBlock(x + 5, y + 25, z + 19, SpaceAgeCore.T0011Surface.blockID, 1, 2);
		world.setBlock(x + 5, y + 25, z + 20, SpaceAgeCore.T0011Surface.blockID, 1, 2);
		world.setBlock(x + 5, y + 25, z + 21, SpaceAgeCore.T0011Surface.blockID, 1, 2);
		world.setBlock(x + 5, y + 25, z + 22, SpaceAgeCore.T0011Surface.blockID, 1, 2);
		world.setBlock(x + 5, y + 26, z + 5, SpaceAgeCore.T0011Surface.blockID, 1, 2);
		world.setBlock(x + 5, y + 26, z + 6, SpaceAgeCore.T0011Surface.blockID, 1, 2);
		world.setBlock(x + 5, y + 26, z + 7, SpaceAgeCore.T0011Surface.blockID, 1, 2);
		world.setBlock(x + 5, y + 26, z + 8, SpaceAgeCore.T0011Surface.blockID, 1, 2);
		world.setBlock(x + 5, y + 26, z + 9, SpaceAgeCore.T0011Surface.blockID, 1, 2);
		world.setBlock(x + 5, y + 26, z + 10, SpaceAgeCore.T0011Surface.blockID, 1, 2);
		world.setBlock(x + 5, y + 26, z + 11, SpaceAgeCore.T0011Surface.blockID, 1, 2);
		world.setBlock(x + 5, y + 26, z + 12, SpaceAgeCore.T0011Surface.blockID, 1, 2);
		world.setBlock(x + 5, y + 26, z + 13, SpaceAgeCore.T0011Surface.blockID, 1, 2);
		world.setBlock(x + 5, y + 26, z + 14, SpaceAgeCore.T0011Surface.blockID, 1, 2);
		world.setBlock(x + 5, y + 26, z + 15, SpaceAgeCore.T0011Surface.blockID, 1, 2);
		world.setBlock(x + 5, y + 26, z + 16, SpaceAgeCore.T0011Surface.blockID, 1, 2);
		world.setBlock(x + 5, y + 26, z + 17, SpaceAgeCore.T0011Surface.blockID, 1, 2);
		world.setBlock(x + 5, y + 26, z + 18, SpaceAgeCore.T0011Surface.blockID, 1, 2);
		world.setBlock(x + 5, y + 26, z + 19, SpaceAgeCore.T0011Surface.blockID, 1, 2);
		world.setBlock(x + 5, y + 26, z + 20, SpaceAgeCore.T0011Surface.blockID, 1, 2);
		world.setBlock(x + 5, y + 26, z + 21, SpaceAgeCore.T0011Surface.blockID, 1, 2);
		world.setBlock(x + 5, y + 27, z + 7, SpaceAgeCore.T0011Surface.blockID, 1, 2);
		world.setBlock(x + 5, y + 27, z + 8, SpaceAgeCore.T0011Surface.blockID, 1, 2);
		world.setBlock(x + 5, y + 27, z + 9, SpaceAgeCore.T0011Surface.blockID, 1, 2);
		world.setBlock(x + 5, y + 27, z + 10, SpaceAgeCore.T0011Surface.blockID, 1, 2);
		world.setBlock(x + 5, y + 27, z + 11, SpaceAgeCore.T0011Surface.blockID, 1, 2);
		world.setBlock(x + 5, y + 27, z + 12, SpaceAgeCore.T0011Surface.blockID, 1, 2);
		world.setBlock(x + 5, y + 27, z + 13, SpaceAgeCore.T0011Surface.blockID, 1, 2);
		world.setBlock(x + 5, y + 27, z + 14, SpaceAgeCore.T0011Surface.blockID, 1, 2);
		world.setBlock(x + 5, y + 27, z + 15, SpaceAgeCore.T0011Surface.blockID, 1, 2);
		world.setBlock(x + 5, y + 27, z + 16, SpaceAgeCore.T0011Surface.blockID, 1, 2);
		world.setBlock(x + 5, y + 27, z + 17, SpaceAgeCore.T0011Surface.blockID, 1, 2);
		world.setBlock(x + 5, y + 27, z + 18, SpaceAgeCore.T0011Surface.blockID, 1, 2);
		world.setBlock(x + 5, y + 27, z + 19, SpaceAgeCore.T0011Surface.blockID, 1, 2);
		world.setBlock(x + 5, y + 28, z + 8, SpaceAgeCore.T0011Surface.blockID, 3, 2);
		world.setBlock(x + 5, y + 28, z + 9, SpaceAgeCore.T0011Surface.blockID, 3, 2);
		world.setBlock(x + 5, y + 28, z + 17, SpaceAgeCore.T0011Surface.blockID, 3, 2);
		world.setBlock(x + 5, y + 28, z + 18, SpaceAgeCore.T0011Surface.blockID, 3, 2);
		world.setBlock(x + 5, y + 29, z + 8, SpaceAgeCore.T0011Surface.blockID, 3, 2);
		world.setBlock(x + 5, y + 29, z + 9, SpaceAgeCore.T0011Surface.blockID, 3, 2);
		world.setBlock(x + 5, y + 29, z + 10, SpaceAgeCore.T0011Surface.blockID, 3, 2);
		world.setBlock(x + 5, y + 29, z + 16, SpaceAgeCore.T0011Surface.blockID, 3, 2);
		world.setBlock(x + 5, y + 29, z + 17, SpaceAgeCore.T0011Surface.blockID, 3, 2);
		world.setBlock(x + 5, y + 29, z + 18, SpaceAgeCore.T0011Surface.blockID, 3, 2);
		world.setBlock(x + 5, y + 30, z + 9, SpaceAgeCore.T0011Surface.blockID, 3, 2);
		world.setBlock(x + 5, y + 30, z + 10, SpaceAgeCore.T0011Surface.blockID, 3, 2);
		world.setBlock(x + 5, y + 30, z + 16, SpaceAgeCore.T0011Surface.blockID, 3, 2);
		world.setBlock(x + 5, y + 30, z + 17, SpaceAgeCore.T0011Surface.blockID, 3, 2);
		world.setBlock(x + 5, y + 31, z + 9, SpaceAgeCore.T0011Surface.blockID, 3, 2);
		world.setBlock(x + 5, y + 31, z + 10, SpaceAgeCore.T0011Surface.blockID, 3, 2);
		world.setBlock(x + 5, y + 31, z + 11, SpaceAgeCore.T0011Surface.blockID, 3, 2);
		world.setBlock(x + 5, y + 31, z + 12, SpaceAgeCore.T0011Surface.blockID, 3, 2);
		world.setBlock(x + 5, y + 31, z + 14, SpaceAgeCore.T0011Surface.blockID, 3, 2);
		world.setBlock(x + 5, y + 31, z + 15, SpaceAgeCore.T0011Surface.blockID, 3, 2);
		world.setBlock(x + 5, y + 31, z + 16, SpaceAgeCore.T0011Surface.blockID, 3, 2);
		world.setBlock(x + 5, y + 31, z + 17, SpaceAgeCore.T0011Surface.blockID, 3, 2);
		world.setBlock(x + 5, y + 32, z + 10, SpaceAgeCore.T0011Surface.blockID, 3, 2);
		world.setBlock(x + 5, y + 32, z + 11, SpaceAgeCore.T0011Surface.blockID, 3, 2);
		world.setBlock(x + 5, y + 32, z + 12, SpaceAgeCore.T0011Surface.blockID, 3, 2);
		world.setBlock(x + 5, y + 32, z + 13, SpaceAgeCore.T0011Surface.blockID, 3, 2);
		world.setBlock(x + 5, y + 32, z + 14, SpaceAgeCore.T0011Surface.blockID, 3, 2);
		world.setBlock(x + 5, y + 32, z + 15, SpaceAgeCore.T0011Surface.blockID, 3, 2);
		world.setBlock(x + 5, y + 32, z + 16, SpaceAgeCore.T0011Surface.blockID, 3, 2);
		world.setBlock(x + 5, y + 33, z + 12, SpaceAgeCore.T0011Surface.blockID, 3, 2);
		world.setBlock(x + 5, y + 33, z + 13, SpaceAgeCore.T0011Surface.blockID, 3, 2);
		world.setBlock(x + 5, y + 33, z + 14, SpaceAgeCore.T0011Surface.blockID, 3, 2);
		world.setBlock(x + 6, y + 24, z + 2, SpaceAgeCore.T0011Surface.blockID, 1, 2);
		world.setBlock(x + 6, y + 24, z + 3, SpaceAgeCore.T0011Surface.blockID, 1, 2);
		world.setBlock(x + 6, y + 24, z + 4, SpaceAgeCore.T0011Surface.blockID, 1, 2);
		world.setBlock(x + 6, y + 24, z + 5, SpaceAgeCore.T0011Surface.blockID, 1, 2);
		world.setBlock(x + 6, y + 24, z + 6, SpaceAgeCore.T0011Surface.blockID, 1, 2);
		world.setBlock(x + 6, y + 24, z + 7, SpaceAgeCore.T0011Surface.blockID, 1, 2);
		world.setBlock(x + 6, y + 24, z + 8, SpaceAgeCore.T0011Surface.blockID, 1, 2);
		world.setBlock(x + 6, y + 24, z + 9, SpaceAgeCore.T0011Surface.blockID, 1, 2);
		world.setBlock(x + 6, y + 24, z + 10, SpaceAgeCore.T0011Surface.blockID, 1, 2);
		world.setBlock(x + 6, y + 24, z + 11, SpaceAgeCore.T0011Surface.blockID, 1, 2);
		world.setBlock(x + 6, y + 24, z + 12, SpaceAgeCore.T0011Surface.blockID, 1, 2);
		world.setBlock(x + 6, y + 24, z + 13, SpaceAgeCore.T0011Surface.blockID, 1, 2);
		world.setBlock(x + 6, y + 24, z + 14, SpaceAgeCore.T0011Surface.blockID, 1, 2);
		world.setBlock(x + 6, y + 24, z + 15, SpaceAgeCore.T0011Surface.blockID, 1, 2);
		world.setBlock(x + 6, y + 24, z + 16, SpaceAgeCore.T0011Surface.blockID, 1, 2);
		world.setBlock(x + 6, y + 24, z + 17, SpaceAgeCore.T0011Surface.blockID, 1, 2);
		world.setBlock(x + 6, y + 24, z + 18, SpaceAgeCore.T0011Surface.blockID, 1, 2);
		world.setBlock(x + 6, y + 24, z + 19, SpaceAgeCore.T0011Surface.blockID, 1, 2);
		world.setBlock(x + 6, y + 24, z + 20, SpaceAgeCore.T0011Surface.blockID, 1, 2);
		world.setBlock(x + 6, y + 24, z + 21, SpaceAgeCore.T0011Surface.blockID, 1, 2);
		world.setBlock(x + 6, y + 24, z + 22, SpaceAgeCore.T0011Surface.blockID, 1, 2);
		world.setBlock(x + 6, y + 24, z + 23, SpaceAgeCore.T0011Surface.blockID, 1, 2);
		world.setBlock(x + 6, y + 24, z + 24, SpaceAgeCore.T0011Surface.blockID, 1, 2);
		world.setBlock(x + 6, y + 25, z + 3, SpaceAgeCore.T0011Surface.blockID, 1, 2);
		world.setBlock(x + 6, y + 25, z + 4, SpaceAgeCore.T0011Surface.blockID, 1, 2);
		world.setBlock(x + 6, y + 25, z + 5, SpaceAgeCore.T0011Surface.blockID, 1, 2);
		world.setBlock(x + 6, y + 25, z + 6, SpaceAgeCore.T0011Surface.blockID, 1, 2);
		world.setBlock(x + 6, y + 25, z + 7, SpaceAgeCore.T0011Surface.blockID, 1, 2);
		world.setBlock(x + 6, y + 25, z + 8, SpaceAgeCore.T0011Surface.blockID, 1, 2);
		world.setBlock(x + 6, y + 25, z + 9, SpaceAgeCore.T0011Surface.blockID, 1, 2);
		world.setBlock(x + 6, y + 25, z + 10, SpaceAgeCore.T0011Surface.blockID, 1, 2);
		world.setBlock(x + 6, y + 25, z + 11, SpaceAgeCore.T0011Surface.blockID, 1, 2);
		world.setBlock(x + 6, y + 25, z + 12, SpaceAgeCore.T0011Surface.blockID, 1, 2);
		world.setBlock(x + 6, y + 25, z + 13, SpaceAgeCore.T0011Surface.blockID, 1, 2);
		world.setBlock(x + 6, y + 25, z + 14, SpaceAgeCore.T0011Surface.blockID, 1, 2);
		world.setBlock(x + 6, y + 25, z + 15, SpaceAgeCore.T0011Surface.blockID, 1, 2);
		world.setBlock(x + 6, y + 25, z + 16, SpaceAgeCore.T0011Surface.blockID, 1, 2);
		world.setBlock(x + 6, y + 25, z + 17, SpaceAgeCore.T0011Surface.blockID, 1, 2);
		world.setBlock(x + 6, y + 25, z + 18, SpaceAgeCore.T0011Surface.blockID, 1, 2);
		world.setBlock(x + 6, y + 25, z + 19, SpaceAgeCore.T0011Surface.blockID, 1, 2);
		world.setBlock(x + 6, y + 25, z + 20, SpaceAgeCore.T0011Surface.blockID, 1, 2);
		world.setBlock(x + 6, y + 25, z + 21, SpaceAgeCore.T0011Surface.blockID, 1, 2);
		world.setBlock(x + 6, y + 25, z + 22, SpaceAgeCore.T0011Surface.blockID, 1, 2);
		world.setBlock(x + 6, y + 25, z + 23, SpaceAgeCore.T0011Surface.blockID, 1, 2);
		world.setBlock(x + 6, y + 26, z + 5, SpaceAgeCore.T0011Surface.blockID, 1, 2);
		world.setBlock(x + 6, y + 26, z + 6, SpaceAgeCore.T0011Surface.blockID, 1, 2);
		world.setBlock(x + 6, y + 26, z + 7, SpaceAgeCore.T0011Surface.blockID, 1, 2);
		world.setBlock(x + 6, y + 26, z + 8, SpaceAgeCore.T0011Surface.blockID, 1, 2);
		world.setBlock(x + 6, y + 26, z + 9, SpaceAgeCore.T0011Surface.blockID, 1, 2);
		world.setBlock(x + 6, y + 26, z + 10, SpaceAgeCore.T0011Surface.blockID, 1, 2);
		world.setBlock(x + 6, y + 26, z + 11, SpaceAgeCore.T0011Surface.blockID, 1, 2);
		world.setBlock(x + 6, y + 26, z + 12, SpaceAgeCore.T0011Surface.blockID, 1, 2);
		world.setBlock(x + 6, y + 26, z + 13, SpaceAgeCore.T0011Surface.blockID, 1, 2);
		world.setBlock(x + 6, y + 26, z + 14, SpaceAgeCore.T0011Surface.blockID, 1, 2);
		world.setBlock(x + 6, y + 26, z + 15, SpaceAgeCore.T0011Surface.blockID, 1, 2);
		world.setBlock(x + 6, y + 26, z + 16, SpaceAgeCore.T0011Surface.blockID, 1, 2);
		world.setBlock(x + 6, y + 26, z + 17, SpaceAgeCore.T0011Surface.blockID, 1, 2);
		world.setBlock(x + 6, y + 26, z + 18, SpaceAgeCore.T0011Surface.blockID, 1, 2);
		world.setBlock(x + 6, y + 26, z + 19, SpaceAgeCore.T0011Surface.blockID, 1, 2);
		world.setBlock(x + 6, y + 26, z + 20, SpaceAgeCore.T0011Surface.blockID, 1, 2);
		world.setBlock(x + 6, y + 26, z + 21, SpaceAgeCore.T0011Surface.blockID, 1, 2);
		world.setBlock(x + 6, y + 27, z + 6, SpaceAgeCore.T0011Surface.blockID, 1, 2);
		world.setBlock(x + 6, y + 27, z + 7, SpaceAgeCore.T0011Surface.blockID, 1, 2);
		world.setBlock(x + 6, y + 27, z + 8, SpaceAgeCore.T0011Surface.blockID, 1, 2);
		world.setBlock(x + 6, y + 27, z + 9, SpaceAgeCore.T0011Surface.blockID, 1, 2);
		world.setBlock(x + 6, y + 27, z + 10, SpaceAgeCore.T0011Surface.blockID, 1, 2);
		world.setBlock(x + 6, y + 27, z + 11, SpaceAgeCore.T0011Surface.blockID, 1, 2);
		world.setBlock(x + 6, y + 27, z + 12, SpaceAgeCore.T0011Surface.blockID, 1, 2);
		world.setBlock(x + 6, y + 27, z + 13, SpaceAgeCore.T0011Surface.blockID, 1, 2);
		world.setBlock(x + 6, y + 27, z + 14, SpaceAgeCore.T0011Surface.blockID, 1, 2);
		world.setBlock(x + 6, y + 27, z + 15, SpaceAgeCore.T0011Surface.blockID, 1, 2);
		world.setBlock(x + 6, y + 27, z + 16, SpaceAgeCore.T0011Surface.blockID, 1, 2);
		world.setBlock(x + 6, y + 27, z + 17, SpaceAgeCore.T0011Surface.blockID, 1, 2);
		world.setBlock(x + 6, y + 27, z + 18, SpaceAgeCore.T0011Surface.blockID, 1, 2);
		world.setBlock(x + 6, y + 27, z + 19, SpaceAgeCore.T0011Surface.blockID, 1, 2);
		world.setBlock(x + 6, y + 27, z + 20, SpaceAgeCore.T0011Surface.blockID, 1, 2);
		world.setBlock(x + 6, y + 28, z + 7, SpaceAgeCore.T0011Surface.blockID, 3, 2);
		world.setBlock(x + 6, y + 28, z + 19, SpaceAgeCore.T0011Surface.blockID, 3, 2);
		world.setBlock(x + 6, y + 29, z + 7, SpaceAgeCore.T0011Surface.blockID, 3, 2);
		world.setBlock(x + 6, y + 29, z + 19, SpaceAgeCore.T0011Surface.blockID, 3, 2);
		world.setBlock(x + 6, y + 30, z + 7, SpaceAgeCore.T0011Surface.blockID, 3, 2);
		world.setBlock(x + 6, y + 30, z + 8, SpaceAgeCore.T0011Surface.blockID, 3, 2);
		world.setBlock(x + 6, y + 30, z + 18, SpaceAgeCore.T0011Surface.blockID, 3, 2);
		world.setBlock(x + 6, y + 30, z + 19, SpaceAgeCore.T0011Surface.blockID, 3, 2);
		world.setBlock(x + 6, y + 31, z + 8, SpaceAgeCore.T0011Surface.blockID, 3, 2);
		world.setBlock(x + 6, y + 31, z + 18, SpaceAgeCore.T0011Surface.blockID, 3, 2);
		world.setBlock(x + 6, y + 32, z + 8, SpaceAgeCore.T0011Surface.blockID, 3, 2);
		world.setBlock(x + 6, y + 32, z + 9, SpaceAgeCore.T0011Surface.blockID, 3, 2);
		world.setBlock(x + 6, y + 32, z + 17, SpaceAgeCore.T0011Surface.blockID, 3, 2);
		world.setBlock(x + 6, y + 32, z + 18, SpaceAgeCore.T0011Surface.blockID, 3, 2);
		world.setBlock(x + 6, y + 33, z + 9, SpaceAgeCore.T0011Surface.blockID, 3, 2);
		world.setBlock(x + 6, y + 33, z + 10, SpaceAgeCore.T0011Surface.blockID, 3, 2);
		world.setBlock(x + 6, y + 33, z + 11, SpaceAgeCore.T0011Surface.blockID, 3, 2);
		world.setBlock(x + 6, y + 33, z + 15, SpaceAgeCore.T0011Surface.blockID, 3, 2);
		world.setBlock(x + 6, y + 33, z + 16, SpaceAgeCore.T0011Surface.blockID, 3, 2);
		world.setBlock(x + 6, y + 33, z + 17, SpaceAgeCore.T0011Surface.blockID, 3, 2);
		world.setBlock(x + 6, y + 34, z + 11, SpaceAgeCore.T0011Surface.blockID, 3, 2);
		world.setBlock(x + 6, y + 34, z + 12, SpaceAgeCore.T0011Surface.blockID, 3, 2);
		world.setBlock(x + 6, y + 34, z + 13, SpaceAgeCore.T0011Surface.blockID, 3, 2);
		world.setBlock(x + 6, y + 34, z + 14, SpaceAgeCore.T0011Surface.blockID, 3, 2);
		world.setBlock(x + 6, y + 34, z + 15, SpaceAgeCore.T0011Surface.blockID, 3, 2);
		world.setBlock(x + 7, y + 24, z + 1, SpaceAgeCore.T0011Surface.blockID, 1, 2);
		world.setBlock(x + 7, y + 24, z + 2, SpaceAgeCore.T0011Surface.blockID, 1, 2);
		world.setBlock(x + 7, y + 24, z + 3, SpaceAgeCore.T0011Surface.blockID, 1, 2);
		world.setBlock(x + 7, y + 24, z + 4, SpaceAgeCore.T0011Surface.blockID, 1, 2);
		world.setBlock(x + 7, y + 24, z + 5, SpaceAgeCore.T0011Surface.blockID, 1, 2);
		world.setBlock(x + 7, y + 24, z + 6, SpaceAgeCore.T0011Surface.blockID, 1, 2);
		world.setBlock(x + 7, y + 24, z + 7, SpaceAgeCore.T0011Surface.blockID, 1, 2);
		world.setBlock(x + 7, y + 24, z + 8, SpaceAgeCore.T0011Surface.blockID, 1, 2);
		world.setBlock(x + 7, y + 24, z + 9, SpaceAgeCore.T0011Surface.blockID, 1, 2);
		world.setBlock(x + 7, y + 24, z + 10, SpaceAgeCore.T0011Surface.blockID, 1, 2);
		world.setBlock(x + 7, y + 24, z + 11, SpaceAgeCore.T0011Surface.blockID, 1, 2);
		world.setBlock(x + 7, y + 24, z + 12, SpaceAgeCore.T0011Surface.blockID, 1, 2);
		world.setBlock(x + 7, y + 24, z + 13, SpaceAgeCore.T0011Surface.blockID, 1, 2);
		world.setBlock(x + 7, y + 24, z + 14, SpaceAgeCore.T0011Surface.blockID, 1, 2);
		world.setBlock(x + 7, y + 24, z + 15, SpaceAgeCore.T0011Surface.blockID, 1, 2);
		world.setBlock(x + 7, y + 24, z + 16, SpaceAgeCore.T0011Surface.blockID, 1, 2);
		world.setBlock(x + 7, y + 24, z + 17, SpaceAgeCore.T0011Surface.blockID, 1, 2);
		world.setBlock(x + 7, y + 24, z + 18, SpaceAgeCore.T0011Surface.blockID, 1, 2);
		world.setBlock(x + 7, y + 24, z + 19, SpaceAgeCore.T0011Surface.blockID, 1, 2);
		world.setBlock(x + 7, y + 24, z + 20, SpaceAgeCore.T0011Surface.blockID, 1, 2);
		world.setBlock(x + 7, y + 24, z + 21, SpaceAgeCore.T0011Surface.blockID, 1, 2);
		world.setBlock(x + 7, y + 24, z + 22, SpaceAgeCore.T0011Surface.blockID, 1, 2);
		world.setBlock(x + 7, y + 24, z + 23, SpaceAgeCore.T0011Surface.blockID, 1, 2);
		world.setBlock(x + 7, y + 24, z + 24, SpaceAgeCore.T0011Surface.blockID, 1, 2);
		world.setBlock(x + 7, y + 25, z + 3, SpaceAgeCore.T0011Surface.blockID, 1, 2);
		world.setBlock(x + 7, y + 25, z + 4, SpaceAgeCore.T0011Surface.blockID, 1, 2);
		world.setBlock(x + 7, y + 25, z + 5, SpaceAgeCore.T0011Surface.blockID, 1, 2);
		world.setBlock(x + 7, y + 25, z + 6, SpaceAgeCore.T0011Surface.blockID, 1, 2);
		world.setBlock(x + 7, y + 25, z + 7, SpaceAgeCore.T0011Surface.blockID, 1, 2);
		world.setBlock(x + 7, y + 25, z + 8, SpaceAgeCore.T0011Surface.blockID, 1, 2);
		world.setBlock(x + 7, y + 25, z + 9, SpaceAgeCore.T0011Surface.blockID, 1, 2);
		world.setBlock(x + 7, y + 25, z + 10, SpaceAgeCore.T0011Surface.blockID, 1, 2);
		world.setBlock(x + 7, y + 25, z + 11, SpaceAgeCore.T0011Surface.blockID, 1, 2);
		world.setBlock(x + 7, y + 25, z + 12, SpaceAgeCore.T0011Surface.blockID, 1, 2);
		world.setBlock(x + 7, y + 25, z + 13, SpaceAgeCore.T0011Surface.blockID, 1, 2);
		world.setBlock(x + 7, y + 25, z + 14, SpaceAgeCore.T0011Surface.blockID, 1, 2);
		world.setBlock(x + 7, y + 25, z + 15, SpaceAgeCore.T0011Surface.blockID, 1, 2);
		world.setBlock(x + 7, y + 25, z + 16, SpaceAgeCore.T0011Surface.blockID, 1, 2);
		world.setBlock(x + 7, y + 25, z + 17, SpaceAgeCore.T0011Surface.blockID, 1, 2);
		world.setBlock(x + 7, y + 25, z + 18, SpaceAgeCore.T0011Surface.blockID, 1, 2);
		world.setBlock(x + 7, y + 25, z + 19, SpaceAgeCore.T0011Surface.blockID, 1, 2);
		world.setBlock(x + 7, y + 25, z + 20, SpaceAgeCore.T0011Surface.blockID, 1, 2);
		world.setBlock(x + 7, y + 25, z + 21, SpaceAgeCore.T0011Surface.blockID, 1, 2);
		world.setBlock(x + 7, y + 25, z + 22, SpaceAgeCore.T0011Surface.blockID, 1, 2);
		world.setBlock(x + 7, y + 25, z + 23, SpaceAgeCore.T0011Surface.blockID, 1, 2);
		world.setBlock(x + 7, y + 26, z + 4, SpaceAgeCore.T0011Surface.blockID, 1, 2);
		world.setBlock(x + 7, y + 26, z + 5, SpaceAgeCore.T0011Surface.blockID, 1, 2);
		world.setBlock(x + 7, y + 26, z + 6, SpaceAgeCore.T0011Surface.blockID, 1, 2);
		world.setBlock(x + 7, y + 26, z + 7, SpaceAgeCore.T0011Surface.blockID, 1, 2);
		world.setBlock(x + 7, y + 26, z + 8, SpaceAgeCore.T0011Surface.blockID, 1, 2);
		world.setBlock(x + 7, y + 26, z + 9, SpaceAgeCore.T0011Surface.blockID, 1, 2);
		world.setBlock(x + 7, y + 26, z + 10, SpaceAgeCore.T0011Surface.blockID, 1, 2);
		world.setBlock(x + 7, y + 26, z + 11, SpaceAgeCore.T0011Surface.blockID, 1, 2);
		world.setBlock(x + 7, y + 26, z + 12, SpaceAgeCore.T0011Surface.blockID, 1, 2);
		world.setBlock(x + 7, y + 26, z + 13, SpaceAgeCore.T0011Surface.blockID, 1, 2);
		world.setBlock(x + 7, y + 26, z + 14, SpaceAgeCore.T0011Surface.blockID, 1, 2);
		world.setBlock(x + 7, y + 26, z + 15, SpaceAgeCore.T0011Surface.blockID, 1, 2);
		world.setBlock(x + 7, y + 26, z + 16, SpaceAgeCore.T0011Surface.blockID, 1, 2);
		world.setBlock(x + 7, y + 26, z + 17, SpaceAgeCore.T0011Surface.blockID, 1, 2);
		world.setBlock(x + 7, y + 26, z + 18, SpaceAgeCore.T0011Surface.blockID, 1, 2);
		world.setBlock(x + 7, y + 26, z + 19, SpaceAgeCore.T0011Surface.blockID, 1, 2);
		world.setBlock(x + 7, y + 26, z + 20, SpaceAgeCore.T0011Surface.blockID, 1, 2);
		world.setBlock(x + 7, y + 26, z + 21, SpaceAgeCore.T0011Surface.blockID, 1, 2);
		world.setBlock(x + 7, y + 26, z + 22, SpaceAgeCore.T0011Surface.blockID, 1, 2);
		world.setBlock(x + 7, y + 27, z + 5, SpaceAgeCore.T0011Surface.blockID, 1, 2);
		world.setBlock(x + 7, y + 27, z + 6, SpaceAgeCore.T0011Surface.blockID, 1, 2);
		world.setBlock(x + 7, y + 27, z + 7, SpaceAgeCore.T0011Surface.blockID, 1, 2);
		world.setBlock(x + 7, y + 27, z + 8, SpaceAgeCore.T0011Surface.blockID, 1, 2);
		world.setBlock(x + 7, y + 27, z + 9, SpaceAgeCore.T0011Surface.blockID, 1, 2);
		world.setBlock(x + 7, y + 27, z + 10, SpaceAgeCore.T0011Surface.blockID, 1, 2);
		world.setBlock(x + 7, y + 27, z + 11, SpaceAgeCore.T0011Surface.blockID, 1, 2);
		world.setBlock(x + 7, y + 27, z + 12, SpaceAgeCore.T0011Surface.blockID, 1, 2);
		world.setBlock(x + 7, y + 27, z + 13, SpaceAgeCore.T0011Surface.blockID, 1, 2);
		world.setBlock(x + 7, y + 27, z + 14, SpaceAgeCore.T0011Surface.blockID, 1, 2);
		world.setBlock(x + 7, y + 27, z + 15, SpaceAgeCore.T0011Surface.blockID, 1, 2);
		world.setBlock(x + 7, y + 27, z + 16, SpaceAgeCore.T0011Surface.blockID, 1, 2);
		world.setBlock(x + 7, y + 27, z + 17, SpaceAgeCore.T0011Surface.blockID, 1, 2);
		world.setBlock(x + 7, y + 27, z + 18, SpaceAgeCore.T0011Surface.blockID, 1, 2);
		world.setBlock(x + 7, y + 27, z + 19, SpaceAgeCore.T0011Surface.blockID, 1, 2);
		world.setBlock(x + 7, y + 27, z + 20, SpaceAgeCore.T0011Surface.blockID, 1, 2);
		world.setBlock(x + 7, y + 27, z + 21, SpaceAgeCore.T0011Surface.blockID, 1, 2);
		world.setBlock(x + 7, y + 28, z + 6, SpaceAgeCore.T0011Surface.blockID, 3, 2);
		world.setBlock(x + 7, y + 28, z + 20, SpaceAgeCore.T0011Surface.blockID, 3, 2);
		world.setBlock(x + 7, y + 29, z + 6, SpaceAgeCore.T0011Surface.blockID, 3, 2);
		world.setBlock(x + 7, y + 29, z + 20, SpaceAgeCore.T0011Surface.blockID, 3, 2);
		world.setBlock(x + 7, y + 30, z + 6, SpaceAgeCore.T0011Surface.blockID, 3, 2);
		world.setBlock(x + 7, y + 30, z + 20, SpaceAgeCore.T0011Surface.blockID, 3, 2);
		world.setBlock(x + 7, y + 31, z + 7, SpaceAgeCore.T0011Surface.blockID, 3, 2);
		world.setBlock(x + 7, y + 31, z + 19, SpaceAgeCore.T0011Surface.blockID, 3, 2);
		world.setBlock(x + 7, y + 32, z + 7, SpaceAgeCore.T0011Surface.blockID, 3, 2);
		world.setBlock(x + 7, y + 32, z + 19, SpaceAgeCore.T0011Surface.blockID, 3, 2);
		world.setBlock(x + 7, y + 33, z + 8, SpaceAgeCore.T0011Surface.blockID, 3, 2);
		world.setBlock(x + 7, y + 33, z + 18, SpaceAgeCore.T0011Surface.blockID, 3, 2);
		world.setBlock(x + 7, y + 34, z + 9, SpaceAgeCore.T0011Surface.blockID, 3, 2);
		world.setBlock(x + 7, y + 34, z + 10, SpaceAgeCore.T0011Surface.blockID, 3, 2);
		world.setBlock(x + 7, y + 34, z + 16, SpaceAgeCore.T0011Surface.blockID, 3, 2);
		world.setBlock(x + 7, y + 34, z + 17, SpaceAgeCore.T0011Surface.blockID, 3, 2);
		world.setBlock(x + 7, y + 35, z + 11, SpaceAgeCore.T0011Surface.blockID, 3, 2);
		world.setBlock(x + 7, y + 35, z + 12, SpaceAgeCore.T0011Surface.blockID, 3, 2);
		world.setBlock(x + 7, y + 35, z + 13, SpaceAgeCore.T0011Surface.blockID, 3, 2);
		world.setBlock(x + 7, y + 35, z + 14, SpaceAgeCore.T0011Surface.blockID, 3, 2);
		world.setBlock(x + 7, y + 35, z + 15, SpaceAgeCore.T0011Surface.blockID, 3, 2);
		world.setBlock(x + 8, y + 24, z + 1, SpaceAgeCore.T0011Surface.blockID, 1, 2);
		world.setBlock(x + 8, y + 24, z + 2, SpaceAgeCore.T0011Surface.blockID, 1, 2);
		world.setBlock(x + 8, y + 24, z + 3, SpaceAgeCore.T0011Surface.blockID, 1, 2);
		world.setBlock(x + 8, y + 24, z + 4, SpaceAgeCore.T0011Surface.blockID, 1, 2);
		world.setBlock(x + 8, y + 24, z + 5, SpaceAgeCore.T0011Surface.blockID, 1, 2);
		world.setBlock(x + 8, y + 24, z + 6, SpaceAgeCore.T0011Surface.blockID, 1, 2);
		world.setBlock(x + 8, y + 24, z + 7, SpaceAgeCore.T0011Surface.blockID, 1, 2);
		world.setBlock(x + 8, y + 24, z + 8, SpaceAgeCore.T0011Surface.blockID, 1, 2);
		world.setBlock(x + 8, y + 24, z + 9, SpaceAgeCore.T0011Surface.blockID, 1, 2);
		world.setBlock(x + 8, y + 24, z + 10, SpaceAgeCore.T0011Surface.blockID, 1, 2);
		world.setBlock(x + 8, y + 24, z + 11, SpaceAgeCore.T0011Surface.blockID, 1, 2);
		world.setBlock(x + 8, y + 24, z + 12, SpaceAgeCore.T0011Surface.blockID, 1, 2);
		world.setBlock(x + 8, y + 24, z + 13, SpaceAgeCore.T0011Surface.blockID, 1, 2);
		world.setBlock(x + 8, y + 24, z + 14, SpaceAgeCore.T0011Surface.blockID, 1, 2);
		world.setBlock(x + 8, y + 24, z + 15, SpaceAgeCore.T0011Surface.blockID, 1, 2);
		world.setBlock(x + 8, y + 24, z + 16, SpaceAgeCore.T0011Surface.blockID, 1, 2);
		world.setBlock(x + 8, y + 24, z + 17, SpaceAgeCore.T0011Surface.blockID, 1, 2);
		world.setBlock(x + 8, y + 24, z + 18, SpaceAgeCore.T0011Surface.blockID, 1, 2);
		world.setBlock(x + 8, y + 24, z + 19, SpaceAgeCore.T0011Surface.blockID, 1, 2);
		world.setBlock(x + 8, y + 24, z + 20, SpaceAgeCore.T0011Surface.blockID, 1, 2);
		world.setBlock(x + 8, y + 24, z + 21, SpaceAgeCore.T0011Surface.blockID, 1, 2);
		world.setBlock(x + 8, y + 24, z + 22, SpaceAgeCore.T0011Surface.blockID, 1, 2);
		world.setBlock(x + 8, y + 24, z + 23, SpaceAgeCore.T0011Surface.blockID, 1, 2);
		world.setBlock(x + 8, y + 24, z + 24, SpaceAgeCore.T0011Surface.blockID, 1, 2);
		world.setBlock(x + 8, y + 25, z + 2, SpaceAgeCore.T0011Surface.blockID, 1, 2);
		world.setBlock(x + 8, y + 25, z + 3, SpaceAgeCore.T0011Surface.blockID, 1, 2);
		world.setBlock(x + 8, y + 25, z + 4, SpaceAgeCore.T0011Surface.blockID, 1, 2);
		world.setBlock(x + 8, y + 25, z + 5, SpaceAgeCore.T0011Surface.blockID, 1, 2);
		world.setBlock(x + 8, y + 25, z + 6, SpaceAgeCore.T0011Surface.blockID, 1, 2);
		world.setBlock(x + 8, y + 25, z + 7, SpaceAgeCore.T0011Surface.blockID, 1, 2);
		world.setBlock(x + 8, y + 25, z + 8, SpaceAgeCore.T0011Surface.blockID, 1, 2);
		world.setBlock(x + 8, y + 25, z + 9, SpaceAgeCore.T0011Surface.blockID, 1, 2);
		world.setBlock(x + 8, y + 25, z + 10, SpaceAgeCore.T0011Surface.blockID, 1, 2);
		world.setBlock(x + 8, y + 25, z + 11, SpaceAgeCore.T0011Surface.blockID, 1, 2);
		world.setBlock(x + 8, y + 25, z + 12, SpaceAgeCore.T0011Surface.blockID, 1, 2);
		world.setBlock(x + 8, y + 25, z + 13, SpaceAgeCore.T0011Surface.blockID, 1, 2);
		world.setBlock(x + 8, y + 25, z + 14, SpaceAgeCore.T0011Surface.blockID, 1, 2);
		world.setBlock(x + 8, y + 25, z + 15, SpaceAgeCore.T0011Surface.blockID, 1, 2);
		world.setBlock(x + 8, y + 25, z + 16, SpaceAgeCore.T0011Surface.blockID, 1, 2);
		world.setBlock(x + 8, y + 25, z + 17, SpaceAgeCore.T0011Surface.blockID, 1, 2);
		world.setBlock(x + 8, y + 25, z + 18, SpaceAgeCore.T0011Surface.blockID, 1, 2);
		world.setBlock(x + 8, y + 25, z + 19, SpaceAgeCore.T0011Surface.blockID, 1, 2);
		world.setBlock(x + 8, y + 25, z + 20, SpaceAgeCore.T0011Surface.blockID, 1, 2);
		world.setBlock(x + 8, y + 25, z + 21, SpaceAgeCore.T0011Surface.blockID, 1, 2);
		world.setBlock(x + 8, y + 25, z + 22, SpaceAgeCore.T0011Surface.blockID, 1, 2);
		world.setBlock(x + 8, y + 25, z + 23, SpaceAgeCore.T0011Surface.blockID, 1, 2);
		world.setBlock(x + 8, y + 25, z + 24, SpaceAgeCore.T0011Surface.blockID, 1, 2);
		world.setBlock(x + 8, y + 26, z + 3, SpaceAgeCore.T0011Surface.blockID, 1, 2);
		world.setBlock(x + 8, y + 26, z + 4, SpaceAgeCore.T0011Surface.blockID, 1, 2);
		world.setBlock(x + 8, y + 26, z + 5, SpaceAgeCore.T0011Surface.blockID, 1, 2);
		world.setBlock(x + 8, y + 26, z + 6, SpaceAgeCore.T0011Surface.blockID, 1, 2);
		world.setBlock(x + 8, y + 26, z + 7, SpaceAgeCore.T0011Surface.blockID, 1, 2);
		world.setBlock(x + 8, y + 26, z + 8, SpaceAgeCore.T0011Surface.blockID, 1, 2);
		world.setBlock(x + 8, y + 26, z + 9, SpaceAgeCore.T0011Surface.blockID, 1, 2);
		world.setBlock(x + 8, y + 26, z + 10, SpaceAgeCore.T0011Surface.blockID, 1, 2);
		world.setBlock(x + 8, y + 26, z + 11, SpaceAgeCore.T0011Surface.blockID, 1, 2);
		world.setBlock(x + 8, y + 26, z + 12, SpaceAgeCore.T0011Surface.blockID, 1, 2);
		world.setBlock(x + 8, y + 26, z + 13, SpaceAgeCore.T0011Surface.blockID, 1, 2);
		world.setBlock(x + 8, y + 26, z + 14, SpaceAgeCore.T0011Surface.blockID, 1, 2);
		world.setBlock(x + 8, y + 26, z + 15, SpaceAgeCore.T0011Surface.blockID, 1, 2);
		world.setBlock(x + 8, y + 26, z + 16, SpaceAgeCore.T0011Surface.blockID, 1, 2);
		world.setBlock(x + 8, y + 26, z + 17, SpaceAgeCore.T0011Surface.blockID, 1, 2);
		world.setBlock(x + 8, y + 26, z + 18, SpaceAgeCore.T0011Surface.blockID, 1, 2);
		world.setBlock(x + 8, y + 26, z + 19, SpaceAgeCore.T0011Surface.blockID, 1, 2);
		world.setBlock(x + 8, y + 26, z + 20, SpaceAgeCore.T0011Surface.blockID, 1, 2);
		world.setBlock(x + 8, y + 26, z + 21, SpaceAgeCore.T0011Surface.blockID, 1, 2);
		world.setBlock(x + 8, y + 26, z + 22, SpaceAgeCore.T0011Surface.blockID, 1, 2);
		world.setBlock(x + 8, y + 26, z + 23, SpaceAgeCore.T0011Surface.blockID, 1, 2);
		world.setBlock(x + 8, y + 27, z + 4, SpaceAgeCore.T0011Surface.blockID, 1, 2);
		world.setBlock(x + 8, y + 27, z + 5, SpaceAgeCore.T0011Surface.blockID, 1, 2);
		world.setBlock(x + 8, y + 27, z + 6, SpaceAgeCore.T0011Surface.blockID, 1, 2);
		world.setBlock(x + 8, y + 27, z + 7, SpaceAgeCore.T0011Surface.blockID, 1, 2);
		world.setBlock(x + 8, y + 27, z + 8, SpaceAgeCore.T0011Surface.blockID, 1, 2);
		world.setBlock(x + 8, y + 27, z + 9, SpaceAgeCore.T0011Surface.blockID, 1, 2);
		world.setBlock(x + 8, y + 27, z + 10, SpaceAgeCore.T0011Surface.blockID, 1, 2);
		world.setBlock(x + 8, y + 27, z + 11, SpaceAgeCore.T0011Surface.blockID, 1, 2);
		world.setBlock(x + 8, y + 27, z + 12, SpaceAgeCore.T0011Surface.blockID, 1, 2);
		world.setBlock(x + 8, y + 27, z + 13, SpaceAgeCore.T0011Surface.blockID, 1, 2);
		world.setBlock(x + 8, y + 27, z + 14, SpaceAgeCore.T0011Surface.blockID, 1, 2);
		world.setBlock(x + 8, y + 27, z + 15, SpaceAgeCore.T0011Surface.blockID, 1, 2);
		world.setBlock(x + 8, y + 27, z + 16, SpaceAgeCore.T0011Surface.blockID, 1, 2);
		world.setBlock(x + 8, y + 27, z + 17, SpaceAgeCore.T0011Surface.blockID, 1, 2);
		world.setBlock(x + 8, y + 27, z + 18, SpaceAgeCore.T0011Surface.blockID, 1, 2);
		world.setBlock(x + 8, y + 27, z + 19, SpaceAgeCore.T0011Surface.blockID, 1, 2);
		world.setBlock(x + 8, y + 27, z + 20, SpaceAgeCore.T0011Surface.blockID, 1, 2);
		world.setBlock(x + 8, y + 27, z + 21, SpaceAgeCore.T0011Surface.blockID, 1, 2);
		world.setBlock(x + 8, y + 27, z + 22, SpaceAgeCore.T0011Surface.blockID, 1, 2);
		world.setBlock(x + 8, y + 28, z + 5, SpaceAgeCore.T0011Surface.blockID, 3, 2);
		world.setBlock(x + 8, y + 28, z + 21, SpaceAgeCore.T0011Surface.blockID, 3, 2);
		world.setBlock(x + 8, y + 29, z + 5, SpaceAgeCore.T0011Surface.blockID, 3, 2);
		world.setBlock(x + 8, y + 29, z + 21, SpaceAgeCore.T0011Surface.blockID, 3, 2);
		world.setBlock(x + 8, y + 30, z + 6, SpaceAgeCore.T0011Surface.blockID, 3, 2);
		world.setBlock(x + 8, y + 30, z + 20, SpaceAgeCore.T0011Surface.blockID, 3, 2);
		world.setBlock(x + 8, y + 31, z + 6, SpaceAgeCore.T0011Surface.blockID, 3, 2);
		world.setBlock(x + 8, y + 31, z + 20, SpaceAgeCore.T0011Surface.blockID, 3, 2);
		world.setBlock(x + 8, y + 32, z + 6, SpaceAgeCore.T0011Surface.blockID, 3, 2);
		world.setBlock(x + 8, y + 32, z + 20, SpaceAgeCore.T0011Surface.blockID, 3, 2);
		world.setBlock(x + 8, y + 33, z + 7, SpaceAgeCore.T0011Surface.blockID, 3, 2);
		world.setBlock(x + 8, y + 33, z + 19, SpaceAgeCore.T0011Surface.blockID, 3, 2);
		world.setBlock(x + 8, y + 34, z + 8, SpaceAgeCore.T0011Surface.blockID, 3, 2);
		world.setBlock(x + 8, y + 34, z + 18, SpaceAgeCore.T0011Surface.blockID, 3, 2);
		world.setBlock(x + 8, y + 35, z + 9, SpaceAgeCore.T0011Surface.blockID, 3, 2);
		world.setBlock(x + 8, y + 35, z + 10, SpaceAgeCore.T0011Surface.blockID, 3, 2);
		world.setBlock(x + 8, y + 35, z + 11, SpaceAgeCore.T0011Surface.blockID, 3, 2);
		world.setBlock(x + 8, y + 35, z + 15, SpaceAgeCore.T0011Surface.blockID, 3, 2);
		world.setBlock(x + 8, y + 35, z + 16, SpaceAgeCore.T0011Surface.blockID, 3, 2);
		world.setBlock(x + 8, y + 35, z + 17, SpaceAgeCore.T0011Surface.blockID, 3, 2);
		world.setBlock(x + 8, y + 36, z + 12, SpaceAgeCore.T0011Surface.blockID, 3, 2);
		world.setBlock(x + 8, y + 36, z + 13, SpaceAgeCore.T0011Surface.blockID, 3, 2);
		world.setBlock(x + 8, y + 36, z + 14, SpaceAgeCore.T0011Surface.blockID, 3, 2);
		world.setBlock(x + 9, y + 24, z + 1, SpaceAgeCore.T0011Surface.blockID, 1, 2);
		world.setBlock(x + 9, y + 24, z + 2, SpaceAgeCore.T0011Surface.blockID, 1, 2);
		world.setBlock(x + 9, y + 24, z + 3, SpaceAgeCore.T0011Surface.blockID, 1, 2);
		world.setBlock(x + 9, y + 24, z + 4, SpaceAgeCore.T0011Surface.blockID, 1, 2);
		world.setBlock(x + 9, y + 24, z + 5, SpaceAgeCore.T0011Surface.blockID, 1, 2);
		world.setBlock(x + 9, y + 24, z + 6, SpaceAgeCore.T0011Surface.blockID, 1, 2);
		world.setBlock(x + 9, y + 24, z + 7, SpaceAgeCore.T0011Surface.blockID, 1, 2);
		world.setBlock(x + 9, y + 24, z + 8, SpaceAgeCore.T0011Surface.blockID, 1, 2);
		world.setBlock(x + 9, y + 24, z + 9, SpaceAgeCore.T0011Surface.blockID, 1, 2);
		world.setBlock(x + 9, y + 24, z + 10, SpaceAgeCore.T0011Surface.blockID, 1, 2);
		world.setBlock(x + 9, y + 24, z + 11, SpaceAgeCore.T0011Surface.blockID, 1, 2);
		world.setBlock(x + 9, y + 24, z + 12, SpaceAgeCore.T0011Surface.blockID, 1, 2);
		world.setBlock(x + 9, y + 24, z + 13, SpaceAgeCore.T0011Surface.blockID, 1, 2);
		world.setBlock(x + 9, y + 24, z + 14, SpaceAgeCore.T0011Surface.blockID, 1, 2);
		world.setBlock(x + 9, y + 24, z + 15, SpaceAgeCore.T0011Surface.blockID, 1, 2);
		world.setBlock(x + 9, y + 24, z + 16, SpaceAgeCore.T0011Surface.blockID, 1, 2);
		world.setBlock(x + 9, y + 24, z + 17, SpaceAgeCore.T0011Surface.blockID, 1, 2);
		world.setBlock(x + 9, y + 24, z + 18, SpaceAgeCore.T0011Surface.blockID, 1, 2);
		world.setBlock(x + 9, y + 24, z + 19, SpaceAgeCore.T0011Surface.blockID, 1, 2);
		world.setBlock(x + 9, y + 24, z + 20, SpaceAgeCore.T0011Surface.blockID, 1, 2);
		world.setBlock(x + 9, y + 24, z + 21, SpaceAgeCore.T0011Surface.blockID, 1, 2);
		world.setBlock(x + 9, y + 24, z + 22, SpaceAgeCore.T0011Surface.blockID, 1, 2);
		world.setBlock(x + 9, y + 24, z + 23, SpaceAgeCore.T0011Surface.blockID, 1, 2);
		world.setBlock(x + 9, y + 24, z + 24, SpaceAgeCore.T0011Surface.blockID, 1, 2);
		world.setBlock(x + 9, y + 25, z + 2, SpaceAgeCore.T0011Surface.blockID, 1, 2);
		world.setBlock(x + 9, y + 25, z + 3, SpaceAgeCore.T0011Surface.blockID, 1, 2);
		world.setBlock(x + 9, y + 25, z + 4, SpaceAgeCore.T0011Surface.blockID, 1, 2);
		world.setBlock(x + 9, y + 25, z + 5, SpaceAgeCore.T0011Surface.blockID, 1, 2);
		world.setBlock(x + 9, y + 25, z + 6, SpaceAgeCore.T0011Surface.blockID, 1, 2);
		world.setBlock(x + 9, y + 25, z + 7, SpaceAgeCore.T0011Surface.blockID, 1, 2);
		world.setBlock(x + 9, y + 25, z + 8, SpaceAgeCore.T0011Surface.blockID, 1, 2);
		world.setBlock(x + 9, y + 25, z + 9, SpaceAgeCore.T0011Surface.blockID, 1, 2);
		world.setBlock(x + 9, y + 25, z + 10, SpaceAgeCore.T0011Surface.blockID, 1, 2);
		world.setBlock(x + 9, y + 25, z + 11, SpaceAgeCore.T0011Surface.blockID, 1, 2);
		world.setBlock(x + 9, y + 25, z + 12, SpaceAgeCore.T0011Surface.blockID, 1, 2);
		world.setBlock(x + 9, y + 25, z + 13, SpaceAgeCore.T0011Surface.blockID, 1, 2);
		world.setBlock(x + 9, y + 25, z + 14, SpaceAgeCore.T0011Surface.blockID, 1, 2);
		world.setBlock(x + 9, y + 25, z + 15, SpaceAgeCore.T0011Surface.blockID, 1, 2);
		world.setBlock(x + 9, y + 25, z + 16, SpaceAgeCore.T0011Surface.blockID, 1, 2);
		world.setBlock(x + 9, y + 25, z + 17, SpaceAgeCore.T0011Surface.blockID, 1, 2);
		world.setBlock(x + 9, y + 25, z + 18, SpaceAgeCore.T0011Surface.blockID, 1, 2);
		world.setBlock(x + 9, y + 25, z + 19, SpaceAgeCore.T0011Surface.blockID, 1, 2);
		world.setBlock(x + 9, y + 25, z + 20, SpaceAgeCore.T0011Surface.blockID, 1, 2);
		world.setBlock(x + 9, y + 25, z + 21, SpaceAgeCore.T0011Surface.blockID, 1, 2);
		world.setBlock(x + 9, y + 25, z + 22, SpaceAgeCore.T0011Surface.blockID, 1, 2);
		world.setBlock(x + 9, y + 25, z + 23, SpaceAgeCore.T0011Surface.blockID, 1, 2);
		world.setBlock(x + 9, y + 25, z + 24, SpaceAgeCore.T0011Surface.blockID, 1, 2);
		world.setBlock(x + 9, y + 26, z + 3, SpaceAgeCore.T0011Surface.blockID, 1, 2);
		world.setBlock(x + 9, y + 26, z + 4, SpaceAgeCore.T0011Surface.blockID, 1, 2);
		world.setBlock(x + 9, y + 26, z + 5, SpaceAgeCore.T0011Surface.blockID, 1, 2);
		world.setBlock(x + 9, y + 26, z + 6, SpaceAgeCore.T0011Surface.blockID, 1, 2);
		world.setBlock(x + 9, y + 26, z + 7, SpaceAgeCore.T0011Surface.blockID, 1, 2);
		world.setBlock(x + 9, y + 26, z + 8, SpaceAgeCore.T0011Surface.blockID, 1, 2);
		world.setBlock(x + 9, y + 26, z + 9, SpaceAgeCore.T0011Surface.blockID, 1, 2);
		world.setBlock(x + 9, y + 26, z + 10, SpaceAgeCore.T0011Surface.blockID, 1, 2);
		world.setBlock(x + 9, y + 26, z + 11, SpaceAgeCore.T0011Surface.blockID, 1, 2);
		world.setBlock(x + 9, y + 26, z + 12, SpaceAgeCore.T0011Surface.blockID, 1, 2);
		world.setBlock(x + 9, y + 26, z + 13, SpaceAgeCore.T0011Surface.blockID, 1, 2);
		world.setBlock(x + 9, y + 26, z + 14, SpaceAgeCore.T0011Surface.blockID, 1, 2);
		world.setBlock(x + 9, y + 26, z + 15, SpaceAgeCore.T0011Surface.blockID, 1, 2);
		world.setBlock(x + 9, y + 26, z + 16, SpaceAgeCore.T0011Surface.blockID, 1, 2);
		world.setBlock(x + 9, y + 26, z + 17, SpaceAgeCore.T0011Surface.blockID, 1, 2);
		world.setBlock(x + 9, y + 26, z + 18, SpaceAgeCore.T0011Surface.blockID, 1, 2);
		world.setBlock(x + 9, y + 26, z + 19, SpaceAgeCore.T0011Surface.blockID, 1, 2);
		world.setBlock(x + 9, y + 26, z + 20, SpaceAgeCore.T0011Surface.blockID, 1, 2);
		world.setBlock(x + 9, y + 26, z + 21, SpaceAgeCore.T0011Surface.blockID, 1, 2);
		world.setBlock(x + 9, y + 26, z + 22, SpaceAgeCore.T0011Surface.blockID, 1, 2);
		world.setBlock(x + 9, y + 26, z + 23, SpaceAgeCore.T0011Surface.blockID, 1, 2);
		world.setBlock(x + 9, y + 27, z + 4, SpaceAgeCore.T0011Surface.blockID, 1, 2);
		world.setBlock(x + 9, y + 27, z + 5, SpaceAgeCore.T0011Surface.blockID, 1, 2);
		world.setBlock(x + 9, y + 27, z + 6, SpaceAgeCore.T0011Surface.blockID, 1, 2);
		world.setBlock(x + 9, y + 27, z + 7, SpaceAgeCore.T0011Surface.blockID, 1, 2);
		world.setBlock(x + 9, y + 27, z + 8, SpaceAgeCore.T0011Surface.blockID, 1, 2);
		world.setBlock(x + 9, y + 27, z + 9, SpaceAgeCore.T0011Surface.blockID, 1, 2);
		world.setBlock(x + 9, y + 27, z + 10, SpaceAgeCore.T0011Surface.blockID, 1, 2);
		world.setBlock(x + 9, y + 27, z + 11, SpaceAgeCore.T0011Surface.blockID, 1, 2);
		world.setBlock(x + 9, y + 27, z + 12, SpaceAgeCore.T0011Surface.blockID, 1, 2);
		world.setBlock(x + 9, y + 27, z + 13, SpaceAgeCore.T0011Surface.blockID, 1, 2);
		world.setBlock(x + 9, y + 27, z + 14, SpaceAgeCore.T0011Surface.blockID, 1, 2);
		world.setBlock(x + 9, y + 27, z + 15, SpaceAgeCore.T0011Surface.blockID, 1, 2);
		world.setBlock(x + 9, y + 27, z + 16, SpaceAgeCore.T0011Surface.blockID, 1, 2);
		world.setBlock(x + 9, y + 27, z + 17, SpaceAgeCore.T0011Surface.blockID, 1, 2);
		world.setBlock(x + 9, y + 27, z + 18, SpaceAgeCore.T0011Surface.blockID, 1, 2);
		world.setBlock(x + 9, y + 27, z + 19, SpaceAgeCore.T0011Surface.blockID, 1, 2);
		world.setBlock(x + 9, y + 27, z + 20, SpaceAgeCore.T0011Surface.blockID, 1, 2);
		world.setBlock(x + 9, y + 27, z + 21, SpaceAgeCore.T0011Surface.blockID, 1, 2);
		world.setBlock(x + 9, y + 27, z + 22, SpaceAgeCore.T0011Surface.blockID, 1, 2);
		world.setBlock(x + 9, y + 28, z + 5, SpaceAgeCore.T0011Surface.blockID, 3, 2);
		world.setBlock(x + 9, y + 28, z + 21, SpaceAgeCore.T0011Surface.blockID, 3, 2);
		world.setBlock(x + 9, y + 29, z + 5, SpaceAgeCore.T0011Surface.blockID, 3, 2);
		world.setBlock(x + 9, y + 29, z + 21, SpaceAgeCore.T0011Surface.blockID, 3, 2);
		world.setBlock(x + 9, y + 30, z + 5, SpaceAgeCore.T0011Surface.blockID, 3, 2);
		world.setBlock(x + 9, y + 30, z + 21, SpaceAgeCore.T0011Surface.blockID, 3, 2);
		world.setBlock(x + 9, y + 31, z + 5, SpaceAgeCore.T0011Surface.blockID, 3, 2);
		world.setBlock(x + 9, y + 31, z + 21, SpaceAgeCore.T0011Surface.blockID, 3, 2);
		world.setBlock(x + 9, y + 32, z + 6, SpaceAgeCore.T0011Surface.blockID, 3, 2);
		world.setBlock(x + 9, y + 32, z + 20, SpaceAgeCore.T0011Surface.blockID, 3, 2);
		world.setBlock(x + 9, y + 33, z + 6, SpaceAgeCore.T0011Surface.blockID, 3, 2);
		world.setBlock(x + 9, y + 33, z + 20, SpaceAgeCore.T0011Surface.blockID, 3, 2);
		world.setBlock(x + 9, y + 34, z + 7, SpaceAgeCore.T0011Surface.blockID, 3, 2);
		world.setBlock(x + 9, y + 34, z + 19, SpaceAgeCore.T0011Surface.blockID, 3, 2);
		world.setBlock(x + 9, y + 35, z + 8, SpaceAgeCore.T0011Surface.blockID, 3, 2);
		world.setBlock(x + 9, y + 35, z + 9, SpaceAgeCore.T0011Surface.blockID, 3, 2);
		world.setBlock(x + 9, y + 35, z + 17, SpaceAgeCore.T0011Surface.blockID, 3, 2);
		world.setBlock(x + 9, y + 35, z + 18, SpaceAgeCore.T0011Surface.blockID, 3, 2);
		world.setBlock(x + 9, y + 36, z + 10, SpaceAgeCore.T0011Surface.blockID, 3, 2);
		world.setBlock(x + 9, y + 36, z + 11, SpaceAgeCore.T0011Surface.blockID, 3, 2);
		world.setBlock(x + 9, y + 36, z + 12, SpaceAgeCore.T0011Surface.blockID, 3, 2);
		world.setBlock(x + 9, y + 36, z + 13, SpaceAgeCore.T0011Surface.blockID, 3, 2);
		world.setBlock(x + 9, y + 36, z + 14, SpaceAgeCore.T0011Surface.blockID, 3, 2);
		world.setBlock(x + 9, y + 36, z + 15, SpaceAgeCore.T0011Surface.blockID, 3, 2);
		world.setBlock(x + 9, y + 36, z + 16, SpaceAgeCore.T0011Surface.blockID, 3, 2);
		world.setBlock(x + 10, y + 24, z + 0, SpaceAgeCore.T0011Surface.blockID, 1, 2);
		world.setBlock(x + 10, y + 24, z + 1, SpaceAgeCore.T0011Surface.blockID, 1, 2);
		world.setBlock(x + 10, y + 24, z + 2, SpaceAgeCore.T0011Surface.blockID, 1, 2);
		world.setBlock(x + 10, y + 24, z + 3, SpaceAgeCore.T0011Surface.blockID, 1, 2);
		world.setBlock(x + 10, y + 24, z + 4, SpaceAgeCore.T0011Surface.blockID, 1, 2);
		world.setBlock(x + 10, y + 24, z + 5, SpaceAgeCore.T0011Surface.blockID, 1, 2);
		world.setBlock(x + 10, y + 24, z + 6, SpaceAgeCore.T0011Surface.blockID, 1, 2);
		world.setBlock(x + 10, y + 24, z + 7, SpaceAgeCore.T0011Surface.blockID, 1, 2);
		world.setBlock(x + 10, y + 24, z + 8, SpaceAgeCore.T0011Surface.blockID, 1, 2);
		world.setBlock(x + 10, y + 24, z + 9, SpaceAgeCore.T0011Surface.blockID, 1, 2);
		world.setBlock(x + 10, y + 24, z + 10, SpaceAgeCore.T0011Surface.blockID, 1, 2);
		world.setBlock(x + 10, y + 24, z + 11, SpaceAgeCore.T0011Surface.blockID, 1, 2);
		world.setBlock(x + 10, y + 24, z + 12, SpaceAgeCore.T0011Surface.blockID, 1, 2);
		world.setBlock(x + 10, y + 24, z + 13, SpaceAgeCore.T0011Surface.blockID, 1, 2);
		world.setBlock(x + 10, y + 24, z + 14, SpaceAgeCore.T0011Surface.blockID, 1, 2);
		world.setBlock(x + 10, y + 24, z + 15, SpaceAgeCore.T0011Surface.blockID, 1, 2);
		world.setBlock(x + 10, y + 24, z + 16, SpaceAgeCore.T0011Surface.blockID, 1, 2);
		world.setBlock(x + 10, y + 24, z + 17, SpaceAgeCore.T0011Surface.blockID, 1, 2);
		world.setBlock(x + 10, y + 24, z + 18, SpaceAgeCore.T0011Surface.blockID, 1, 2);
		world.setBlock(x + 10, y + 24, z + 19, SpaceAgeCore.T0011Surface.blockID, 1, 2);
		world.setBlock(x + 10, y + 24, z + 20, SpaceAgeCore.T0011Surface.blockID, 1, 2);
		world.setBlock(x + 10, y + 24, z + 21, SpaceAgeCore.T0011Surface.blockID, 1, 2);
		world.setBlock(x + 10, y + 24, z + 22, SpaceAgeCore.T0011Surface.blockID, 1, 2);
		world.setBlock(x + 10, y + 24, z + 23, SpaceAgeCore.T0011Surface.blockID, 1, 2);
		world.setBlock(x + 10, y + 24, z + 24, SpaceAgeCore.T0011Surface.blockID, 1, 2);
		world.setBlock(x + 10, y + 25, z + 1, SpaceAgeCore.T0011Surface.blockID, 1, 2);
		world.setBlock(x + 10, y + 25, z + 2, SpaceAgeCore.T0011Surface.blockID, 1, 2);
		world.setBlock(x + 10, y + 25, z + 3, SpaceAgeCore.T0011Surface.blockID, 1, 2);
		world.setBlock(x + 10, y + 25, z + 4, SpaceAgeCore.T0011Surface.blockID, 1, 2);
		world.setBlock(x + 10, y + 25, z + 5, SpaceAgeCore.T0011Surface.blockID, 1, 2);
		world.setBlock(x + 10, y + 25, z + 6, SpaceAgeCore.T0011Surface.blockID, 1, 2);
		world.setBlock(x + 10, y + 25, z + 7, SpaceAgeCore.T0011Surface.blockID, 1, 2);
		world.setBlock(x + 10, y + 25, z + 8, SpaceAgeCore.T0011Surface.blockID, 1, 2);
		world.setBlock(x + 10, y + 25, z + 9, SpaceAgeCore.T0011Surface.blockID, 1, 2);
		world.setBlock(x + 10, y + 25, z + 10, SpaceAgeCore.T0011Surface.blockID, 1, 2);
		world.setBlock(x + 10, y + 25, z + 11, SpaceAgeCore.T0011Surface.blockID, 1, 2);
		world.setBlock(x + 10, y + 25, z + 12, SpaceAgeCore.T0011Surface.blockID, 1, 2);
		world.setBlock(x + 10, y + 25, z + 13, SpaceAgeCore.T0011Surface.blockID, 1, 2);
		world.setBlock(x + 10, y + 25, z + 14, SpaceAgeCore.T0011Surface.blockID, 1, 2);
		world.setBlock(x + 10, y + 25, z + 15, SpaceAgeCore.T0011Surface.blockID, 1, 2);
		world.setBlock(x + 10, y + 25, z + 16, SpaceAgeCore.T0011Surface.blockID, 1, 2);
		world.setBlock(x + 10, y + 25, z + 17, SpaceAgeCore.T0011Surface.blockID, 1, 2);
		world.setBlock(x + 10, y + 25, z + 18, SpaceAgeCore.T0011Surface.blockID, 1, 2);
		world.setBlock(x + 10, y + 25, z + 19, SpaceAgeCore.T0011Surface.blockID, 1, 2);
		world.setBlock(x + 10, y + 25, z + 20, SpaceAgeCore.T0011Surface.blockID, 1, 2);
		world.setBlock(x + 10, y + 25, z + 21, SpaceAgeCore.T0011Surface.blockID, 1, 2);
		world.setBlock(x + 10, y + 25, z + 22, SpaceAgeCore.T0011Surface.blockID, 1, 2);
		world.setBlock(x + 10, y + 25, z + 23, SpaceAgeCore.T0011Surface.blockID, 1, 2);
		world.setBlock(x + 10, y + 25, z + 24, SpaceAgeCore.T0011Surface.blockID, 1, 2);
		world.setBlock(x + 10, y + 26, z + 3, SpaceAgeCore.T0011Surface.blockID, 1, 2);
		world.setBlock(x + 10, y + 26, z + 4, SpaceAgeCore.T0011Surface.blockID, 1, 2);
		world.setBlock(x + 10, y + 26, z + 5, SpaceAgeCore.T0011Surface.blockID, 1, 2);
		world.setBlock(x + 10, y + 26, z + 6, SpaceAgeCore.T0011Surface.blockID, 1, 2);
		world.setBlock(x + 10, y + 26, z + 7, SpaceAgeCore.T0011Surface.blockID, 1, 2);
		world.setBlock(x + 10, y + 26, z + 8, SpaceAgeCore.T0011Surface.blockID, 1, 2);
		world.setBlock(x + 10, y + 26, z + 9, SpaceAgeCore.T0011Surface.blockID, 1, 2);
		world.setBlock(x + 10, y + 26, z + 10, SpaceAgeCore.T0011Surface.blockID, 1, 2);
		world.setBlock(x + 10, y + 26, z + 11, SpaceAgeCore.T0011Surface.blockID, 1, 2);
		world.setBlock(x + 10, y + 26, z + 12, SpaceAgeCore.T0011Surface.blockID, 1, 2);
		world.setBlock(x + 10, y + 26, z + 13, SpaceAgeCore.T0011Surface.blockID, 1, 2);
		world.setBlock(x + 10, y + 26, z + 14, SpaceAgeCore.T0011Surface.blockID, 1, 2);
		world.setBlock(x + 10, y + 26, z + 15, SpaceAgeCore.T0011Surface.blockID, 1, 2);
		world.setBlock(x + 10, y + 26, z + 16, SpaceAgeCore.T0011Surface.blockID, 1, 2);
		world.setBlock(x + 10, y + 26, z + 17, SpaceAgeCore.T0011Surface.blockID, 1, 2);
		world.setBlock(x + 10, y + 26, z + 18, SpaceAgeCore.T0011Surface.blockID, 1, 2);
		world.setBlock(x + 10, y + 26, z + 19, SpaceAgeCore.T0011Surface.blockID, 1, 2);
		world.setBlock(x + 10, y + 26, z + 20, SpaceAgeCore.T0011Surface.blockID, 1, 2);
		world.setBlock(x + 10, y + 26, z + 21, SpaceAgeCore.T0011Surface.blockID, 1, 2);
		world.setBlock(x + 10, y + 26, z + 22, SpaceAgeCore.T0011Surface.blockID, 1, 2);
		world.setBlock(x + 10, y + 26, z + 23, SpaceAgeCore.T0011Surface.blockID, 1, 2);
		world.setBlock(x + 10, y + 27, z + 4, SpaceAgeCore.T0011Surface.blockID, 1, 2);
		world.setBlock(x + 10, y + 27, z + 5, SpaceAgeCore.T0011Surface.blockID, 1, 2);
		world.setBlock(x + 10, y + 27, z + 6, SpaceAgeCore.T0011Surface.blockID, 1, 2);
		world.setBlock(x + 10, y + 27, z + 7, SpaceAgeCore.T0011Surface.blockID, 1, 2);
		world.setBlock(x + 10, y + 27, z + 8, SpaceAgeCore.T0011Surface.blockID, 1, 2);
		world.setBlock(x + 10, y + 27, z + 9, SpaceAgeCore.T0011Surface.blockID, 1, 2);
		world.setBlock(x + 10, y + 27, z + 10, SpaceAgeCore.T0011Surface.blockID, 1, 2);
		world.setBlock(x + 10, y + 27, z + 11, SpaceAgeCore.T0011Surface.blockID, 1, 2);
		world.setBlock(x + 10, y + 27, z + 12, SpaceAgeCore.T0011Surface.blockID, 1, 2);
		world.setBlock(x + 10, y + 27, z + 13, SpaceAgeCore.T0011Surface.blockID, 1, 2);
		world.setBlock(x + 10, y + 27, z + 14, SpaceAgeCore.T0011Surface.blockID, 1, 2);
		world.setBlock(x + 10, y + 27, z + 15, SpaceAgeCore.T0011Surface.blockID, 1, 2);
		world.setBlock(x + 10, y + 27, z + 16, SpaceAgeCore.T0011Surface.blockID, 1, 2);
		world.setBlock(x + 10, y + 27, z + 17, SpaceAgeCore.T0011Surface.blockID, 1, 2);
		world.setBlock(x + 10, y + 27, z + 18, SpaceAgeCore.T0011Surface.blockID, 1, 2);
		world.setBlock(x + 10, y + 27, z + 19, SpaceAgeCore.T0011Surface.blockID, 1, 2);
		world.setBlock(x + 10, y + 27, z + 20, SpaceAgeCore.T0011Surface.blockID, 1, 2);
		world.setBlock(x + 10, y + 27, z + 21, SpaceAgeCore.T0011Surface.blockID, 1, 2);
		world.setBlock(x + 10, y + 27, z + 22, SpaceAgeCore.T0011Surface.blockID, 1, 2);
		world.setBlock(x + 10, y + 28, z + 4, SpaceAgeCore.T0011Surface.blockID, 3, 2);
		world.setBlock(x + 10, y + 28, z + 22, SpaceAgeCore.T0011Surface.blockID, 3, 2);
		world.setBlock(x + 10, y + 29, z + 5, SpaceAgeCore.T0011Surface.blockID, 3, 2);
		world.setBlock(x + 10, y + 29, z + 21, SpaceAgeCore.T0011Surface.blockID, 3, 2);
		world.setBlock(x + 10, y + 30, z + 5, SpaceAgeCore.T0011Surface.blockID, 3, 2);
		world.setBlock(x + 10, y + 30, z + 21, SpaceAgeCore.T0011Surface.blockID, 3, 2);
		world.setBlock(x + 10, y + 31, z + 5, SpaceAgeCore.T0011Surface.blockID, 3, 2);
		world.setBlock(x + 10, y + 31, z + 21, SpaceAgeCore.T0011Surface.blockID, 3, 2);
		world.setBlock(x + 10, y + 32, z + 5, SpaceAgeCore.T0011Surface.blockID, 3, 2);
		world.setBlock(x + 10, y + 32, z + 21, SpaceAgeCore.T0011Surface.blockID, 3, 2);
		world.setBlock(x + 10, y + 33, z + 6, SpaceAgeCore.T0011Surface.blockID, 3, 2);
		world.setBlock(x + 10, y + 33, z + 20, SpaceAgeCore.T0011Surface.blockID, 3, 2);
		world.setBlock(x + 10, y + 34, z + 7, SpaceAgeCore.T0011Surface.blockID, 3, 2);
		world.setBlock(x + 10, y + 34, z + 19, SpaceAgeCore.T0011Surface.blockID, 3, 2);
		world.setBlock(x + 10, y + 35, z + 8, SpaceAgeCore.T0011Surface.blockID, 3, 2);
		world.setBlock(x + 10, y + 35, z + 18, SpaceAgeCore.T0011Surface.blockID, 3, 2);
		world.setBlock(x + 10, y + 36, z + 9, SpaceAgeCore.T0011Surface.blockID, 3, 2);
		world.setBlock(x + 10, y + 36, z + 10, SpaceAgeCore.T0011Surface.blockID, 3, 2);
		world.setBlock(x + 10, y + 36, z + 11, SpaceAgeCore.T0011Surface.blockID, 3, 2);
		world.setBlock(x + 10, y + 36, z + 12, SpaceAgeCore.T0011Surface.blockID, 3, 2);
		world.setBlock(x + 10, y + 36, z + 14, SpaceAgeCore.T0011Surface.blockID, 3, 2);
		world.setBlock(x + 10, y + 36, z + 15, SpaceAgeCore.T0011Surface.blockID, 3, 2);
		world.setBlock(x + 10, y + 36, z + 16, SpaceAgeCore.T0011Surface.blockID, 3, 2);
		world.setBlock(x + 10, y + 36, z + 17, SpaceAgeCore.T0011Surface.blockID, 3, 2);
		world.setBlock(x + 10, y + 37, z + 13, SpaceAgeCore.T0011Surface.blockID, 3, 2);
		world.setBlock(x + 11, y + 12, z + 19, SpaceAgeCore.T0011Surface.blockID, 1, 2);
		world.setBlock(x + 11, y + 12, z + 20, SpaceAgeCore.T0011Surface.blockID, 1, 2);
		world.setBlock(x + 11, y + 12, z + 21, SpaceAgeCore.T0011Surface.blockID, 1, 2);
		world.setBlock(x + 11, y + 24, z + 0, SpaceAgeCore.T0011Surface.blockID, 1, 2);
		world.setBlock(x + 11, y + 24, z + 1, SpaceAgeCore.T0011Surface.blockID, 1, 2);
		world.setBlock(x + 11, y + 24, z + 2, SpaceAgeCore.T0011Surface.blockID, 1, 2);
		world.setBlock(x + 11, y + 24, z + 3, SpaceAgeCore.T0011Surface.blockID, 1, 2);
		world.setBlock(x + 11, y + 24, z + 4, SpaceAgeCore.T0011Surface.blockID, 1, 2);
		world.setBlock(x + 11, y + 24, z + 5, SpaceAgeCore.T0011Surface.blockID, 1, 2);
		world.setBlock(x + 11, y + 24, z + 6, SpaceAgeCore.T0011Surface.blockID, 1, 2);
		world.setBlock(x + 11, y + 24, z + 7, SpaceAgeCore.T0011Surface.blockID, 1, 2);
		world.setBlock(x + 11, y + 24, z + 8, SpaceAgeCore.T0011Surface.blockID, 1, 2);
		world.setBlock(x + 11, y + 24, z + 9, SpaceAgeCore.T0011Surface.blockID, 1, 2);
		world.setBlock(x + 11, y + 24, z + 10, SpaceAgeCore.T0011Surface.blockID, 1, 2);
		world.setBlock(x + 11, y + 24, z + 11, SpaceAgeCore.T0011Surface.blockID, 1, 2);
		world.setBlock(x + 11, y + 24, z + 12, SpaceAgeCore.T0011Surface.blockID, 1, 2);
		world.setBlock(x + 11, y + 24, z + 13, SpaceAgeCore.T0011Surface.blockID, 1, 2);
		world.setBlock(x + 11, y + 24, z + 14, SpaceAgeCore.T0011Surface.blockID, 1, 2);
		world.setBlock(x + 11, y + 24, z + 15, SpaceAgeCore.T0011Surface.blockID, 1, 2);
		world.setBlock(x + 11, y + 24, z + 16, SpaceAgeCore.T0011Surface.blockID, 1, 2);
		world.setBlock(x + 11, y + 24, z + 17, SpaceAgeCore.T0011Surface.blockID, 1, 2);
		world.setBlock(x + 11, y + 24, z + 18, SpaceAgeCore.T0011Surface.blockID, 1, 2);
		world.setBlock(x + 11, y + 24, z + 19, SpaceAgeCore.T0011Surface.blockID, 1, 2);
		world.setBlock(x + 11, y + 24, z + 20, SpaceAgeCore.T0011Surface.blockID, 1, 2);
		world.setBlock(x + 11, y + 24, z + 21, SpaceAgeCore.T0011Surface.blockID, 1, 2);
		world.setBlock(x + 11, y + 24, z + 22, SpaceAgeCore.T0011Surface.blockID, 1, 2);
		world.setBlock(x + 11, y + 24, z + 23, SpaceAgeCore.T0011Surface.blockID, 1, 2);
		world.setBlock(x + 11, y + 24, z + 24, SpaceAgeCore.T0011Surface.blockID, 1, 2);
		world.setBlock(x + 11, y + 25, z + 1, SpaceAgeCore.T0011Surface.blockID, 1, 2);
		world.setBlock(x + 11, y + 25, z + 2, SpaceAgeCore.T0011Surface.blockID, 1, 2);
		world.setBlock(x + 11, y + 25, z + 3, SpaceAgeCore.T0011Surface.blockID, 1, 2);
		world.setBlock(x + 11, y + 25, z + 4, SpaceAgeCore.T0011Surface.blockID, 1, 2);
		world.setBlock(x + 11, y + 25, z + 5, SpaceAgeCore.T0011Surface.blockID, 1, 2);
		world.setBlock(x + 11, y + 25, z + 6, SpaceAgeCore.T0011Surface.blockID, 1, 2);
		world.setBlock(x + 11, y + 25, z + 7, SpaceAgeCore.T0011Surface.blockID, 1, 2);
		world.setBlock(x + 11, y + 25, z + 8, SpaceAgeCore.T0011Surface.blockID, 1, 2);
		world.setBlock(x + 11, y + 25, z + 9, SpaceAgeCore.T0011Surface.blockID, 1, 2);
		world.setBlock(x + 11, y + 25, z + 10, SpaceAgeCore.T0011Surface.blockID, 1, 2);
		world.setBlock(x + 11, y + 25, z + 11, SpaceAgeCore.T0011Surface.blockID, 1, 2);
		world.setBlock(x + 11, y + 25, z + 12, SpaceAgeCore.T0011Surface.blockID, 1, 2);
		world.setBlock(x + 11, y + 25, z + 13, SpaceAgeCore.T0011Surface.blockID, 1, 2);
		world.setBlock(x + 11, y + 25, z + 14, SpaceAgeCore.T0011Surface.blockID, 1, 2);
		world.setBlock(x + 11, y + 25, z + 15, SpaceAgeCore.T0011Surface.blockID, 1, 2);
		world.setBlock(x + 11, y + 25, z + 16, SpaceAgeCore.T0011Surface.blockID, 1, 2);
		world.setBlock(x + 11, y + 25, z + 17, SpaceAgeCore.T0011Surface.blockID, 1, 2);
		world.setBlock(x + 11, y + 25, z + 18, SpaceAgeCore.T0011Surface.blockID, 1, 2);
		world.setBlock(x + 11, y + 25, z + 19, SpaceAgeCore.T0011Surface.blockID, 1, 2);
		world.setBlock(x + 11, y + 25, z + 20, SpaceAgeCore.T0011Surface.blockID, 1, 2);
		world.setBlock(x + 11, y + 25, z + 21, SpaceAgeCore.T0011Surface.blockID, 1, 2);
		world.setBlock(x + 11, y + 25, z + 22, SpaceAgeCore.T0011Surface.blockID, 1, 2);
		world.setBlock(x + 11, y + 25, z + 23, SpaceAgeCore.T0011Surface.blockID, 1, 2);
		world.setBlock(x + 11, y + 25, z + 24, SpaceAgeCore.T0011Surface.blockID, 1, 2);
		world.setBlock(x + 11, y + 26, z + 2, SpaceAgeCore.T0011Surface.blockID, 1, 2);
		world.setBlock(x + 11, y + 26, z + 3, SpaceAgeCore.T0011Surface.blockID, 1, 2);
		world.setBlock(x + 11, y + 26, z + 4, SpaceAgeCore.T0011Surface.blockID, 1, 2);
		world.setBlock(x + 11, y + 26, z + 5, SpaceAgeCore.T0011Surface.blockID, 1, 2);
		world.setBlock(x + 11, y + 26, z + 6, SpaceAgeCore.T0011Surface.blockID, 1, 2);
		world.setBlock(x + 11, y + 26, z + 7, SpaceAgeCore.T0011Surface.blockID, 1, 2);
		world.setBlock(x + 11, y + 26, z + 8, SpaceAgeCore.T0011Surface.blockID, 1, 2);
		world.setBlock(x + 11, y + 26, z + 9, SpaceAgeCore.T0011Surface.blockID, 1, 2);
		world.setBlock(x + 11, y + 26, z + 10, SpaceAgeCore.T0011Surface.blockID, 1, 2);
		world.setBlock(x + 11, y + 26, z + 11, SpaceAgeCore.T0011Surface.blockID, 1, 2);
		world.setBlock(x + 11, y + 26, z + 12, SpaceAgeCore.T0011Surface.blockID, 1, 2);
		world.setBlock(x + 11, y + 26, z + 13, SpaceAgeCore.T0011Surface.blockID, 1, 2);
		world.setBlock(x + 11, y + 26, z + 14, SpaceAgeCore.T0011Surface.blockID, 1, 2);
		world.setBlock(x + 11, y + 26, z + 15, SpaceAgeCore.T0011Surface.blockID, 1, 2);
		world.setBlock(x + 11, y + 26, z + 16, SpaceAgeCore.T0011Surface.blockID, 1, 2);
		world.setBlock(x + 11, y + 26, z + 17, SpaceAgeCore.T0011Surface.blockID, 1, 2);
		world.setBlock(x + 11, y + 26, z + 18, SpaceAgeCore.T0011Surface.blockID, 1, 2);
		world.setBlock(x + 11, y + 26, z + 19, SpaceAgeCore.T0011Surface.blockID, 1, 2);
		world.setBlock(x + 11, y + 26, z + 20, SpaceAgeCore.T0011Surface.blockID, 1, 2);
		world.setBlock(x + 11, y + 26, z + 21, SpaceAgeCore.T0011Surface.blockID, 1, 2);
		world.setBlock(x + 11, y + 26, z + 22, SpaceAgeCore.T0011Surface.blockID, 1, 2);
		world.setBlock(x + 11, y + 26, z + 23, SpaceAgeCore.T0011Surface.blockID, 1, 2);
		world.setBlock(x + 11, y + 26, z + 24, SpaceAgeCore.T0011Surface.blockID, 1, 2);
		world.setBlock(x + 11, y + 27, z + 3, SpaceAgeCore.T0011Surface.blockID, 1, 2);
		world.setBlock(x + 11, y + 27, z + 4, SpaceAgeCore.T0011Surface.blockID, 1, 2);
		world.setBlock(x + 11, y + 27, z + 5, SpaceAgeCore.T0011Surface.blockID, 1, 2);
		world.setBlock(x + 11, y + 27, z + 6, SpaceAgeCore.T0011Surface.blockID, 1, 2);
		world.setBlock(x + 11, y + 27, z + 7, SpaceAgeCore.T0011Surface.blockID, 1, 2);
		world.setBlock(x + 11, y + 27, z + 8, SpaceAgeCore.T0011Surface.blockID, 1, 2);
		world.setBlock(x + 11, y + 27, z + 9, SpaceAgeCore.T0011Surface.blockID, 1, 2);
		world.setBlock(x + 11, y + 27, z + 10, SpaceAgeCore.T0011Surface.blockID, 1, 2);
		world.setBlock(x + 11, y + 27, z + 11, SpaceAgeCore.T0011Surface.blockID, 1, 2);
		world.setBlock(x + 11, y + 27, z + 12, SpaceAgeCore.T0011Surface.blockID, 1, 2);
		world.setBlock(x + 11, y + 27, z + 13, SpaceAgeCore.T0011Surface.blockID, 1, 2);
		world.setBlock(x + 11, y + 27, z + 14, SpaceAgeCore.T0011Surface.blockID, 1, 2);
		world.setBlock(x + 11, y + 27, z + 15, SpaceAgeCore.T0011Surface.blockID, 1, 2);
		world.setBlock(x + 11, y + 27, z + 16, SpaceAgeCore.T0011Surface.blockID, 1, 2);
		world.setBlock(x + 11, y + 27, z + 17, SpaceAgeCore.T0011Surface.blockID, 1, 2);
		world.setBlock(x + 11, y + 27, z + 18, SpaceAgeCore.T0011Surface.blockID, 1, 2);
		world.setBlock(x + 11, y + 27, z + 19, SpaceAgeCore.T0011Surface.blockID, 1, 2);
		world.setBlock(x + 11, y + 27, z + 20, SpaceAgeCore.T0011Surface.blockID, 1, 2);
		world.setBlock(x + 11, y + 27, z + 21, SpaceAgeCore.T0011Surface.blockID, 1, 2);
		world.setBlock(x + 11, y + 27, z + 22, SpaceAgeCore.T0011Surface.blockID, 1, 2);
		world.setBlock(x + 11, y + 27, z + 23, SpaceAgeCore.T0011Surface.blockID, 1, 2);
		world.setBlock(x + 11, y + 28, z + 4, SpaceAgeCore.T0011Surface.blockID, 3, 2);
		world.setBlock(x + 11, y + 28, z + 22, SpaceAgeCore.T0011Surface.blockID, 3, 2);
		world.setBlock(x + 11, y + 29, z + 4, SpaceAgeCore.T0011Surface.blockID, 3, 2);
		world.setBlock(x + 11, y + 29, z + 22, SpaceAgeCore.T0011Surface.blockID, 3, 2);
		world.setBlock(x + 11, y + 30, z + 4, SpaceAgeCore.T0011Surface.blockID, 3, 2);
		world.setBlock(x + 11, y + 30, z + 22, SpaceAgeCore.T0011Surface.blockID, 3, 2);
		world.setBlock(x + 11, y + 31, z + 5, SpaceAgeCore.T0011Surface.blockID, 3, 2);
		world.setBlock(x + 11, y + 31, z + 21, SpaceAgeCore.T0011Surface.blockID, 3, 2);
		world.setBlock(x + 11, y + 32, z + 5, SpaceAgeCore.T0011Surface.blockID, 3, 2);
		world.setBlock(x + 11, y + 32, z + 21, SpaceAgeCore.T0011Surface.blockID, 3, 2);
		world.setBlock(x + 11, y + 33, z + 6, SpaceAgeCore.T0011Surface.blockID, 3, 2);
		world.setBlock(x + 11, y + 33, z + 20, SpaceAgeCore.T0011Surface.blockID, 3, 2);
		world.setBlock(x + 11, y + 34, z + 6, SpaceAgeCore.T0011Surface.blockID, 3, 2);
		world.setBlock(x + 11, y + 34, z + 20, SpaceAgeCore.T0011Surface.blockID, 3, 2);
		world.setBlock(x + 11, y + 35, z + 7, SpaceAgeCore.T0011Surface.blockID, 3, 2);
		world.setBlock(x + 11, y + 35, z + 8, SpaceAgeCore.T0011Surface.blockID, 3, 2);
		world.setBlock(x + 11, y + 35, z + 18, SpaceAgeCore.T0011Surface.blockID, 3, 2);
		world.setBlock(x + 11, y + 35, z + 19, SpaceAgeCore.T0011Surface.blockID, 3, 2);
		world.setBlock(x + 11, y + 36, z + 9, SpaceAgeCore.T0011Surface.blockID, 3, 2);
		world.setBlock(x + 11, y + 36, z + 10, SpaceAgeCore.T0011Surface.blockID, 3, 2);
		world.setBlock(x + 11, y + 36, z + 16, SpaceAgeCore.T0011Surface.blockID, 3, 2);
		world.setBlock(x + 11, y + 36, z + 17, SpaceAgeCore.T0011Surface.blockID, 3, 2);
		world.setBlock(x + 11, y + 37, z + 11, SpaceAgeCore.T0011Surface.blockID, 3, 2);
		world.setBlock(x + 11, y + 37, z + 12, SpaceAgeCore.T0011Surface.blockID, 3, 2);
		world.setBlock(x + 11, y + 37, z + 13, SpaceAgeCore.T0011Surface.blockID, 3, 2);
		world.setBlock(x + 11, y + 37, z + 14, SpaceAgeCore.T0011Surface.blockID, 3, 2);
		world.setBlock(x + 11, y + 37, z + 15, SpaceAgeCore.T0011Surface.blockID, 3, 2);
		world.setBlock(x + 12, y + 0, z + 12, SpaceAgeCore.T0011Surface.blockID, 2, 2);
		world.setBlock(x + 12, y + 0, z + 13, SpaceAgeCore.T0011Surface.blockID, 2, 2);
		world.setBlock(x + 12, y + 0, z + 14, SpaceAgeCore.T0011Surface.blockID, 2, 2);
		world.setBlock(x + 12, y + 1, z + 12, SpaceAgeCore.T0011Surface.blockID, 2, 2);
		world.setBlock(x + 12, y + 1, z + 13, SpaceAgeCore.T0011Surface.blockID, 2, 2);
		world.setBlock(x + 12, y + 1, z + 14, SpaceAgeCore.T0011Surface.blockID, 2, 2);
		world.setBlock(x + 12, y + 2, z + 12, SpaceAgeCore.T0011Surface.blockID, 2, 2);
		world.setBlock(x + 12, y + 2, z + 13, SpaceAgeCore.T0011Surface.blockID, 2, 2);
		world.setBlock(x + 12, y + 2, z + 14, SpaceAgeCore.T0011Surface.blockID, 2, 2);
		world.setBlock(x + 12, y + 3, z + 12, SpaceAgeCore.T0011Surface.blockID, 2, 2);
		world.setBlock(x + 12, y + 3, z + 13, SpaceAgeCore.T0011Surface.blockID, 2, 2);
		world.setBlock(x + 12, y + 3, z + 14, SpaceAgeCore.T0011Surface.blockID, 2, 2);
		world.setBlock(x + 12, y + 4, z + 12, SpaceAgeCore.T0011Surface.blockID, 2, 2);
		world.setBlock(x + 12, y + 4, z + 13, SpaceAgeCore.T0011Surface.blockID, 2, 2);
		world.setBlock(x + 12, y + 4, z + 14, SpaceAgeCore.T0011Surface.blockID, 2, 2);
		world.setBlock(x + 12, y + 5, z + 12, SpaceAgeCore.T0011Surface.blockID, 2, 2);
		world.setBlock(x + 12, y + 5, z + 13, SpaceAgeCore.T0011Surface.blockID, 2, 2);
		world.setBlock(x + 12, y + 5, z + 14, SpaceAgeCore.T0011Surface.blockID, 2, 2);
		world.setBlock(x + 12, y + 6, z + 12, SpaceAgeCore.T0011Surface.blockID, 2, 2);
		world.setBlock(x + 12, y + 6, z + 13, SpaceAgeCore.T0011Surface.blockID, 2, 2);
		world.setBlock(x + 12, y + 6, z + 14, SpaceAgeCore.T0011Surface.blockID, 2, 2);
		world.setBlock(x + 12, y + 7, z + 12, SpaceAgeCore.T0011Surface.blockID, 2, 2);
		world.setBlock(x + 12, y + 7, z + 13, SpaceAgeCore.T0011Surface.blockID, 2, 2);
		world.setBlock(x + 12, y + 7, z + 14, SpaceAgeCore.T0011Surface.blockID, 2, 2);
		world.setBlock(x + 12, y + 8, z + 12, SpaceAgeCore.T0011Surface.blockID, 2, 2);
		world.setBlock(x + 12, y + 8, z + 13, SpaceAgeCore.T0011Surface.blockID, 2, 2);
		world.setBlock(x + 12, y + 8, z + 14, SpaceAgeCore.T0011Surface.blockID, 2, 2);
		world.setBlock(x + 12, y + 9, z + 12, SpaceAgeCore.T0011Surface.blockID, 2, 2);
		world.setBlock(x + 12, y + 9, z + 13, SpaceAgeCore.T0011Surface.blockID, 2, 2);
		world.setBlock(x + 12, y + 9, z + 14, SpaceAgeCore.T0011Surface.blockID, 2, 2);
		world.setBlock(x + 12, y + 10, z + 12, SpaceAgeCore.T0011Surface.blockID, 2, 2);
		world.setBlock(x + 12, y + 10, z + 13, SpaceAgeCore.T0011Surface.blockID, 2, 2);
		world.setBlock(x + 12, y + 10, z + 14, SpaceAgeCore.T0011Surface.blockID, 2, 2);
		world.setBlock(x + 12, y + 11, z + 12, SpaceAgeCore.T0011Surface.blockID, 2, 2);
		world.setBlock(x + 12, y + 11, z + 13, SpaceAgeCore.T0011Surface.blockID, 2, 2);
		world.setBlock(x + 12, y + 11, z + 14, SpaceAgeCore.T0011Surface.blockID, 2, 2);
		world.setBlock(x + 12, y + 12, z + 12, SpaceAgeCore.T0011Surface.blockID, 2, 2);
		world.setBlock(x + 12, y + 12, z + 13, SpaceAgeCore.T0011Surface.blockID, 2, 2);
		world.setBlock(x + 12, y + 12, z + 14, SpaceAgeCore.T0011Surface.blockID, 2, 2);
		world.setBlock(x + 12, y + 12, z + 18, SpaceAgeCore.T0011Surface.blockID, 1, 2);
		world.setBlock(x + 12, y + 12, z + 19, SpaceAgeCore.T0011Surface.blockID, 1, 2);
		world.setBlock(x + 12, y + 12, z + 20, SpaceAgeCore.T0011Surface.blockID, 1, 2);
		world.setBlock(x + 12, y + 12, z + 21, SpaceAgeCore.T0011Surface.blockID, 1, 2);
		world.setBlock(x + 12, y + 12, z + 22, SpaceAgeCore.T0011Surface.blockID, 1, 2);
		world.setBlock(x + 12, y + 13, z + 12, SpaceAgeCore.T0011Surface.blockID, 2, 2);
		world.setBlock(x + 12, y + 13, z + 13, SpaceAgeCore.T0011Surface.blockID, 2, 2);
		world.setBlock(x + 12, y + 13, z + 14, SpaceAgeCore.T0011Surface.blockID, 2, 2);
		world.setBlock(x + 12, y + 13, z + 19, SpaceAgeCore.T0011Surface.blockID, 1, 2);
		world.setBlock(x + 12, y + 13, z + 20, SpaceAgeCore.T0011Surface.blockID, 1, 2);
		world.setBlock(x + 12, y + 13, z + 21, SpaceAgeCore.T0011Surface.blockID, 1, 2);
		world.setBlock(x + 12, y + 14, z + 12, SpaceAgeCore.T0011Surface.blockID, 2, 2);
		world.setBlock(x + 12, y + 14, z + 13, SpaceAgeCore.T0011Surface.blockID, 2, 2);
		world.setBlock(x + 12, y + 14, z + 14, SpaceAgeCore.T0011Surface.blockID, 2, 2);
		world.setBlock(x + 12, y + 15, z + 12, SpaceAgeCore.T0011Surface.blockID, 2, 2);
		world.setBlock(x + 12, y + 15, z + 13, SpaceAgeCore.T0011Surface.blockID, 2, 2);
		world.setBlock(x + 12, y + 15, z + 14, SpaceAgeCore.T0011Surface.blockID, 2, 2);
		world.setBlock(x + 12, y + 16, z + 12, SpaceAgeCore.T0011Surface.blockID, 2, 2);
		world.setBlock(x + 12, y + 16, z + 13, SpaceAgeCore.T0011Surface.blockID, 2, 2);
		world.setBlock(x + 12, y + 16, z + 14, SpaceAgeCore.T0011Surface.blockID, 2, 2);
		world.setBlock(x + 12, y + 17, z + 12, SpaceAgeCore.T0011Surface.blockID, 2, 2);
		world.setBlock(x + 12, y + 17, z + 13, SpaceAgeCore.T0011Surface.blockID, 2, 2);
		world.setBlock(x + 12, y + 17, z + 14, SpaceAgeCore.T0011Surface.blockID, 2, 2);
		world.setBlock(x + 12, y + 18, z + 12, SpaceAgeCore.T0011Surface.blockID, 2, 2);
		world.setBlock(x + 12, y + 18, z + 13, SpaceAgeCore.T0011Surface.blockID, 2, 2);
		world.setBlock(x + 12, y + 18, z + 14, SpaceAgeCore.T0011Surface.blockID, 2, 2);
		world.setBlock(x + 12, y + 19, z + 5, SpaceAgeCore.T0011Surface.blockID, 1, 2);
		world.setBlock(x + 12, y + 19, z + 6, SpaceAgeCore.T0011Surface.blockID, 1, 2);
		world.setBlock(x + 12, y + 19, z + 7, SpaceAgeCore.T0011Surface.blockID, 1, 2);
		world.setBlock(x + 12, y + 19, z + 12, SpaceAgeCore.T0011Surface.blockID, 2, 2);
		world.setBlock(x + 12, y + 19, z + 13, SpaceAgeCore.T0011Surface.blockID, 2, 2);
		world.setBlock(x + 12, y + 19, z + 14, SpaceAgeCore.T0011Surface.blockID, 2, 2);
		world.setBlock(x + 12, y + 20, z + 12, SpaceAgeCore.T0011Surface.blockID, 2, 2);
		world.setBlock(x + 12, y + 20, z + 13, SpaceAgeCore.T0011Surface.blockID, 2, 2);
		world.setBlock(x + 12, y + 20, z + 14, SpaceAgeCore.T0011Surface.blockID, 2, 2);
		world.setBlock(x + 12, y + 21, z + 12, SpaceAgeCore.T0011Surface.blockID, 2, 2);
		world.setBlock(x + 12, y + 21, z + 13, SpaceAgeCore.T0011Surface.blockID, 2, 2);
		world.setBlock(x + 12, y + 21, z + 14, SpaceAgeCore.T0011Surface.blockID, 2, 2);
		world.setBlock(x + 12, y + 22, z + 12, SpaceAgeCore.T0011Surface.blockID, 2, 2);
		world.setBlock(x + 12, y + 22, z + 13, SpaceAgeCore.T0011Surface.blockID, 2, 2);
		world.setBlock(x + 12, y + 22, z + 14, SpaceAgeCore.T0011Surface.blockID, 2, 2);
		world.setBlock(x + 12, y + 23, z + 12, SpaceAgeCore.T0011Surface.blockID, 2, 2);
		world.setBlock(x + 12, y + 23, z + 13, SpaceAgeCore.T0011Surface.blockID, 2, 2);
		world.setBlock(x + 12, y + 23, z + 14, SpaceAgeCore.T0011Surface.blockID, 2, 2);
		world.setBlock(x + 12, y + 24, z + 0, SpaceAgeCore.T0011Surface.blockID, 1, 2);
		world.setBlock(x + 12, y + 24, z + 1, SpaceAgeCore.T0011Surface.blockID, 1, 2);
		world.setBlock(x + 12, y + 24, z + 2, SpaceAgeCore.T0011Surface.blockID, 1, 2);
		world.setBlock(x + 12, y + 24, z + 3, SpaceAgeCore.T0011Surface.blockID, 1, 2);
		world.setBlock(x + 12, y + 24, z + 4, SpaceAgeCore.T0011Surface.blockID, 1, 2);
		world.setBlock(x + 12, y + 24, z + 5, SpaceAgeCore.T0011Surface.blockID, 1, 2);
		world.setBlock(x + 12, y + 24, z + 6, SpaceAgeCore.T0011Surface.blockID, 1, 2);
		world.setBlock(x + 12, y + 24, z + 7, SpaceAgeCore.T0011Surface.blockID, 1, 2);
		world.setBlock(x + 12, y + 24, z + 8, SpaceAgeCore.T0011Surface.blockID, 1, 2);
		world.setBlock(x + 12, y + 24, z + 9, SpaceAgeCore.T0011Surface.blockID, 1, 2);
		world.setBlock(x + 12, y + 24, z + 10, SpaceAgeCore.T0011Surface.blockID, 1, 2);
		world.setBlock(x + 12, y + 24, z + 11, SpaceAgeCore.T0011Surface.blockID, 1, 2);
		world.setBlock(x + 12, y + 24, z + 12, SpaceAgeCore.T0011Surface.blockID, 2, 2);
		world.setBlock(x + 12, y + 24, z + 13, SpaceAgeCore.T0011Surface.blockID, 2, 2);
		world.setBlock(x + 12, y + 24, z + 14, SpaceAgeCore.T0011Surface.blockID, 2, 2);
		world.setBlock(x + 12, y + 24, z + 15, SpaceAgeCore.T0011Surface.blockID, 1, 2);
		world.setBlock(x + 12, y + 24, z + 16, SpaceAgeCore.T0011Surface.blockID, 1, 2);
		world.setBlock(x + 12, y + 24, z + 17, SpaceAgeCore.T0011Surface.blockID, 1, 2);
		world.setBlock(x + 12, y + 24, z + 18, SpaceAgeCore.T0011Surface.blockID, 1, 2);
		world.setBlock(x + 12, y + 24, z + 19, SpaceAgeCore.T0011Surface.blockID, 1, 2);
		world.setBlock(x + 12, y + 24, z + 20, SpaceAgeCore.T0011Surface.blockID, 1, 2);
		world.setBlock(x + 12, y + 24, z + 21, SpaceAgeCore.T0011Surface.blockID, 1, 2);
		world.setBlock(x + 12, y + 24, z + 22, SpaceAgeCore.T0011Surface.blockID, 1, 2);
		world.setBlock(x + 12, y + 24, z + 23, SpaceAgeCore.T0011Surface.blockID, 1, 2);
		world.setBlock(x + 12, y + 24, z + 24, SpaceAgeCore.T0011Surface.blockID, 1, 2);
		world.setBlock(x + 12, y + 25, z + 1, SpaceAgeCore.T0011Surface.blockID, 1, 2);
		world.setBlock(x + 12, y + 25, z + 2, SpaceAgeCore.T0011Surface.blockID, 1, 2);
		world.setBlock(x + 12, y + 25, z + 3, SpaceAgeCore.T0011Surface.blockID, 1, 2);
		world.setBlock(x + 12, y + 25, z + 4, SpaceAgeCore.T0011Surface.blockID, 1, 2);
		world.setBlock(x + 12, y + 25, z + 5, SpaceAgeCore.T0011Surface.blockID, 1, 2);
		world.setBlock(x + 12, y + 25, z + 6, SpaceAgeCore.T0011Surface.blockID, 1, 2);
		world.setBlock(x + 12, y + 25, z + 7, SpaceAgeCore.T0011Surface.blockID, 1, 2);
		world.setBlock(x + 12, y + 25, z + 8, SpaceAgeCore.T0011Surface.blockID, 1, 2);
		world.setBlock(x + 12, y + 25, z + 9, SpaceAgeCore.T0011Surface.blockID, 1, 2);
		world.setBlock(x + 12, y + 25, z + 10, SpaceAgeCore.T0011Surface.blockID, 1, 2);
		world.setBlock(x + 12, y + 25, z + 11, SpaceAgeCore.T0011Surface.blockID, 1, 2);
		world.setBlock(x + 12, y + 25, z + 12, SpaceAgeCore.T0011Surface.blockID, 2, 2);
		world.setBlock(x + 12, y + 25, z + 13, SpaceAgeCore.T0011Surface.blockID, 2, 2);
		world.setBlock(x + 12, y + 25, z + 14, SpaceAgeCore.T0011Surface.blockID, 2, 2);
		world.setBlock(x + 12, y + 25, z + 15, SpaceAgeCore.T0011Surface.blockID, 1, 2);
		world.setBlock(x + 12, y + 25, z + 16, SpaceAgeCore.T0011Surface.blockID, 1, 2);
		world.setBlock(x + 12, y + 25, z + 17, SpaceAgeCore.T0011Surface.blockID, 1, 2);
		world.setBlock(x + 12, y + 25, z + 18, SpaceAgeCore.T0011Surface.blockID, 1, 2);
		world.setBlock(x + 12, y + 25, z + 19, SpaceAgeCore.T0011Surface.blockID, 1, 2);
		world.setBlock(x + 12, y + 25, z + 20, SpaceAgeCore.T0011Surface.blockID, 1, 2);
		world.setBlock(x + 12, y + 25, z + 21, SpaceAgeCore.T0011Surface.blockID, 1, 2);
		world.setBlock(x + 12, y + 25, z + 22, SpaceAgeCore.T0011Surface.blockID, 1, 2);
		world.setBlock(x + 12, y + 25, z + 23, SpaceAgeCore.T0011Surface.blockID, 1, 2);
		world.setBlock(x + 12, y + 25, z + 24, SpaceAgeCore.T0011Surface.blockID, 1, 2);
		world.setBlock(x + 12, y + 26, z + 2, SpaceAgeCore.T0011Surface.blockID, 1, 2);
		world.setBlock(x + 12, y + 26, z + 3, SpaceAgeCore.T0011Surface.blockID, 1, 2);
		world.setBlock(x + 12, y + 26, z + 4, SpaceAgeCore.T0011Surface.blockID, 1, 2);
		world.setBlock(x + 12, y + 26, z + 5, SpaceAgeCore.T0011Surface.blockID, 1, 2);
		world.setBlock(x + 12, y + 26, z + 6, SpaceAgeCore.T0011Surface.blockID, 1, 2);
		world.setBlock(x + 12, y + 26, z + 7, SpaceAgeCore.T0011Surface.blockID, 1, 2);
		world.setBlock(x + 12, y + 26, z + 8, SpaceAgeCore.T0011Surface.blockID, 1, 2);
		world.setBlock(x + 12, y + 26, z + 9, SpaceAgeCore.T0011Surface.blockID, 1, 2);
		world.setBlock(x + 12, y + 26, z + 10, SpaceAgeCore.T0011Surface.blockID, 1, 2);
		world.setBlock(x + 12, y + 26, z + 11, SpaceAgeCore.T0011Surface.blockID, 1, 2);
		world.setBlock(x + 12, y + 26, z + 12, SpaceAgeCore.T0011Surface.blockID, 2, 2);
		world.setBlock(x + 12, y + 26, z + 13, SpaceAgeCore.T0011Surface.blockID, 2, 2);
		world.setBlock(x + 12, y + 26, z + 14, SpaceAgeCore.T0011Surface.blockID, 2, 2);
		world.setBlock(x + 12, y + 26, z + 15, SpaceAgeCore.T0011Surface.blockID, 1, 2);
		world.setBlock(x + 12, y + 26, z + 16, SpaceAgeCore.T0011Surface.blockID, 1, 2);
		world.setBlock(x + 12, y + 26, z + 17, SpaceAgeCore.T0011Surface.blockID, 1, 2);
		world.setBlock(x + 12, y + 26, z + 18, SpaceAgeCore.T0011Surface.blockID, 1, 2);
		world.setBlock(x + 12, y + 26, z + 19, SpaceAgeCore.T0011Surface.blockID, 1, 2);
		world.setBlock(x + 12, y + 26, z + 20, SpaceAgeCore.T0011Surface.blockID, 1, 2);
		world.setBlock(x + 12, y + 26, z + 21, SpaceAgeCore.T0011Surface.blockID, 1, 2);
		world.setBlock(x + 12, y + 26, z + 22, SpaceAgeCore.T0011Surface.blockID, 1, 2);
		world.setBlock(x + 12, y + 26, z + 23, SpaceAgeCore.T0011Surface.blockID, 1, 2);
		world.setBlock(x + 12, y + 26, z + 24, SpaceAgeCore.T0011Surface.blockID, 1, 2);
		world.setBlock(x + 12, y + 27, z + 3, SpaceAgeCore.T0011Surface.blockID, 1, 2);
		world.setBlock(x + 12, y + 27, z + 4, SpaceAgeCore.T0011Surface.blockID, 1, 2);
		world.setBlock(x + 12, y + 27, z + 5, SpaceAgeCore.T0011Surface.blockID, 1, 2);
		world.setBlock(x + 12, y + 27, z + 6, SpaceAgeCore.T0011Surface.blockID, 1, 2);
		world.setBlock(x + 12, y + 27, z + 7, SpaceAgeCore.T0011Surface.blockID, 1, 2);
		world.setBlock(x + 12, y + 27, z + 8, SpaceAgeCore.T0011Surface.blockID, 1, 2);
		world.setBlock(x + 12, y + 27, z + 9, SpaceAgeCore.T0011Surface.blockID, 1, 2);
		world.setBlock(x + 12, y + 27, z + 10, SpaceAgeCore.T0011Surface.blockID, 1, 2);
		world.setBlock(x + 12, y + 27, z + 11, SpaceAgeCore.T0011Surface.blockID, 1, 2);
		world.setBlock(x + 12, y + 27, z + 12, SpaceAgeCore.T0011Surface.blockID, 2, 2);
		world.setBlock(x + 12, y + 27, z + 13, SpaceAgeCore.T0011Surface.blockID, 2, 2);
		world.setBlock(x + 12, y + 27, z + 14, SpaceAgeCore.T0011Surface.blockID, 2, 2);
		world.setBlock(x + 12, y + 27, z + 15, SpaceAgeCore.T0011Surface.blockID, 1, 2);
		world.setBlock(x + 12, y + 27, z + 16, SpaceAgeCore.T0011Surface.blockID, 1, 2);
		world.setBlock(x + 12, y + 27, z + 17, SpaceAgeCore.T0011Surface.blockID, 1, 2);
		world.setBlock(x + 12, y + 27, z + 18, SpaceAgeCore.T0011Surface.blockID, 1, 2);
		world.setBlock(x + 12, y + 27, z + 19, SpaceAgeCore.T0011Surface.blockID, 1, 2);
		world.setBlock(x + 12, y + 27, z + 20, SpaceAgeCore.T0011Surface.blockID, 1, 2);
		world.setBlock(x + 12, y + 27, z + 21, SpaceAgeCore.T0011Surface.blockID, 1, 2);
		world.setBlock(x + 12, y + 27, z + 22, SpaceAgeCore.T0011Surface.blockID, 1, 2);
		world.setBlock(x + 12, y + 27, z + 23, SpaceAgeCore.T0011Surface.blockID, 1, 2);
		world.setBlock(x + 12, y + 28, z + 4, SpaceAgeCore.T0011Surface.blockID, 3, 2);
		world.setBlock(x + 12, y + 28, z + 22, SpaceAgeCore.T0011Surface.blockID, 3, 2);
		world.setBlock(x + 12, y + 29, z + 4, SpaceAgeCore.T0011Surface.blockID, 3, 2);
		world.setBlock(x + 12, y + 29, z + 22, SpaceAgeCore.T0011Surface.blockID, 3, 2);
		world.setBlock(x + 12, y + 30, z + 4, SpaceAgeCore.T0011Surface.blockID, 3, 2);
		world.setBlock(x + 12, y + 30, z + 22, SpaceAgeCore.T0011Surface.blockID, 3, 2);
		world.setBlock(x + 12, y + 31, z + 5, SpaceAgeCore.T0011Surface.blockID, 3, 2);
		world.setBlock(x + 12, y + 31, z + 21, SpaceAgeCore.T0011Surface.blockID, 3, 2);
		world.setBlock(x + 12, y + 32, z + 5, SpaceAgeCore.T0011Surface.blockID, 3, 2);
		world.setBlock(x + 12, y + 32, z + 21, SpaceAgeCore.T0011Surface.blockID, 3, 2);
		world.setBlock(x + 12, y + 33, z + 5, SpaceAgeCore.T0011Surface.blockID, 3, 2);
		world.setBlock(x + 12, y + 33, z + 21, SpaceAgeCore.T0011Surface.blockID, 3, 2);
		world.setBlock(x + 12, y + 34, z + 6, SpaceAgeCore.T0011Surface.blockID, 3, 2);
		world.setBlock(x + 12, y + 34, z + 20, SpaceAgeCore.T0011Surface.blockID, 3, 2);
		world.setBlock(x + 12, y + 35, z + 7, SpaceAgeCore.T0011Surface.blockID, 3, 2);
		world.setBlock(x + 12, y + 35, z + 19, SpaceAgeCore.T0011Surface.blockID, 3, 2);
		world.setBlock(x + 12, y + 36, z + 8, SpaceAgeCore.T0011Surface.blockID, 3, 2);
		world.setBlock(x + 12, y + 36, z + 9, SpaceAgeCore.T0011Surface.blockID, 3, 2);
		world.setBlock(x + 12, y + 36, z + 10, SpaceAgeCore.T0011Surface.blockID, 3, 2);
		world.setBlock(x + 12, y + 36, z + 16, SpaceAgeCore.T0011Surface.blockID, 3, 2);
		world.setBlock(x + 12, y + 36, z + 17, SpaceAgeCore.T0011Surface.blockID, 3, 2);
		world.setBlock(x + 12, y + 36, z + 18, SpaceAgeCore.T0011Surface.blockID, 3, 2);
		world.setBlock(x + 12, y + 37, z + 11, SpaceAgeCore.T0011Surface.blockID, 3, 2);
		world.setBlock(x + 12, y + 37, z + 12, SpaceAgeCore.T0011Surface.blockID, 3, 2);
		world.setBlock(x + 12, y + 37, z + 13, SpaceAgeCore.T0011Surface.blockID, 3, 2);
		world.setBlock(x + 12, y + 37, z + 14, SpaceAgeCore.T0011Surface.blockID, 3, 2);
		world.setBlock(x + 12, y + 37, z + 15, SpaceAgeCore.T0011Surface.blockID, 3, 2);
		world.setBlock(x + 13, y + 0, z + 12, SpaceAgeCore.T0011Surface.blockID, 2, 2);
		world.setBlock(x + 13, y + 0, z + 14, SpaceAgeCore.T0011Surface.blockID, 2, 2);
		world.setBlock(x + 13, y + 1, z + 12, SpaceAgeCore.T0011Surface.blockID, 2, 2);
		world.setBlock(x + 13, y + 1, z + 14, SpaceAgeCore.T0011Surface.blockID, 2, 2);
		world.setBlock(x + 13, y + 2, z + 12, SpaceAgeCore.T0011Surface.blockID, 2, 2);
		world.setBlock(x + 13, y + 2, z + 14, SpaceAgeCore.T0011Surface.blockID, 2, 2);
		world.setBlock(x + 13, y + 3, z + 12, SpaceAgeCore.T0011Surface.blockID, 2, 2);
		world.setBlock(x + 13, y + 3, z + 14, SpaceAgeCore.T0011Surface.blockID, 2, 2);
		world.setBlock(x + 13, y + 4, z + 12, SpaceAgeCore.T0011Surface.blockID, 2, 2);
		world.setBlock(x + 13, y + 4, z + 14, SpaceAgeCore.T0011Surface.blockID, 2, 2);
		world.setBlock(x + 13, y + 5, z + 12, SpaceAgeCore.T0011Surface.blockID, 2, 2);
		world.setBlock(x + 13, y + 5, z + 14, SpaceAgeCore.T0011Surface.blockID, 2, 2);
		world.setBlock(x + 13, y + 6, z + 12, SpaceAgeCore.T0011Surface.blockID, 2, 2);
		world.setBlock(x + 13, y + 6, z + 14, SpaceAgeCore.T0011Surface.blockID, 2, 2);
		world.setBlock(x + 13, y + 7, z + 12, SpaceAgeCore.T0011Surface.blockID, 2, 2);
		world.setBlock(x + 13, y + 7, z + 14, SpaceAgeCore.T0011Surface.blockID, 2, 2);
		world.setBlock(x + 13, y + 8, z + 12, SpaceAgeCore.T0011Surface.blockID, 2, 2);
		world.setBlock(x + 13, y + 8, z + 14, SpaceAgeCore.T0011Surface.blockID, 2, 2);
		world.setBlock(x + 13, y + 9, z + 12, SpaceAgeCore.T0011Surface.blockID, 2, 2);
		world.setBlock(x + 13, y + 9, z + 14, SpaceAgeCore.T0011Surface.blockID, 2, 2);
		world.setBlock(x + 13, y + 10, z + 12, SpaceAgeCore.T0011Surface.blockID, 2, 2);
		world.setBlock(x + 13, y + 10, z + 14, SpaceAgeCore.T0011Surface.blockID, 2, 2);
		world.setBlock(x + 13, y + 11, z + 12, SpaceAgeCore.T0011Surface.blockID, 2, 2);
		world.setBlock(x + 13, y + 11, z + 14, SpaceAgeCore.T0011Surface.blockID, 2, 2);
		world.setBlock(x + 13, y + 12, z + 12, SpaceAgeCore.T0011Surface.blockID, 2, 2);
		world.setBlock(x + 13, y + 12, z + 14, SpaceAgeCore.T0011Surface.blockID, 2, 2);
		world.setBlock(x + 13, y + 12, z + 15, SpaceAgeCore.T0011Surface.blockID, 2, 2);
		world.setBlock(x + 13, y + 12, z + 16, SpaceAgeCore.T0011Surface.blockID, 2, 2);
		world.setBlock(x + 13, y + 12, z + 17, SpaceAgeCore.T0011Surface.blockID, 1, 2);
		world.setBlock(x + 13, y + 12, z + 18, SpaceAgeCore.T0011Surface.blockID, 1, 2);
		world.setBlock(x + 13, y + 12, z + 19, SpaceAgeCore.T0011Surface.blockID, 1, 2);
		world.setBlock(x + 13, y + 12, z + 20, SpaceAgeCore.T0011Surface.blockID, 1, 2);
		world.setBlock(x + 13, y + 12, z + 21, SpaceAgeCore.T0011Surface.blockID, 1, 2);
		world.setBlock(x + 13, y + 12, z + 22, SpaceAgeCore.T0011Surface.blockID, 1, 2);
		world.setBlock(x + 13, y + 12, z + 23, SpaceAgeCore.T0011Surface.blockID, 1, 2);
		world.setBlock(x + 13, y + 13, z + 12, SpaceAgeCore.T0011Surface.blockID, 2, 2);
		world.setBlock(x + 13, y + 13, z + 14, SpaceAgeCore.T0011Surface.blockID, 2, 2);
		world.setBlock(x + 13, y + 13, z + 18, SpaceAgeCore.T0011Surface.blockID, 1, 2);
		world.setBlock(x + 13, y + 13, z + 19, SpaceAgeCore.T0011Surface.blockID, 1, 2);
