package spaceage.planets.eden;

import java.util.Random;

import spaceage.common.SpaceAgeCore;

import net.minecraft.world.World;
import net.minecraft.world.gen.feature.WorldGenerator;

public class WorldGenEdenTrees extends WorldGenerator {

	public WorldGenEdenTrees(boolean par1) {
		super(par1);
	}
	
	@Override
	public boolean generate(World world, Random random, int x, int y, int z) {
		switch(random.nextInt(3)) {
			case 0:
				generateSmallTree(world, random, x, y, z);
			case 1:
				generateLargeTree(world, random, x, y, z);
			case 2:
				generateJuvenileTree(world, random, x, y, z);
		}
		return true;
	}

	public void generateJuvenileTree(World world, Random random, int x, int y, int z) { //TODO JUVENILE TREE CHECKPOINT
		if((world.getBlockId(x, y, z) == 0)) {
			generateJuvenileTree2(world, random, x, y, z);
			
		} else if((world.getBlockId(x, y, z) == SpaceAgeCore.metaSaplingID) && (world.getBlockMetadata(x, y, z) == 2)) {
			generateJuvenileTree2(world, random, x, y, z);
		}
	}

	public boolean generateJuvenileTree2(World world, Random rand, int i, int j, int k) {
		world.setBlock(i + 0, j + 18, k + 2, SpaceAgeCore.edenSurface.blockID, 0, 2);
		world.setBlock(i + 0, j + 18, k + 3, SpaceAgeCore.edenSurface.blockID, 0, 2);
		world.setBlock(i + 0, j + 18, k + 4, SpaceAgeCore.edenSurface.blockID, 0, 2);
		world.setBlock(i + 0, j + 18, k + 5, SpaceAgeCore.edenSurface.blockID, 0, 2);
		world.setBlock(i + 0, j + 18, k + 6, SpaceAgeCore.edenSurface.blockID, 0, 2);
		world.setBlock(i + 1, j + 18, k + 1, SpaceAgeCore.edenSurface.blockID, 0, 2);
		world.setBlock(i + 1, j + 18, k + 2, SpaceAgeCore.edenSurface.blockID, 0, 2);
		world.setBlock(i + 1, j + 18, k + 3, SpaceAgeCore.edenSurface.blockID, 0, 2);
		world.setBlock(i + 1, j + 18, k + 4, SpaceAgeCore.edenSurface.blockID, 0, 2);
		world.setBlock(i + 1, j + 18, k + 5, SpaceAgeCore.edenSurface.blockID, 0, 2);
		world.setBlock(i + 1, j + 18, k + 6, SpaceAgeCore.edenSurface.blockID, 0, 2);
		world.setBlock(i + 1, j + 18, k + 7, SpaceAgeCore.edenSurface.blockID, 0, 2);
		world.setBlock(i + 1, j + 19, k + 3, SpaceAgeCore.edenSurface.blockID, 0, 2);
		world.setBlock(i + 1, j + 19, k + 4, SpaceAgeCore.edenSurface.blockID, 0, 2);
		world.setBlock(i + 1, j + 19, k + 5, SpaceAgeCore.edenSurface.blockID, 0, 2);
		world.setBlock(i + 2, j + 18, k + 0, SpaceAgeCore.edenSurface.blockID, 0, 2);
		world.setBlock(i + 2, j + 18, k + 1, SpaceAgeCore.edenSurface.blockID, 0, 2);
		world.setBlock(i + 2, j + 18, k + 2, SpaceAgeCore.edenSurface.blockID, 0, 2);
		world.setBlock(i + 2, j + 18, k + 3, SpaceAgeCore.edenSurface.blockID, 0, 2);
		world.setBlock(i + 2, j + 18, k + 4, SpaceAgeCore.edenSurface.blockID, 0, 2);
		world.setBlock(i + 2, j + 18, k + 5, SpaceAgeCore.edenSurface.blockID, 0, 2);
		world.setBlock(i + 2, j + 18, k + 6, SpaceAgeCore.edenSurface.blockID, 0, 2);
		world.setBlock(i + 2, j + 18, k + 7, SpaceAgeCore.edenSurface.blockID, 0, 2);
		world.setBlock(i + 2, j + 18, k + 8, SpaceAgeCore.edenSurface.blockID, 0, 2);
		world.setBlock(i + 2, j + 19, k + 2, SpaceAgeCore.edenSurface.blockID, 0, 2);
		world.setBlock(i + 2, j + 19, k + 6, SpaceAgeCore.edenSurface.blockID, 0, 2);
		world.setBlock(i + 2, j + 20, k + 3, SpaceAgeCore.edenSurface.blockID, 0, 2);
		world.setBlock(i + 2, j + 20, k + 4, SpaceAgeCore.edenSurface.blockID, 0, 2);
		world.setBlock(i + 2, j + 20, k + 5, SpaceAgeCore.edenSurface.blockID, 0, 2);
		world.setBlock(i + 3, j + 18, k + 0, SpaceAgeCore.edenSurface.blockID, 0, 2);
		world.setBlock(i + 3, j + 18, k + 1, SpaceAgeCore.edenSurface.blockID, 0, 2);
		world.setBlock(i + 3, j + 18, k + 2, SpaceAgeCore.edenSurface.blockID, 0, 2);
		world.setBlock(i + 3, j + 18, k + 3, SpaceAgeCore.edenSurface.blockID, 0, 2);
		world.setBlock(i + 3, j + 18, k + 4, SpaceAgeCore.edenSurface.blockID, 0, 2);
		world.setBlock(i + 3, j + 18, k + 5, SpaceAgeCore.edenSurface.blockID, 0, 2);
		world.setBlock(i + 3, j + 18, k + 6, SpaceAgeCore.edenSurface.blockID, 0, 2);
		world.setBlock(i + 3, j + 18, k + 7, SpaceAgeCore.edenSurface.blockID, 0, 2);
		world.setBlock(i + 3, j + 18, k + 8, SpaceAgeCore.edenSurface.blockID, 0, 2);
		world.setBlock(i + 3, j + 19, k + 1, SpaceAgeCore.edenSurface.blockID, 0, 2);
		world.setBlock(i + 3, j + 19, k + 7, SpaceAgeCore.edenSurface.blockID, 0, 2);
		world.setBlock(i + 3, j + 20, k + 2, SpaceAgeCore.edenSurface.blockID, 0, 2);
		world.setBlock(i + 3, j + 20, k + 3, SpaceAgeCore.edenSurface.blockID, 0, 2);
		world.setBlock(i + 3, j + 20, k + 4, SpaceAgeCore.edenSurface.blockID, 0, 2);
		world.setBlock(i + 3, j + 20, k + 5, SpaceAgeCore.edenSurface.blockID, 0, 2);
		world.setBlock(i + 3, j + 20, k + 6, SpaceAgeCore.edenSurface.blockID, 0, 2);
		world.setBlock(i + 4, j + 0, k + 4, SpaceAgeCore.edenSurface.blockID, 1, 2);
		world.setBlock(i + 4, j + 1, k + 4, SpaceAgeCore.edenSurface.blockID, 1, 2);
		world.setBlock(i + 4, j + 2, k + 4, SpaceAgeCore.edenSurface.blockID, 1, 2);
		world.setBlock(i + 4, j + 3, k + 4, SpaceAgeCore.edenSurface.blockID, 1, 2);
		world.setBlock(i + 4, j + 4, k + 4, SpaceAgeCore.edenSurface.blockID, 1, 2);
		world.setBlock(i + 4, j + 5, k + 4, SpaceAgeCore.edenSurface.blockID, 1, 2);
		world.setBlock(i + 4, j + 6, k + 4, SpaceAgeCore.edenSurface.blockID, 1, 2);
		world.setBlock(i + 4, j + 7, k + 4, SpaceAgeCore.edenSurface.blockID, 1, 2);
		world.setBlock(i + 4, j + 8, k + 4, SpaceAgeCore.edenSurface.blockID, 1, 2);
		world.setBlock(i + 4, j + 9, k + 4, SpaceAgeCore.edenSurface.blockID, 1, 2);
		world.setBlock(i + 4, j + 10, k + 4, SpaceAgeCore.edenSurface.blockID, 1, 2);
		world.setBlock(i + 4, j + 11, k + 4, SpaceAgeCore.edenSurface.blockID, 1, 2);
		world.setBlock(i + 4, j + 12, k + 4, SpaceAgeCore.edenSurface.blockID, 1, 2);
		world.setBlock(i + 4, j + 13, k + 4, SpaceAgeCore.edenSurface.blockID, 1, 2);
		world.setBlock(i + 4, j + 14, k + 4, SpaceAgeCore.edenSurface.blockID, 1, 2);
		world.setBlock(i + 4, j + 15, k + 4, SpaceAgeCore.edenSurface.blockID, 1, 2);
		world.setBlock(i + 4, j + 16, k + 4, SpaceAgeCore.edenSurface.blockID, 1, 2);
		world.setBlock(i + 4, j + 17, k + 4, SpaceAgeCore.edenSurface.blockID, 1, 2);
		world.setBlock(i + 4, j + 18, k + 0, SpaceAgeCore.edenSurface.blockID, 0, 2);
		world.setBlock(i + 4, j + 18, k + 1, SpaceAgeCore.edenSurface.blockID, 0, 2);
		world.setBlock(i + 4, j + 18, k + 2, SpaceAgeCore.edenSurface.blockID, 0, 2);
		world.setBlock(i + 4, j + 18, k + 3, SpaceAgeCore.edenSurface.blockID, 0, 2);
		world.setBlock(i + 4, j + 18, k + 4, SpaceAgeCore.edenSurface.blockID, 1, 2);
		world.setBlock(i + 4, j + 18, k + 5, SpaceAgeCore.edenSurface.blockID, 0, 2);
		world.setBlock(i + 4, j + 18, k + 6, SpaceAgeCore.edenSurface.blockID, 0, 2);
		world.setBlock(i + 4, j + 18, k + 7, SpaceAgeCore.edenSurface.blockID, 0, 2);
		world.setBlock(i + 4, j + 18, k + 8, SpaceAgeCore.edenSurface.blockID, 0, 2);
		world.setBlock(i + 4, j + 19, k + 1, SpaceAgeCore.edenSurface.blockID, 0, 2);
		world.setBlock(i + 4, j + 19, k + 7, SpaceAgeCore.edenSurface.blockID, 0, 2);
		world.setBlock(i + 4, j + 20, k + 2, SpaceAgeCore.edenSurface.blockID, 0, 2);
		world.setBlock(i + 4, j + 20, k + 3, SpaceAgeCore.edenSurface.blockID, 0, 2);
		world.setBlock(i + 4, j + 20, k + 4, SpaceAgeCore.edenSurface.blockID, 0, 2);
		world.setBlock(i + 4, j + 20, k + 5, SpaceAgeCore.edenSurface.blockID, 0, 2);
		world.setBlock(i + 4, j + 20, k + 6, SpaceAgeCore.edenSurface.blockID, 0, 2);
		world.setBlock(i + 5, j + 18, k + 0, SpaceAgeCore.edenSurface.blockID, 0, 2);
		world.setBlock(i + 5, j + 18, k + 1, SpaceAgeCore.edenSurface.blockID, 0, 2);
		world.setBlock(i + 5, j + 18, k + 2, SpaceAgeCore.edenSurface.blockID, 0, 2);
		world.setBlock(i + 5, j + 18, k + 3, SpaceAgeCore.edenSurface.blockID, 0, 2);
		world.setBlock(i + 5, j + 18, k + 4, SpaceAgeCore.edenSurface.blockID, 0, 2);
		world.setBlock(i + 5, j + 18, k + 5, SpaceAgeCore.edenSurface.blockID, 0, 2);
		world.setBlock(i + 5, j + 18, k + 6, SpaceAgeCore.edenSurface.blockID, 0, 2);
		world.setBlock(i + 5, j + 18, k + 7, SpaceAgeCore.edenSurface.blockID, 0, 2);
		world.setBlock(i + 5, j + 18, k + 8, SpaceAgeCore.edenSurface.blockID, 0, 2);
		world.setBlock(i + 5, j + 19, k + 1, SpaceAgeCore.edenSurface.blockID, 0, 2);
		world.setBlock(i + 5, j + 19, k + 7, SpaceAgeCore.edenSurface.blockID, 0, 2);
		world.setBlock(i + 5, j + 20, k + 2, SpaceAgeCore.edenSurface.blockID, 0, 2);
		world.setBlock(i + 5, j + 20, k + 3, SpaceAgeCore.edenSurface.blockID, 0, 2);
		world.setBlock(i + 5, j + 20, k + 4, SpaceAgeCore.edenSurface.blockID, 0, 2);
		world.setBlock(i + 5, j + 20, k + 5, SpaceAgeCore.edenSurface.blockID, 0, 2);
		world.setBlock(i + 5, j + 20, k + 6, SpaceAgeCore.edenSurface.blockID, 0, 2);
		world.setBlock(i + 6, j + 18, k + 0, SpaceAgeCore.edenSurface.blockID, 0, 2);
		world.setBlock(i + 6, j + 18, k + 1, SpaceAgeCore.edenSurface.blockID, 0, 2);
		world.setBlock(i + 6, j + 18, k + 2, SpaceAgeCore.edenSurface.blockID, 0, 2);
		world.setBlock(i + 6, j + 18, k + 3, SpaceAgeCore.edenSurface.blockID, 0, 2);
		world.setBlock(i + 6, j + 18, k + 4, SpaceAgeCore.edenSurface.blockID, 0, 2);
		world.setBlock(i + 6, j + 18, k + 5, SpaceAgeCore.edenSurface.blockID, 0, 2);
		world.setBlock(i + 6, j + 18, k + 6, SpaceAgeCore.edenSurface.blockID, 0, 2);
		world.setBlock(i + 6, j + 18, k + 7, SpaceAgeCore.edenSurface.blockID, 0, 2);
		world.setBlock(i + 6, j + 18, k + 8, SpaceAgeCore.edenSurface.blockID, 0, 2);
		world.setBlock(i + 6, j + 19, k + 2, SpaceAgeCore.edenSurface.blockID, 0, 2);
		world.setBlock(i + 6, j + 19, k + 6, SpaceAgeCore.edenSurface.blockID, 0, 2);
		world.setBlock(i + 6, j + 20, k + 3, SpaceAgeCore.edenSurface.blockID, 0, 2);
		world.setBlock(i + 6, j + 20, k + 4, SpaceAgeCore.edenSurface.blockID, 0, 2);
		world.setBlock(i + 6, j + 20, k + 5, SpaceAgeCore.edenSurface.blockID, 0, 2);
		world.setBlock(i + 7, j + 18, k + 1, SpaceAgeCore.edenSurface.blockID, 0, 2);
		world.setBlock(i + 7, j + 18, k + 2, SpaceAgeCore.edenSurface.blockID, 0, 2);
		world.setBlock(i + 7, j + 18, k + 3, SpaceAgeCore.edenSurface.blockID, 0, 2);
		world.setBlock(i + 7, j + 18, k + 4, SpaceAgeCore.edenSurface.blockID, 0, 2);
		world.setBlock(i + 7, j + 18, k + 5, SpaceAgeCore.edenSurface.blockID, 0, 2);
		world.setBlock(i + 7, j + 18, k + 6, SpaceAgeCore.edenSurface.blockID, 0, 2);
		world.setBlock(i + 7, j + 18, k + 7, SpaceAgeCore.edenSurface.blockID, 0, 2);
		world.setBlock(i + 7, j + 19, k + 3, SpaceAgeCore.edenSurface.blockID, 0, 2);
		world.setBlock(i + 7, j + 19, k + 4, SpaceAgeCore.edenSurface.blockID, 0, 2);
		world.setBlock(i + 7, j + 19, k + 5, SpaceAgeCore.edenSurface.blockID, 0, 2);
		world.setBlock(i + 8, j + 18, k + 2, SpaceAgeCore.edenSurface.blockID, 0, 2);
		world.setBlock(i + 8, j + 18, k + 3, SpaceAgeCore.edenSurface.blockID, 0, 2);
		world.setBlock(i + 8, j + 18, k + 4, SpaceAgeCore.edenSurface.blockID, 0, 2);
		world.setBlock(i + 8, j + 18, k + 5, SpaceAgeCore.edenSurface.blockID, 0, 2);
		world.setBlock(i + 8, j + 18, k + 6, SpaceAgeCore.edenSurface.blockID, 0, 2);

		return true;
	}

	public void generateLargeTree(World world, Random random, int x, int y, int z) { //TODO LARGE TREE CHECKPOINT
		//CHECK IF VALID POSITION
		if((world.getBlockId(x, y, z) == 0) && (world.getBlockId(x + 1, y, z) == 0) && (world.getBlockId(x, y, z + 1) == 0) && (world.getBlockId(x + 1, y, z + 1) == 0) && (world.getBlockId(x - 1, y, z) == 0) && (world.getBlockId(x - 1, y, z - 1) == 0) && (world.getBlockId(x, y, z - 1) == 0) && (world.getBlockId(x + 1, y, z - 1) == 0) && (world.getBlockId(x - 1, y, z + 1) == 0)) {
			generateLargeTree2(world, random, x, y, z);

		} else if((world.getBlockId(x, y, z) == SpaceAgeCore.metaSaplingID) && (world.getBlockMetadata(x, y, z) == 2)) {
			if((world.getBlockId(x + 1, y, z) == SpaceAgeCore.metaSaplingID) && (world.getBlockMetadata(x + 1, y, z) == 2) && (world.getBlockId(x, y, z + 1) == SpaceAgeCore.metaSaplingID) && (world.getBlockMetadata(x, y, z + 1) == 2) && (world.getBlockId(x + 1, y, z + 1) == SpaceAgeCore.metaSaplingID) && (world.getBlockMetadata(x + 1, y, z + 1) == 2) && (world.getBlockId(x - 1, y, z) == SpaceAgeCore.metaSaplingID) && (world.getBlockMetadata(x - 1, y, z) == 2) && (world.getBlockId(x - 1, y, z - 1) == SpaceAgeCore.metaSaplingID) && (world.getBlockMetadata(x - 1, y, z - 1) == 2) && (world.getBlockId(x, y, z - 1) == SpaceAgeCore.metaSaplingID) && (world.getBlockMetadata(x, y, z - 1) == 2) && (world.getBlockId(x + 1, y, z - 1) == SpaceAgeCore.metaSaplingID) && (world.getBlockMetadata(x + 1, y, z - 1) == 2) && (world.getBlockId(x - 1, y, z + 1) == SpaceAgeCore.metaSaplingID) && (world.getBlockMetadata(x - 1, y, z + 1) == 2)) {
				generateLargeTree2(world, random, x, y, z);
			} 
		} else {
			generateSmallTree(world, random, x, y, z);
		}
	}

	public boolean generateLargeTree2(World world, Random rand, int i, int j, int k) {
		world.setBlock(i + 0, j + 71, k + 14, SpaceAgeCore.edenSurface.blockID, 0, 2);
		world.setBlock(i + 0, j + 71, k + 15, SpaceAgeCore.edenSurface.blockID, 0, 2);
		world.setBlock(i + 0, j + 71, k + 16, SpaceAgeCore.edenSurface.blockID, 0, 2);
		world.setBlock(i + 0, j + 71, k + 17, SpaceAgeCore.edenSurface.blockID, 0, 2);
		world.setBlock(i + 0, j + 71, k + 18, SpaceAgeCore.edenSurface.blockID, 0, 2);
		world.setBlock(i + 0, j + 71, k + 19, SpaceAgeCore.edenSurface.blockID, 0, 2);
		world.setBlock(i + 0, j + 71, k + 20, SpaceAgeCore.edenSurface.blockID, 0, 2);
		world.setBlock(i + 0, j + 71, k + 21, SpaceAgeCore.edenSurface.blockID, 0, 2);
		world.setBlock(i + 0, j + 71, k + 22, SpaceAgeCore.edenSurface.blockID, 0, 2);
		world.setBlock(i + 1, j + 71, k + 11, SpaceAgeCore.edenSurface.blockID, 0, 2);
		world.setBlock(i + 1, j + 71, k + 12, SpaceAgeCore.edenSurface.blockID, 0, 2);
		world.setBlock(i + 1, j + 71, k + 13, SpaceAgeCore.edenSurface.blockID, 0, 2);
		world.setBlock(i + 1, j + 71, k + 14, SpaceAgeCore.edenSurface.blockID, 0, 2);
		world.setBlock(i + 1, j + 71, k + 15, SpaceAgeCore.edenSurface.blockID, 0, 2);
		world.setBlock(i + 1, j + 71, k + 16, SpaceAgeCore.edenSurface.blockID, 0, 2);
		world.setBlock(i + 1, j + 71, k + 17, SpaceAgeCore.edenSurface.blockID, 0, 2);
		world.setBlock(i + 1, j + 71, k + 18, SpaceAgeCore.edenSurface.blockID, 0, 2);
		world.setBlock(i + 1, j + 71, k + 19, SpaceAgeCore.edenSurface.blockID, 0, 2);
		world.setBlock(i + 1, j + 71, k + 20, SpaceAgeCore.edenSurface.blockID, 0, 2);
		world.setBlock(i + 1, j + 71, k + 21, SpaceAgeCore.edenSurface.blockID, 0, 2);
		world.setBlock(i + 1, j + 71, k + 22, SpaceAgeCore.edenSurface.blockID, 0, 2);
		world.setBlock(i + 1, j + 71, k + 23, SpaceAgeCore.edenSurface.blockID, 0, 2);
		world.setBlock(i + 1, j + 71, k + 24, SpaceAgeCore.edenSurface.blockID, 0, 2);
		world.setBlock(i + 1, j + 71, k + 25, SpaceAgeCore.edenSurface.blockID, 0, 2);
		world.setBlock(i + 1, j + 72, k + 14, SpaceAgeCore.edenSurface.blockID, 0, 2);
		world.setBlock(i + 1, j + 72, k + 15, SpaceAgeCore.edenSurface.blockID, 0, 2);
		world.setBlock(i + 1, j + 72, k + 16, SpaceAgeCore.edenSurface.blockID, 0, 2);
		world.setBlock(i + 1, j + 72, k + 17, SpaceAgeCore.edenSurface.blockID, 0, 2);
		world.setBlock(i + 1, j + 72, k + 18, SpaceAgeCore.edenSurface.blockID, 0, 2);
		world.setBlock(i + 1, j + 72, k + 19, SpaceAgeCore.edenSurface.blockID, 0, 2);
		world.setBlock(i + 1, j + 72, k + 20, SpaceAgeCore.edenSurface.blockID, 0, 2);
		world.setBlock(i + 1, j + 72, k + 21, SpaceAgeCore.edenSurface.blockID, 0, 2);
		world.setBlock(i + 1, j + 72, k + 22, SpaceAgeCore.edenSurface.blockID, 0, 2);
		world.setBlock(i + 2, j + 71, k + 9, SpaceAgeCore.edenSurface.blockID, 0, 2);
		world.setBlock(i + 2, j + 71, k + 10, SpaceAgeCore.edenSurface.blockID, 0, 2);
		world.setBlock(i + 2, j + 71, k + 11, SpaceAgeCore.edenSurface.blockID, 0, 2);
		world.setBlock(i + 2, j + 71, k + 12, SpaceAgeCore.edenSurface.blockID, 0, 2);
		world.setBlock(i + 2, j + 71, k + 13, SpaceAgeCore.edenSurface.blockID, 0, 2);
		world.setBlock(i + 2, j + 71, k + 14, SpaceAgeCore.edenSurface.blockID, 0, 2);
		world.setBlock(i + 2, j + 71, k + 15, SpaceAgeCore.edenSurface.blockID, 0, 2);
		world.setBlock(i + 2, j + 71, k + 16, SpaceAgeCore.edenSurface.blockID, 0, 2);
		world.setBlock(i + 2, j + 71, k + 17, SpaceAgeCore.edenSurface.blockID, 0, 2);
		world.setBlock(i + 2, j + 71, k + 18, SpaceAgeCore.edenSurface.blockID, 0, 2);
		world.setBlock(i + 2, j + 71, k + 19, SpaceAgeCore.edenSurface.blockID, 0, 2);
		world.setBlock(i + 2, j + 71, k + 20, SpaceAgeCore.edenSurface.blockID, 0, 2);
		world.setBlock(i + 2, j + 71, k + 21, SpaceAgeCore.edenSurface.blockID, 0, 2);
		world.setBlock(i + 2, j + 71, k + 22, SpaceAgeCore.edenSurface.blockID, 0, 2);
		world.setBlock(i + 2, j + 71, k + 23, SpaceAgeCore.edenSurface.blockID, 0, 2);
		world.setBlock(i + 2, j + 71, k + 24, SpaceAgeCore.edenSurface.blockID, 0, 2);
		world.setBlock(i + 2, j + 71, k + 25, SpaceAgeCore.edenSurface.blockID, 0, 2);
		world.setBlock(i + 2, j + 71, k + 26, SpaceAgeCore.edenSurface.blockID, 0, 2);
		world.setBlock(i + 2, j + 71, k + 27, SpaceAgeCore.edenSurface.blockID, 0, 2);
		world.setBlock(i + 2, j + 72, k + 11, SpaceAgeCore.edenSurface.blockID, 0, 2);
		world.setBlock(i + 2, j + 72, k + 12, SpaceAgeCore.edenSurface.blockID, 0, 2);
		world.setBlock(i + 2, j + 72, k + 13, SpaceAgeCore.edenSurface.blockID, 0, 2);
		world.setBlock(i + 2, j + 72, k + 23, SpaceAgeCore.edenSurface.blockID, 0, 2);
		world.setBlock(i + 2, j + 72, k + 24, SpaceAgeCore.edenSurface.blockID, 0, 2);
		world.setBlock(i + 2, j + 72, k + 25, SpaceAgeCore.edenSurface.blockID, 0, 2);
		world.setBlock(i + 2, j + 73, k + 14, SpaceAgeCore.edenSurface.blockID, 0, 2);
		world.setBlock(i + 2, j + 73, k + 15, SpaceAgeCore.edenSurface.blockID, 0, 2);
		world.setBlock(i + 2, j + 73, k + 16, SpaceAgeCore.edenSurface.blockID, 0, 2);
		world.setBlock(i + 2, j + 73, k + 17, SpaceAgeCore.edenSurface.blockID, 0, 2);
		world.setBlock(i + 2, j + 73, k + 18, SpaceAgeCore.edenSurface.blockID, 0, 2);
		world.setBlock(i + 2, j + 73, k + 19, SpaceAgeCore.edenSurface.blockID, 0, 2);
		world.setBlock(i + 2, j + 73, k + 20, SpaceAgeCore.edenSurface.blockID, 0, 2);
		world.setBlock(i + 2, j + 73, k + 21, SpaceAgeCore.edenSurface.blockID, 0, 2);
		world.setBlock(i + 2, j + 73, k + 22, SpaceAgeCore.edenSurface.blockID, 0, 2);
		world.setBlock(i + 3, j + 71, k + 8, SpaceAgeCore.edenSurface.blockID, 0, 2);
		world.setBlock(i + 3, j + 71, k + 9, SpaceAgeCore.edenSurface.blockID, 0, 2);
		world.setBlock(i + 3, j + 71, k + 10, SpaceAgeCore.edenSurface.blockID, 0, 2);
		world.setBlock(i + 3, j + 71, k + 11, SpaceAgeCore.edenSurface.blockID, 0, 2);
		world.setBlock(i + 3, j + 71, k + 12, SpaceAgeCore.edenSurface.blockID, 0, 2);
		world.setBlock(i + 3, j + 71, k + 13, SpaceAgeCore.edenSurface.blockID, 0, 2);
		world.setBlock(i + 3, j + 71, k + 14, SpaceAgeCore.edenSurface.blockID, 0, 2);
		world.setBlock(i + 3, j + 71, k + 15, SpaceAgeCore.edenSurface.blockID, 0, 2);
		world.setBlock(i + 3, j + 71, k + 16, SpaceAgeCore.edenSurface.blockID, 0, 2);
		world.setBlock(i + 3, j + 71, k + 17, SpaceAgeCore.edenSurface.blockID, 0, 2);
		world.setBlock(i + 3, j + 71, k + 18, SpaceAgeCore.edenSurface.blockID, 0, 2);
		world.setBlock(i + 3, j + 71, k + 19, SpaceAgeCore.edenSurface.blockID, 0, 2);
		world.setBlock(i + 3, j + 71, k + 20, SpaceAgeCore.edenSurface.blockID, 0, 2);
		world.setBlock(i + 3, j + 71, k + 21, SpaceAgeCore.edenSurface.blockID, 0, 2);
		world.setBlock(i + 3, j + 71, k + 22, SpaceAgeCore.edenSurface.blockID, 0, 2);
		world.setBlock(i + 3, j + 71, k + 23, SpaceAgeCore.edenSurface.blockID, 0, 2);
		world.setBlock(i + 3, j + 71, k + 24, SpaceAgeCore.edenSurface.blockID, 0, 2);
		world.setBlock(i + 3, j + 71, k + 25, SpaceAgeCore.edenSurface.blockID, 0, 2);
		world.setBlock(i + 3, j + 71, k + 26, SpaceAgeCore.edenSurface.blockID, 0, 2);
		world.setBlock(i + 3, j + 71, k + 27, SpaceAgeCore.edenSurface.blockID, 0, 2);
		world.setBlock(i + 3, j + 71, k + 28, SpaceAgeCore.edenSurface.blockID, 0, 2);
		world.setBlock(i + 3, j + 72, k + 9, SpaceAgeCore.edenSurface.blockID, 0, 2);
		world.setBlock(i + 3, j + 72, k + 10, SpaceAgeCore.edenSurface.blockID, 0, 2);
		world.setBlock(i + 3, j + 72, k + 11, SpaceAgeCore.edenSurface.blockID, 0, 2);
		world.setBlock(i + 3, j + 72, k + 25, SpaceAgeCore.edenSurface.blockID, 0, 2);
		world.setBlock(i + 3, j + 72, k + 26, SpaceAgeCore.edenSurface.blockID, 0, 2);
		world.setBlock(i + 3, j + 72, k + 27, SpaceAgeCore.edenSurface.blockID, 0, 2);
		world.setBlock(i + 3, j + 73, k + 12, SpaceAgeCore.edenSurface.blockID, 0, 2);
		world.setBlock(i + 3, j + 73, k + 13, SpaceAgeCore.edenSurface.blockID, 0, 2);
		world.setBlock(i + 3, j + 73, k + 14, SpaceAgeCore.edenSurface.blockID, 0, 2);
		world.setBlock(i + 3, j + 73, k + 22, SpaceAgeCore.edenSurface.blockID, 0, 2);
		world.setBlock(i + 3, j + 73, k + 23, SpaceAgeCore.edenSurface.blockID, 0, 2);
		world.setBlock(i + 3, j + 73, k + 24, SpaceAgeCore.edenSurface.blockID, 0, 2);
		world.setBlock(i + 3, j + 74, k + 15, SpaceAgeCore.edenSurface.blockID, 0, 2);
		world.setBlock(i + 3, j + 74, k + 16, SpaceAgeCore.edenSurface.blockID, 0, 2);
		world.setBlock(i + 3, j + 74, k + 17, SpaceAgeCore.edenSurface.blockID, 0, 2);
		world.setBlock(i + 3, j + 74, k + 18, SpaceAgeCore.edenSurface.blockID, 0, 2);
		world.setBlock(i + 3, j + 74, k + 19, SpaceAgeCore.edenSurface.blockID, 0, 2);
		world.setBlock(i + 3, j + 74, k + 20, SpaceAgeCore.edenSurface.blockID, 0, 2);
		world.setBlock(i + 3, j + 74, k + 21, SpaceAgeCore.edenSurface.blockID, 0, 2);
		world.setBlock(i + 4, j + 71, k + 6, SpaceAgeCore.edenSurface.blockID, 0, 2);
		world.setBlock(i + 4, j + 71, k + 7, SpaceAgeCore.edenSurface.blockID, 0, 2);
		world.setBlock(i + 4, j + 71, k + 8, SpaceAgeCore.edenSurface.blockID, 0, 2);
		world.setBlock(i + 4, j + 71, k + 9, SpaceAgeCore.edenSurface.blockID, 0, 2);
		world.setBlock(i + 4, j + 71, k + 10, SpaceAgeCore.edenSurface.blockID, 0, 2);
		world.setBlock(i + 4, j + 71, k + 11, SpaceAgeCore.edenSurface.blockID, 0, 2);
		world.setBlock(i + 4, j + 71, k + 12, SpaceAgeCore.edenSurface.blockID, 0, 2);
		world.setBlock(i + 4, j + 71, k + 13, SpaceAgeCore.edenSurface.blockID, 0, 2);
		world.setBlock(i + 4, j + 71, k + 14, SpaceAgeCore.edenSurface.blockID, 0, 2);
		world.setBlock(i + 4, j + 71, k + 15, SpaceAgeCore.edenSurface.blockID, 0, 2);
		world.setBlock(i + 4, j + 71, k + 16, SpaceAgeCore.edenSurface.blockID, 0, 2);
		world.setBlock(i + 4, j + 71, k + 17, SpaceAgeCore.edenSurface.blockID, 0, 2);
		world.setBlock(i + 4, j + 71, k + 18, SpaceAgeCore.edenSurface.blockID, 0, 2);
		world.setBlock(i + 4, j + 71, k + 19, SpaceAgeCore.edenSurface.blockID, 0, 2);
		world.setBlock(i + 4, j + 71, k + 20, SpaceAgeCore.edenSurface.blockID, 0, 2);
		world.setBlock(i + 4, j + 71, k + 21, SpaceAgeCore.edenSurface.blockID, 0, 2);
		world.setBlock(i + 4, j + 71, k + 22, SpaceAgeCore.edenSurface.blockID, 0, 2);
		world.setBlock(i + 4, j + 71, k + 23, SpaceAgeCore.edenSurface.blockID, 0, 2);
		world.setBlock(i + 4, j + 71, k + 24, SpaceAgeCore.edenSurface.blockID, 0, 2);
		world.setBlock(i + 4, j + 71, k + 25, SpaceAgeCore.edenSurface.blockID, 0, 2);
		world.setBlock(i + 4, j + 71, k + 26, SpaceAgeCore.edenSurface.blockID, 0, 2);
		world.setBlock(i + 4, j + 71, k + 27, SpaceAgeCore.edenSurface.blockID, 0, 2);
		world.setBlock(i + 4, j + 71, k + 28, SpaceAgeCore.edenSurface.blockID, 0, 2);
		world.setBlock(i + 4, j + 71, k + 29, SpaceAgeCore.edenSurface.blockID, 0, 2);
		world.setBlock(i + 4, j + 71, k + 30, SpaceAgeCore.edenSurface.blockID, 0, 2);
		world.setBlock(i + 4, j + 72, k + 8, SpaceAgeCore.edenSurface.blockID, 0, 2);
		world.setBlock(i + 4, j + 72, k + 9, SpaceAgeCore.edenSurface.blockID, 0, 2);
		world.setBlock(i + 4, j + 72, k + 27, SpaceAgeCore.edenSurface.blockID, 0, 2);
		world.setBlock(i + 4, j + 72, k + 28, SpaceAgeCore.edenSurface.blockID, 0, 2);
		world.setBlock(i + 4, j + 73, k + 10, SpaceAgeCore.edenSurface.blockID, 0, 2);
		world.setBlock(i + 4, j + 73, k + 11, SpaceAgeCore.edenSurface.blockID, 0, 2);
		world.setBlock(i + 4, j + 73, k + 25, SpaceAgeCore.edenSurface.blockID, 0, 2);
		world.setBlock(i + 4, j + 73, k + 26, SpaceAgeCore.edenSurface.blockID, 0, 2);
		world.setBlock(i + 4, j + 74, k + 12, SpaceAgeCore.edenSurface.blockID, 0, 2);
		world.setBlock(i + 4, j + 74, k + 13, SpaceAgeCore.edenSurface.blockID, 0, 2);
		world.setBlock(i + 4, j + 74, k + 14, SpaceAgeCore.edenSurface.blockID, 0, 2);
		world.setBlock(i + 4, j + 74, k + 22, SpaceAgeCore.edenSurface.blockID, 0, 2);
		world.setBlock(i + 4, j + 74, k + 23, SpaceAgeCore.edenSurface.blockID, 0, 2);
		world.setBlock(i + 4, j + 74, k + 24, SpaceAgeCore.edenSurface.blockID, 0, 2);
		world.setBlock(i + 4, j + 75, k + 15, SpaceAgeCore.edenSurface.blockID, 0, 2);
		world.setBlock(i + 4, j + 75, k + 16, SpaceAgeCore.edenSurface.blockID, 0, 2);
		world.setBlock(i + 4, j + 75, k + 17, SpaceAgeCore.edenSurface.blockID, 0, 2);
		world.setBlock(i + 4, j + 75, k + 18, SpaceAgeCore.edenSurface.blockID, 0, 2);
		world.setBlock(i + 4, j + 75, k + 19, SpaceAgeCore.edenSurface.blockID, 0, 2);
		world.setBlock(i + 4, j + 75, k + 20, SpaceAgeCore.edenSurface.blockID, 0, 2);
		world.setBlock(i + 4, j + 75, k + 21, SpaceAgeCore.edenSurface.blockID, 0, 2);
		world.setBlock(i + 5, j + 71, k + 5, SpaceAgeCore.edenSurface.blockID, 0, 2);
		world.setBlock(i + 5, j + 71, k + 6, SpaceAgeCore.edenSurface.blockID, 0, 2);
		world.setBlock(i + 5, j + 71, k + 7, SpaceAgeCore.edenSurface.blockID, 0, 2);
		world.setBlock(i + 5, j + 71, k + 8, SpaceAgeCore.edenSurface.blockID, 0, 2);
		world.setBlock(i + 5, j + 71, k + 9, SpaceAgeCore.edenSurface.blockID, 0, 2);
		world.setBlock(i + 5, j + 71, k + 10, SpaceAgeCore.edenSurface.blockID, 0, 2);
		world.setBlock(i + 5, j + 71, k + 11, SpaceAgeCore.edenSurface.blockID, 0, 2);
		world.setBlock(i + 5, j + 71, k + 12, SpaceAgeCore.edenSurface.blockID, 0, 2);
		world.setBlock(i + 5, j + 71, k + 13, SpaceAgeCore.edenSurface.blockID, 0, 2);
		world.setBlock(i + 5, j + 71, k + 14, SpaceAgeCore.edenSurface.blockID, 0, 2);
		world.setBlock(i + 5, j + 71, k + 15, SpaceAgeCore.edenSurface.blockID, 0, 2);
		world.setBlock(i + 5, j + 71, k + 16, SpaceAgeCore.edenSurface.blockID, 0, 2);
		world.setBlock(i + 5, j + 71, k + 17, SpaceAgeCore.edenSurface.blockID, 0, 2);
		world.setBlock(i + 5, j + 71, k + 18, SpaceAgeCore.edenSurface.blockID, 0, 2);
		world.setBlock(i + 5, j + 71, k + 19, SpaceAgeCore.edenSurface.blockID, 0, 2);
		world.setBlock(i + 5, j + 71, k + 20, SpaceAgeCore.edenSurface.blockID, 0, 2);
		world.setBlock(i + 5, j + 71, k + 21, SpaceAgeCore.edenSurface.blockID, 0, 2);
		world.setBlock(i + 5, j + 71, k + 22, SpaceAgeCore.edenSurface.blockID, 0, 2);
		world.setBlock(i + 5, j + 71, k + 23, SpaceAgeCore.edenSurface.blockID, 0, 2);
		world.setBlock(i + 5, j + 71, k + 24, SpaceAgeCore.edenSurface.blockID, 0, 2);
		world.setBlock(i + 5, j + 71, k + 25, SpaceAgeCore.edenSurface.blockID, 0, 2);
		world.setBlock(i + 5, j + 71, k + 26, SpaceAgeCore.edenSurface.blockID, 0, 2);
		world.setBlock(i + 5, j + 71, k + 27, SpaceAgeCore.edenSurface.blockID, 0, 2);
		world.setBlock(i + 5, j + 71, k + 28, SpaceAgeCore.edenSurface.blockID, 0, 2);
		world.setBlock(i + 5, j + 71, k + 29, SpaceAgeCore.edenSurface.blockID, 0, 2);
		world.setBlock(i + 5, j + 71, k + 30, SpaceAgeCore.edenSurface.blockID, 0, 2);
		world.setBlock(i + 5, j + 71, k + 31, SpaceAgeCore.edenSurface.blockID, 0, 2);
		world.setBlock(i + 5, j + 72, k + 7, SpaceAgeCore.edenSurface.blockID, 0, 2);
		world.setBlock(i + 5, j + 72, k + 29, SpaceAgeCore.edenSurface.blockID, 0, 2);
		world.setBlock(i + 5, j + 73, k + 8, SpaceAgeCore.edenSurface.blockID, 0, 2);
		world.setBlock(i + 5, j + 73, k + 9, SpaceAgeCore.edenSurface.blockID, 0, 2);
		world.setBlock(i + 5, j + 73, k + 27, SpaceAgeCore.edenSurface.blockID, 0, 2);
		world.setBlock(i + 5, j + 73, k + 28, SpaceAgeCore.edenSurface.blockID, 0, 2);
		world.setBlock(i + 5, j + 74, k + 10, SpaceAgeCore.edenSurface.blockID, 0, 2);
		world.setBlock(i + 5, j + 74, k + 11, SpaceAgeCore.edenSurface.blockID, 0, 2);
		world.setBlock(i + 5, j + 74, k + 25, SpaceAgeCore.edenSurface.blockID, 0, 2);
		world.setBlock(i + 5, j + 74, k + 26, SpaceAgeCore.edenSurface.blockID, 0, 2);
		world.setBlock(i + 5, j + 75, k + 12, SpaceAgeCore.edenSurface.blockID, 0, 2);
		world.setBlock(i + 5, j + 75, k + 13, SpaceAgeCore.edenSurface.blockID, 0, 2);
		world.setBlock(i + 5, j + 75, k + 14, SpaceAgeCore.edenSurface.blockID, 0, 2);
		world.setBlock(i + 5, j + 75, k + 22, SpaceAgeCore.edenSurface.blockID, 0, 2);
		world.setBlock(i + 5, j + 75, k + 23, SpaceAgeCore.edenSurface.blockID, 0, 2);
		world.setBlock(i + 5, j + 75, k + 24, SpaceAgeCore.edenSurface.blockID, 0, 2);
		world.setBlock(i + 5, j + 76, k + 15, SpaceAgeCore.edenSurface.blockID, 0, 2);
		world.setBlock(i + 5, j + 76, k + 16, SpaceAgeCore.edenSurface.blockID, 0, 2);
		world.setBlock(i + 5, j + 76, k + 17, SpaceAgeCore.edenSurface.blockID, 0, 2);
		world.setBlock(i + 5, j + 76, k + 18, SpaceAgeCore.edenSurface.blockID, 0, 2);
		world.setBlock(i + 5, j + 76, k + 19, SpaceAgeCore.edenSurface.blockID, 0, 2);
		world.setBlock(i + 5, j + 76, k + 20, SpaceAgeCore.edenSurface.blockID, 0, 2);
		world.setBlock(i + 5, j + 76, k + 21, SpaceAgeCore.edenSurface.blockID, 0, 2);
		world.setBlock(i + 6, j + 71, k + 4, SpaceAgeCore.edenSurface.blockID, 0, 2);
		world.setBlock(i + 6, j + 71, k + 5, SpaceAgeCore.edenSurface.blockID, 0, 2);
		world.setBlock(i + 6, j + 71, k + 6, SpaceAgeCore.edenSurface.blockID, 0, 2);
		world.setBlock(i + 6, j + 71, k + 7, SpaceAgeCore.edenSurface.blockID, 0, 2);
		world.setBlock(i + 6, j + 71, k + 8, SpaceAgeCore.edenSurface.blockID, 0, 2);
		world.setBlock(i + 6, j + 71, k + 9, SpaceAgeCore.edenSurface.blockID, 0, 2);
		world.setBlock(i + 6, j + 71, k + 10, SpaceAgeCore.edenSurface.blockID, 0, 2);
		world.setBlock(i + 6, j + 71, k + 11, SpaceAgeCore.edenSurface.blockID, 0, 2);
		world.setBlock(i + 6, j + 71, k + 12, SpaceAgeCore.edenSurface.blockID, 0, 2);
		world.setBlock(i + 6, j + 71, k + 13, SpaceAgeCore.edenSurface.blockID, 0, 2);
		world.setBlock(i + 6, j + 71, k + 14, SpaceAgeCore.edenSurface.blockID, 0, 2);
		world.setBlock(i + 6, j + 71, k + 15, SpaceAgeCore.edenSurface.blockID, 0, 2);
		world.setBlock(i + 6, j + 71, k + 16, SpaceAgeCore.edenSurface.blockID, 0, 2);
		world.setBlock(i + 6, j + 71, k + 17, SpaceAgeCore.edenSurface.blockID, 0, 2);
		world.setBlock(i + 6, j + 71, k + 18, SpaceAgeCore.edenSurface.blockID, 0, 2);
		world.setBlock(i + 6, j + 71, k + 19, SpaceAgeCore.edenSurface.blockID, 0, 2);
		world.setBlock(i + 6, j + 71, k + 20, SpaceAgeCore.edenSurface.blockID, 0, 2);
		world.setBlock(i + 6, j + 71, k + 21, SpaceAgeCore.edenSurface.blockID, 0, 2);
		world.setBlock(i + 6, j + 71, k + 22, SpaceAgeCore.edenSurface.blockID, 0, 2);
		world.setBlock(i + 6, j + 71, k + 23, SpaceAgeCore.edenSurface.blockID, 0, 2);
		world.setBlock(i + 6, j + 71, k + 24, SpaceAgeCore.edenSurface.blockID, 0, 2);
		world.setBlock(i + 6, j + 71, k + 25, SpaceAgeCore.edenSurface.blockID, 0, 2);
		world.setBlock(i + 6, j + 71, k + 26, SpaceAgeCore.edenSurface.blockID, 0, 2);
		world.setBlock(i + 6, j + 71, k + 27, SpaceAgeCore.edenSurface.blockID, 0, 2);
		world.setBlock(i + 6, j + 71, k + 28, SpaceAgeCore.edenSurface.blockID, 0, 2);
		world.setBlock(i + 6, j + 71, k + 29, SpaceAgeCore.edenSurface.blockID, 0, 2);
		world.setBlock(i + 6, j + 71, k + 30, SpaceAgeCore.edenSurface.blockID, 0, 2);
		world.setBlock(i + 6, j + 71, k + 31, SpaceAgeCore.edenSurface.blockID, 0, 2);
		world.setBlock(i + 6, j + 71, k + 32, SpaceAgeCore.edenSurface.blockID, 0, 2);
		world.setBlock(i + 6, j + 72, k + 6, SpaceAgeCore.edenSurface.blockID, 0, 2);
		world.setBlock(i + 6, j + 72, k + 30, SpaceAgeCore.edenSurface.blockID, 0, 2);
		world.setBlock(i + 6, j + 73, k + 7, SpaceAgeCore.edenSurface.blockID, 0, 2);
		world.setBlock(i + 6, j + 73, k + 8, SpaceAgeCore.edenSurface.blockID, 0, 2);
		world.setBlock(i + 6, j + 73, k + 28, SpaceAgeCore.edenSurface.blockID, 0, 2);
		world.setBlock(i + 6, j + 73, k + 29, SpaceAgeCore.edenSurface.blockID, 0, 2);
		world.setBlock(i + 6, j + 74, k + 9, SpaceAgeCore.edenSurface.blockID, 0, 2);
		world.setBlock(i + 6, j + 74, k + 27, SpaceAgeCore.edenSurface.blockID, 0, 2);
		world.setBlock(i + 6, j + 75, k + 10, SpaceAgeCore.edenSurface.blockID, 0, 2);
		world.setBlock(i + 6, j + 75, k + 11, SpaceAgeCore.edenSurface.blockID, 0, 2);
		world.setBlock(i + 6, j + 75, k + 25, SpaceAgeCore.edenSurface.blockID, 0, 2);
		world.setBlock(i + 6, j + 75, k + 26, SpaceAgeCore.edenSurface.blockID, 0, 2);
		world.setBlock(i + 6, j + 76, k + 12, SpaceAgeCore.edenSurface.blockID, 0, 2);
		world.setBlock(i + 6, j + 76, k + 13, SpaceAgeCore.edenSurface.blockID, 0, 2);
		world.setBlock(i + 6, j + 76, k + 14, SpaceAgeCore.edenSurface.blockID, 0, 2);
		world.setBlock(i + 6, j + 76, k + 22, SpaceAgeCore.edenSurface.blockID, 0, 2);
		world.setBlock(i + 6, j + 76, k + 23, SpaceAgeCore.edenSurface.blockID, 0, 2);
		world.setBlock(i + 6, j + 76, k + 24, SpaceAgeCore.edenSurface.blockID, 0, 2);
		world.setBlock(i + 6, j + 77, k + 15, SpaceAgeCore.edenSurface.blockID, 0, 2);
		world.setBlock(i + 6, j + 77, k + 16, SpaceAgeCore.edenSurface.blockID, 0, 2);
		world.setBlock(i + 6, j + 77, k + 17, SpaceAgeCore.edenSurface.blockID, 0, 2);
		world.setBlock(i + 6, j + 77, k + 18, SpaceAgeCore.edenSurface.blockID, 0, 2);
		world.setBlock(i + 6, j + 77, k + 19, SpaceAgeCore.edenSurface.blockID, 0, 2);
		world.setBlock(i + 6, j + 77, k + 20, SpaceAgeCore.edenSurface.blockID, 0, 2);
		world.setBlock(i + 6, j + 77, k + 21, SpaceAgeCore.edenSurface.blockID, 0, 2);
		world.setBlock(i + 7, j + 71, k + 4, SpaceAgeCore.edenSurface.blockID, 0, 2);
		world.setBlock(i + 7, j + 71, k + 5, SpaceAgeCore.edenSurface.blockID, 0, 2);
		world.setBlock(i + 7, j + 71, k + 6, SpaceAgeCore.edenSurface.blockID, 0, 2);
		world.setBlock(i + 7, j + 71, k + 7, SpaceAgeCore.edenSurface.blockID, 0, 2);
		world.setBlock(i + 7, j + 71, k + 8, SpaceAgeCore.edenSurface.blockID, 0, 2);
		world.setBlock(i + 7, j + 71, k + 9, SpaceAgeCore.edenSurface.blockID, 0, 2);
		world.setBlock(i + 7, j + 71, k + 10, SpaceAgeCore.edenSurface.blockID, 0, 2);
		world.setBlock(i + 7, j + 71, k + 11, SpaceAgeCore.edenSurface.blockID, 0, 2);
		world.setBlock(i + 7, j + 71, k + 12, SpaceAgeCore.edenSurface.blockID, 0, 2);
		world.setBlock(i + 7, j + 71, k + 13, SpaceAgeCore.edenSurface.blockID, 0, 2);
		world.setBlock(i + 7, j + 71, k + 14, SpaceAgeCore.edenSurface.blockID, 0, 2);
		world.setBlock(i + 7, j + 71, k + 15, SpaceAgeCore.edenSurface.blockID, 0, 2);
		world.setBlock(i + 7, j + 71, k + 16, SpaceAgeCore.edenSurface.blockID, 0, 2);
		world.setBlock(i + 7, j + 71, k + 17, SpaceAgeCore.edenSurface.blockID, 0, 2);
		world.setBlock(i + 7, j + 71, k + 18, SpaceAgeCore.edenSurface.blockID, 0, 2);
		world.setBlock(i + 7, j + 71, k + 19, SpaceAgeCore.edenSurface.blockID, 0, 2);
		world.setBlock(i + 7, j + 71, k + 20, SpaceAgeCore.edenSurface.blockID, 0, 2);
		world.setBlock(i + 7, j + 71, k + 21, SpaceAgeCore.edenSurface.blockID, 0, 2);
		world.setBlock(i + 7, j + 71, k + 22, SpaceAgeCore.edenSurface.blockID, 0, 2);
		world.setBlock(i + 7, j + 71, k + 23, SpaceAgeCore.edenSurface.blockID, 0, 2);
		world.setBlock(i + 7, j + 71, k + 24, SpaceAgeCore.edenSurface.blockID, 0, 2);
		world.setBlock(i + 7, j + 71, k + 25, SpaceAgeCore.edenSurface.blockID, 0, 2);
		world.setBlock(i + 7, j + 71, k + 26, SpaceAgeCore.edenSurface.blockID, 0, 2);
		world.setBlock(i + 7, j + 71, k + 27, SpaceAgeCore.edenSurface.blockID, 0, 2);
		world.setBlock(i + 7, j + 71, k + 28, SpaceAgeCore.edenSurface.blockID, 0, 2);
		world.setBlock(i + 7, j + 71, k + 29, SpaceAgeCore.edenSurface.blockID, 0, 2);
		world.setBlock(i + 7, j + 71, k + 30, SpaceAgeCore.edenSurface.blockID, 0, 2);
		world.setBlock(i + 7, j + 71, k + 31, SpaceAgeCore.edenSurface.blockID, 0, 2);
		world.setBlock(i + 7, j + 71, k + 32, SpaceAgeCore.edenSurface.blockID, 0, 2);
		world.setBlock(i + 7, j + 72, k + 5, SpaceAgeCore.edenSurface.blockID, 0, 2);
		world.setBlock(i + 7, j + 72, k + 31, SpaceAgeCore.edenSurface.blockID, 0, 2);
		world.setBlock(i + 7, j + 73, k + 6, SpaceAgeCore.edenSurface.blockID, 0, 2);
		world.setBlock(i + 7, j + 73, k + 7, SpaceAgeCore.edenSurface.blockID, 0, 2);
		world.setBlock(i + 7, j + 73, k + 29, SpaceAgeCore.edenSurface.blockID, 0, 2);
		world.setBlock(i + 7, j + 73, k + 30, SpaceAgeCore.edenSurface.blockID, 0, 2);
		world.setBlock(i + 7, j + 74, k + 8, SpaceAgeCore.edenSurface.blockID, 0, 2);
		world.setBlock(i + 7, j + 74, k + 28, SpaceAgeCore.edenSurface.blockID, 0, 2);
		world.setBlock(i + 7, j + 75, k + 9, SpaceAgeCore.edenSurface.blockID, 0, 2);
		world.setBlock(i + 7, j + 75, k + 10, SpaceAgeCore.edenSurface.blockID, 0, 2);
		world.setBlock(i + 7, j + 75, k + 26, SpaceAgeCore.edenSurface.blockID, 0, 2);
		world.setBlock(i + 7, j + 75, k + 27, SpaceAgeCore.edenSurface.blockID, 0, 2);
		world.setBlock(i + 7, j + 76, k + 11, SpaceAgeCore.edenSurface.blockID, 0, 2);
		world.setBlock(i + 7, j + 76, k + 12, SpaceAgeCore.edenSurface.blockID, 0, 2);
		world.setBlock(i + 7, j + 76, k + 24, SpaceAgeCore.edenSurface.blockID, 0, 2);
		world.setBlock(i + 7, j + 76, k + 25, SpaceAgeCore.edenSurface.blockID, 0, 2);
		world.setBlock(i + 7, j + 77, k + 13, SpaceAgeCore.edenSurface.blockID, 0, 2);
		world.setBlock(i + 7, j + 77, k + 14, SpaceAgeCore.edenSurface.blockID, 0, 2);
		world.setBlock(i + 7, j + 77, k + 22, SpaceAgeCore.edenSurface.blockID, 0, 2);
		world.setBlock(i + 7, j + 77, k + 23, SpaceAgeCore.edenSurface.blockID, 0, 2);
		world.setBlock(i + 7, j + 78, k + 15, SpaceAgeCore.edenSurface.blockID, 0, 2);
		world.setBlock(i + 7, j + 78, k + 16, SpaceAgeCore.edenSurface.blockID, 0, 2);
		world.setBlock(i + 7, j + 78, k + 17, SpaceAgeCore.edenSurface.blockID, 0, 2);
		world.setBlock(i + 7, j + 78, k + 18, SpaceAgeCore.edenSurface.blockID, 0, 2);
		world.setBlock(i + 7, j + 78, k + 19, SpaceAgeCore.edenSurface.blockID, 0, 2);
		world.setBlock(i + 7, j + 78, k + 20, SpaceAgeCore.edenSurface.blockID, 0, 2);
		world.setBlock(i + 7, j + 78, k + 21, SpaceAgeCore.edenSurface.blockID, 0, 2);
		world.setBlock(i + 8, j + 71, k + 3, SpaceAgeCore.edenSurface.blockID, 0, 2);
		world.setBlock(i + 8, j + 71, k + 4, SpaceAgeCore.edenSurface.blockID, 0, 2);
		world.setBlock(i + 8, j + 71, k + 5, SpaceAgeCore.edenSurface.blockID, 0, 2);
		world.setBlock(i + 8, j + 71, k + 6, SpaceAgeCore.edenSurface.blockID, 0, 2);
		world.setBlock(i + 8, j + 71, k + 7, SpaceAgeCore.edenSurface.blockID, 0, 2);
		world.setBlock(i + 8, j + 71, k + 8, SpaceAgeCore.edenSurface.blockID, 0, 2);
		world.setBlock(i + 8, j + 71, k + 9, SpaceAgeCore.edenSurface.blockID, 0, 2);
		world.setBlock(i + 8, j + 71, k + 10, SpaceAgeCore.edenSurface.blockID, 0, 2);
		world.setBlock(i + 8, j + 71, k + 11, SpaceAgeCore.edenSurface.blockID, 0, 2);
		world.setBlock(i + 8, j + 71, k + 12, SpaceAgeCore.edenSurface.blockID, 0, 2);
		world.setBlock(i + 8, j + 71, k + 13, SpaceAgeCore.edenSurface.blockID, 0, 2);
		world.setBlock(i + 8, j + 71, k + 14, SpaceAgeCore.edenSurface.blockID, 0, 2);
		world.setBlock(i + 8, j + 71, k + 15, SpaceAgeCore.edenSurface.blockID, 0, 2);
		world.setBlock(i + 8, j + 71, k + 16, SpaceAgeCore.edenSurface.blockID, 0, 2);
		world.setBlock(i + 8, j + 71, k + 17, SpaceAgeCore.edenSurface.blockID, 0, 2);
		world.setBlock(i + 8, j + 71, k + 18, SpaceAgeCore.edenSurface.blockID, 0, 2);
		world.setBlock(i + 8, j + 71, k + 19, SpaceAgeCore.edenSurface.blockID, 0, 2);
		world.setBlock(i + 8, j + 71, k + 20, SpaceAgeCore.edenSurface.blockID, 0, 2);
		world.setBlock(i + 8, j + 71, k + 21, SpaceAgeCore.edenSurface.blockID, 0, 2);
		world.setBlock(i + 8, j + 71, k + 22, SpaceAgeCore.edenSurface.blockID, 0, 2);
		world.setBlock(i + 8, j + 71, k + 23, SpaceAgeCore.edenSurface.blockID, 0, 2);
		world.setBlock(i + 8, j + 71, k + 24, SpaceAgeCore.edenSurface.blockID, 0, 2);
		world.setBlock(i + 8, j + 71, k + 25, SpaceAgeCore.edenSurface.blockID, 0, 2);
		world.setBlock(i + 8, j + 71, k + 26, SpaceAgeCore.edenSurface.blockID, 0, 2);
		world.setBlock(i + 8, j + 71, k + 27, SpaceAgeCore.edenSurface.blockID, 0, 2);
		world.setBlock(i + 8, j + 71, k + 28, SpaceAgeCore.edenSurface.blockID, 0, 2);
		world.setBlock(i + 8, j + 71, k + 29, SpaceAgeCore.edenSurface.blockID, 0, 2);
		world.setBlock(i + 8, j + 71, k + 30, SpaceAgeCore.edenSurface.blockID, 0, 2);
		world.setBlock(i + 8, j + 71, k + 31, SpaceAgeCore.edenSurface.blockID, 0, 2);
		world.setBlock(i + 8, j + 71, k + 32, SpaceAgeCore.edenSurface.blockID, 0, 2);
		world.setBlock(i + 8, j + 71, k + 33, SpaceAgeCore.edenSurface.blockID, 0, 2);
		world.setBlock(i + 8, j + 72, k + 4, SpaceAgeCore.edenSurface.blockID, 0, 2);
		world.setBlock(i + 8, j + 72, k + 32, SpaceAgeCore.edenSurface.blockID, 0, 2);
		world.setBlock(i + 8, j + 73, k + 5, SpaceAgeCore.edenSurface.blockID, 0, 2);
		world.setBlock(i + 8, j + 73, k + 6, SpaceAgeCore.edenSurface.blockID, 0, 2);
		world.setBlock(i + 8, j + 73, k + 30, SpaceAgeCore.edenSurface.blockID, 0, 2);
		world.setBlock(i + 8, j + 73, k + 31, SpaceAgeCore.edenSurface.blockID, 0, 2);
		world.setBlock(i + 8, j + 74, k + 7, SpaceAgeCore.edenSurface.blockID, 0, 2);
		world.setBlock(i + 8, j + 74, k + 29, SpaceAgeCore.edenSurface.blockID, 0, 2);
		world.setBlock(i + 8, j + 75, k + 8, SpaceAgeCore.edenSurface.blockID, 0, 2);
		world.setBlock(i + 8, j + 75, k + 28, SpaceAgeCore.edenSurface.blockID, 0, 2);
		world.setBlock(i + 8, j + 76, k + 9, SpaceAgeCore.edenSurface.blockID, 0, 2);
		world.setBlock(i + 8, j + 76, k + 10, SpaceAgeCore.edenSurface.blockID, 0, 2);
		world.setBlock(i + 8, j + 76, k + 26, SpaceAgeCore.edenSurface.blockID, 0, 2);
		world.setBlock(i + 8, j + 76, k + 27, SpaceAgeCore.edenSurface.blockID, 0, 2);
		world.setBlock(i + 8, j + 77, k + 11, SpaceAgeCore.edenSurface.blockID, 0, 2);
		world.setBlock(i + 8, j + 77, k + 12, SpaceAgeCore.edenSurface.blockID, 0, 2);
		world.setBlock(i + 8, j + 77, k + 24, SpaceAgeCore.edenSurface.blockID, 0, 2);
		world.setBlock(i + 8, j + 77, k + 25, SpaceAgeCore.edenSurface.blockID, 0, 2);
		world.setBlock(i + 8, j + 78, k + 13, SpaceAgeCore.edenSurface.blockID, 0, 2);
		world.setBlock(i + 8, j + 78, k + 14, SpaceAgeCore.edenSurface.blockID, 0, 2);
		world.setBlock(i + 8, j + 78, k + 22, SpaceAgeCore.edenSurface.blockID, 0, 2);
		world.setBlock(i + 8, j + 78, k + 23, SpaceAgeCore.edenSurface.blockID, 0, 2);
		world.setBlock(i + 8, j + 79, k + 15, SpaceAgeCore.edenSurface.blockID, 0, 2);
		world.setBlock(i + 8, j + 79, k + 16, SpaceAgeCore.edenSurface.blockID, 0, 2);
		world.setBlock(i + 8, j + 79, k + 17, SpaceAgeCore.edenSurface.blockID, 0, 2);
		world.setBlock(i + 8, j + 79, k + 18, SpaceAgeCore.edenSurface.blockID, 0, 2);
		world.setBlock(i + 8, j + 79, k + 19, SpaceAgeCore.edenSurface.blockID, 0, 2);
		world.setBlock(i + 8, j + 79, k + 20, SpaceAgeCore.edenSurface.blockID, 0, 2);
		world.setBlock(i + 8, j + 79, k + 21, SpaceAgeCore.edenSurface.blockID, 0, 2);
		world.setBlock(i + 9, j + 71, k + 2, SpaceAgeCore.edenSurface.blockID, 0, 2);
		world.setBlock(i + 9, j + 71, k + 3, SpaceAgeCore.edenSurface.blockID, 0, 2);
		world.setBlock(i + 9, j + 71, k + 4, SpaceAgeCore.edenSurface.blockID, 0, 2);
		world.setBlock(i + 9, j + 71, k + 5, SpaceAgeCore.edenSurface.blockID, 0, 2);
		world.setBlock(i + 9, j + 71, k + 6, SpaceAgeCore.edenSurface.blockID, 0, 2);
		world.setBlock(i + 9, j + 71, k + 7, SpaceAgeCore.edenSurface.blockID, 0, 2);
		world.setBlock(i + 9, j + 71, k + 8, SpaceAgeCore.edenSurface.blockID, 0, 2);
		world.setBlock(i + 9, j + 71, k + 9, SpaceAgeCore.edenSurface.blockID, 0, 2);
		world.setBlock(i + 9, j + 71, k + 10, SpaceAgeCore.edenSurface.blockID, 0, 2);
		world.setBlock(i + 9, j + 71, k + 11, SpaceAgeCore.edenSurface.blockID, 0, 2);
		world.setBlock(i + 9, j + 71, k + 12, SpaceAgeCore.edenSurface.blockID, 0, 2);
		world.setBlock(i + 9, j + 71, k + 13, SpaceAgeCore.edenSurface.blockID, 0, 2);
		world.setBlock(i + 9, j + 71, k + 14, SpaceAgeCore.edenSurface.blockID, 0, 2);
		world.setBlock(i + 9, j + 71, k + 15, SpaceAgeCore.edenSurface.blockID, 0, 2);
		world.setBlock(i + 9, j + 71, k + 16, SpaceAgeCore.edenSurface.blockID, 0, 2);
		world.setBlock(i + 9, j + 71, k + 17, SpaceAgeCore.edenSurface.blockID, 0, 2);
		world.setBlock(i + 9, j + 71, k + 18, SpaceAgeCore.edenSurface.blockID, 0, 2);
		world.setBlock(i + 9, j + 71, k + 19, SpaceAgeCore.edenSurface.blockID, 0, 2);
		world.setBlock(i + 9, j + 71, k + 20, SpaceAgeCore.edenSurface.blockID, 0, 2);
		world.setBlock(i + 9, j + 71, k + 21, SpaceAgeCore.edenSurface.blockID, 0, 2);
		world.setBlock(i + 9, j + 71, k + 22, SpaceAgeCore.edenSurface.blockID, 0, 2);
		world.setBlock(i + 9, j + 71, k + 23, SpaceAgeCore.edenSurface.blockID, 0, 2);
		world.setBlock(i + 9, j + 71, k + 24, SpaceAgeCore.edenSurface.blockID, 0, 2);
		world.setBlock(i + 9, j + 71, k + 25, SpaceAgeCore.edenSurface.blockID, 0, 2);
		world.setBlock(i + 9, j + 71, k + 26, SpaceAgeCore.edenSurface.blockID, 0, 2);
		world.setBlock(i + 9, j + 71, k + 27, SpaceAgeCore.edenSurface.blockID, 0, 2);
		world.setBlock(i + 9, j + 71, k + 28, SpaceAgeCore.edenSurface.blockID, 0, 2);
		world.setBlock(i + 9, j + 71, k + 29, SpaceAgeCore.edenSurface.blockID, 0, 2);
		world.setBlock(i + 9, j + 71, k + 30, SpaceAgeCore.edenSurface.blockID, 0, 2);
		world.setBlock(i + 9, j + 71, k + 31, SpaceAgeCore.edenSurface.blockID, 0, 2);
		world.setBlock(i + 9, j + 71, k + 32, SpaceAgeCore.edenSurface.blockID, 0, 2);
		world.setBlock(i + 9, j + 71, k + 33, SpaceAgeCore.edenSurface.blockID, 0, 2);
		world.setBlock(i + 9, j + 71, k + 34, SpaceAgeCore.edenSurface.blockID, 0, 2);
		world.setBlock(i + 9, j + 72, k + 3, SpaceAgeCore.edenSurface.blockID, 0, 2);
		world.setBlock(i + 9, j + 72, k + 4, SpaceAgeCore.edenSurface.blockID, 0, 2);
		world.setBlock(i + 9, j + 72, k + 32, SpaceAgeCore.edenSurface.blockID, 0, 2);
		world.setBlock(i + 9, j + 72, k + 33, SpaceAgeCore.edenSurface.blockID, 0, 2);
		world.setBlock(i + 9, j + 73, k + 5, SpaceAgeCore.edenSurface.blockID, 0, 2);
		world.setBlock(i + 9, j + 73, k + 31, SpaceAgeCore.edenSurface.blockID, 0, 2);
		world.setBlock(i + 9, j + 74, k + 6, SpaceAgeCore.edenSurface.blockID, 0, 2);
		world.setBlock(i + 9, j + 74, k + 30, SpaceAgeCore.edenSurface.blockID, 0, 2);
		world.setBlock(i + 9, j + 75, k + 7, SpaceAgeCore.edenSurface.blockID, 0, 2);
		world.setBlock(i + 9, j + 75, k + 29, SpaceAgeCore.edenSurface.blockID, 0, 2);
		world.setBlock(i + 9, j + 76, k + 8, SpaceAgeCore.edenSurface.blockID, 0, 2);
		world.setBlock(i + 9, j + 76, k + 9, SpaceAgeCore.edenSurface.blockID, 0, 2);
		world.setBlock(i + 9, j + 76, k + 27, SpaceAgeCore.edenSurface.blockID, 0, 2);
		world.setBlock(i + 9, j + 76, k + 28, SpaceAgeCore.edenSurface.blockID, 0, 2);
		world.setBlock(i + 9, j + 77, k + 10, SpaceAgeCore.edenSurface.blockID, 0, 2);
		world.setBlock(i + 9, j + 77, k + 26, SpaceAgeCore.edenSurface.blockID, 0, 2);
		world.setBlock(i + 9, j + 78, k + 11, SpaceAgeCore.edenSurface.blockID, 0, 2);
		world.setBlock(i + 9, j + 78, k + 12, SpaceAgeCore.edenSurface.blockID, 0, 2);
		world.setBlock(i + 9, j + 78, k + 24, SpaceAgeCore.edenSurface.blockID, 0, 2);
		world.setBlock(i + 9, j + 78, k + 25, SpaceAgeCore.edenSurface.blockID, 0, 2);
		world.setBlock(i + 9, j + 79, k + 13, SpaceAgeCore.edenSurface.blockID, 0, 2);
		world.setBlock(i + 9, j + 79, k + 14, SpaceAgeCore.edenSurface.blockID, 0, 2);
		world.setBlock(i + 9, j + 79, k + 15, SpaceAgeCore.edenSurface.blockID, 0, 2);
		world.setBlock(i + 9, j + 79, k + 16, SpaceAgeCore.edenSurface.blockID, 0, 2);
		world.setBlock(i + 9, j + 79, k + 17, SpaceAgeCore.edenSurface.blockID, 0, 2);
		world.setBlock(i + 9, j + 79, k + 18, SpaceAgeCore.edenSurface.blockID, 0, 2);
		world.setBlock(i + 9, j + 79, k + 19, SpaceAgeCore.edenSurface.blockID, 0, 2);
		world.setBlock(i + 9, j + 79, k + 20, SpaceAgeCore.edenSurface.blockID, 0, 2);
		world.setBlock(i + 9, j + 79, k + 21, SpaceAgeCore.edenSurface.blockID, 0, 2);
		world.setBlock(i + 9, j + 79, k + 22, SpaceAgeCore.edenSurface.blockID, 0, 2);
		world.setBlock(i + 9, j + 79, k + 23, SpaceAgeCore.edenSurface.blockID, 0, 2);
		world.setBlock(i + 10, j + 71, k + 2, SpaceAgeCore.edenSurface.blockID, 0, 2);
		world.setBlock(i + 10, j + 71, k + 3, SpaceAgeCore.edenSurface.blockID, 0, 2);
		world.setBlock(i + 10, j + 71, k + 4, SpaceAgeCore.edenSurface.blockID, 0, 2);
		world.setBlock(i + 10, j + 71, k + 5, SpaceAgeCore.edenSurface.blockID, 0, 2);
		world.setBlock(i + 10, j + 71, k + 6, SpaceAgeCore.edenSurface.blockID, 0, 2);
		world.setBlock(i + 10, j + 71, k + 7, SpaceAgeCore.edenSurface.blockID, 0, 2);
		world.setBlock(i + 10, j + 71, k + 8, SpaceAgeCore.edenSurface.blockID, 0, 2);
		world.setBlock(i + 10, j + 71, k + 9, SpaceAgeCore.edenSurface.blockID, 0, 2);
		world.setBlock(i + 10, j + 71, k + 10, SpaceAgeCore.edenSurface.blockID, 0, 2);
		world.setBlock(i + 10, j + 71, k + 11, SpaceAgeCore.edenSurface.blockID, 0, 2);
		world.setBlock(i + 10, j + 71, k + 12, SpaceAgeCore.edenSurface.blockID, 0, 2);
		world.setBlock(i + 10, j + 71, k + 13, SpaceAgeCore.edenSurface.blockID, 0, 2);
		world.setBlock(i + 10, j + 71, k + 14, SpaceAgeCore.edenSurface.blockID, 0, 2);
		world.setBlock(i + 10, j + 71, k + 15, SpaceAgeCore.edenSurface.blockID, 0, 2);
		world.setBlock(i + 10, j + 71, k + 16, SpaceAgeCore.edenSurface.blockID, 0, 2);
		world.setBlock(i + 10, j + 71, k + 17, SpaceAgeCore.edenSurface.blockID, 0, 2);
		world.setBlock(i + 10, j + 71, k + 18, SpaceAgeCore.edenSurface.blockID, 0, 2);
		world.setBlock(i + 10, j + 71, k + 19, SpaceAgeCore.edenSurface.blockID, 0, 2);
		world.setBlock(i + 10, j + 71, k + 20, SpaceAgeCore.edenSurface.blockID, 0, 2);
		world.setBlock(i + 10, j + 71, k + 21, SpaceAgeCore.edenSurface.blockID, 0, 2);
		world.setBlock(i + 10, j + 71, k + 22, SpaceAgeCore.edenSurface.blockID, 0, 2);
		world.setBlock(i + 10, j + 71, k + 23, SpaceAgeCore.edenSurface.blockID, 0, 2);
		world.setBlock(i + 10, j + 71, k + 24, SpaceAgeCore.edenSurface.blockID, 0, 2);
		world.setBlock(i + 10, j + 71, k + 25, SpaceAgeCore.edenSurface.blockID, 0, 2);
		world.setBlock(i + 10, j + 71, k + 26, SpaceAgeCore.edenSurface.blockID, 0, 2);
		world.setBlock(i + 10, j + 71, k + 27, SpaceAgeCore.edenSurface.blockID, 0, 2);
		world.setBlock(i + 10, j + 71, k + 28, SpaceAgeCore.edenSurface.blockID, 0, 2);
		world.setBlock(i + 10, j + 71, k + 29, SpaceAgeCore.edenSurface.blockID, 0, 2);
		world.setBlock(i + 10, j + 71, k + 30, SpaceAgeCore.edenSurface.blockID, 0, 2);
		world.setBlock(i + 10, j + 71, k + 31, SpaceAgeCore.edenSurface.blockID, 0, 2);
		world.setBlock(i + 10, j + 71, k + 32, SpaceAgeCore.edenSurface.blockID, 0, 2);
		world.setBlock(i + 10, j + 71, k + 33, SpaceAgeCore.edenSurface.blockID, 0, 2);
		world.setBlock(i + 10, j + 71, k + 34, SpaceAgeCore.edenSurface.blockID, 0, 2);
		world.setBlock(i + 10, j + 72, k + 3, SpaceAgeCore.edenSurface.blockID, 0, 2);
		world.setBlock(i + 10, j + 72, k + 33, SpaceAgeCore.edenSurface.blockID, 0, 2);
		world.setBlock(i + 10, j + 73, k + 4, SpaceAgeCore.edenSurface.blockID, 0, 2);
		world.setBlock(i + 10, j + 73, k + 32, SpaceAgeCore.edenSurface.blockID, 0, 2);
		world.setBlock(i + 10, j + 74, k + 5, SpaceAgeCore.edenSurface.blockID, 0, 2);
		world.setBlock(i + 10, j + 74, k + 31, SpaceAgeCore.edenSurface.blockID, 0, 2);
		world.setBlock(i + 10, j + 75, k + 6, SpaceAgeCore.edenSurface.blockID, 0, 2);
		world.setBlock(i + 10, j + 75, k + 7, SpaceAgeCore.edenSurface.blockID, 0, 2);
		world.setBlock(i + 10, j + 75, k + 29, SpaceAgeCore.edenSurface.blockID, 0, 2);
		world.setBlock(i + 10, j + 75, k + 30, SpaceAgeCore.edenSurface.blockID, 0, 2);
		world.setBlock(i + 10, j + 76, k + 8, SpaceAgeCore.edenSurface.blockID, 0, 2);
		world.setBlock(i + 10, j + 76, k + 28, SpaceAgeCore.edenSurface.blockID, 0, 2);
		world.setBlock(i + 10, j + 77, k + 9, SpaceAgeCore.edenSurface.blockID, 0, 2);
		world.setBlock(i + 10, j + 77, k + 27, SpaceAgeCore.edenSurface.blockID, 0, 2);
		world.setBlock(i + 10, j + 78, k + 10, SpaceAgeCore.edenSurface.blockID, 0, 2);
		world.setBlock(i + 10, j + 78, k + 11, SpaceAgeCore.edenSurface.blockID, 0, 2);
		world.setBlock(i + 10, j + 78, k + 25, SpaceAgeCore.edenSurface.blockID, 0, 2);
		world.setBlock(i + 10, j + 78, k + 26, SpaceAgeCore.edenSurface.blockID, 0, 2);
		world.setBlock(i + 10, j + 79, k + 12, SpaceAgeCore.edenSurface.blockID, 0, 2);
		world.setBlock(i + 10, j + 79, k + 13, SpaceAgeCore.edenSurface.blockID, 0, 2);
		world.setBlock(i + 10, j + 79, k + 14, SpaceAgeCore.edenSurface.blockID, 0, 2);
		world.setBlock(i + 10, j + 79, k + 15, SpaceAgeCore.edenSurface.blockID, 0, 2);
		world.setBlock(i + 10, j + 79, k + 16, SpaceAgeCore.edenSurface.blockID, 0, 2);
		world.setBlock(i + 10, j + 79, k + 17, SpaceAgeCore.edenSurface.blockID, 0, 2);
		world.setBlock(i + 10, j + 79, k + 18, SpaceAgeCore.edenSurface.blockID, 0, 2);
		world.setBlock(i + 10, j + 79, k + 19, SpaceAgeCore.edenSurface.blockID, 0, 2);
		world.setBlock(i + 10, j + 79, k + 20, SpaceAgeCore.edenSurface.blockID, 0, 2);
		world.setBlock(i + 10, j + 79, k + 21, SpaceAgeCore.edenSurface.blockID, 0, 2);
		world.setBlock(i + 10, j + 79, k + 22, SpaceAgeCore.edenSurface.blockID, 0, 2);
		world.setBlock(i + 10, j + 79, k + 23, SpaceAgeCore.edenSurface.blockID, 0, 2);
		world.setBlock(i + 10, j + 79, k + 24, SpaceAgeCore.edenSurface.blockID, 0, 2);
		world.setBlock(i + 11, j + 71, k + 1, SpaceAgeCore.edenSurface.blockID, 0, 2);
		world.setBlock(i + 11, j + 71, k + 2, SpaceAgeCore.edenSurface.blockID, 0, 2);
		world.setBlock(i + 11, j + 71, k + 3, SpaceAgeCore.edenSurface.blockID, 0, 2);
		world.setBlock(i + 11, j + 71, k + 4, SpaceAgeCore.edenSurface.blockID, 0, 2);
		world.setBlock(i + 11, j + 71, k + 5, SpaceAgeCore.edenSurface.blockID, 0, 2);
		world.setBlock(i + 11, j + 71, k + 6, SpaceAgeCore.edenSurface.blockID, 0, 2);
		world.setBlock(i + 11, j + 71, k + 7, SpaceAgeCore.edenSurface.blockID, 0, 2);
		world.setBlock(i + 11, j + 71, k + 8, SpaceAgeCore.edenSurface.blockID, 0, 2);
		world.setBlock(i + 11, j + 71, k + 9, SpaceAgeCore.edenSurface.blockID, 0, 2);
		world.setBlock(i + 11, j + 71, k + 10, SpaceAgeCore.edenSurface.blockID, 0, 2);
		world.setBlock(i + 11, j + 71, k + 11, SpaceAgeCore.edenSurface.blockID, 0, 2);
		world.setBlock(i + 11, j + 71, k + 12, SpaceAgeCore.edenSurface.blockID, 0, 2);
		world.setBlock(i + 11, j + 71, k + 13, SpaceAgeCore.edenSurface.blockID, 0, 2);
		world.setBlock(i + 11, j + 71, k + 14, SpaceAgeCore.edenSurface.blockID, 0, 2);
		world.setBlock(i + 11, j + 71, k + 15, SpaceAgeCore.edenSurface.blockID, 0, 2);
		world.setBlock(i + 11, j + 71, k + 16, SpaceAgeCore.edenSurface.blockID, 0, 2);
		world.setBlock(i + 11, j + 71, k + 17, SpaceAgeCore.edenSurface.blockID, 0, 2);
		world.setBlock(i + 11, j + 71, k + 18, SpaceAgeCore.edenSurface.blockID, 0, 2);
		world.setBlock(i + 11, j + 71, k + 19, SpaceAgeCore.edenSurface.blockID, 0, 2);
		world.setBlock(i + 11, j + 71, k + 20, SpaceAgeCore.edenSurface.blockID, 0, 2);
		world.setBlock(i + 11, j + 71, k + 21, SpaceAgeCore.edenSurface.blockID, 0, 2);
		world.setBlock(i + 11, j + 71, k + 22, SpaceAgeCore.edenSurface.blockID, 0, 2);
		world.setBlock(i + 11, j + 71, k + 23, SpaceAgeCore.edenSurface.blockID, 0, 2);
		world.setBlock(i + 11, j + 71, k + 24, SpaceAgeCore.edenSurface.blockID, 0, 2);
		world.setBlock(i + 11, j + 71, k + 25, SpaceAgeCore.edenSurface.blockID, 0, 2);
		world.setBlock(i + 11, j + 71, k + 26, SpaceAgeCore.edenSurface.blockID, 0, 2);
		world.setBlock(i + 11, j + 71, k + 27, SpaceAgeCore.edenSurface.blockID, 0, 2);
		world.setBlock(i + 11, j + 71, k + 28, SpaceAgeCore.edenSurface.blockID, 0, 2);
		world.setBlock(i + 11, j + 71, k + 29, SpaceAgeCore.edenSurface.blockID, 0, 2);
		world.setBlock(i + 11, j + 71, k + 30, SpaceAgeCore.edenSurface.blockID, 0, 2);
		world.setBlock(i + 11, j + 71, k + 31, SpaceAgeCore.edenSurface.blockID, 0, 2);
		world.setBlock(i + 11, j + 71, k + 32, SpaceAgeCore.edenSurface.blockID, 0, 2);
		world.setBlock(i + 11, j + 71, k + 33, SpaceAgeCore.edenSurface.blockID, 0, 2);
		world.setBlock(i + 11, j + 71, k + 34, SpaceAgeCore.edenSurface.blockID, 0, 2);
		world.setBlock(i + 11, j + 71, k + 35, SpaceAgeCore.edenSurface.blockID, 0, 2);
		world.setBlock(i + 11, j + 72, k + 2, SpaceAgeCore.edenSurface.blockID, 0, 2);
		world.setBlock(i + 11, j + 72, k + 3, SpaceAgeCore.edenSurface.blockID, 0, 2);
		world.setBlock(i + 11, j + 72, k + 33, SpaceAgeCore.edenSurface.blockID, 0, 2);
		world.setBlock(i + 11, j + 72, k + 34, SpaceAgeCore.edenSurface.blockID, 0, 2);
		world.setBlock(i + 11, j + 73, k + 4, SpaceAgeCore.edenSurface.blockID, 0, 2);
		world.setBlock(i + 11, j + 73, k + 32, SpaceAgeCore.edenSurface.blockID, 0, 2);
		world.setBlock(i + 11, j + 74, k + 5, SpaceAgeCore.edenSurface.blockID, 0, 2);
		world.setBlock(i + 11, j + 74, k + 31, SpaceAgeCore.edenSurface.blockID, 0, 2);
		world.setBlock(i + 11, j + 75, k + 6, SpaceAgeCore.edenSurface.blockID, 0, 2);
		world.setBlock(i + 11, j + 75, k + 30, SpaceAgeCore.edenSurface.blockID, 0, 2);
		world.setBlock(i + 11, j + 76, k + 7, SpaceAgeCore.edenSurface.blockID, 0, 2);
		world.setBlock(i + 11, j + 76, k + 29, SpaceAgeCore.edenSurface.blockID, 0, 2);
		world.setBlock(i + 11, j + 77, k + 8, SpaceAgeCore.edenSurface.blockID, 0, 2);
		world.setBlock(i + 11, j + 77, k + 28, SpaceAgeCore.edenSurface.blockID, 0, 2);
		world.setBlock(i + 11, j + 78, k + 9, SpaceAgeCore.edenSurface.blockID, 0, 2);
		world.setBlock(i + 11, j + 78, k + 10, SpaceAgeCore.edenSurface.blockID, 0, 2);
		world.setBlock(i + 11, j + 78, k + 26, SpaceAgeCore.edenSurface.blockID, 0, 2);
		world.setBlock(i + 11, j + 78, k + 27, SpaceAgeCore.edenSurface.blockID, 0, 2);
		world.setBlock(i + 11, j + 79, k + 11, SpaceAgeCore.edenSurface.blockID, 0, 2);
		world.setBlock(i + 11, j + 79, k + 12, SpaceAgeCore.edenSurface.blockID, 0, 2);
		world.setBlock(i + 11, j + 79, k + 13, SpaceAgeCore.edenSurface.blockID, 0, 2);
		world.setBlock(i + 11, j + 79, k + 14, SpaceAgeCore.edenSurface.blockID, 0, 2);
		world.setBlock(i + 11, j + 79, k + 15, SpaceAgeCore.edenSurface.blockID, 0, 2);
		world.setBlock(i + 11, j + 79, k + 16, SpaceAgeCore.edenSurface.blockID, 0, 2);
		world.setBlock(i + 11, j + 79, k + 17, SpaceAgeCore.edenSurface.blockID, 0, 2);
		world.setBlock(i + 11, j + 79, k + 18, SpaceAgeCore.edenSurface.blockID, 0, 2);
		world.setBlock(i + 11, j + 79, k + 19, SpaceAgeCore.edenSurface.blockID, 0, 2);
		world.setBlock(i + 11, j + 79, k + 20, SpaceAgeCore.edenSurface.blockID, 0, 2);
		world.setBlock(i + 11, j + 79, k + 21, SpaceAgeCore.edenSurface.blockID, 0, 2);
		world.setBlock(i + 11, j + 79, k + 22, SpaceAgeCore.edenSurface.blockID, 0, 2);
		world.setBlock(i + 11, j + 79, k + 23, SpaceAgeCore.edenSurface.blockID, 0, 2);
		world.setBlock(i + 11, j + 79, k + 24, SpaceAgeCore.edenSurface.blockID, 0, 2);
		world.setBlock(i + 11, j + 79, k + 25, SpaceAgeCore.edenSurface.blockID, 0, 2);
		world.setBlock(i + 12, j + 71, k + 1, SpaceAgeCore.edenSurface.blockID, 0, 2);
		world.setBlock(i + 12, j + 71, k + 2, SpaceAgeCore.edenSurface.blockID, 0, 2);
		world.setBlock(i + 12, j + 71, k + 3, SpaceAgeCore.edenSurface.blockID, 0, 2);
		world.setBlock(i + 12, j + 71, k + 4, SpaceAgeCore.edenSurface.blockID, 0, 2);
		world.setBlock(i + 12, j + 71, k + 5, SpaceAgeCore.edenSurface.blockID, 0, 2);
		world.setBlock(i + 12, j + 71, k + 6, SpaceAgeCore.edenSurface.blockID, 0, 2);
		world.setBlock(i + 12, j + 71, k + 7, SpaceAgeCore.edenSurface.blockID, 0, 2);
		world.setBlock(i + 12, j + 71, k + 8, SpaceAgeCore.edenSurface.blockID, 0, 2);
		world.setBlock(i + 12, j + 71, k + 9, SpaceAgeCore.edenSurface.blockID, 0, 2);
		world.setBlock(i + 12, j + 71, k + 10, SpaceAgeCore.edenSurface.blockID, 0, 2);
		world.setBlock(i + 12, j + 71, k + 11, SpaceAgeCore.edenSurface.blockID, 0, 2);
		world.setBlock(i + 12, j + 71, k + 12, SpaceAgeCore.edenSurface.blockID, 0, 2);
		world.setBlock(i + 12, j + 71, k + 13, SpaceAgeCore.edenSurface.blockID, 0, 2);
		world.setBlock(i + 12, j + 71, k + 14, SpaceAgeCore.edenSurface.blockID, 0, 2);
		world.setBlock(i + 12, j + 71, k + 15, SpaceAgeCore.edenSurface.blockID, 0, 2);
		world.setBlock(i + 12, j + 71, k + 16, SpaceAgeCore.edenSurface.blockID, 0, 2);
		world.setBlock(i + 12, j + 71, k + 17, SpaceAgeCore.edenSurface.blockID, 0, 2);
		world.setBlock(i + 12, j + 71, k + 18, SpaceAgeCore.edenSurface.blockID, 0, 2);
		world.setBlock(i + 12, j + 71, k + 19, SpaceAgeCore.edenSurface.blockID, 0, 2);
		world.setBlock(i + 12, j + 71, k + 20, SpaceAgeCore.edenSurface.blockID, 0, 2);
		world.setBlock(i + 12, j + 71, k + 21, SpaceAgeCore.edenSurface.blockID, 0, 2);
		world.setBlock(i + 12, j + 71, k + 22, SpaceAgeCore.edenSurface.blockID, 0, 2);
		world.setBlock(i + 12, j + 71, k + 23, SpaceAgeCore.edenSurface.blockID, 0, 2);
		world.setBlock(i + 12, j + 71, k + 24, SpaceAgeCore.edenSurface.blockID, 0, 2);
		world.setBlock(i + 12, j + 71, k + 25, SpaceAgeCore.edenSurface.blockID, 0, 2);
		world.setBlock(i + 12, j + 71, k + 26, SpaceAgeCore.edenSurface.blockID, 0, 2);
		world.setBlock(i + 12, j + 71, k + 27, SpaceAgeCore.edenSurface.blockID, 0, 2);
		world.setBlock(i + 12, j + 71, k + 28, SpaceAgeCore.edenSurface.blockID, 0, 2);
		world.setBlock(i + 12, j + 71, k + 29, SpaceAgeCore.edenSurface.blockID, 0, 2);
		world.setBlock(i + 12, j + 71, k + 30, SpaceAgeCore.edenSurface.blockID, 0, 2);
		world.setBlock(i + 12, j + 71, k + 31, SpaceAgeCore.edenSurface.blockID, 0, 2);
		world.setBlock(i + 12, j + 71, k + 32, SpaceAgeCore.edenSurface.blockID, 0, 2);
		world.setBlock(i + 12, j + 71, k + 33, SpaceAgeCore.edenSurface.blockID, 0, 2);
		world.setBlock(i + 12, j + 71, k + 34, SpaceAgeCore.edenSurface.blockID, 0, 2);
		world.setBlock(i + 12, j + 71, k + 35, SpaceAgeCore.edenSurface.blockID, 0, 2);
		world.setBlock(i + 12, j + 72, k + 2, SpaceAgeCore.edenSurface.blockID, 0, 2);
		world.setBlock(i + 12, j + 72, k + 34, SpaceAgeCore.edenSurface.blockID, 0, 2);
		world.setBlock(i + 12, j + 73, k + 3, SpaceAgeCore.edenSurface.blockID, 0, 2);
		world.setBlock(i + 12, j + 73, k + 33, SpaceAgeCore.edenSurface.blockID, 0, 2);
		world.setBlock(i + 12, j + 74, k + 4, SpaceAgeCore.edenSurface.blockID, 0, 2);
		world.setBlock(i + 12, j + 74, k + 32, SpaceAgeCore.edenSurface.blockID, 0, 2);
		world.setBlock(i + 12, j + 75, k + 5, SpaceAgeCore.edenSurface.blockID, 0, 2);
		world.setBlock(i + 12, j + 75, k + 31, SpaceAgeCore.edenSurface.blockID, 0, 2);
		world.setBlock(i + 12, j + 76, k + 6, SpaceAgeCore.edenSurface.blockID, 0, 2);
		world.setBlock(i + 12, j + 76, k + 7, SpaceAgeCore.edenSurface.blockID, 0, 2);
		world.setBlock(i + 12, j + 76, k + 29, SpaceAgeCore.edenSurface.blockID, 0, 2);
		world.setBlock(i + 12, j + 76, k + 30, SpaceAgeCore.edenSurface.blockID, 0, 2);
		world.setBlock(i + 12, j + 77, k + 8, SpaceAgeCore.edenSurface.blockID, 0, 2);
		world.setBlock(i + 12, j + 77, k + 28, SpaceAgeCore.edenSurface.blockID, 0, 2);
		world.setBlock(i + 12, j + 78, k + 9, SpaceAgeCore.edenSurface.blockID, 0, 2);
		world.setBlock(i + 12, j + 78, k + 27, SpaceAgeCore.edenSurface.blockID, 0, 2);
		world.setBlock(i + 12, j + 79, k + 10, SpaceAgeCore.edenSurface.blockID, 0, 2);
		world.setBlock(i + 12, j + 79, k + 11, SpaceAgeCore.edenSurface.blockID, 0, 2);
		world.setBlock(i + 12, j + 79, k + 12, SpaceAgeCore.edenSurface.blockID, 0, 2);
		world.setBlock(i + 12, j + 79, k + 13, SpaceAgeCore.edenSurface.blockID, 0, 2);
		world.setBlock(i + 12, j + 79, k + 14, SpaceAgeCore.edenSurface.blockID, 0, 2);
		world.setBlock(i + 12, j + 79, k + 15, SpaceAgeCore.edenSurface.blockID, 0, 2);
		world.setBlock(i + 12, j + 79, k + 16, SpaceAgeCore.edenSurface.blockID, 0, 2);
		world.setBlock(i + 12, j + 79, k + 17, SpaceAgeCore.edenSurface.blockID, 0, 2);
		world.setBlock(i + 12, j + 79, k + 18, SpaceAgeCore.edenSurface.blockID, 0, 2);
		world.setBlock(i + 12, j + 79, k + 19, SpaceAgeCore.edenSurface.blockID, 0, 2);
		world.setBlock(i + 12, j + 79, k + 20, SpaceAgeCore.edenSurface.blockID, 0, 2);
		world.setBlock(i + 12, j + 79, k + 21, SpaceAgeCore.edenSurface.blockID, 0, 2);
		world.setBlock(i + 12, j + 79, k + 22, SpaceAgeCore.edenSurface.blockID, 0, 2);
		world.setBlock(i + 12, j + 79, k + 23, SpaceAgeCore.edenSurface.blockID, 0, 2);
		world.setBlock(i + 12, j + 79, k + 24, SpaceAgeCore.edenSurface.blockID, 0, 2);
		world.setBlock(i + 12, j + 79, k + 25, SpaceAgeCore.edenSurface.blockID, 0, 2);
		world.setBlock(i + 12, j + 79, k + 26, SpaceAgeCore.edenSurface.blockID, 0, 2);
		world.setBlock(i + 13, j + 71, k + 1, SpaceAgeCore.edenSurface.blockID, 0, 2);
		world.setBlock(i + 13, j + 71, k + 2, SpaceAgeCore.edenSurface.blockID, 0, 2);
		world.setBlock(i + 13, j + 71, k + 3, SpaceAgeCore.edenSurface.blockID, 0, 2);
		world.setBlock(i + 13, j + 71, k + 4, SpaceAgeCore.edenSurface.blockID, 0, 2);
		world.setBlock(i + 13, j + 71, k + 5, SpaceAgeCore.edenSurface.blockID, 0, 2);
		world.setBlock(i + 13, j + 71, k + 6, SpaceAgeCore.edenSurface.blockID, 0, 2);
		world.setBlock(i + 13, j + 71, k + 7, SpaceAgeCore.edenSurface.blockID, 0, 2);
		world.setBlock(i + 13, j + 71, k + 8, SpaceAgeCore.edenSurface.blockID, 0, 2);
		world.setBlock(i + 13, j + 71, k + 9, SpaceAgeCore.edenSurface.blockID, 0, 2);
		world.setBlock(i + 13, j + 71, k + 10, SpaceAgeCore.edenSurface.blockID, 0, 2);
		world.setBlock(i + 13, j + 71, k + 11, SpaceAgeCore.edenSurface.blockID, 0, 2);
		world.setBlock(i + 13, j + 71, k + 12, SpaceAgeCore.edenSurface.blockID, 0, 2);
		world.setBlock(i + 13, j + 71, k + 13, SpaceAgeCore.edenSurface.blockID, 0, 2);
		world.setBlock(i + 13, j + 71, k + 14, SpaceAgeCore.edenSurface.blockID, 0, 2);
		world.setBlock(i + 13, j + 71, k + 15, SpaceAgeCore.edenSurface.blockID, 0, 2);
		world.setBlock(i + 13, j + 71, k + 16, SpaceAgeCore.edenSurface.blockID, 0, 2);
		world.setBlock(i + 13, j + 71, k + 17, SpaceAgeCore.edenSurface.blockID, 0, 2);
		world.setBlock(i + 13, j + 71, k + 18, SpaceAgeCore.edenSurface.blockID, 0, 2);
		world.setBlock(i + 13, j + 71, k + 19, SpaceAgeCore.edenSurface.blockID, 0, 2);
		world.setBlock(i + 13, j + 71, k + 20, SpaceAgeCore.edenSurface.blockID, 0, 2);
		world.setBlock(i + 13, j + 71, k + 21, SpaceAgeCore.edenSurface.blockID, 0, 2);
		world.setBlock(i + 13, j + 71, k + 22, SpaceAgeCore.edenSurface.blockID, 0, 2);
		world.setBlock(i + 13, j + 71, k + 23, SpaceAgeCore.edenSurface.blockID, 0, 2);
		world.setBlock(i + 13, j + 71, k + 24, SpaceAgeCore.edenSurface.blockID, 0, 2);
		world.setBlock(i + 13, j + 71, k + 25, SpaceAgeCore.edenSurface.blockID, 0, 2);
		world.setBlock(i + 13, j + 71, k + 26, SpaceAgeCore.edenSurface.blockID, 0, 2);
		world.setBlock(i + 13, j + 71, k + 27, SpaceAgeCore.edenSurface.blockID, 0, 2);
		world.setBlock(i + 13, j + 71, k + 28, SpaceAgeCore.edenSurface.blockID, 0, 2);
		world.setBlock(i + 13, j + 71, k + 29, SpaceAgeCore.edenSurface.blockID, 0, 2);
		world.setBlock(i + 13, j + 71, k + 30, SpaceAgeCore.edenSurface.blockID, 0, 2);
		world.setBlock(i + 13, j + 71, k + 31, SpaceAgeCore.edenSurface.blockID, 0, 2);
		world.setBlock(i + 13, j + 71, k + 32, SpaceAgeCore.edenSurface.blockID, 0, 2);
		world.setBlock(i + 13, j + 71, k + 33, SpaceAgeCore.edenSurface.blockID, 0, 2);
		world.setBlock(i + 13, j + 71, k + 34, SpaceAgeCore.edenSurface.blockID, 0, 2);
		world.setBlock(i + 13, j + 71, k + 35, SpaceAgeCore.edenSurface.blockID, 0, 2);
		world.setBlock(i + 13, j + 72, k + 2, SpaceAgeCore.edenSurface.blockID, 0, 2);
		world.setBlock(i + 13, j + 72, k + 34, SpaceAgeCore.edenSurface.blockID, 0, 2);
		world.setBlock(i + 13, j + 73, k + 3, SpaceAgeCore.edenSurface.blockID, 0, 2);
		world.setBlock(i + 13, j + 73, k + 33, SpaceAgeCore.edenSurface.blockID, 0, 2);
		world.setBlock(i + 13, j + 74, k + 4, SpaceAgeCore.edenSurface.blockID, 0, 2);
		world.setBlock(i + 13, j + 74, k + 32, SpaceAgeCore.edenSurface.blockID, 0, 2);
		world.setBlock(i + 13, j + 75, k + 5, SpaceAgeCore.edenSurface.blockID, 0, 2);
		world.setBlock(i + 13, j + 75, k + 31, SpaceAgeCore.edenSurface.blockID, 0, 2);
		world.setBlock(i + 13, j + 76, k + 6, SpaceAgeCore.edenSurface.blockID, 0, 2);
		world.setBlock(i + 13, j + 76, k + 30, SpaceAgeCore.edenSurface.blockID, 0, 2);
		world.setBlock(i + 13, j + 77, k + 7, SpaceAgeCore.edenSurface.blockID, 0, 2);
		world.setBlock(i + 13, j + 77, k + 29, SpaceAgeCore.edenSurface.blockID, 0, 2);
		world.setBlock(i + 13, j + 78, k + 8, SpaceAgeCore.edenSurface.blockID, 0, 2);
		world.setBlock(i + 13, j + 78, k + 28, SpaceAgeCore.edenSurface.blockID, 0, 2);
		world.setBlock(i + 13, j + 79, k + 9, SpaceAgeCore.edenSurface.blockID, 0, 2);
		world.setBlock(i + 13, j + 79, k + 10, SpaceAgeCore.edenSurface.blockID, 0, 2);
		world.setBlock(i + 13, j + 79, k + 11, SpaceAgeCore.edenSurface.blockID, 0, 2);
		world.setBlock(i + 13, j + 79, k + 12, SpaceAgeCore.edenSurface.blockID, 0, 2);
		world.setBlock(i + 13, j + 79, k + 13, SpaceAgeCore.edenSurface.blockID, 0, 2);
		world.setBlock(i + 13, j + 79, k + 14, SpaceAgeCore.edenSurface.blockID, 0, 2);
		world.setBlock(i + 13, j + 79, k + 15, SpaceAgeCore.edenSurface.blockID, 0, 2);
		world.setBlock(i + 13, j + 79, k + 16, SpaceAgeCore.edenSurface.blockID, 0, 2);
		world.setBlock(i + 13, j + 79, k + 17, SpaceAgeCore.edenSurface.blockID, 0, 2);
		world.setBlock(i + 13, j + 79, k + 18, SpaceAgeCore.edenSurface.blockID, 0, 2);
		world.setBlock(i + 13, j + 79, k + 19, SpaceAgeCore.edenSurface.blockID, 0, 2);
		world.setBlock(i + 13, j + 79, k + 20, SpaceAgeCore.edenSurface.blockID, 0, 2);
		world.setBlock(i + 13, j + 79, k + 21, SpaceAgeCore.edenSurface.blockID, 0, 2);
		world.setBlock(i + 13, j + 79, k + 22, SpaceAgeCore.edenSurface.blockID, 0, 2);
		world.setBlock(i + 13, j + 79, k + 23, SpaceAgeCore.edenSurface.blockID, 0, 2);
		world.setBlock(i + 13, j + 79, k + 24, SpaceAgeCore.edenSurface.blockID, 0, 2);
		world.setBlock(i + 13, j + 79, k + 25, SpaceAgeCore.edenSurface.blockID, 0, 2);
		world.setBlock(i + 13, j + 79, k + 26, SpaceAgeCore.edenSurface.blockID, 0, 2);
		world.setBlock(i + 13, j + 79, k + 27, SpaceAgeCore.edenSurface.blockID, 0, 2);
		world.setBlock(i + 14, j + 71, k + 0, SpaceAgeCore.edenSurface.blockID, 0, 2);
		world.setBlock(i + 14, j + 71, k + 1, SpaceAgeCore.edenSurface.blockID, 0, 2);
		world.setBlock(i + 14, j + 71, k + 2, SpaceAgeCore.edenSurface.blockID, 0, 2);
		world.setBlock(i + 14, j + 71, k + 3, SpaceAgeCore.edenSurface.blockID, 0, 2);
		world.setBlock(i + 14, j + 71, k + 4, SpaceAgeCore.edenSurface.blockID, 0, 2);
		world.setBlock(i + 14, j + 71, k + 5, SpaceAgeCore.edenSurface.blockID, 0, 2);
		world.setBlock(i + 14, j + 71, k + 6, SpaceAgeCore.edenSurface.blockID, 0, 2);
		world.setBlock(i + 14, j + 71, k + 7, SpaceAgeCore.edenSurface.blockID, 0, 2);
		world.setBlock(i + 14, j + 71, k + 8, SpaceAgeCore.edenSurface.blockID, 0, 2);
		world.setBlock(i + 14, j + 71, k + 9, SpaceAgeCore.edenSurface.blockID, 0, 2);
		world.setBlock(i + 14, j + 71, k + 10, SpaceAgeCore.edenSurface.blockID, 0, 2);
		world.setBlock(i + 14, j + 71, k + 11, SpaceAgeCore.edenSurface.blockID, 0, 2);
		world.setBlock(i + 14, j + 71, k + 12, SpaceAgeCore.edenSurface.blockID, 0, 2);
		world.setBlock(i + 14, j + 71, k + 13, SpaceAgeCore.edenSurface.blockID, 0, 2);
		world.setBlock(i + 14, j + 71, k + 14, SpaceAgeCore.edenSurface.blockID, 0, 2);
		world.setBlock(i + 14, j + 71, k + 15, SpaceAgeCore.edenSurface.blockID, 0, 2);
		world.setBlock(i + 14, j + 71, k + 16, SpaceAgeCore.edenSurface.blockID, 0, 2);
		world.setBlock(i + 14, j + 71, k + 17, SpaceAgeCore.edenSurface.blockID, 0, 2);
		world.setBlock(i + 14, j + 71, k + 18, SpaceAgeCore.edenSurface.blockID, 0, 2);
		world.setBlock(i + 14, j + 71, k + 19, SpaceAgeCore.edenSurface.blockID, 0, 2);
		world.setBlock(i + 14, j + 71, k + 20, SpaceAgeCore.edenSurface.blockID, 0, 2);
		world.setBlock(i + 14, j + 71, k + 21, SpaceAgeCore.edenSurface.blockID, 0, 2);
		world.setBlock(i + 14, j + 71, k + 22, SpaceAgeCore.edenSurface.blockID, 0, 2);
		world.setBlock(i + 14, j + 71, k + 23, SpaceAgeCore.edenSurface.blockID, 0, 2);
		world.setBlock(i + 14, j + 71, k + 24, SpaceAgeCore.edenSurface.blockID, 0, 2);
		world.setBlock(i + 14, j + 71, k + 25, SpaceAgeCore.edenSurface.blockID, 0, 2);
		world.setBlock(i + 14, j + 71, k + 26, SpaceAgeCore.edenSurface.blockID, 0, 2);
		world.setBlock(i + 14, j + 71, k + 27, SpaceAgeCore.edenSurface.blockID, 0, 2);
		world.setBlock(i + 14, j + 71, k + 28, SpaceAgeCore.edenSurface.blockID, 0, 2);
		world.setBlock(i + 14, j + 71, k + 29, SpaceAgeCore.edenSurface.blockID, 0, 2);
		world.setBlock(i + 14, j + 71, k + 30, SpaceAgeCore.edenSurface.blockID, 0, 2);
		world.setBlock(i + 14, j + 71, k + 31, SpaceAgeCore.edenSurface.blockID, 0, 2);
		world.setBlock(i + 14, j + 71, k + 32, SpaceAgeCore.edenSurface.blockID, 0, 2);
		world.setBlock(i + 14, j + 71, k + 33, SpaceAgeCore.edenSurface.blockID, 0, 2);
		world.setBlock(i + 14, j + 71, k + 34, SpaceAgeCore.edenSurface.blockID, 0, 2);
		world.setBlock(i + 14, j + 71, k + 35, SpaceAgeCore.edenSurface.blockID, 0, 2);
		world.setBlock(i + 14, j + 71, k + 36, SpaceAgeCore.edenSurface.blockID, 0, 2);
		world.setBlock(i + 14, j + 72, k + 1, SpaceAgeCore.edenSurface.blockID, 0, 2);
		world.setBlock(i + 14, j + 72, k + 35, SpaceAgeCore.edenSurface.blockID, 0, 2);
		world.setBlock(i + 14, j + 73, k + 2, SpaceAgeCore.edenSurface.blockID, 0, 2);
		world.setBlock(i + 14, j + 73, k + 3, SpaceAgeCore.edenSurface.blockID, 0, 2);
		world.setBlock(i + 14, j + 73, k + 33, SpaceAgeCore.edenSurface.blockID, 0, 2);
		world.setBlock(i + 14, j + 73, k + 34, SpaceAgeCore.edenSurface.blockID, 0, 2);
		world.setBlock(i + 14, j + 74, k + 4, SpaceAgeCore.edenSurface.blockID, 0, 2);
		world.setBlock(i + 14, j + 74, k + 32, SpaceAgeCore.edenSurface.blockID, 0, 2);
		world.setBlock(i + 14, j + 75, k + 5, SpaceAgeCore.edenSurface.blockID, 0, 2);
		world.setBlock(i + 14, j + 75, k + 31, SpaceAgeCore.edenSurface.blockID, 0, 2);
		world.setBlock(i + 14, j + 76, k + 6, SpaceAgeCore.edenSurface.blockID, 0, 2);
		world.setBlock(i + 14, j + 76, k + 30, SpaceAgeCore.edenSurface.blockID, 0, 2);
		world.setBlock(i + 14, j + 77, k + 7, SpaceAgeCore.edenSurface.blockID, 0, 2);
		world.setBlock(i + 14, j + 77, k + 29, SpaceAgeCore.edenSurface.blockID, 0, 2);
		world.setBlock(i + 14, j + 78, k + 8, SpaceAgeCore.edenSurface.blockID, 0, 2);
		world.setBlock(i + 14, j + 78, k + 28, SpaceAgeCore.edenSurface.blockID, 0, 2);
		world.setBlock(i + 14, j + 79, k + 9, SpaceAgeCore.edenSurface.blockID, 0, 2);
		world.setBlock(i + 14, j + 79, k + 10, SpaceAgeCore.edenSurface.blockID, 0, 2);
		world.setBlock(i + 14, j + 79, k + 11, SpaceAgeCore.edenSurface.blockID, 0, 2);
		world.setBlock(i + 14, j + 79, k + 12, SpaceAgeCore.edenSurface.blockID, 0, 2);
		world.setBlock(i + 14, j + 79, k + 13, SpaceAgeCore.edenSurface.blockID, 0, 2);
		world.setBlock(i + 14, j + 79, k + 14, SpaceAgeCore.edenSurface.blockID, 0, 2);
		world.setBlock(i + 14, j + 79, k + 15, SpaceAgeCore.edenSurface.blockID, 0, 2);
		world.setBlock(i + 14, j + 79, k + 16, SpaceAgeCore.edenSurface.blockID, 0, 2);
		world.setBlock(i + 14, j + 79, k + 17, SpaceAgeCore.edenSurface.blockID, 0, 2);
		world.setBlock(i + 14, j + 79, k + 18, SpaceAgeCore.edenSurface.blockID, 0, 2);
		world.setBlock(i + 14, j + 79, k + 19, SpaceAgeCore.edenSurface.blockID, 0, 2);
		world.setBlock(i + 14, j + 79, k + 20, SpaceAgeCore.edenSurface.blockID, 0, 2);
		world.setBlock(i + 14, j + 79, k + 21, SpaceAgeCore.edenSurface.blockID, 0, 2);
		world.setBlock(i + 14, j + 79, k + 22, SpaceAgeCore.edenSurface.blockID, 0, 2);
		world.setBlock(i + 14, j + 79, k + 23, SpaceAgeCore.edenSurface.blockID, 0, 2);
		world.setBlock(i + 14, j + 79, k + 24, SpaceAgeCore.edenSurface.blockID, 0, 2);
		world.setBlock(i + 14, j + 79, k + 25, SpaceAgeCore.edenSurface.blockID, 0, 2);
		world.setBlock(i + 14, j + 79, k + 26, SpaceAgeCore.edenSurface.blockID, 0, 2);
		world.setBlock(i + 14, j + 79, k + 27, SpaceAgeCore.edenSurface.blockID, 0, 2);
		world.setBlock(i + 15, j + 71, k + 0, SpaceAgeCore.edenSurface.blockID, 0, 2);
		world.setBlock(i + 15, j + 71, k + 1, SpaceAgeCore.edenSurface.blockID, 0, 2);
		world.setBlock(i + 15, j + 71, k + 2, SpaceAgeCore.edenSurface.blockID, 0, 2);
		world.setBlock(i + 15, j + 71, k + 3, SpaceAgeCore.edenSurface.blockID, 0, 2);
		world.setBlock(i + 15, j + 71, k + 4, SpaceAgeCore.edenSurface.blockID, 0, 2);
		world.setBlock(i + 15, j + 71, k + 5, SpaceAgeCore.edenSurface.blockID, 0, 2);
		world.setBlock(i + 15, j + 71, k + 6, SpaceAgeCore.edenSurface.blockID, 0, 2);
		world.setBlock(i + 15, j + 71, k + 7, SpaceAgeCore.edenSurface.blockID, 0, 2);
		world.setBlock(i + 15, j + 71, k + 8, SpaceAgeCore.edenSurface.blockID, 0, 2);
		world.setBlock(i + 15, j + 71, k + 9, SpaceAgeCore.edenSurface.blockID, 0, 2);
		world.setBlock(i + 15, j + 71, k + 10, SpaceAgeCore.edenSurface.blockID, 0, 2);
		world.setBlock(i + 15, j + 71, k + 11, SpaceAgeCore.edenSurface.blockID, 0, 2);
		world.setBlock(i + 15, j + 71, k + 12, SpaceAgeCore.edenSurface.blockID, 0, 2);
		world.setBlock(i + 15, j + 71, k + 13, SpaceAgeCore.edenSurface.blockID, 0, 2);
		world.setBlock(i + 15, j + 71, k + 14, SpaceAgeCore.edenSurface.blockID, 0, 2);
		world.setBlock(i + 15, j + 71, k + 15, SpaceAgeCore.edenSurface.blockID, 0, 2);
		world.setBlock(i + 15, j + 71, k + 16, SpaceAgeCore.edenSurface.blockID, 0, 2);
		world.setBlock(i + 15, j + 71, k + 17, SpaceAgeCore.edenSurface.blockID, 0, 2);
		world.setBlock(i + 15, j + 71, k + 18, SpaceAgeCore.edenSurface.blockID, 0, 2);
		world.setBlock(i + 15, j + 71, k + 19, SpaceAgeCore.edenSurface.blockID, 0, 2);
		world.setBlock(i + 15, j + 71, k + 20, SpaceAgeCore.edenSurface.blockID, 0, 2);
		world.setBlock(i + 15, j + 71, k + 21, SpaceAgeCore.edenSurface.blockID, 0, 2);
		world.setBlock(i + 15, j + 71, k + 22, SpaceAgeCore.edenSurface.blockID, 0, 2);
		world.setBlock(i + 15, j + 71, k + 23, SpaceAgeCore.edenSurface.blockID, 0, 2);
		world.setBlock(i + 15, j + 71, k + 24, SpaceAgeCore.edenSurface.blockID, 0, 2);
		world.setBlock(i + 15, j + 71, k + 25, SpaceAgeCore.edenSurface.blockID, 0, 2);
		world.setBlock(i + 15, j + 71, k + 26, SpaceAgeCore.edenSurface.blockID, 0, 2);
		world.setBlock(i + 15, j + 71, k + 27, SpaceAgeCore.edenSurface.blockID, 0, 2);
		world.setBlock(i + 15, j + 71, k + 28, SpaceAgeCore.edenSurface.blockID, 0, 2);
		world.setBlock(i + 15, j + 71, k + 29, SpaceAgeCore.edenSurface.blockID, 0, 2);
		world.setBlock(i + 15, j + 71, k + 30, SpaceAgeCore.edenSurface.blockID, 0, 2);
		world.setBlock(i + 15, j + 71, k + 31, SpaceAgeCore.edenSurface.blockID, 0, 2);
		world.setBlock(i + 15, j + 71, k + 32, SpaceAgeCore.edenSurface.blockID, 0, 2);
		world.setBlock(i + 15, j + 71, k + 33, SpaceAgeCore.edenSurface.blockID, 0, 2);
		world.setBlock(i + 15, j + 71, k + 34, SpaceAgeCore.edenSurface.blockID, 0, 2);
		world.setBlock(i + 15, j + 71, k + 35, SpaceAgeCore.edenSurface.blockID, 0, 2);
		world.setBlock(i + 15, j + 71, k + 36, SpaceAgeCore.edenSurface.blockID, 0, 2);
		world.setBlock(i + 15, j + 72, k + 1, SpaceAgeCore.edenSurface.blockID, 0, 2);
		world.setBlock(i + 15, j + 72, k + 35, SpaceAgeCore.edenSurface.blockID, 0, 2);
		world.setBlock(i + 15, j + 73, k + 2, SpaceAgeCore.edenSurface.blockID, 0, 2);
		world.setBlock(i + 15, j + 73, k + 34, SpaceAgeCore.edenSurface.blockID, 0, 2);
		world.setBlock(i + 15, j + 74, k + 3, SpaceAgeCore.edenSurface.blockID, 0, 2);
		world.setBlock(i + 15, j + 74, k + 33, SpaceAgeCore.edenSurface.blockID, 0, 2);
		world.setBlock(i + 15, j + 75, k + 4, SpaceAgeCore.edenSurface.blockID, 0, 2);
		world.setBlock(i + 15, j + 75, k + 32, SpaceAgeCore.edenSurface.blockID, 0, 2);
		world.setBlock(i + 15, j + 76, k + 5, SpaceAgeCore.edenSurface.blockID, 0, 2);
		world.setBlock(i + 15, j + 76, k + 31, SpaceAgeCore.edenSurface.blockID, 0, 2);
		world.setBlock(i + 15, j + 77, k + 6, SpaceAgeCore.edenSurface.blockID, 0, 2);
		world.setBlock(i + 15, j + 77, k + 30, SpaceAgeCore.edenSurface.blockID, 0, 2);
		world.setBlock(i + 15, j + 78, k + 7, SpaceAgeCore.edenSurface.blockID, 0, 2);
		world.setBlock(i + 15, j + 78, k + 29, SpaceAgeCore.edenSurface.blockID, 0, 2);
		world.setBlock(i + 15, j + 79, k + 8, SpaceAgeCore.edenSurface.blockID, 0, 2);
		world.setBlock(i + 15, j + 79, k + 9, SpaceAgeCore.edenSurface.blockID, 0, 2);
		world.setBlock(i + 15, j + 79, k + 10, SpaceAgeCore.edenSurface.blockID, 0, 2);
		world.setBlock(i + 15, j + 79, k + 11, SpaceAgeCore.edenSurface.blockID, 0, 2);
		world.setBlock(i + 15, j + 79, k + 12, SpaceAgeCore.edenSurface.blockID, 0, 2);
		world.setBlock(i + 15, j + 79, k + 13, SpaceAgeCore.edenSurface.blockID, 0, 2);
		world.setBlock(i + 15, j + 79, k + 14, SpaceAgeCore.edenSurface.blockID, 0, 2);
		world.setBlock(i + 15, j + 79, k + 15, SpaceAgeCore.edenSurface.blockID, 0, 2);
		world.setBlock(i + 15, j + 79, k + 16, SpaceAgeCore.edenSurface.blockID, 0, 2);
		world.setBlock(i + 15, j + 79, k + 17, SpaceAgeCore.edenSurface.blockID, 0, 2);
		world.setBlock(i + 15, j + 79, k + 18, SpaceAgeCore.edenSurface.blockID, 0, 2);
		world.setBlock(i + 15, j + 79, k + 19, SpaceAgeCore.edenSurface.blockID, 0, 2);
		world.setBlock(i + 15, j + 79, k + 20, SpaceAgeCore.edenSurface.blockID, 0, 2);
		world.setBlock(i + 15, j + 79, k + 21, SpaceAgeCore.edenSurface.blockID, 0, 2);
		world.setBlock(i + 15, j + 79, k + 22, SpaceAgeCore.edenSurface.blockID, 0, 2);
		world.setBlock(i + 15, j + 79, k + 23, SpaceAgeCore.edenSurface.blockID, 0, 2);
		world.setBlock(i + 15, j + 79, k + 24, SpaceAgeCore.edenSurface.blockID, 0, 2);
		world.setBlock(i + 15, j + 79, k + 25, SpaceAgeCore.edenSurface.blockID, 0, 2);
		world.setBlock(i + 15, j + 79, k + 26, SpaceAgeCore.edenSurface.blockID, 0, 2);
		world.setBlock(i + 15, j + 79, k + 27, SpaceAgeCore.edenSurface.blockID, 0, 2);
		world.setBlock(i + 15, j + 79, k + 28, SpaceAgeCore.edenSurface.blockID, 0, 2);
		world.setBlock(i + 16, j + 71, k + 0, SpaceAgeCore.edenSurface.blockID, 0, 2);
		world.setBlock(i + 16, j + 71, k + 1, SpaceAgeCore.edenSurface.blockID, 0, 2);
		world.setBlock(i + 16, j + 71, k + 2, SpaceAgeCore.edenSurface.blockID, 0, 2);
		world.setBlock(i + 16, j + 71, k + 3, SpaceAgeCore.edenSurface.blockID, 0, 2);
		world.setBlock(i + 16, j + 71, k + 4, SpaceAgeCore.edenSurface.blockID, 0, 2);
		world.setBlock(i + 16, j + 71, k + 5, SpaceAgeCore.edenSurface.blockID, 0, 2);
		world.setBlock(i + 16, j + 71, k + 6, SpaceAgeCore.edenSurface.blockID, 0, 2);
		world.setBlock(i + 16, j + 71, k + 7, SpaceAgeCore.edenSurface.blockID, 0, 2);
		world.setBlock(i + 16, j + 71, k + 8, SpaceAgeCore.edenSurface.blockID, 0, 2);
		world.setBlock(i + 16, j + 71, k + 9, SpaceAgeCore.edenSurface.blockID, 0, 2);
		world.setBlock(i + 16, j + 71, k + 10, SpaceAgeCore.edenSurface.blockID, 0, 2);
		world.setBlock(i + 16, j + 71, k + 11, SpaceAgeCore.edenSurface.blockID, 0, 2);
		world.setBlock(i + 16, j + 71, k + 12, SpaceAgeCore.edenSurface.blockID, 0, 2);
		world.setBlock(i + 16, j + 71, k + 13, SpaceAgeCore.edenSurface.blockID, 0, 2);
		world.setBlock(i + 16, j + 71, k + 14, SpaceAgeCore.edenSurface.blockID, 0, 2);
		world.setBlock(i + 16, j + 71, k + 15, SpaceAgeCore.edenSurface.blockID, 0, 2);
		world.setBlock(i + 16, j + 71, k + 16, SpaceAgeCore.edenSurface.blockID, 0, 2);
		world.setBlock(i + 16, j + 71, k + 17, SpaceAgeCore.edenSurface.blockID, 0, 2);
		world.setBlock(i + 16, j + 71, k + 18, SpaceAgeCore.edenSurface.blockID, 0, 2);
		world.setBlock(i + 16, j + 71, k + 19, SpaceAgeCore.edenSurface.blockID, 0, 2);
		world.setBlock(i + 16, j + 71, k + 20, SpaceAgeCore.edenSurface.blockID, 0, 2);
		world.setBlock(i + 16, j + 71, k + 21, SpaceAgeCore.edenSurface.blockID, 0, 2);
		world.setBlock(i + 16, j + 71, k + 22, SpaceAgeCore.edenSurface.blockID, 0, 2);
		world.setBlock(i + 16, j + 71, k + 23, SpaceAgeCore.edenSurface.blockID, 0, 2);
		world.setBlock(i + 16, j + 71, k + 24, SpaceAgeCore.edenSurface.blockID, 0, 2);
		world.setBlock(i + 16, j + 71, k + 25, SpaceAgeCore.edenSurface.blockID, 0, 2);
		world.setBlock(i + 16, j + 71, k + 26, SpaceAgeCore.edenSurface.blockID, 0, 2);
		world.setBlock(i + 16, j + 71, k + 27, SpaceAgeCore.edenSurface.blockID, 0, 2);
		world.setBlock(i + 16, j + 71, k + 28, SpaceAgeCore.edenSurface.blockID, 0, 2);
		world.setBlock(i + 16, j + 71, k + 29, SpaceAgeCore.edenSurface.blockID, 0, 2);
		world.setBlock(i + 16, j + 71, k + 30, SpaceAgeCore.edenSurface.blockID, 0, 2);
		world.setBlock(i + 16, j + 71, k + 31, SpaceAgeCore.edenSurface.blockID, 0, 2);
		world.setBlock(i + 16, j + 71, k + 32, SpaceAgeCore.edenSurface.blockID, 0, 2);
		world.setBlock(i + 16, j + 71, k + 33, SpaceAgeCore.edenSurface.blockID, 0, 2);
		world.setBlock(i + 16, j + 71, k + 34, SpaceAgeCore.edenSurface.blockID, 0, 2);
		world.setBlock(i + 16, j + 71, k + 35, SpaceAgeCore.edenSurface.blockID, 0, 2);
		world.setBlock(i + 16, j + 71, k + 36, SpaceAgeCore.edenSurface.blockID, 0, 2);
		world.setBlock(i + 16, j + 72, k + 1, SpaceAgeCore.edenSurface.blockID, 0, 2);
		world.setBlock(i + 16, j + 72, k + 35, SpaceAgeCore.edenSurface.blockID, 0, 2);
		world.setBlock(i + 16, j + 73, k + 2, SpaceAgeCore.edenSurface.blockID, 0, 2);
		world.setBlock(i + 16, j + 73, k + 34, SpaceAgeCore.edenSurface.blockID, 0, 2);
		world.setBlock(i + 16, j + 74, k + 3, SpaceAgeCore.edenSurface.blockID, 0, 2);
		world.setBlock(i + 16, j + 74, k + 33, SpaceAgeCore.edenSurface.blockID, 0, 2);
		world.setBlock(i + 16, j + 75, k + 4, SpaceAgeCore.edenSurface.blockID, 0, 2);
		world.setBlock(i + 16, j + 75, k + 32, SpaceAgeCore.edenSurface.blockID, 0, 2);
		world.setBlock(i + 16, j + 76, k + 5, SpaceAgeCore.edenSurface.blockID, 0, 2);
		world.setBlock(i + 16, j + 76, k + 31, SpaceAgeCore.edenSurface.blockID, 0, 2);
		world.setBlock(i + 16, j + 77, k + 6, SpaceAgeCore.edenSurface.blockID, 0, 2);
		world.setBlock(i + 16, j + 77, k + 30, SpaceAgeCore.edenSurface.blockID, 0, 2);
		world.setBlock(i + 16, j + 78, k + 7, SpaceAgeCore.edenSurface.blockID, 0, 2);
		world.setBlock(i + 16, j + 78, k + 29, SpaceAgeCore.edenSurface.blockID, 0, 2);
		world.setBlock(i + 16, j + 79, k + 8, SpaceAgeCore.edenSurface.blockID, 0, 2);
		world.setBlock(i + 16, j + 79, k + 9, SpaceAgeCore.edenSurface.blockID, 0, 2);
		world.setBlock(i + 16, j + 79, k + 10, SpaceAgeCore.edenSurface.blockID, 0, 2);
		world.setBlock(i + 16, j + 79, k + 11, SpaceAgeCore.edenSurface.blockID, 0, 2);
		world.setBlock(i + 16, j + 79, k + 12, SpaceAgeCore.edenSurface.blockID, 0, 2);
		world.setBlock(i + 16, j + 79, k + 13, SpaceAgeCore.edenSurface.blockID, 0, 2);
		world.setBlock(i + 16, j + 79, k + 14, SpaceAgeCore.edenSurface.blockID, 0, 2);
		world.setBlock(i + 16, j + 79, k + 15, SpaceAgeCore.edenSurface.blockID, 0, 2);
		world.setBlock(i + 16, j + 79, k + 16, SpaceAgeCore.edenSurface.blockID, 0, 2);
		world.setBlock(i + 16, j + 79, k + 17, SpaceAgeCore.edenSurface.blockID, 0, 2);
		world.setBlock(i + 16, j + 79, k + 18, SpaceAgeCore.edenSurface.blockID, 0, 2);
		world.setBlock(i + 16, j + 79, k + 19, SpaceAgeCore.edenSurface.blockID, 0, 2);
		world.setBlock(i + 16, j + 79, k + 20, SpaceAgeCore.edenSurface.blockID, 0, 2);
		world.setBlock(i + 16, j + 79, k + 21, SpaceAgeCore.edenSurface.blockID, 0, 2);
		world.setBlock(i + 16, j + 79, k + 22, SpaceAgeCore.edenSurface.blockID, 0, 2);
		world.setBlock(i + 16, j + 79, k + 23, SpaceAgeCore.edenSurface.blockID, 0, 2);
		world.setBlock(i + 16, j + 79, k + 24, SpaceAgeCore.edenSurface.blockID, 0, 2);
		world.setBlock(i + 16, j + 79, k + 25, SpaceAgeCore.edenSurface.blockID, 0, 2);
		world.setBlock(i + 16, j + 79, k + 26, SpaceAgeCore.edenSurface.blockID, 0, 2);
		world.setBlock(i + 16, j + 79, k + 27, SpaceAgeCore.edenSurface.blockID, 0, 2);
		world.setBlock(i + 16, j + 79, k + 28, SpaceAgeCore.edenSurface.blockID, 0, 2);
		world.setBlock(i + 17, j + 0, k + 17, SpaceAgeCore.edenSurface.blockID, 1, 2);
		world.setBlock(i + 17, j + 0, k + 18, SpaceAgeCore.edenSurface.blockID, 1, 2);
		world.setBlock(i + 17, j + 0, k + 19, SpaceAgeCore.edenSurface.blockID, 1, 2);
		world.setBlock(i + 17, j + 1, k + 17, SpaceAgeCore.edenSurface.blockID, 1, 2);
		world.setBlock(i + 17, j + 1, k + 18, SpaceAgeCore.edenSurface.blockID, 1, 2);
		world.setBlock(i + 17, j + 1, k + 19, SpaceAgeCore.edenSurface.blockID, 1, 2);
		world.setBlock(i + 17, j + 2, k + 17, SpaceAgeCore.edenSurface.blockID, 1, 2);
		world.setBlock(i + 17, j + 2, k + 18, SpaceAgeCore.edenSurface.blockID, 1, 2);
		world.setBlock(i + 17, j + 2, k + 19, SpaceAgeCore.edenSurface.blockID, 1, 2);
		world.setBlock(i + 17, j + 3, k + 17, SpaceAgeCore.edenSurface.blockID, 1, 2);
		world.setBlock(i + 17, j + 3, k + 18, SpaceAgeCore.edenSurface.blockID, 1, 2);
		world.setBlock(i + 17, j + 3, k + 19, SpaceAgeCore.edenSurface.blockID, 1, 2);
		world.setBlock(i + 17, j + 4, k + 17, SpaceAgeCore.edenSurface.blockID, 1, 2);
		world.setBlock(i + 17, j + 4, k + 18, SpaceAgeCore.edenSurface.blockID, 1, 2);
		world.setBlock(i + 17, j + 4, k + 19, SpaceAgeCore.edenSurface.blockID, 1, 2);
		world.setBlock(i + 17, j + 5, k + 17, SpaceAgeCore.edenSurface.blockID, 1, 2);
		world.setBlock(i + 17, j + 5, k + 18, SpaceAgeCore.edenSurface.blockID, 1, 2);
		world.setBlock(i + 17, j + 5, k + 19, SpaceAgeCore.edenSurface.blockID, 1, 2);
		world.setBlock(i + 17, j + 6, k + 17, SpaceAgeCore.edenSurface.blockID, 1, 2);
		world.setBlock(i + 17, j + 6, k + 18, SpaceAgeCore.edenSurface.blockID, 1, 2);
		world.setBlock(i + 17, j + 6, k + 19, SpaceAgeCore.edenSurface.blockID, 1, 2);
		world.setBlock(i + 17, j + 7, k + 17, SpaceAgeCore.edenSurface.blockID, 1, 2);
		world.setBlock(i + 17, j + 7, k + 18, SpaceAgeCore.edenSurface.blockID, 1, 2);
		world.setBlock(i + 17, j + 7, k + 19, SpaceAgeCore.edenSurface.blockID, 1, 2);
		world.setBlock(i + 17, j + 8, k + 17, SpaceAgeCore.edenSurface.blockID, 1, 2);
		world.setBlock(i + 17, j + 8, k + 18, SpaceAgeCore.edenSurface.blockID, 1, 2);
		world.setBlock(i + 17, j + 8, k + 19, SpaceAgeCore.edenSurface.blockID, 1, 2);
		world.setBlock(i + 17, j + 9, k + 17, SpaceAgeCore.edenSurface.blockID, 1, 2);
		world.setBlock(i + 17, j + 9, k + 18, SpaceAgeCore.edenSurface.blockID, 1, 2);
		world.setBlock(i + 17, j + 9, k + 19, SpaceAgeCore.edenSurface.blockID, 1, 2);
		world.setBlock(i + 17, j + 10, k + 17, SpaceAgeCore.edenSurface.blockID, 1, 2);
		world.setBlock(i + 17, j + 10, k + 18, SpaceAgeCore.edenSurface.blockID, 1, 2);
		world.setBlock(i + 17, j + 10, k + 19, SpaceAgeCore.edenSurface.blockID, 1, 2);
		world.setBlock(i + 17, j + 11, k + 17, SpaceAgeCore.edenSurface.blockID, 1, 2);
		world.setBlock(i + 17, j + 11, k + 18, SpaceAgeCore.edenSurface.blockID, 1, 2);
		world.setBlock(i + 17, j + 11, k + 19, SpaceAgeCore.edenSurface.blockID, 1, 2);
		world.setBlock(i + 17, j + 12, k + 17, SpaceAgeCore.edenSurface.blockID, 1, 2);
		world.setBlock(i + 17, j + 12, k + 18, SpaceAgeCore.edenSurface.blockID, 1, 2);
		world.setBlock(i + 17, j + 12, k + 19, SpaceAgeCore.edenSurface.blockID, 1, 2);
		world.setBlock(i + 17, j + 13, k + 17, SpaceAgeCore.edenSurface.blockID, 1, 2);
		world.setBlock(i + 17, j + 13, k + 18, SpaceAgeCore.edenSurface.blockID, 1, 2);
		world.setBlock(i + 17, j + 13, k + 19, SpaceAgeCore.edenSurface.blockID, 1, 2);
		world.setBlock(i + 17, j + 14, k + 17, SpaceAgeCore.edenSurface.blockID, 1, 2);
		world.setBlock(i + 17, j + 14, k + 18, SpaceAgeCore.edenSurface.blockID, 1, 2);
		world.setBlock(i + 17, j + 14, k + 19, SpaceAgeCore.edenSurface.blockID, 1, 2);
		world.setBlock(i + 17, j + 15, k + 17, SpaceAgeCore.edenSurface.blockID, 1, 2);
		world.setBlock(i + 17, j + 15, k + 18, SpaceAgeCore.edenSurface.blockID, 1, 2);
		world.setBlock(i + 17, j + 15, k + 19, SpaceAgeCore.edenSurface.blockID, 1, 2);
		world.setBlock(i + 17, j + 16, k + 17, SpaceAgeCore.edenSurface.blockID, 1, 2);
		world.setBlock(i + 17, j + 16, k + 18, SpaceAgeCore.edenSurface.blockID, 1, 2);
		world.setBlock(i + 17, j + 16, k + 19, SpaceAgeCore.edenSurface.blockID, 1, 2);
		world.setBlock(i + 17, j + 17, k + 17, SpaceAgeCore.edenSurface.blockID, 1, 2);
		world.setBlock(i + 17, j + 17, k + 18, SpaceAgeCore.edenSurface.blockID, 1, 2);
		world.setBlock(i + 17, j + 17, k + 19, SpaceAgeCore.edenSurface.blockID, 1, 2);
		world.setBlock(i + 17, j + 18, k + 17, SpaceAgeCore.edenSurface.blockID, 1, 2);
		world.setBlock(i + 17, j + 18, k + 18, SpaceAgeCore.edenSurface.blockID, 1, 2);
		world.setBlock(i + 17, j + 18, k + 19, SpaceAgeCore.edenSurface.blockID, 1, 2);
		world.setBlock(i + 17, j + 19, k + 17, SpaceAgeCore.edenSurface.blockID, 1, 2);
		world.setBlock(i + 17, j + 19, k + 18, SpaceAgeCore.edenSurface.blockID, 1, 2);
		world.setBlock(i + 17, j + 19, k + 19, SpaceAgeCore.edenSurface.blockID, 1, 2);
		world.setBlock(i + 17, j + 20, k + 17, SpaceAgeCore.edenSurface.blockID, 1, 2);
		world.setBlock(i + 17, j + 20, k + 18, SpaceAgeCore.edenSurface.blockID, 1, 2);
		world.setBlock(i + 17, j + 20, k + 19, SpaceAgeCore.edenSurface.blockID, 1, 2);
		world.setBlock(i + 17, j + 21, k + 17, SpaceAgeCore.edenSurface.blockID, 1, 2);
		world.setBlock(i + 17, j + 21, k + 18, SpaceAgeCore.edenSurface.blockID, 1, 2);
		world.setBlock(i + 17, j + 21, k + 19, SpaceAgeCore.edenSurface.blockID, 1, 2);
		world.setBlock(i + 17, j + 22, k + 17, SpaceAgeCore.edenSurface.blockID, 1, 2);
		world.setBlock(i + 17, j + 22, k + 18, SpaceAgeCore.edenSurface.blockID, 1, 2);
		world.setBlock(i + 17, j + 22, k + 19, SpaceAgeCore.edenSurface.blockID, 1, 2);
		world.setBlock(i + 17, j + 23, k + 17, SpaceAgeCore.edenSurface.blockID, 1, 2);
		world.setBlock(i + 17, j + 23, k + 18, SpaceAgeCore.edenSurface.blockID, 1, 2);
		world.setBlock(i + 17, j + 23, k + 19, SpaceAgeCore.edenSurface.blockID, 1, 2);
		world.setBlock(i + 17, j + 24, k + 17, SpaceAgeCore.edenSurface.blockID, 1, 2);
		world.setBlock(i + 17, j + 24, k + 18, SpaceAgeCore.edenSurface.blockID, 1, 2);
		world.setBlock(i + 17, j + 24, k + 19, SpaceAgeCore.edenSurface.blockID, 1, 2);
		world.setBlock(i + 17, j + 25, k + 17, SpaceAgeCore.edenSurface.blockID, 1, 2);
		world.setBlock(i + 17, j + 25, k + 18, SpaceAgeCore.edenSurface.blockID, 1, 2);
		world.setBlock(i + 17, j + 25, k + 19, SpaceAgeCore.edenSurface.blockID, 1, 2);
		world.setBlock(i + 17, j + 26, k + 17, SpaceAgeCore.edenSurface.blockID, 1, 2);
		world.setBlock(i + 17, j + 26, k + 18, SpaceAgeCore.edenSurface.blockID, 1, 2);
		world.setBlock(i + 17, j + 26, k + 19, SpaceAgeCore.edenSurface.blockID, 1, 2);
		world.setBlock(i + 17, j + 27, k + 17, SpaceAgeCore.edenSurface.blockID, 1, 2);
		world.setBlock(i + 17, j + 27, k + 18, SpaceAgeCore.edenSurface.blockID, 1, 2);
		world.setBlock(i + 17, j + 27, k + 19, SpaceAgeCore.edenSurface.blockID, 1, 2);
		world.setBlock(i + 17, j + 28, k + 17, SpaceAgeCore.edenSurface.blockID, 1, 2);
		world.setBlock(i + 17, j + 28, k + 18, SpaceAgeCore.edenSurface.blockID, 1, 2);
		world.setBlock(i + 17, j + 28, k + 19, SpaceAgeCore.edenSurface.blockID, 1, 2);
		world.setBlock(i + 17, j + 29, k + 17, SpaceAgeCore.edenSurface.blockID, 1, 2);
		world.setBlock(i + 17, j + 29, k + 18, SpaceAgeCore.edenSurface.blockID, 1, 2);
		world.setBlock(i + 17, j + 29, k + 19, SpaceAgeCore.edenSurface.blockID, 1, 2);
		world.setBlock(i + 17, j + 30, k + 17, SpaceAgeCore.edenSurface.blockID, 1, 2);
		world.setBlock(i + 17, j + 30, k + 18, SpaceAgeCore.edenSurface.blockID, 1, 2);
		world.setBlock(i + 17, j + 30, k + 19, SpaceAgeCore.edenSurface.blockID, 1, 2);
		world.setBlock(i + 17, j + 31, k + 17, SpaceAgeCore.edenSurface.blockID, 1, 2);
		world.setBlock(i + 17, j + 31, k + 18, SpaceAgeCore.edenSurface.blockID, 1, 2);
		world.setBlock(i + 17, j + 31, k + 19, SpaceAgeCore.edenSurface.blockID, 1, 2);
		world.setBlock(i + 17, j + 32, k + 17, SpaceAgeCore.edenSurface.blockID, 1, 2);
		world.setBlock(i + 17, j + 32, k + 18, SpaceAgeCore.edenSurface.blockID, 1, 2);
		world.setBlock(i + 17, j + 32, k + 19, SpaceAgeCore.edenSurface.blockID, 1, 2);
		world.setBlock(i + 17, j + 33, k + 17, SpaceAgeCore.edenSurface.blockID, 1, 2);
		world.setBlock(i + 17, j + 33, k + 18, SpaceAgeCore.edenSurface.blockID, 1, 2);
		world.setBlock(i + 17, j + 33, k + 19, SpaceAgeCore.edenSurface.blockID, 1, 2);
		world.setBlock(i + 17, j + 34, k + 17, SpaceAgeCore.edenSurface.blockID, 1, 2);
		world.setBlock(i + 17, j + 34, k + 18, SpaceAgeCore.edenSurface.blockID, 1, 2);
		world.setBlock(i + 17, j + 34, k + 19, SpaceAgeCore.edenSurface.blockID, 1, 2);
		world.setBlock(i + 17, j + 35, k + 17, SpaceAgeCore.edenSurface.blockID, 1, 2);
		world.setBlock(i + 17, j + 35, k + 18, SpaceAgeCore.edenSurface.blockID, 1, 2);
		world.setBlock(i + 17, j + 35, k + 19, SpaceAgeCore.edenSurface.blockID, 1, 2);
		world.setBlock(i + 17, j + 36, k + 17, SpaceAgeCore.edenSurface.blockID, 1, 2);
		world.setBlock(i + 17, j + 36, k + 18, SpaceAgeCore.edenSurface.blockID, 1, 2);
		world.setBlock(i + 17, j + 36, k + 19, SpaceAgeCore.edenSurface.blockID, 1, 2);
		world.setBlock(i + 17, j + 37, k + 17, SpaceAgeCore.edenSurface.blockID, 1, 2);
		world.setBlock(i + 17, j + 37, k + 18, SpaceAgeCore.edenSurface.blockID, 1, 2);
		world.setBlock(i + 17, j + 37, k + 19, SpaceAgeCore.edenSurface.blockID, 1, 2);
		world.setBlock(i + 17, j + 38, k + 17, SpaceAgeCore.edenSurface.blockID, 1, 2);
		world.setBlock(i + 17, j + 38, k + 18, SpaceAgeCore.edenSurface.blockID, 1, 2);
		world.setBlock(i + 17, j + 38, k + 19, SpaceAgeCore.edenSurface.blockID, 1, 2);
		world.setBlock(i + 17, j + 39, k + 17, SpaceAgeCore.edenSurface.blockID, 1, 2);
		world.setBlock(i + 17, j + 39, k + 18, SpaceAgeCore.edenSurface.blockID, 1, 2);
		world.setBlock(i + 17, j + 39, k + 19, SpaceAgeCore.edenSurface.blockID, 1, 2);
		world.setBlock(i + 17, j + 40, k + 17, SpaceAgeCore.edenSurface.blockID, 1, 2);
		world.setBlock(i + 17, j + 40, k + 18, SpaceAgeCore.edenSurface.blockID, 1, 2);
		world.setBlock(i + 17, j + 40, k + 19, SpaceAgeCore.edenSurface.blockID, 1, 2);
		world.setBlock(i + 17, j + 41, k + 17, SpaceAgeCore.edenSurface.blockID, 1, 2);
		world.setBlock(i + 17, j + 41, k + 18, SpaceAgeCore.edenSurface.blockID, 1, 2);
		world.setBlock(i + 17, j + 41, k + 19, SpaceAgeCore.edenSurface.blockID, 1, 2);
		world.setBlock(i + 17, j + 42, k + 17, SpaceAgeCore.edenSurface.blockID, 1, 2);
		world.setBlock(i + 17, j + 42, k + 18, SpaceAgeCore.edenSurface.blockID, 1, 2);
		world.setBlock(i + 17, j + 42, k + 19, SpaceAgeCore.edenSurface.blockID, 1, 2);
		world.setBlock(i + 17, j + 43, k + 17, SpaceAgeCore.edenSurface.blockID, 1, 2);
		world.setBlock(i + 17, j + 43, k + 18, SpaceAgeCore.edenSurface.blockID, 1, 2);
		world.setBlock(i + 17, j + 43, k + 19, SpaceAgeCore.edenSurface.blockID, 1, 2);
		world.setBlock(i + 17, j + 44, k + 17, SpaceAgeCore.edenSurface.blockID, 1, 2);
		world.setBlock(i + 17, j + 44, k + 18, SpaceAgeCore.edenSurface.blockID, 1, 2);
		world.setBlock(i + 17, j + 44, k + 19, SpaceAgeCore.edenSurface.blockID, 1, 2);
		world.setBlock(i + 17, j + 45, k + 17, SpaceAgeCore.edenSurface.blockID, 1, 2);
		world.setBlock(i + 17, j + 45, k + 18, SpaceAgeCore.edenSurface.blockID, 1, 2);
		world.setBlock(i + 17, j + 45, k + 19, SpaceAgeCore.edenSurface.blockID, 1, 2);
		world.setBlock(i + 17, j + 46, k + 17, SpaceAgeCore.edenSurface.blockID, 1, 2);
		world.setBlock(i + 17, j + 46, k + 18, SpaceAgeCore.edenSurface.blockID, 1, 2);
		world.setBlock(i + 17, j + 46, k + 19, SpaceAgeCore.edenSurface.blockID, 1, 2);
		world.setBlock(i + 17, j + 47, k + 17, SpaceAgeCore.edenSurface.blockID, 1, 2);
		world.setBlock(i + 17, j + 47, k + 18, SpaceAgeCore.edenSurface.blockID, 1, 2);
		world.setBlock(i + 17, j + 47, k + 19, SpaceAgeCore.edenSurface.blockID, 1, 2);
		world.setBlock(i + 17, j + 48, k + 17, SpaceAgeCore.edenSurface.blockID, 1, 2);
		world.setBlock(i + 17, j + 48, k + 18, SpaceAgeCore.edenSurface.blockID, 1, 2);
		world.setBlock(i + 17, j + 48, k + 19, SpaceAgeCore.edenSurface.blockID, 1, 2);
		world.setBlock(i + 17, j + 49, k + 17, SpaceAgeCore.edenSurface.blockID, 1, 2);
		world.setBlock(i + 17, j + 49, k + 18, SpaceAgeCore.edenSurface.blockID, 1, 2);
		world.setBlock(i + 17, j + 49, k + 19, SpaceAgeCore.edenSurface.blockID, 1, 2);
